Workbook

Sheet Vu_khi
A1: id | B1: ten_that | C1: ho_id | D1: bien_the_id | E1: dong_vu_khi_id | F1: nhom | G1: co_mm | H1: dau_no_kg | I1: cong_suat_kw | J1: nang_luong_mj | K1: loai_sat_thuong | L1: xuyen | M1: dang_dan | N1: so_nong | O1: che_do_nong | P1: so_phat_moi_loat | Q1: khoang_phat_trong_loat_s | R1: thoi_gian_nap_s | S1: bang_dan | T1: nap_bang_s | U1: so_loat_mang | V1: nap_lai_kho_s | W1: sat_thuong_moi_phat | X1: loi_m | Y1: ria_m | Z1: toc_do_dan_m_s | AA1: tam_m | AB1: tam_toi_thieu_m | AC1: muc_tieu | AD1: tran_ban_m | AE1: do_tan | AF1: bac_no | AG1: danh_noc | AH1: bay_cong | AI1: nhiet_ap | AJ1: chi_danh_chan | AK1: dat_boi_boss | AL1: tia | AM1: dan_huong | AN1: kich_co | AO1: so_vien_mang_may_bay | AP1: bac_co | AQ1: ke_thua_tu | AR1: dan_thay_the | AS1: cua_ai | AT1: mang_boi | AU1: so_don_vi_mang | AV1: ten_be | AW1: thoi_gian_canh_bao_s | AX1: co_vong_canh_bao | AY1: lech_nong_s | AZ1: thoi_gian_bay_toi_tam_s | BA1: thoi_gian_bay_toi_tam_s_game | BB1: ngoai_doi_phat_phut_toi_da | BC1: ngoai_doi_phat_phut_duy_tri | BD1: ngoai_doi_loai | BE1: ngoai_doi_nguon | BF1: ly_do_sua | BG1: so_voi_ban_goc | BH1: sat_thuong_moi_phat_truoc | BI1: sat_thuong_moi_phat_sau | BJ1: thoi_gian_nap_s_truoc | BK1: thoi_gian_nap_s_sau | BL1: tam_m_truoc | BM1: tam_m_sau | BN1: loi_m_truoc | BO1: loi_m_sau | BP1: ria_m_truoc | BQ1: ria_m_sau | BR1: toc_do_dan_m_s_truoc | BS1: toc_do_dan_m_s_sau | BT1: so_phat_moi_loat_truoc | BU1: so_phat_moi_loat_sau | BV1: khoang_phat_trong_loat_s_truoc | BW1: khoang_phat_trong_loat_s_sau | BX1: so_nong_truoc | BY1: so_nong_sau | BZ1: che_do_nong_truoc | CA1: che_do_nong_sau | CB1: xuyen_truoc | CC1: xuyen_sau | CD1: loai_sat_thuong_truoc | CE1: loai_sat_thuong_sau | CF1: bang_dan_truoc | CG1: bang_dan_sau | CH1: nap_bang_s_truoc | CI1: nap_bang_s_sau | CJ1: dang_dan_truoc | CK1: dang_dan_sau | CL1: muc_tieu_truoc | CM1: muc_tieu_sau | CN1: ammo | CO1: barrels | CP1: beam | CQ1: bonuses | CR1: burst | CS1: burst_interval_s | CT1: caliber_mm | CU1: ceiling_m | CV1: charge | CW1: clip | CX1: clip_reload_s | CY1: cluster_count | CZ1: cluster_damage | DA1: cluster_radius_m | DB1: cluster_splash_m | DC1: cluster_tier | DD1: cooldown_s | DE1: damage | DF1: damage_type | DG1: edge_m | DH1: elite | DI1: energy_mj | DJ1: family | DK1: flare_resist | DL1: flight_profile | DM1: for | DN1: form | DO1: ground_min_reach_m | DP1: guided | DQ1: he | DR1: impact_scale | DS1: impact_tier | DT1: inherits | DU1: intercept_only | DV1: laid | DW1: load | DX1: lobs | DY1: melee | DZ1: min_range_m | EA1: mrsi | EB1: pen | EC1: pierce | ED1: pierce_max | EE1: piercing | EF1: power_kw | EG1: prey | EH1: projectile | EI1: projectile_model | EJ1: projectile_scale | EK1: projectile_speed_m_s | EL1: ramp_from | EM1: ramp_grace_s | EN1: ramp_seconds_s | EO1: ramp_to | EP1: range_m | EQ1: real | ER1: reload_s | ES1: round | ET1: round_length | EU1: round_of | EV1: round_weight | EW1: salvo_mode | EX1: size | EY1: splash_m | EZ1: spread | FA1: stick_anchor | FB1: stick_bay_open_s | FC1: stick_bombs | FD1: stick_drop | FE1: stick_exit_m | FF1: stick_fall_time_s | FG1: stick_heading_deg | FH1: stick_interval_s | FI1: stick_jitter_across_m | FJ1: stick_jitter_along_m | FK1: stick_lead_m | FL1: stick_length_m | FM1: stick_min_targets | FN1: stick_mode | FO1: stick_overlap | FP1: stick_release_speed_m_s | FQ1: stick_safety_m | FR1: stick_spacing_m | FS1: stick_straight_time_s | FT1: stick_warn_shape | FU1: stick_width_m | FV1: swarm | FW1: targets | FX1: thermobaric | FY1: top_attack | FZ1: warhead_kg | GA1: weapon_family | GB1: weapon_family_id | GC1: weapon_variant_id | GD1: nguon | GE1: raw_json
A2: aa_25_triple | B2: Type 96 25 mm (triple) | C2: cal_25 | D2: flak | F2: autocannon | G2: 25 | K2: Fragmentation | L2: 1 | M2: Bullet | N2: 1 | O2: RIPPLE | P2: 1 | Q2: 0.1 | R2: 0.05 | S2: 15 | T2: 2.4 | U2: 0 | V2: 0 | W2: 17 | X2: 0 | Y2: 0 | Z2: 240 | AA2: 42 | AB2: 0 | AC2: Air | AE2: 1.6 | AF2: Small | AG2: FALSE | AH2: FALSE | AI2: FALSE | AJ2: FALSE | AK2: FALSE | AL2: FALSE | AM2: FALSE | AN2: 25 | AO2: 0 | AP2: T1 | AQ2: zu23 | AR2: aa_25_triple_ap | AS2: boss | AT2: kraken;leviathan | AU2: 2 | AV2: kraken:10;kraken:11;kraken:12;kraken:13;kraken:14;kraken:7;kraken:8;kraken:9;leviathan:10;leviathan:11;leviathan:12;leviathan:13;leviathan:14;leviathan:7;leviathan:8;leviathan:9 | AW2: 0 | AX2: FALSE | AZ2: =IF(AND($AX$2,$AW$2>$AA$2/$Z$2),$AW$2,$AA$2/$Z$2) | BA2: 0.175 | BB2: 260 | BC2: 130 | BD2: aa | BE2: Wikipedia 'Type 96 25 mm AT/AA gun': 220-260 rpm a barrel | BG2: giong | CO2: 1 | CT2: 25 | CW2: 15 | CX2: 2.4 | DD2: 0.05 | DE2: 17 | DJ2: autocannon | DT2: zu23 | EB2: 1 | EP2: 42 | EQ2: Type 96 25 mm (triple) | EX2: 25 | FW2: Air | GB2: cal_25 | GC2: flak | GD2: Assets/MachineBrigade/Resources/Data/balance.json: weapons[290] | GE2: {"id":"aa_25_triple","inherits":"zu23","barrels":1,"weaponFamilyId":"cal_25","weaponVariantId":"flak","real":"Type 96 25 mm (triple)","family":"autocannon","size":25,"caliberMm":25,"pen":1,"damage":17,"cooldown":0.05,"range":42,"targets":"Air","clip":15,"clipReload":2.4}
A3: aa_25_triple_ap | B3: Type 96 25 mm AP (triple) | C3: cal_25 | F3: autocannon | G3: 25 | K3: Kinetic | L3: 2 | M3: Bullet | N3: 1 | O3: RIPPLE | P3: 1 | Q3: 0.1 | R3: 0.05 | S3: 15 | T3: 2.4 | U3: 0 | V3: 0 | W3: 17 | X3: 0 | Y3: 0 | Z3: 240 | AA3: 42 | AB3: 0 | AC3: Ground | AE3: 1.6 | AF3: Small | AG3: FALSE | AH3: FALSE | AI3: FALSE | AJ3: FALSE | AK3: FALSE | AL3: FALSE | AM3: FALSE | AN3: 25 | AO3: 0 | AP3: T1 | AQ3: aa_25_triple | AU3: 0 | AW3: 0 | AX3: FALSE | AZ3: =IF(AND($AX$3,$AW$3>$AA$3/$Z$3),$AW$3,$AA$3/$Z$3) | BA3: 0.175 | BB3: 260 | BC3: 130 | BD3: aa | BE3: Wikipedia 'Type 96 25 mm AT/AA gun': 220-260 rpm a barrel | BG3: giong | DE3: 17 | DF3: Kinetic | DM3: ground | DN3: BeltedAutocannon | DT3: aa_25_triple | EB3: 2 | EE3: TRUE | EQ3: Type 96 25 mm AP (triple) | ES3: ap | EU3: aa_25_triple | EY3: 0 | FW3: Ground | GD3: Assets/MachineBrigade/Resources/Data/balance.json: secondRounds.rounds[0] | GE3: {"id":"aa_25_triple_ap","roundOf":"aa_25_triple","inherits":"aa_25_triple","weaponVariantId":"","weaponFamily":"","round":"ap","for":["ground"],"real":"Type 96 25 mm AP (triple)","damageType":"Kinetic","pen":2,"damage":17,"splash":0,"form":"BeltedAutocannon","piercing":true,"targets":"Ground"}
A4: agl_40 | B4: Mk 19 40 mm | C4: gl_40 | E4: mk_19_40_mm | F4: grenade | G4: 40 | K4: HighExplosive | L4: 2 | M4: Bullet | N4: 1 | O4: RIPPLE | P4: 6 | Q4: 0.2 | R4: 3.2 | S4: 0 | T4: 0 | U4: 0 | V4: 0 | W4: 26 | X4: 2 | Y4: 0 | Z4: 70 | AA4: 30 | AB4: 0 | AC4: Ground | AE4: 2.2 | AF4: Small | AG4: FALSE | AH4: FALSE | AI4: FALSE | AJ4: FALSE | AK4: FALSE | AL4: FALSE | AM4: FALSE | AN4: 40 | AO4: 0 | AP4: T1 | AS4: xe | AT4: river_patrol_boat;twin_rotor_gunship | AU4: 2 | AV4: river_patrol_boat:1;twin_rotor_gunship:1 | AW4: 0 | AX4: FALSE | AZ4: =IF(AND($AX$4,$AW$4>$AA$4/$Z$4),$AW$4,$AA$4/$Z$4) | BA4: 0.42857143 | BB4: 375 | BC4: 60 | BD4: ac | BE4: US Army FM 3-22.27: 325-375 cyclic, 60 rapid | BG4: giong | CR4: 6 | CS4: 0.2 | CT4: 40 | DD4: 3.2 | DE4: 26 | DF4: HighExplosive | DJ4: grenade | DS4: Small | EB4: 2 | EH4: Bullet | EP4: 30 | EQ4: Mk 19 40 mm | EX4: 40 | EZ4: 2.2 | GA4: mk_19_40_mm | GB4: gl_40 | GD4: Assets/MachineBrigade/Resources/Data/balance.json: weapons[234] | GE4: {"id":"agl_40","weaponFamilyId":"gl_40","weaponFamily":"mk_19_40_mm","real":"Mk 19 40 mm","family":"grenade","size":40,"caliberMm":40,"pen":2,"damageType":"HighExplosive","damage":26,"cooldown":3.2,"range":30,"spread":2.2,"impactTier":"Small","projectile":"Bullet","burst":6,"burstInterval":0.2}
A5: air_cruise_missile | B5: Kh-101 (400 kg) | C5: cruise_kh_101 | F5: cruise | H5: 400 | K5: HighExplosive | L5: 3 | M5: Missile | N5: 1 | O5: RIPPLE | P5: 1 | Q5: 0.1 | R5: 11.2 | S5: 0 | T5: 0 | U5: 0 | V5: 0 | W5: 378 | X5: 9 | Y5: 0 | Z5: 65 | AA5: 110 | AB5: 0 | AC5: Ground | AE5: 0 | AF5: Huge | AG5: FALSE | AH5: FALSE | AI5: FALSE | AJ5: FALSE | AK5: FALSE | AL5: FALSE | AM5: FALSE | AN5: 400 | AO5: 2 | AP5: T4 | AS5: xe | AT5: heavy_bomber | AU5: 1 | AV5: heavy_bomber:2 | AW5: 2.5 | AX5: FALSE | AZ5: =IF(AND($AX$5,$AW$5>$AA$5/$Z$5),$AW$5,$AA$5/$Z$5) | BA5: 1.6923077 | BB5: 20 | BC5: 6 | BD5: missile | BE5: cruise missiles: ~3 s between launches (est.) | BG5: doi | BR5: 22 | BS5: 65 | DD5: 11.2 | DE5: 378 | DF5: HighExplosive | DJ5: cruise | DS5: Huge | DW5: 2 | EB5: 3 | EH5: Missile | EI5: cruise_missile | EK5: 65 | EP5: 110 | EQ5: Kh-101 (400 kg) | EV5: 450 | EX5: 400 | EY5: 9 | FZ5: 400 | GB5: cruise_kh_101 | GD5: Assets/MachineBrigade/Resources/Data/balance.json: weapons[68] | GE5: {"id":"air_cruise_missile","weaponFamilyId":"cruise_kh_101","load":2,"real":"Kh-101 (400 kg)","family":"cruise","size":400,"warheadKg":400,"pen":3,"projectileModel":"cruise_missile","damageType":"HighExplosive","damage":378,"cooldown":11.2,"range":110,"projectileSpeed":65,"splash":9,"impactTier":"Huge","projectile":"Missile","roundWeight":450}
A6: air_to_air | B6: AIM-120 AMRAAM | C6: sam_aim_120_amraam | F6: aa_missile | H6: 20 | K6: Fragmentation | L6: 3 | M6: Missile | N6: 1 | O6: RIPPLE | P6: 1 | Q6: 0.1 | R6: 3.99 | S6: 0 | T6: 0 | U6: 0 | V6: 0 | W6: 294 | X6: 2 | Y6: 0 | Z6: 300 | AA6: 60 | AB6: 0 | AC6: Air | AD6: high | AE6: 0 | AF6: Medium | AG6: FALSE | AH6: FALSE | AI6: FALSE | AJ6: FALSE | AK6: FALSE | AL6: FALSE | AM6: FALSE | AN6: 20 | AO6: 4 | AP6: T2 | AS6: xe | AT6: fighter_jet;stealth_fighter | AU6: 2 | AV6: fighter_jet:0;stealth_fighter:0 | AW6: 0 | AX6: FALSE | AZ6: =IF(AND($AX$6,$AW$6>$AA$6/$Z$6),$AW$6,$AA$6/$Z$6) | BA6: 0.2 | BB6: 60 | BD6: missile | BE6: air-to-air: ~1 s between launches (est.) | BG6: doi | BR6: 60 | BS6: 300 | CU6: high | DD6: 3.99 | DE6: 294 | DF6: Fragmentation | DJ6: aa_missile | DS6: Medium | DW6: 4 | EB6: 3 | EH6: Missile | EI6: aim120 | EJ6: 0.85 | EK6: 300 | EP6: 60 | EQ6: AIM-120 AMRAAM | EV6: 351 | EX6: 20 | EY6: 2 | FW6: Air | FZ6: 20 | GB6: sam_aim_120_amraam | GD6: Assets/MachineBrigade/Resources/Data/balance.json: weapons[62] | GE6: {"id":"air_to_air","weaponFamilyId":"sam_aim_120_amraam","ceiling":"high","load":4,"real":"AIM-120 AMRAAM","family":"aa_missile","size":20,"warheadKg":20,"pen":3,"projectileModel":"aim120","projectileScale":0.85,"damageType":"Fragmentation","damage":294,"cooldown":3.99,"range":60,"projectileSpeed":300,"splash":2,"impactTier":"Medium","projectile":"Missile","targets":"Air","roundWeight":351}
A7: airship_drones | B7: FPV drone (1.5 kg) | C7: drone_fpv_drone | E7: fpv_drone | F7: drone | H7: 1.5 | K7: ShapedCharge | L7: 3 | M7: Drone | N7: 1 | O7: RIPPLE | P7: 3 | Q7: 0.35 | R7: 8.35 | S7: 0 | T7: 0 | U7: 0 | V7: 0 | W7: 140 | X7: 2.5 | Y7: 0 | Z7: 26 | AA7: 70 | AB7: 0 | AC7: Ground | AE7: 0 | AF7: Large | AG7: TRUE | AH7: FALSE | AI7: FALSE | AJ7: FALSE | AK7: FALSE | AL7: FALSE | AM7: FALSE | AN7: 1.5 | AO7: 0 | AP7: T2 | AU7: 0 | AW7: 0 | AX7: FALSE | AZ7: =IF(AND($AX$7,$AW$7>$AA$7/$Z$7),$AW$7,$AA$7/$Z$7) | BA7: 2.6923077 | BB7: NEED_SOURCE | BC7: NEED_SOURCE | BE7: NEED_SOURCE | BG7: giong | CR7: 3 | CS7: 0.35 | DD7: 8.35 | DE7: 140 | DF7: ShapedCharge | DJ7: drone | DS7: Large | EB7: 3 | EE7: TRUE | EH7: Drone | EP7: 70 | EQ7: FPV drone (1.5 kg) | EX7: 1.5 | FY7: TRUE | FZ7: 1.5 | GA7: fpv_drone | GB7: drone_fpv_drone | GD7: Assets/MachineBrigade/Resources/Data/balance.json: weapons[246] | GE7: {"id":"airship_drones","weaponFamilyId":"drone_fpv_drone","weaponFamily":"fpv_drone","real":"FPV drone (1.5 kg)","family":"drone","size":1.5,"warheadKg":1.5,"pen":3,"topAttack":true,"piercing":true,"damageType":"ShapedCharge","damage":140,"cooldown":8.35,"range":70,"impactTier":"Large","projectile":"Drone","burst":3,"burstInterval":0.35}
A8: airship_flak | B8: S-60 57 mm | C8: cal_57 | D8: flak | F8: autocannon | G8: 57 | K8: Fragmentation | L8: 2 | M8: Bullet | N8: 1 | O8: RIPPLE | P8: 1 | Q8: 0.1 | R8: 0.5 | S8: 8 | T8: 1.38 | U8: 0 | V8: 0 | W8: 70 | X8: 3 | Y8: 0 | Z8: 280 | AA8: 48 | AB8: 0 | AC8: All | AE8: 1.4 | AF8: Medium | AG8: FALSE | AH8: FALSE | AI8: FALSE | AJ8: FALSE | AK8: FALSE | AL8: FALSE | AM8: FALSE | AN8: 57 | AO8: 0 | AP8: T2 | AU8: 0 | AW8: 0 | AX8: FALSE | AZ8: =IF(AND($AX$8,$AW$8>$AA$8/$Z$8),$AW$8,$AA$8/$Z$8) | BA8: 0.17142857 | BB8: 120 | BC8: 70 | BD8: aa | BE8: Wikipedia 'AZP S-60': 105-120 cyclic, 70 practical | BG8: giong | CT8: 57 | CW8: 8 | CX8: 1.38 | DD8: 0.5 | DE8: 70 | DF8: Fragmentation | DJ8: autocannon | DS8: Medium | EB8: 2 | EH8: Bullet | EK8: 280 | EP8: 48 | EQ8: S-60 57 mm | EX8: 57 | EY8: 3 | EZ8: 1.4 | FW8: All | GB8: cal_57 | GC8: flak | GD8: Assets/MachineBrigade/Resources/Data/balance.json: weapons[245] | GE8: {"id":"airship_flak","weaponFamilyId":"cal_57","weaponVariantId":"flak","real":"S-60 57 mm","family":"autocannon","size":57,"caliberMm":57,"pen":2,"damageType":"Fragmentation","damage":70,"cooldown":0.5,"range":48,"projectileSpeed":280,"splash":3,"spread":1.4,"impactTier":"Medium","projectile":"Bullet","targets":"All","clip":8,"clipReload":1.38}
A9: amos_120 | B9: 120 mm AMOS (twin) | C9: cal_120_he | D9: mortar | F9: mortar | G9: 120 | K9: HighExplosive | L9: 2 | M9: Shell | N9: 1 | O9: RIPPLE | P9: 4 | Q9: 0.25 | R9: 14.607 | S9: 0 | T9: 0 | U9: 0 | V9: 0 | W9: 214 | X9: 5 | Y9: 0 | Z9: 60 | AA9: 60 | AB9: 10 | AC9: Ground | AE9: 4.5 | AF9: Large | AG9: FALSE | AH9: FALSE | AI9: FALSE | AJ9: FALSE | AK9: FALSE | AL9: FALSE | AM9: FALSE | AN9: 120 | AO9: 0 | AP9: T3 | AS9: xe | AT9: sp_mortar | AU9: 1 | AV9: sp_mortar:0 | AW9: 0 | AX9: FALSE | AZ9: =IF(AND($AX$9,$AW$9>$AA$9/$Z$9),$AW$9,$AA$9/$Z$9) | BA9: 1 | BB9: 13 | BC9: 10 | BD9: gun | BE9: Wikipedia 'AMOS': 26 rpm the twin-barrel turret | BG9: doi | BH9: 150 | BI9: 214 | BJ9: 10 | BK9: 14.607 | BR9: 32 | BS9: 60 | CR9: 4 | CS9: 0.25 | CT9: 120 | DD9: 14.607 | DE9: 214 | DF9: HighExplosive | DJ9: mortar | DS9: Large | DZ9: 10 | EA9: TRUE | EB9: 2 | EI9: mortar_bomb | EK9: 60 | EP9: 60 | EQ9: 120 mm AMOS (twin) | EX9: 120 | EY9: 5 | EZ9: 4.5 | GB9: cal_120_he | GC9: mortar | GD9: Assets/MachineBrigade/Resources/Data/balance.json: weapons[281] | GE9: {"id":"amos_120","weaponFamilyId":"cal_120_he","weaponVariantId":"mortar","real":"120 mm AMOS (twin)","family":"mortar","size":120,"caliberMm":120,"pen":2,"damageType":"HighExplosive","damage":214,"burst":4,"burstInterval":0.25,"cooldown":14.607,"range":60,"minRange":10,"projectileSpeed":60,"splash":5,"spread":4.5,"impactTier":"Large","projectileModel":"mortar_bomb","mrsi":true}
A10: anti_ship_missile | B10: NSM / P-800 Oniks | C10: msl_nsm_p_800_oniks | E10: nsm_oniks | F10: missile | H10: 250 | K10: HighExplosive | L10: 4 | M10: Missile | N10: 1 | O10: RIPPLE | P10: 1 | Q10: 0.1 | R10: 30 | S10: 0 | T10: 0 | U10: 0 | V10: 0 | W10: 450 | X10: 7 | Y10: 0 | Z10: 225 | AA10: 140 | AB10: 0 | AC10: Ground | AE10: 0 | AF10: Huge | AG10: FALSE | AH10: FALSE | AI10: FALSE | AJ10: FALSE | AK10: FALSE | AL10: FALSE | AM10: FALSE | AN10: 680 | AO10: 0 | AP10: T4 | AU10: 0 | AW10: 2.5 | AX10: FALSE | AZ10: =IF(AND($AX$10,$AW$10>$AA$10/$Z$10),$AW$10,$AA$10/$Z$10) | BA10: 0.62222222 | BB10: 20 | BC10: 6 | BD10: missile | BE10: cruise missiles: ~3 s between launches (est.) | BG10: doi | BR10: 30 | BS10: 225 | DD10: 30 | DE10: 450 | DF10: HighExplosive | DJ10: missile | DS10: Huge | EB10: 4 | EH10: Missile | EI10: nsm_oniks | EK10: 30 | EP10: 140 | EQ10: NSM / P-800 Oniks | ET10: 3.17 | EX10: 680 | EY10: 7 | FZ10: 250 | GA10: nsm_oniks | GB10: msl_nsm_p_800_oniks | GD10: Assets/MachineBrigade/Resources/Data/balance.json: weapons[292] | GE10: {"id":"anti_ship_missile","weaponFamilyId":"msl_nsm_p_800_oniks","real":"NSM / P-800 Oniks","weaponFamily":"nsm_oniks","family":"missile","size":680,"warheadKg":250,"pen":4,"damageType":"HighExplosive","damage":450,"cooldown":30,"range":140,"projectileSpeed":30,"splash":7,"impactTier":"Huge","projectile":"Missile","projectileModel":"nsm_oniks","roundLength":3.17}
A11: apkws_rocket | B11: APKWS (laser-guided Hydra 70) | C11: rkt_70_80 | D11: guided | E11: apkws | F11: rocket | G11: 70 | K11: ShapedCharge | L11: 2 | M11: Rocket | N11: 1 | O11: RIPPLE | P11: 1 | Q11: 0.1 | R11: 1 | S11: 0 | T11: 0 | U11: 0 | V11: 0 | W11: 90 | X11: 2 | Y11: 0 | Z11: 180 | AA11: 40 | AB11: 0 | AC11: All | AE11: 0 | AF11: Medium | AG11: FALSE | AH11: FALSE | AI11: FALSE | AJ11: FALSE | AK11: FALSE | AL11: FALSE | AM11: FALSE | AN11: 70 | AO11: 0 | AP11: T2 | AS11: xe | AT11: attack_helicopter | AU11: 1 | AV11: attack_helicopter:4 | AW11: 0 | AX11: FALSE | AZ11: =IF(AND($AX$11,$AW$11>$AA$11/$Z$11),$AW$11,$AA$11/$Z$11) | BA11: 0.22222222 | BB11: 900 | BD11: rocket | BE11: rocket pods: ripples of 0.05-0.12 s (DECISIONS 19R) | BG11: doi | BR11: 45 | BS11: 180 | CT11: 70 | DD11: 1 | DE11: 90 | DF11: ShapedCharge | DJ11: rocket | DS11: Medium | EB11: 2 | EH11: Rocket | EI11: apkws | EK11: 45 | EP11: 40 | EQ11: APKWS (laser-guided Hydra 70) | ET11: 0.8 | EX11: 70 | EY11: 2 | FW11: All | GA11: apkws | GB11: rkt_70_80 | GC11: guided | GD11: Assets/MachineBrigade/Resources/Data/balance.json: weapons[291] | GE11: {"id":"apkws_rocket","weaponFamilyId":"rkt_70_80","weaponVariantId":"guided","real":"APKWS (laser-guided Hydra 70)","weaponFamily":"apkws","family":"rocket","size":70,"caliberMm":70,"pen":2,"damageType":"ShapedCharge","damage":90,"cooldown":1,"range":40,"projectileSpeed":45,"splash":2,"impactTier":"Medium","projectile":"Rocket","projectileModel":"apkws","roundLength":0.8,"targets":"All"}
A12: atgm | B12: BGM-71 TOW-2 | C12: atgm_bgm_71_tow_2 | F12: atgm | H12: 5.9 | K12: ShapedCharge | L12: 4 | M12: Missile | N12: 1 | O12: RIPPLE | P12: 1 | Q12: 0.1 | R12: 12.33 | S12: 0 | T12: 0 | U12: 0 | V12: 0 | W12: 190 | X12: 0 | Y12: 0 | Z12: 80 | AA12: 40 | AB12: 0 | AC12: Ground | AE12: 0 | AF12: Medium | AG12: FALSE | AH12: FALSE | AI12: FALSE | AJ12: FALSE | AK12: FALSE | AL12: FALSE | AM12: FALSE | AN12: 22.6 | AO12: 0 | AP12: T2 | AS12: xe | AT12: elite_apc;ifv;titan_tank | AU12: 3 | AV12: elite_apc:2;ifv:2;titan_tank:3 | AW12: 0 | AX12: FALSE | AZ12: =IF(AND($AX$12,$AW$12>$AA$12/$Z$12),$AW$12,$AA$12/$Z$12) | BA12: 0.5 | BB12: 3 | BC12: 2 | BD12: atgm | BE12: Wikipedia 'BGM-71 TOW': ~3 rpm | BG12: doi | BR12: 20 | BS12: 80 | DD12: 12.33 | DE12: 190 | DF12: ShapedCharge | DJ12: atgm | DS12: Medium | EB12: 4 | EE12: TRUE | EH12: Missile | EI12: atgm_tow | EJ12: 0.8 | EK12: 80 | EP12: 40 | EQ12: BGM-71 TOW-2 | EX12: 22.6 | FZ12: 5.9 | GB12: atgm_bgm_71_tow_2 | GD12: Assets/MachineBrigade/Resources/Data/balance.json: weapons[13] | GE12: {"id":"atgm","weaponFamilyId":"atgm_bgm_71_tow_2","real":"BGM-71 TOW-2","family":"atgm","size":22.6,"warheadKg":5.9,"pen":4,"piercing":true,"projectileModel":"atgm_tow","projectileScale":0.8,"damageType":"ShapedCharge","damage":190,"cooldown":12.33,"range":40,"projectileSpeed":80,"impactTier":"Medium","projectile":"Missile"}
A13: atgm_heavy | B13: 9M133 Kornet | C13: atgm_kornet | E13: 9m133_kornet | F13: atgm | H13: 7 | K13: ShapedCharge | L13: 4 | M13: Missile | N13: 1 | O13: RIPPLE | P13: 2 | Q13: 0.7 | R13: 6.8 | S13: 0 | T13: 0 | U13: 0 | V13: 0 | W13: 230 | X13: 0 | Y13: 0 | Z13: 80 | AA13: 42 | AB13: 0 | AC13: Ground | AE13: 0 | AF13: Medium | AG13: FALSE | AH13: FALSE | AI13: FALSE | AJ13: FALSE | AK13: FALSE | AL13: FALSE | AM13: FALSE | AN13: 29 | AO13: 0 | AP13: T2 | AU13: 0 | AW13: 0 | AX13: FALSE | AZ13: =IF(AND($AX$13,$AW$13>$AA$13/$Z$13),$AW$13,$AA$13/$Z$13) | BA13: 0.525 | BB13: 3 | BC13: 3 | BD13: atgm | BE13: Wikipedia '9M133 Kornet': 2-3 rpm | BG13: doi | BR13: 22 | BS13: 80 | CR13: 2 | CS13: 0.7 | DD13: 6.8 | DE13: 230 | DF13: ShapedCharge | DJ13: atgm | DS13: Medium | EB13: 4 | EE13: TRUE | EH13: Missile | EP13: 42 | EQ13: 9M133 Kornet | EX13: 29 | FZ13: 7 | GA13: 9m133_kornet | GB13: atgm_kornet | GD13: Assets/MachineBrigade/Resources/Data/balance.json: weapons[34] | GE13: {"id":"atgm_heavy","weaponFamilyId":"atgm_kornet","weaponFamily":"9m133_kornet","real":"9M133 Kornet","family":"atgm","size":29,"warheadKg":7,"pen":4,"piercing":true,"damageType":"ShapedCharge","damage":230,"cooldown":6.8,"range":42,"impactTier":"Medium","projectile":"Missile","burst":2,"burstInterval":0.7}
A14: atgm_post | B14: 9M113 Konkurs | C14: atgm_9m113_konkurs | F14: atgm | H14: 2.7 | K14: ShapedCharge | L14: 3 | M14: Missile | N14: 1 | O14: RIPPLE | P14: 1 | Q14: 0.1 | R14: 12.1 | S14: 0 | T14: 0 | U14: 0 | V14: 0 | W14: 190 | X14: 0 | Y14: 0 | Z14: 60 | AA14: 34 | AB14: 0 | AC14: Ground | AE14: 0 | AF14: Medium | AG14: FALSE | AH14: FALSE | AI14: FALSE | AJ14: FALSE | AK14: FALSE | AL14: FALSE | AM14: FALSE | AN14: 25 | AO14: 0 | AP14: T2 | AU14: 0 | AW14: 0 | AX14: FALSE | AZ14: =IF(AND($AX$14,$AW$14>$AA$14/$Z$14),$AW$14,$AA$14/$Z$14) | BA14: 0.56666667 | BB14: 3 | BC14: 2 | BD14: atgm | BE14: Wikipedia '9M113 Konkurs': 2-3 rpm | BG14: doi | BR14: 19 | BS14: 60 | DD14: 12.1 | DE14: 190 | DF14: ShapedCharge | DJ14: atgm | DS14: Medium | EB14: 3 | EE14: TRUE | EH14: Missile | EI14: atgm_kornet | EK14: 60 | EP14: 34 | EQ14: 9M113 Konkurs | EX14: 25 | FZ14: 2.7 | GB14: atgm_9m113_konkurs | GD14: Assets/MachineBrigade/Resources/Data/balance.json: weapons[237] | GE14: {"id":"atgm_post","weaponFamilyId":"atgm_9m113_konkurs","real":"9M113 Konkurs","family":"atgm","size":25,"warheadKg":2.7,"pen":3,"piercing":true,"projectileModel":"atgm_kornet","damageType":"ShapedCharge","damage":190,"cooldown":12.1,"range":34,"projectileSpeed":60,"impactTier":"Medium","projectile":"Missile"}
A15: autocannon_25 | B15: M242 Bushmaster 25 mm | C15: cal_25 | E15: m242_bushmaster_25_mm | F15: autocannon | G15: 25 | K15: Kinetic | L15: 2 | M15: Bullet | N15: 1 | O15: RIPPLE | P15: 8 | Q15: 0.1667 | R15: 1.4667 | S15: 0 | T15: 0 | U15: 0 | V15: 0 | W15: 17 | X15: 0 | Y15: 0 | Z15: 210 | AA15: 30 | AB15: 0 | AC15: Ground | AE15: 0.9 | AF15: Small | AG15: FALSE | AH15: FALSE | AI15: FALSE | AJ15: FALSE | AK15: FALSE | AL15: FALSE | AM15: FALSE | AN15: 25 | AO15: 0 | AP15: T1 | AR15: autocannon_25_flak | AS15: thap;xe | AT15: armored_car;guard_tower.nest | AU15: 2 | AV15: armored_car:0;guard_tower.nest:other | AW15: 0 | AX15: FALSE | AZ15: =IF(AND($AX$15,$AW$15>$AA$15/$Z$15),$AW$15,$AA$15/$Z$15) | BA15: 0.14285714 | BB15: 500 | BC15: 200 | BD15: ac | BE15: Wikipedia 'M242 Bushmaster': 200 or 500 rpm | BG15: giong | CR15: 8 | CS15: 0.1667 | CT15: 25 | DD15: 1.4667 | DE15: 17 | DF15: Kinetic | DJ15: autocannon | DS15: Small | EB15: 2 | EH15: Bullet | EP15: 30 | EQ15: M242 Bushmaster 25 mm | EV15: 22 | EX15: 25 | EZ15: 0.9 | FW15: Ground | GA15: m242_bushmaster_25_mm | GB15: cal_25 | GD15: Assets/MachineBrigade/Resources/Data/balance.json: weapons[25] | GE15: {"id":"autocannon_25","weaponFamilyId":"cal_25","weaponFamily":"m242_bushmaster_25_mm","burstInterval":0.1667,"burst":8,"real":"M242 Bushmaster 25 mm","family":"autocannon","size":25,"caliberMm":25,"pen":2,"damageType":"Kinetic","damage":17,"cooldown":1.4667,"range":30,"spread":0.9,"impactTier":"Small","projectile":"Bullet","targets":"Ground","roundWeight":22}
A16: autocannon_25_flak | B16: M242 Bushmaster 25 mm air-burst | C16: cal_25 | D16: flak | E16: m242_bushmaster_25_mm_air_burst | F16: autocannon | G16: 25 | K16: Fragmentation | L16: 1 | M16: Bullet | N16: 1 | O16: RIPPLE | P16: 8 | Q16: 0.1667 | R16: 1.4667 | S16: 0 | T16: 0 | U16: 0 | V16: 0 | W16: 17 | X16: 2 | Y16: 0 | Z16: 210 | AA16: 30 | AB16: 0 | AC16: Air | AE16: 0.9 | AF16: Small | AG16: FALSE | AH16: FALSE | AI16: FALSE | AJ16: FALSE | AK16: FALSE | AL16: FALSE | AM16: FALSE | AN16: 25 | AO16: 0 | AP16: T1 | AQ16: autocannon_25 | AU16: 0 | AW16: 0 | AX16: FALSE | AZ16: =IF(AND($AX$16,$AW$16>$AA$16/$Z$16),$AW$16,$AA$16/$Z$16) | BA16: 0.14285714 | BB16: 500 | BC16: 200 | BD16: ac | BE16: Wikipedia 'M242 Bushmaster': 200 or 500 rpm | BG16: giong | DE16: 17 | DF16: Fragmentation | DM16: air | DN16: Airburst | DT16: autocannon_25 | EB16: 1 | EE16: FALSE | EQ16: M242 Bushmaster 25 mm air-burst | ES16: flak | EU16: autocannon_25 | EY16: 2 | FW16: Air | GA16: m242_bushmaster_25_mm_air_burst | GC16: flak | GD16: Assets/MachineBrigade/Resources/Data/balance.json: secondRounds.rounds[1] | GE16: {"id":"autocannon_25_flak","roundOf":"autocannon_25","inherits":"autocannon_25","weaponVariantId":"flak","weaponFamily":"m242_bushmaster_25_mm_air_burst","round":"flak","for":["air"],"real":"M242 Bushmaster 25 mm air-burst","damageType":"Fragmentation","pen":1,"damage":17,"splash":2,"form":"Airburst","piercing":false,"targets":"Air"}
A17: autocannon_30 | B17: 2A42 30 mm | C17: cal_30 | E17: 2a42_30_mm | F17: autocannon | G17: 30 | K17: Kinetic | L17: 2 | M17: Bullet | N17: 1 | O17: RIPPLE | P17: 10 | Q17: 0.1111 | R17: 1.6111 | S17: 0 | T17: 0 | U17: 0 | V17: 0 | W17: 22 | X17: 0 | Y17: 0 | Z17: 200 | AA17: 30 | AB17: 0 | AC17: Ground | AE17: 0.8 | AF17: Small | AG17: FALSE | AH17: FALSE | AI17: FALSE | AJ17: FALSE | AK17: FALSE | AL17: FALSE | AM17: FALSE | AN17: 30 | AO17: 0 | AP17: T1 | AR17: autocannon_30_flak | AS17: boss_part;xe | AT17: elite_apc;elite_heavy_tank;gun_30;heavy_tank | AU17: 4 | AV17: elite_apc:0;elite_heavy_tank:1;gun_30:part;heavy_tank:1 | AW17: 0 | AX17: FALSE | AZ17: =IF(AND($AX$17,$AW$17>$AA$17/$Z$17),$AW$17,$AA$17/$Z$17) | BA17: 0.15 | BB17: 800 | BC17: 300 | BD17: ac | BE17: Wikipedia '2A42': 550-800 high, 200-300 low rpm | BG17: giong | CR17: 10 | CS17: 0.1111 | CT17: 30 | DD17: 1.6111 | DE17: 22 | DF17: Kinetic | DJ17: autocannon | DS17: Small | EB17: 2 | EH17: Bullet | EP17: 30 | EQ17: 2A42 30 mm | EX17: 30 | EZ17: 0.8 | FW17: Ground | GA17: 2a42_30_mm | GB17: cal_30 | GD17: Assets/MachineBrigade/Resources/Data/balance.json: weapons[8] | GE17: {"id":"autocannon_30","weaponFamilyId":"cal_30","weaponFamily":"2a42_30_mm","burstInterval":0.1111,"burst":10,"real":"2A42 30 mm","family":"autocannon","size":30,"caliberMm":30,"pen":2,"damageType":"Kinetic","damage":22,"cooldown":1.6111,"range":30,"spread":0.8,"impactTier":"Small","projectile":"Bullet","targets":"Ground"}
A18: autocannon_30_flak | B18: 2A42 30 mm air-burst | C18: cal_30 | D18: flak | E18: 2a42_30_mm_air_burst | F18: autocannon | G18: 30 | K18: Fragmentation | L18: 2 | M18: Bullet | N18: 1 | O18: RIPPLE | P18: 10 | Q18: 0.1111 | R18: 1.6111 | S18: 0 | T18: 0 | U18: 0 | V18: 0 | W18: 22 | X18: 2.5 | Y18: 0 | Z18: 200 | AA18: 30 | AB18: 0 | AC18: Air | AE18: 0.8 | AF18: Small | AG18: FALSE | AH18: FALSE | AI18: FALSE | AJ18: FALSE | AK18: FALSE | AL18: FALSE | AM18: FALSE | AN18: 30 | AO18: 0 | AP18: T1 | AQ18: autocannon_30 | AU18: 0 | AW18: 0 | AX18: FALSE | AZ18: =IF(AND($AX$18,$AW$18>$AA$18/$Z$18),$AW$18,$AA$18/$Z$18) | BA18: 0.15 | BB18: 800 | BC18: 300 | BD18: ac | BE18: Wikipedia '2A42': 550-800 high, 200-300 low rpm | BG18: giong | DE18: 22 | DF18: Fragmentation | DM18: air | DN18: Airburst | DT18: autocannon_30 | EB18: 2 | EE18: FALSE | EQ18: 2A42 30 mm air-burst | ES18: flak | EU18: autocannon_30 | EY18: 2.5 | FW18: Air | GA18: 2a42_30_mm_air_burst | GC18: flak | GD18: Assets/MachineBrigade/Resources/Data/balance.json: secondRounds.rounds[2] | GE18: {"id":"autocannon_30_flak","roundOf":"autocannon_30","inherits":"autocannon_30","weaponVariantId":"flak","weaponFamily":"2a42_30_mm_air_burst","round":"flak","for":["air"],"real":"2A42 30 mm air-burst","damageType":"Fragmentation","pen":2,"damage":22,"splash":2.5,"form":"Airburst","piercing":false,"targets":"Air"}
A19: autocannon_40 | B19: Bofors 40 mm | C19: cal_40 | F19: autocannon | G19: 40 | K19: Kinetic | L19: 2 | M19: Bullet | N19: 1 | O19: RIPPLE | P19: 1 | Q19: 0.1 | R19: 0.2 | S19: 10 | T19: 1.72 | U19: 0 | V19: 0 | W19: 30 | X19: 1 | Y19: 0 | Z19: 210 | AA19: 28 | AB19: 0 | AC19: All | AE19: 0.8 | AF19: Small | AG19: FALSE | AH19: FALSE | AI19: FALSE | AJ19: FALSE | AK19: FALSE | AL19: FALSE | AM19: FALSE | AN19: 40 | AO19: 0 | AP19: T1 | AR19: autocannon_40_flak | AS19: boss_part | AT19: gun_40 | AU19: 1 | AV19: gun_40:part | AW19: 0 | AX19: FALSE | AZ19: =IF(AND($AX$19,$AW$19>$AA$19/$Z$19),$AW$19,$AA$19/$Z$19) | BA19: 0.13333333 | BB19: 330 | BC19: 120 | BD19: aa | BE19: Wikipedia 'Bofors 40 mm L/70': 240-330 rpm | BF19: Gungnir's 40 mm guns: frozen (fix rule 8); their 1 m burst is Gungnir's own | BG19: giong | CT19: 40 | CW19: 10 | CX19: 1.72 | DD19: 0.2 | DE19: 30 | DF19: Kinetic | DJ19: autocannon | DS19: Small | EB19: 2 | EH19: Bullet | EK19: 210 | EP19: 28 | EQ19: Bofors 40 mm | EV19: 51 | EX19: 40 | EY19: 1 | EZ19: 0.8 | FW19: All | GB19: cal_40 | GD19: Assets/MachineBrigade/Resources/Data/balance.json: weapons[99] | GE19: {"id":"autocannon_40","weaponFamilyId":"cal_40","real":"Bofors 40 mm","family":"autocannon","size":40,"caliberMm":40,"pen":2,"damageType":"Kinetic","damage":30,"cooldown":0.2,"range":28,"projectileSpeed":210,"splash":1,"spread":0.8,"impactTier":"Small","projectile":"Bullet","targets":"All","clip":10,"clipReload":1.72,"roundWeight":51}
A20: autocannon_40_flak | B20: Bofors 40 mm air-burst | C20: cal_40 | D20: flak | F20: autocannon | G20: 40 | K20: Fragmentation | L20: 2 | M20: Bullet | N20: 1 | O20: RIPPLE | P20: 1 | Q20: 0.1 | R20: 0.2 | S20: 10 | T20: 1.72 | U20: 0 | V20: 0 | W20: 30 | X20: 3.5 | Y20: 0 | Z20: 210 | AA20: 28 | AB20: 0 | AC20: Air | AE20: 0.8 | AF20: Small | AG20: FALSE | AH20: FALSE | AI20: FALSE | AJ20: FALSE | AK20: FALSE | AL20: FALSE | AM20: FALSE | AN20: 40 | AO20: 0 | AP20: T1 | AQ20: autocannon_40 | AU20: 0 | AW20: 0 | AX20: FALSE | AZ20: =IF(AND($AX$20,$AW$20>$AA$20/$Z$20),$AW$20,$AA$20/$Z$20) | BA20: 0.13333333 | BB20: 330 | BC20: 120 | BD20: aa | BE20: Wikipedia 'Bofors 40 mm L/70': 240-330 rpm | BG20: giong | DE20: 30 | DF20: Fragmentation | DM20: air | DN20: Airburst | DT20: autocannon_40 | EB20: 2 | EE20: FALSE | EQ20: Bofors 40 mm air-burst | ES20: flak | EU20: autocannon_40 | EY20: 3.5 | FW20: Air | GC20: flak | GD20: Assets/MachineBrigade/Resources/Data/balance.json: secondRounds.rounds[3] | GE20: {"id":"autocannon_40_flak","roundOf":"autocannon_40","inherits":"autocannon_40","weaponVariantId":"flak","weaponFamily":"","round":"flak","for":["air"],"real":"Bofors 40 mm air-burst","damageType":"Fragmentation","pen":2,"damage":30,"splash":3.5,"form":"Airburst","piercing":false,"targets":"Air"}
A21: ballistic_missile | B21: 9M723 Iskander (700 kg) | C21: bal_9m723_iskander | F21: ballistic | H21: 480 | K21: HighExplosive | L21: 4 | M21: Rocket | N21: 1 | O21: RIPPLE | P21: 2 | Q21: 1.5 | R21: 22.71 | S21: 0 | T21: 0 | U21: 2 | V21: 0 | W21: 630 | X21: 10 | Y21: 0 | Z21: 200 | AA21: 180 | AB21: 40 | AC21: Ground | AE21: 5 | AF21: Ultimate | AG21: FALSE | AH21: FALSE | AI21: FALSE | AJ21: FALSE | AK21: FALSE | AL21: FALSE | AM21: FALSE | AN21: 700 | AO21: 0 | AP21: T4 | AS21: xe | AT21: ballistic_launcher | AU21: 1 | AV21: ballistic_launcher:0 | AW21: 2.7222222 | AX21: TRUE | AZ21: =IF(AND($AX$21,$AW$21>$AA$21/$Z$21),$AW$21,$AA$21/$Z$21) | BA21: 2.7222222 | BB21: 2 | BC21: 2 | BD21: missile | BE21: Wikipedia '9K720 Iskander': two missiles within a minute | BG21: doi | BR21: 50 | BS21: 200 | CN21: 2 | CR21: 2 | CS21: 1.5 | DD21: 22.71 | DE21: 630 | DF21: HighExplosive | DJ21: ballistic | DS21: Ultimate | DZ21: 40 | EB21: 4 | EH21: Rocket | EJ21: 0.85 | EK21: 200 | EP21: 180 | EQ21: 9M723 Iskander (700 kg) | EV21: 700 | EX21: 700 | EY21: 10 | EZ21: 5 | FZ21: 480 | GB21: bal_9m723_iskander | GD21: Assets/MachineBrigade/Resources/Data/balance.json: weapons[59] | GE21: {"id":"ballistic_missile","weaponFamilyId":"bal_9m723_iskander","real":"9M723 Iskander (700 kg)","family":"ballistic","size":700,"warheadKg":480,"pen":4,"projectileScale":0.85,"damageType":"HighExplosive","damage":630,"cooldown":22.71,"range":180,"minRange":40,"projectileSpeed":200,"splash":10,"spread":5,"impactTier":"Ultimate","projectile":"Rocket","burst":2,"burstInterval":1.5,"ammo":2,"roundWeight":700}
A22: bastion_gun | B22: 2A83 152 mm (twin) | C22: cal_152_155 | D22: ap | E22: 2a83_152_mm | F22: tank_gun | G22: 152 | K22: Kinetic | L22: 4 | M22: Shell | N22: 2 | O22: SIMULTANEOUS | P22: 1 | Q22: 0.05 | R22: 7.443 | S22: 0 | T22: 0 | U22: 0 | V22: 0 | W22: 457 | X22: 2.5 | Y22: 0 | Z22: 160 | AA22: 40 | AB22: 0 | AC22: Ground | AE22: 0.3 | AF22: Large | AG22: FALSE | AH22: FALSE | AI22: FALSE | AJ22: FALSE | AK22: FALSE | AL22: FALSE | AM22: FALSE | AN22: 152 | AO22: 0 | AP22: T3 | AR22: bastion_gun_he | AS22: cong_trinh;thap | AT22: headquarters;headquarters.fortress_air;headquarters.fortress_ground;headquarters.shield;spawn_bastion | AU22: 5 | AV22: headquarters:0;headquarters.fortress_air:0;headquarters.fortress_ground:0;headquarters.shield:0;spawn_bastion:0 | AW22: 0 | AX22: FALSE | AZ22: =IF(AND($AX$22,$AW$22>$AA$22/$Z$22),$AW$22,$AA$22/$Z$22) | BA22: 0.25 | BB22: 10 | BC22: 8 | BD22: gun | BE22: Object 195 / T-14 152 mm, est. ~10 rpm (the sheet) | BG22: doi | BH22: 320 | BI22: 457 | BJ22: 5.16 | BK22: 7.443 | BT22: 2 | BU22: 1 | BX22: 1 | BY22: 2 | BZ22: RIPPLE | CA22: SIMULTANEOUS | CO22: 2 | CR22: 1 | CS22: 0.05 | CT22: 152 | DD22: 7.443 | DE22: 457 | DF22: Kinetic | DJ22: tank_gun | DR22: 1.5 | DS22: Large | EB22: 4 | EE22: TRUE | EP22: 40 | EQ22: 2A83 152 mm (twin) | EW22: SIMULTANEOUS | EX22: 152 | EZ22: 0.3 | GA22: 2a83_152_mm | GB22: cal_152_155 | GC22: ap | GD22: Assets/MachineBrigade/Resources/Data/balance.json: weapons[91] | GE22: {"id":"bastion_gun","weaponFamilyId":"cal_152_155","weaponVariantId":"ap","salvoMode":"SIMULTANEOUS","barrels":2,"weaponFamily":"2a83_152_mm","real":"2A83 152 mm (twin)","family":"tank_gun","size":152,"caliberMm":152,"pen":4,"piercing":true,"damageType":"Kinetic","damage":457,"cooldown":7.443,"range":40,"spread":0.3,"impactTier":"Large","burst":1,"burstInterval":0.05,"impactScale":1.5}
A23: bastion_gun_he | B23: 2A83 152 mm HE-FRAG (twin) | C23: cal_152_155 | E23: 2a83_152_mm_he_frag | F23: tank_gun | G23: 152 | K23: HighExplosive | L23: 3 | M23: Shell | N23: 2 | O23: SIMULTANEOUS | P23: 1 | Q23: 0.05 | R23: 7.443 | S23: 0 | T23: 0 | U23: 0 | V23: 0 | W23: 457 | X23: 6.5 | Y23: 0 | Z23: 150 | AA23: 40 | AB23: 0 | AC23: Ground | AE23: 0.3 | AF23: Huge | AG23: FALSE | AH23: FALSE | AI23: FALSE | AJ23: FALSE | AK23: FALSE | AL23: FALSE | AM23: FALSE | AN23: 152 | AO23: 0 | AP23: T3 | AQ23: bastion_gun | AU23: 0 | AW23: 0 | AX23: FALSE | AZ23: =IF(AND($AX$23,$AW$23>$AA$23/$Z$23),$AW$23,$AA$23/$Z$23) | BA23: 0.26666667 | BB23: 10 | BC23: 8 | BD23: gun | BE23: Object 195 / T-14 152 mm, est. ~10 rpm (the sheet) | BG23: doi | BH23: 320 | BI23: 457 | BJ23: 5.16 | BK23: 7.443 | BT23: 2 | BU23: 1 | BX23: 1 | BY23: 2 | BZ23: RIPPLE | CA23: SIMULTANEOUS | DE23: 457 | DF23: HighExplosive | DM23: light;structure | DN23: HeShell | DS23: Huge | DT23: bastion_gun | EB23: 3 | EE23: FALSE | EK23: 150 | EQ23: 2A83 152 mm HE-FRAG (twin) | ES23: he | EU23: bastion_gun | EV23: 343 | EY23: 6.5 | FW23: Ground | GA23: 2a83_152_mm_he_frag | GD23: Assets/MachineBrigade/Resources/Data/balance.json: secondRounds.rounds[4] | GE23: {"id":"bastion_gun_he","roundOf":"bastion_gun","inherits":"bastion_gun","weaponVariantId":"","weaponFamily":"2a83_152_mm_he_frag","round":"he","for":["light","structure"],"real":"2A83 152 mm HE-FRAG (twin)","damageType":"HighExplosive","pen":3,"damage":457,"splash":6.5,"form":"HeShell","piercing":false,"targets":"Ground","projectileSpeed":150,"impactTier":"Huge","roundWeight":343}
A24: boat_rockets | B24: S-8 80 mm | C24: rkt_70_80 | E24: s_8_80_mm_boat | F24: rocket | G24: 80 | K24: HighExplosive | L24: 2 | M24: Rocket | N24: 1 | O24: RIPPLE | P24: 10 | Q24: 0.12 | R24: 7 | S24: 0 | T24: 0 | U24: 0 | V24: 0 | W24: 32 | X24: 3.5 | Y24: 7 | Z24: 180 | AA24: 55 | AB24: 0 | AC24: Ground | AE24: 4 | AF24: Medium | AG24: FALSE | AH24: FALSE | AI24: FALSE | AJ24: FALSE | AK24: FALSE | AL24: FALSE | AM24: FALSE | AN24: 80 | AO24: 0 | AP24: T2 | AS24: xe | AT24: missile_boat | AU24: 1 | AV24: missile_boat:0 | AW24: 0 | AX24: FALSE | AZ24: =IF(AND($AX$24,$AW$24>$AA$24/$Z$24),$AW$24,$AA$24/$Z$24) | BA24: 0.30555556 | BB24: 900 | BD24: rocket | BE24: rocket pods: ripples of 0.05-0.12 s (DECISIONS 19R) | BG24: doi | BN24: 3 | BO24: 3.5 | BP24: 0 | BQ24: 7 | BR24: 40 | BS24: 180 | CR24: 10 | CS24: 0.12 | CT24: 80 | DD24: 7 | DE24: 32 | DF24: HighExplosive | DG24: 7 | DJ24: rocket | DS24: Medium | EB24: 2 | EH24: Rocket | EJ24: 0.9 | EP24: 55 | EQ24: S-8 80 mm | EX24: 80 | EZ24: 4 | GA24: s_8_80_mm_boat | GB24: rkt_70_80 | GD24: Assets/MachineBrigade/Resources/Data/balance.json: weapons[255] | GE24: {"id":"boat_rockets","weaponFamilyId":"rkt_70_80","weaponFamily":"s_8_80_mm_boat","real":"S-8 80 mm","family":"rocket","size":80,"caliberMm":80,"pen":2,"projectileScale":0.9,"damageType":"HighExplosive","damage":32,"cooldown":7,"edge":7,"range":55,"spread":4,"impactTier":"Medium","projectile":"Rocket","burst":10,"burstInterval":0.12}
A25: bofors_l70 | B25: Bofors 40 mm L/70 | C25: cal_40 | D25: flak | E25: bofors_40_mm_l_70 | F25: autocannon | G25: 40 | K25: Fragmentation | L25: 2 | M25: Bullet | N25: 1 | O25: RIPPLE | P25: 1 | Q25: 0.1 | R25: 0.25 | S25: 20 | T25: 3 | U25: 0 | V25: 0 | W25: 30 | X25: 2.5 | Y25: 0 | Z25: 220 | AA25: 48 | AB25: 0 | AC25: All | AE25: 1.2 | AF25: Small | AG25: FALSE | AH25: FALSE | AI25: FALSE | AJ25: FALSE | AK25: FALSE | AL25: FALSE | AM25: FALSE | AN25: 40 | AO25: 0 | AP25: T1 | AS25: cong_trinh;thap;xe | AT25: aa_gun_tower;aa_gun_vehicle;headquarters.fortress_air | AU25: 3 | AV25: aa_gun_tower:0;aa_gun_vehicle:0;headquarters.fortress_air:4 | AW25: 0 | AX25: FALSE | AZ25: =IF(AND($AX$25,$AW$25>$AA$25/$Z$25),$AW$25,$AA$25/$Z$25) | BA25: 0.21818182 | BB25: 330 | BC25: 120 | BD25: aa | BE25: Wikipedia 'Bofors 40 mm L/70': 240-330 rpm | BG25: giong | CT25: 40 | CW25: 20 | CX25: 3 | DD25: 0.25 | DE25: 30 | DF25: Fragmentation | DJ25: autocannon | DS25: Small | EB25: 2 | EH25: Bullet | EP25: 48 | EQ25: Bofors 40 mm L/70 | EX25: 40 | EZ25: 1.2 | FW25: All | GA25: bofors_40_mm_l_70 | GB25: cal_40 | GC25: flak | GD25: Assets/MachineBrigade/Resources/Data/balance.json: weapons[279] | GE25: {"id":"bofors_l70","weaponFamilyId":"cal_40","weaponVariantId":"flak","weaponFamily":"bofors_40_mm_l_70","real":"Bofors 40 mm L/70","family":"autocannon","size":40,"caliberMm":40,"pen":2,"damageType":"Fragmentation","damage":30,"cooldown":0.25,"range":48,"spread":1.2,"impactTier":"Small","projectile":"Bullet","targets":"All","clip":20,"clipReload":3}
A26: bomber_payload | B26: FAB-500 (500 kg) | C26: bomb_fab_500 | F26: bomb | H26: 500 | K26: HighExplosive | L26: 3 | M26: Bomb | N26: 1 | O26: RIPPLE | P26: 7 | Q26: 0.2 | R26: 11.2 | S26: 0 | T26: 0 | U26: 0 | V26: 0 | W26: 420 | X26: 10 | Y26: 0 | Z26: 35 | AA26: 28 | AB26: 0 | AC26: Ground | AE26: 7 | AF26: Huge | AG26: FALSE | AH26: FALSE | AI26: FALSE | AJ26: FALSE | AK26: FALSE | AL26: FALSE | AM26: FALSE | AN26: 500 | AO26: 7 | AP26: T4 | AS26: xe | AT26: heavy_bomber | AU26: 1 | AV26: heavy_bomber:0 | AW26: 2.7222222 | AX26: TRUE | AZ26: =IF(AND($AX$26,$AW$26>$AA$26/$Z$26),$AW$26,$AA$26/$Z$26) | BA26: 0.8 | BB26: 600 | BD26: bomb | BE26: a stick's release, 0.1 s and up (est.) | BG26: giong | CR26: 7 | CS26: 0.2 | DD26: 11.2 | DE26: 420 | DF26: HighExplosive | DJ26: bomb | DS26: Huge | DW26: 7 | EB26: 3 | EH26: Bomb | EI26: bomb | EJ26: 0.7324 | EK26: 35 | EP26: 28 | EQ26: FAB-500 (500 kg) | ET26: 1.2 | EX26: 500 | EY26: 10 | EZ26: 7 | FA26: CENTER | FB26: 1.5 | FC26: 7 | FD26: OVERFLY | FE26: 40 | FF26: 1.449 | FG26: AXIS | FH26: 0.625 | FI26: 2.5 | FJ26: 1.65 | FK26: 25.5 | FL26: 66 | FM26: 3 | FN26: STICK | FO26: 0.909 | FP26: 17.6 | FQ26: 10 | FR26: 11 | FS26: 6.2 | FT26: STICK_RECT | FU26: 25 | FZ26: 500 | GB26: bomb_fab_500 | GD26: Assets/MachineBrigade/Resources/Data/balance.json: weapons[48] | GE26: {"id":"bomber_payload","weaponFamilyId":"bomb_fab_500","load":7,"real":"FAB-500 (500 kg)","family":"bomb","size":500,"warheadKg":500,"pen":3,"projectileModel":"bomb","projectileScale":0.7324,"roundLength":1.2,"damageType":"HighExplosive","damage":420,"cooldown":11.2,"range":28,"projectileSpeed":35,"splash":10,"spread":7,"impactTier":"Huge","projectile":"Bomb","burst":7,"burstInterval":0.2,"stick":{"mode":"STICK","bombs":7,"spacing":11,"length":66,"interval":0.625,"releaseSpeed":17.6,"fallTime":1.449,"lead":25.5,"heading":"AXIS","anchor":"CENTER","drop":"OVERFLY","jitterAcross":2.5,"jitterAlong":1.65,"overlap":0.909,"width":25,"minTargets":3,"safety":10,"straightTime":6.2,"exit":40,"bayOpen":1.5,"warnShape":"STICK_RECT"}}
A27: bomber_tail_guns | B27: M3 12.7 mm (quad tail) | C27: cal_12_7 | F27: mg | G27: 12.7 | K27: Kinetic | L27: 1 | M27: Bullet | N27: 1 | O27: RIPPLE | P27: 1 | Q27: 0.1 | R27: 0.0167 | S27: 26 | T27: 2.78 | U27: 0 | V27: 0 | W27: 9.5 | X27: 0 | Y27: 0 | Z27: 240 | AA27: 30 | AB27: 0 | AC27: Air | AE27: 1.5 | AF27: Small | AG27: FALSE | AH27: FALSE | AI27: FALSE | AJ27: FALSE | AK27: FALSE | AL27: FALSE | AM27: FALSE | AN27: 12.7 | AO27: 0 | AP27: T0 | AR27: bomber_tail_guns_api | AS27: xe | AT27: heavy_bomber | AU27: 1 | AV27: heavy_bomber:1 | AW27: 0 | AX27: FALSE | AZ27: =IF(AND($AX$27,$AW$27>$AA$27/$Z$27),$AW$27,$AA$27/$Z$27) | BA27: 0.125 | BB27: 1200 | BC27: 200 | BD27: mg | BE27: Wikipedia 'M3 Browning' (AN/M3): 1,100-1,250 rpm | BG27: giong | CT27: 12.7 | CW27: 26 | CX27: 2.78 | DD27: 0.0167 | DE27: 9.5 | DF27: Kinetic | DJ27: mg | DS27: Small | EB27: 1 | EH27: Bullet | EK27: 240 | EP27: 30 | EQ27: M3 12.7 mm (quad tail) | EV27: 19 | EX27: 12.7 | EZ27: 1.5 | FW27: Air | GB27: cal_12_7 | GD27: Assets/MachineBrigade/Resources/Data/balance.json: weapons[49] | GE27: {"id":"bomber_tail_guns","weaponFamilyId":"cal_12_7","real":"M3 12.7 mm (quad tail)","family":"mg","size":12.7,"caliberMm":12.7,"pen":1,"damageType":"Kinetic","damage":9.5,"cooldown":0.0167,"range":30,"projectileSpeed":240,"spread":1.5,"impactTier":"Small","projectile":"Bullet","targets":"Air","roundWeight":19,"clip":26,"clipReload":2.78}
A28: bomber_tail_guns_api | B28: M3 12.7 mm API (quad tail) | C28: cal_12_7 | F28: mg | G28: 12.7 | K28: Kinetic | L28: 2 | M28: Bullet | N28: 1 | O28: RIPPLE | P28: 1 | Q28: 0.1 | R28: 0.0167 | S28: 26 | T28: 2.78 | U28: 0 | V28: 0 | W28: 9.5 | X28: 0 | Y28: 0 | Z28: 240 | AA28: 30 | AB28: 0 | AC28: Air | AE28: 1.5 | AF28: Small | AG28: FALSE | AH28: FALSE | AI28: FALSE | AJ28: FALSE | AK28: FALSE | AL28: FALSE | AM28: FALSE | AN28: 12.7 | AO28: 0 | AP28: T0 | AQ28: bomber_tail_guns | AU28: 0 | AW28: 0 | AX28: FALSE | AZ28: =IF(AND($AX$28,$AW$28>$AA$28/$Z$28),$AW$28,$AA$28/$Z$28) | BA28: 0.125 | BB28: 1200 | BC28: 200 | BD28: mg | BE28: Wikipedia 'M3 Browning' (AN/M3): 1,100-1,250 rpm | BG28: giong | DE28: 9.5 | DF28: Kinetic | DH28: TRUE | DM28: any | DN28: BulletBig | DT28: bomber_tail_guns | EB28: 2 | EE28: TRUE | EQ28: M3 12.7 mm API (quad tail) | ES28: api | EU28: bomber_tail_guns | GD28: Assets/MachineBrigade/Resources/Data/balance.json: secondRounds.rounds[5] | GE28: {"id":"bomber_tail_guns_api","roundOf":"bomber_tail_guns","inherits":"bomber_tail_guns","weaponFamily":"","round":"api","for":["any"],"elite":true,"real":"M3 12.7 mm API (quad tail)","damageType":"Kinetic","pen":2,"damage":9.5,"form":"BulletBig","piercing":true}
A29: borer_cannon | B29: 2A70 100/76 mm | C29: cal_76 | F29: tank_gun | G29: 76 | K29: Kinetic | L29: 3 | M29: Shell | N29: 1 | O29: RIPPLE | P29: 1 | Q29: 0.1 | R29: 6 | S29: 0 | T29: 0 | U29: 0 | V29: 0 | W29: 120 | X29: 1.5 | Y29: 0 | Z29: 170 | AA29: 34 | AB29: 0 | AC29: Ground | AE29: 0.7 | AF29: Medium | AG29: FALSE | AH29: FALSE | AI29: FALSE | AJ29: FALSE | AK29: FALSE | AL29: FALSE | AM29: FALSE | AN29: 76 | AO29: 0 | AP29: T2 | AR29: borer_cannon_he | AS29: boss | AT29: earth_borer | AU29: 1 | AV29: earth_borer:1;earth_borer:2 | AW29: 0 | AX29: FALSE | AZ29: =IF(AND($AX$29,$AW$29>$AA$29/$Z$29),$AW$29,$AA$29/$Z$29) | BA29: 0.2 | BB29: 10 | BC29: 8 | BD29: gun | BE29: Wikipedia '2A70': 10 rpm (100 mm), BMP-3 | BF29: real 2A70 10 rpm (6 s); 2.08 s was too fast | BG29: doi | BJ29: 2.08 | BK29: 6 | CT29: 76 | DD29: 6 | DE29: 120 | DF29: Kinetic | DJ29: tank_gun | DO29: 16 | DS29: Medium | EB29: 3 | EE29: TRUE | EK29: 170 | EP29: 34 | EQ29: 2A70 100/76 mm | EV29: 150 | EX29: 76 | EY29: 1.5 | EZ29: 0.7 | GB29: cal_76 | GD29: Assets/MachineBrigade/Resources/Data/balance.json: weapons[244] | GE29: {"id":"borer_cannon","groundMinReach":16,"weaponFamilyId":"cal_76","real":"2A70 100/76 mm","family":"tank_gun","size":76,"caliberMm":76,"pen":3,"piercing":true,"damageType":"Kinetic","damage":120,"cooldown":6,"range":34,"projectileSpeed":170,"splash":1.5,"spread":0.7,"impactTier":"Medium","roundWeight":150}
A30: borer_cannon_he | B30: 2A70 100/76 mm HE | C30: cal_76 | F30: tank_gun | G30: 76 | K30: HighExplosive | L30: 2 | M30: Shell | N30: 1 | O30: RIPPLE | P30: 1 | Q30: 0.1 | R30: 6 | S30: 0 | T30: 0 | U30: 0 | V30: 0 | W30: 120 | X30: 3 | Y30: 0 | Z30: 170 | AA30: 34 | AB30: 0 | AC30: Ground | AE30: 0.7 | AF30: Large | AG30: FALSE | AH30: FALSE | AI30: FALSE | AJ30: FALSE | AK30: FALSE | AL30: FALSE | AM30: FALSE | AN30: 76 | AO30: 0 | AP30: T2 | AQ30: borer_cannon | AU30: 0 | AW30: 0 | AX30: FALSE | AZ30: =IF(AND($AX$30,$AW$30>$AA$30/$Z$30),$AW$30,$AA$30/$Z$30) | BA30: 0.2 | BB30: 10 | BC30: 8 | BD30: gun | BE30: Wikipedia '2A70': 10 rpm (100 mm), BMP-3 | BG30: doi | BJ30: 2.08 | BK30: 6 | DE30: 120 | DF30: HighExplosive | DM30: light;structure | DN30: HeShell | DS30: Large | DT30: borer_cannon | EB30: 2 | EE30: FALSE | EQ30: 2A70 100/76 mm HE | ES30: he | EU30: borer_cannon | EY30: 3 | FW30: Ground | GD30: Assets/MachineBrigade/Resources/Data/balance.json: secondRounds.rounds[7] | GE30: {"id":"borer_cannon_he","roundOf":"borer_cannon","inherits":"borer_cannon","weaponFamily":"","round":"he","for":["light","structure"],"real":"2A70 100/76 mm HE","damageType":"HighExplosive","pen":2,"damage":120,"splash":3,"form":"HeShell","piercing":false,"targets":"Ground","impactTier":"Large"}
A31: borer_drill | B31: drill head | C31: melee_drill_head | F31: melee | K31: Kinetic | L31: 4 | M31: Bullet | N31: 1 | O31: RIPPLE | P31: 1 | Q31: 0.1 | R31: 1.5 | S31: 0 | T31: 0 | U31: 0 | V31: 0 | W31: 260 | X31: 0 | Y31: 0 | Z31: 400 | AA31: 7 | AB31: 0 | AC31: Ground | AE31: 0 | AF31: Large | AG31: FALSE | AH31: FALSE | AI31: FALSE | AJ31: FALSE | AK31: FALSE | AL31: FALSE | AM31: FALSE | AN31: 2 | AO31: 0 | AP31: T0 | AS31: boss | AT31: earth_borer | AU31: 1 | AV31: earth_borer:0 | AW31: 0 | AX31: FALSE | AZ31: =IF(AND($AX$31,$AW$31>$AA$31/$Z$31),$AW$31,$AA$31/$Z$31) | BA31: 0.0175 | BB31: NEED_SOURCE | BC31: NEED_SOURCE | BE31: NEED_SOURCE | BG31: giong | DD31: 1.5 | DE31: 260 | DF31: Kinetic | DJ31: melee | DS31: Large | DY31: TRUE | EB31: 4 | EE31: TRUE | EH31: Bullet | EK31: 400 | EP31: 7 | EQ31: drill head | EX31: 2 | FW31: Ground | GB31: melee_drill_head | GD31: Assets/MachineBrigade/Resources/Data/balance.json: weapons[243] | GE31: {"id":"borer_drill","weaponFamilyId":"melee_drill_head","real":"drill head","family":"melee","size":2,"pen":4,"piercing":true,"melee":true,"damageType":"Kinetic","damage":260,"cooldown":1.5,"range":7,"projectileSpeed":400,"impactTier":"Large","projectile":"Bullet","targets":"Ground","bonuses":[{"armor":"Structure","mult":2}]}
A32: boss_flak | B32: Oerlikon 35 mm (twin) | C32: cal_35 | E32: oerlikon_35_mm | F32: autocannon | G32: 35 | K32: Fragmentation | L32: 2 | M32: Bullet | N32: 1 | O32: RIPPLE | P32: 1 | Q32: 0.1 | R32: 0.05 | S32: 41 | T32: 3.38 | U32: 0 | V32: 0 | W32: 25 | X32: 2.5 | Y32: 0 | Z32: 260 | AA32: 40 | AB32: 0 | AC32: All | AE32: 1.5 | AF32: Small | AG32: FALSE | AH32: FALSE | AI32: FALSE | AJ32: FALSE | AK32: FALSE | AL32: FALSE | AM32: FALSE | AN32: 35 | AO32: 0 | AP32: T1 | AR32: boss_flak_ap | AS32: boss;boss_part;xe | AT32: armored_train;flak_35;mara_behemoth | AU32: 3 | AV32: armored_train:3;armored_train:5;flak_35:part;mara_behemoth:2;mara_behemoth:3 | AW32: 0 | AX32: FALSE | AZ32: =IF(AND($AX$32,$AW$32>$AA$32/$Z$32),$AW$32,$AA$32/$Z$32) | BA32: 0.15384615 | BB32: 550 | BC32: 300 | BD32: aa | BE32: Wikipedia 'Oerlikon GDF': 550 rpm a gun (the twin: 1,100) | BG32: giong | CT32: 35 | CW32: 41 | CX32: 3.38 | DD32: 0.05 | DE32: 25 | DF32: Fragmentation | DJ32: autocannon | DS32: Small | EB32: 2 | EH32: Bullet | EP32: 40 | EQ32: Oerlikon 35 mm (twin) | EX32: 35 | EZ32: 1.5 | FW32: All | GA32: oerlikon_35_mm | GB32: cal_35 | GD32: Assets/MachineBrigade/Resources/Data/balance.json: weapons[232] | GE32: {"id":"boss_flak","weaponFamilyId":"cal_35","weaponFamily":"oerlikon_35_mm","real":"Oerlikon 35 mm (twin)","family":"autocannon","size":35,"caliberMm":35,"pen":2,"damageType":"Fragmentation","damage":25,"cooldown":0.05,"range":40,"spread":1.5,"impactTier":"Small","projectile":"Bullet","targets":"All","clip":41,"clipReload":3.38}
A33: boss_flak_ap | B33: Oerlikon 35 mm AP (twin) | C33: cal_35 | D33: ap | E33: oerlikon_35_mm_ap | F33: autocannon | G33: 35 | K33: Kinetic | L33: 2 | M33: Bullet | N33: 1 | O33: RIPPLE | P33: 1 | Q33: 0.1 | R33: 0.05 | S33: 41 | T33: 3.38 | U33: 0 | V33: 0 | W33: 25 | X33: 0 | Y33: 0 | Z33: 260 | AA33: 40 | AB33: 0 | AC33: Ground | AE33: 1.5 | AF33: Small | AG33: FALSE | AH33: FALSE | AI33: FALSE | AJ33: FALSE | AK33: FALSE | AL33: FALSE | AM33: FALSE | AN33: 35 | AO33: 0 | AP33: T1 | AQ33: boss_flak | AU33: 0 | AW33: 0 | AX33: FALSE | AZ33: =IF(AND($AX$33,$AW$33>$AA$33/$Z$33),$AW$33,$AA$33/$Z$33) | BA33: 0.15384615 | BB33: 550 | BC33: 300 | BD33: aa | BE33: Wikipedia 'Oerlikon GDF': 550 rpm a gun (the twin: 1,100) | BG33: giong | DE33: 25 | DF33: Kinetic | DM33: ground | DN33: BeltedAutocannon | DT33: boss_flak | EB33: 2 | EE33: TRUE | EQ33: Oerlikon 35 mm AP (twin) | ES33: ap | EU33: boss_flak | EY33: 0 | FW33: Ground | GA33: oerlikon_35_mm_ap | GC33: ap | GD33: Assets/MachineBrigade/Resources/Data/balance.json: secondRounds.rounds[8] | GE33: {"id":"boss_flak_ap","roundOf":"boss_flak","inherits":"boss_flak","weaponVariantId":"ap","weaponFamily":"oerlikon_35_mm_ap","round":"ap","for":["ground"],"real":"Oerlikon 35 mm AP (twin)","damageType":"Kinetic","pen":2,"damage":25,"splash":0,"form":"BeltedAutocannon","piercing":true,"targets":"Ground"}
A34: boss_flamer | B34: flamethrower (heavy) | C34: flame_flamethrower | F34: flame | K34: Fire | L34: 2 | M34: Flame | N34: 1 | O34: RIPPLE | P34: 1 | Q34: 0.1 | R34: 0.25 | S34: 0 | T34: 0 | U34: 0 | V34: 0 | W34: 30 | X34: 3.5 | Y34: 0 | Z34: 38 | AA34: 20 | AB34: 0 | AC34: Ground | AE34: 0.8 | AF34: Medium | AG34: FALSE | AH34: FALSE | AI34: FALSE | AJ34: FALSE | AK34: FALSE | AL34: FALSE | AM34: FALSE | AN34: 3 | AO34: 0 | AP34: T1 | AS34: boss | AT34: behemoth_inferno | AU34: 1 | AV34: behemoth_inferno:0;behemoth_inferno:2 | AW34: 0 | AX34: FALSE | AZ34: =IF(AND($AX$34,$AW$34>$AA$34/$Z$34),$AW$34,$AA$34/$Z$34) | BA34: 0.52631579 | BB34: NEED_SOURCE | BC34: NEED_SOURCE | BE34: NEED_SOURCE | BG34: giong | DD34: 0.25 | DE34: 30 | DF34: Fire | DJ34: flame | DS34: Medium | EB34: 2 | EH34: Flame | EK34: 38 | EP34: 20 | EQ34: flamethrower (heavy) | EX34: 3 | EY34: 3.5 | EZ34: 0.8 | GB34: flame_flamethrower | GD34: Assets/MachineBrigade/Resources/Data/balance.json: weapons[239] | GE34: {"id":"boss_flamer","weaponFamilyId":"flame_flamethrower","real":"flamethrower (heavy)","family":"flame","size":3,"pen":2,"damageType":"Fire","damage":30,"cooldown":0.25,"range":20,"projectileSpeed":38,"splash":3.5,"spread":0.8,"impactTier":"Medium","projectile":"Flame"}
A35: boss_heli_gun | B35: M230 30 mm | C35: cal_30 | F35: autocannon | G35: 30 | K35: Kinetic | L35: 2 | M35: Bullet | N35: 1 | O35: RIPPLE | P35: 1 | Q35: 0.1 | R35: 0.1667 | S35: 40 | T35: 3.167 | U35: 0 | V35: 0 | W35: 22 | X35: 0 | Y35: 0 | Z35: 200 | AA35: 26 | AB35: 0 | AC35: All | AE35: 1.3 | AF35: Small | AG35: FALSE | AH35: FALSE | AI35: FALSE | AJ35: FALSE | AK35: FALSE | AL35: FALSE | AM35: FALSE | AN35: 30 | AO35: 0 | AP35: T1 | AQ35: heli_gun | AR35: boss_heli_gun_flak | AS35: boss | AT35: mega_gunship | AU35: 1 | AV35: mega_gunship:1;mega_gunship:2 | AW35: 0 | AX35: FALSE | AZ35: =IF(AND($AX$35,$AW$35>$AA$35/$Z$35),$AW$35,$AA$35/$Z$35) | BA35: 0.13 | BB35: 625 | BC35: 300 | BD35: ac | BE35: Wikipedia 'M230 chain gun': 625 rpm | BG35: doi | BR35: 220 | BS35: 200 | CH35: 3.1667 | CI35: 3.167 | CT35: 30 | CW35: 40 | CX35: 3.167 | DD35: 0.1667 | DJ35: autocannon | DT35: heli_gun | EB35: 2 | EK35: 200 | EQ35: M230 30 mm | EX35: 30 | EY35: 0 | GD35: Assets/MachineBrigade/Resources/Data/balance.json: weapons[247] | GE35: {"id":"boss_heli_gun","weaponFamily":"","real":"M230 30 mm","family":"autocannon","size":30,"caliberMm":30,"pen":2,"inherits":"heli_gun","splash":0,"projectileSpeed":200,"cooldown":0.1667,"clip":40,"clipReload":3.167}
A36: boss_heli_gun_flak | B36: M230 30 mm air-burst | C36: cal_30 | D36: flak | E36: m230_30_mm_air_burst | F36: autocannon | G36: 30 | K36: Fragmentation | L36: 2 | M36: Bullet | N36: 1 | O36: RIPPLE | P36: 1 | Q36: 0.1 | R36: 0.1667 | S36: 40 | T36: 3.167 | U36: 0 | V36: 0 | W36: 22 | X36: 2.5 | Y36: 0 | Z36: 220 | AA36: 26 | AB36: 0 | AC36: Air | AE36: 1.3 | AF36: Small | AG36: FALSE | AH36: FALSE | AI36: FALSE | AJ36: FALSE | AK36: FALSE | AL36: FALSE | AM36: FALSE | AN36: 30 | AO36: 0 | AP36: T1 | AQ36: boss_heli_gun | AU36: 0 | AW36: 0 | AX36: FALSE | AZ36: =IF(AND($AX$36,$AW$36>$AA$36/$Z$36),$AW$36,$AA$36/$Z$36) | BA36: 0.11818182 | BB36: 625 | BC36: 300 | BD36: ac | BE36: Wikipedia 'M230 chain gun': 625 rpm | BG36: doi | CH36: 3.1667 | CI36: 3.167 | DE36: 22 | DF36: Fragmentation | DM36: air | DN36: Airburst | DT36: boss_heli_gun | EB36: 2 | EE36: FALSE | EQ36: M230 30 mm air-burst | ES36: flak | EU36: boss_heli_gun | EY36: 2.5 | FW36: Air | GA36: m230_30_mm_air_burst | GC36: flak | GD36: Assets/MachineBrigade/Resources/Data/balance.json: secondRounds.rounds[9] | GE36: {"id":"boss_heli_gun_flak","roundOf":"boss_heli_gun","inherits":"boss_heli_gun","weaponVariantId":"flak","weaponFamily":"m230_30_mm_air_burst","round":"flak","for":["air"],"real":"M230 30 mm air-burst","damageType":"Fragmentation","pen":2,"damage":22,"splash":2.5,"form":"Airburst","piercing":false,"targets":"Air"}
A37: boss_hmg | B37: NSV 12.7 mm | C37: cal_12_7 | E37: nsv_12_7_mm | F37: mg | G37: 12.7 | K37: Kinetic | L37: 1 | M37: Bullet | N37: 1 | O37: RIPPLE | P37: 1 | Q37: 0.1 | R37: 0.0833 | S37: 100 | T37: 5 | U37: 0 | V37: 0 | W37: 15 | X37: 0 | Y37: 0 | Z37: 240 | AA37: 30 | AB37: 0 | AC37: All | AE37: 1.3 | AF37: Small | AG37: FALSE | AH37: FALSE | AI37: FALSE | AJ37: FALSE | AK37: FALSE | AL37: FALSE | AM37: FALSE | AN37: 12.7 | AO37: 0 | AP37: T0 | AQ37: hmg_roof | AR37: boss_hmg_api | AS37: boss | AT37: armored_train;mega_gunship | AU37: 2 | AV37: armored_train:2;mega_gunship:5;mega_gunship:6 | AW37: 0 | AX37: FALSE | AZ37: =IF(AND($AX$37,$AW$37>$AA$37/$Z$37),$AW$37,$AA$37/$Z$37) | BA37: 0.125 | BB37: 800 | BC37: 100 | BD37: mg | BE37: Wikipedia 'NSV machine gun': 700-800 cyclic, 100 practical | BF37: wave 1 boss_hmg: 100 rounds at 720 rpm, changed in 5 s (NSV 700-800 rpm) | BG37: doi | BH37: 9.5 | BI37: 15 | CH37: 5.0833 | CI37: 5 | CT37: 12.7 | CW37: 100 | CX37: 5 | DD37: 0.0833 | DE37: 15 | DJ37: mg | DT37: hmg_roof | EB37: 1 | EQ37: NSV 12.7 mm | EX37: 12.7 | GA37: nsv_12_7_mm | GD37: Assets/MachineBrigade/Resources/Data/balance.json: weapons[249] | GE37: {"id":"boss_hmg","weaponFamily":"nsv_12_7_mm","real":"NSV 12.7 mm","family":"mg","size":12.7,"caliberMm":12.7,"pen":1,"inherits":"hmg_roof","damage":15,"cooldown":0.0833,"clip":100,"clipReload":5}
A38: boss_hmg_api | B38: NSV 12.7 mm API | C38: cal_12_7 | E38: nsv_12_7_mm_api | F38: mg | G38: 12.7 | K38: Kinetic | L38: 2 | M38: Bullet | N38: 1 | O38: RIPPLE | P38: 1 | Q38: 0.1 | R38: 0.0833 | S38: 100 | T38: 5 | U38: 0 | V38: 0 | W38: 15 | X38: 0 | Y38: 0 | Z38: 240 | AA38: 30 | AB38: 0 | AC38: All | AE38: 1.3 | AF38: Small | AG38: FALSE | AH38: FALSE | AI38: FALSE | AJ38: FALSE | AK38: FALSE | AL38: FALSE | AM38: FALSE | AN38: 12.7 | AO38: 0 | AP38: T0 | AQ38: boss_hmg | AU38: 0 | AW38: 0 | AX38: FALSE | AZ38: =IF(AND($AX$38,$AW$38>$AA$38/$Z$38),$AW$38,$AA$38/$Z$38) | BA38: 0.125 | BB38: 800 | BC38: 100 | BD38: mg | BE38: Wikipedia 'NSV machine gun': 700-800 cyclic, 100 practical | BG38: doi | BH38: 9.5 | BI38: 15 | CH38: 5.0833 | CI38: 5 | DE38: 15 | DF38: Kinetic | DH38: TRUE | DM38: any | DN38: BulletBig | DT38: boss_hmg | EB38: 2 | EE38: TRUE | EQ38: NSV 12.7 mm API | ES38: api | EU38: boss_hmg | GA38: nsv_12_7_mm_api | GD38: Assets/MachineBrigade/Resources/Data/balance.json: secondRounds.rounds[10] | GE38: {"id":"boss_hmg_api","roundOf":"boss_hmg","inherits":"boss_hmg","weaponFamily":"nsv_12_7_mm_api","round":"api","for":["any"],"elite":true,"real":"NSV 12.7 mm API","damageType":"Kinetic","pen":2,"damage":15,"form":"BulletBig","piercing":true}
A39: boss_howitzer | B39: 2A44 203 mm | C39: cal_203 | F39: howitzer | G39: 203 | K39: HighExplosive | L39: 4 | M39: Shell | N39: 1 | O39: RIPPLE | P39: 1 | Q39: 0.1 | R39: 9.44 | S39: 0 | T39: 0 | U39: 0 | V39: 0 | W39: 420 | X39: 8 | Y39: 0 | Z39: 100 | AA39: 60 | AB39: 0 | AC39: Ground | AE39: 3 | AF39: Huge | AG39: FALSE | AH39: FALSE | AI39: FALSE | AJ39: FALSE | AK39: FALSE | AL39: FALSE | AM39: FALSE | AN39: 203 | AO39: 0 | AP39: T4 | AR39: boss_howitzer_guided | AS39: boss_part | AT39: howitzer_203 | AU39: 1 | AV39: howitzer_203:part | AW39: 2.5 | AX39: TRUE | AZ39: =IF(AND($AX$39,$AW$39>$AA$39/$Z$39),$AW$39,$AA$39/$Z$39) | BA39: 2.5 | BB39: 2.5 | BC39: 1 | BD39: gun | BE39: Wikipedia '2S7 Pion': 1.5 rpm (2S7M Malka 2.5) | BG39: doi | BR39: 60 | BS39: 100 | CT39: 203 | DD39: 9.44 | DE39: 420 | DF39: HighExplosive | DJ39: howitzer | DS39: Huge | DX39: TRUE | EB39: 4 | EI39: shell_155 | EJ39: 0.9455 | EK39: 100 | EP39: 60 | EQ39: 2A44 203 mm | ET39: 1.04 | EX39: 203 | EY39: 8 | EZ39: 3 | GB39: cal_203 | GD39: Assets/MachineBrigade/Resources/Data/balance.json: weapons[137] | GE39: {"id":"boss_howitzer","lobs":true,"weaponFamilyId":"cal_203","real":"2A44 203 mm","family":"howitzer","size":203,"caliberMm":203,"pen":4,"projectileModel":"shell_155","projectileScale":0.9455,"roundLength":1.04,"damageType":"HighExplosive","damage":420,"cooldown":9.44,"range":60,"projectileSpeed":100,"splash":8,"spread":3,"impactTier":"Huge"}
A40: boss_howitzer_guided | B40: 2A44 203 mm guided | C40: cal_203 | F40: howitzer | G40: 203 | K40: HighExplosive | L40: 4 | M40: Shell | N40: 1 | O40: RIPPLE | P40: 1 | Q40: 0.1 | R40: 9.44 | S40: 0 | T40: 0 | U40: 0 | V40: 0 | W40: 420 | X40: 8 | Y40: 0 | Z40: 100 | AA40: 60 | AB40: 0 | AC40: Ground | AE40: 0 | AF40: Huge | AG40: FALSE | AH40: FALSE | AI40: FALSE | AJ40: FALSE | AK40: FALSE | AL40: FALSE | AM40: TRUE | AN40: 203 | AO40: 0 | AP40: T4 | AQ40: boss_howitzer | AU40: 0 | AW40: 2.5 | AX40: TRUE | AZ40: =IF(AND($AX$40,$AW$40>$AA$40/$Z$40),$AW$40,$AA$40/$Z$40) | BA40: 2.5 | BB40: 2.5 | BC40: 1 | BD40: gun | BE40: Wikipedia '2S7 Pion': 1.5 rpm (2S7M Malka 2.5) | BG40: doi | BR40: 60 | BS40: 100 | CR40: 1 | DE40: 420 | DF40: HighExplosive | DH40: TRUE | DM40: armour | DN40: HeShell | DP40: TRUE | DT40: boss_howitzer | EB40: 4 | EQ40: 2A44 203 mm guided | ES40: guided | EU40: boss_howitzer | EZ40: 0 | FW40: Ground | GD40: Assets/MachineBrigade/Resources/Data/balance.json: secondRounds.rounds[11] | GE40: {"id":"boss_howitzer_guided","roundOf":"boss_howitzer","inherits":"boss_howitzer","weaponFamily":"","round":"guided","for":["armour"],"elite":true,"real":"2A44 203 mm guided","damageType":"HighExplosive","pen":4,"damage":420,"spread":0,"burst":1,"guided":true,"form":"HeShell","targets":"Ground"}
...

Sheet Vu_khi_he_so_thuong
A1: id | B1: vu_khi_id | C1: thu_tu | D1: armor | E1: class | F1: flank | G1: mult | H1: still | I1: nguon | J1: raw_json
A2: borer_drill/0 | B2: borer_drill | C2: 0 | D2: Structure | G2: 2 | I2: Assets/MachineBrigade/Resources/Data/balance.json: weapons[243].bonuses[0] | J2: {"armor":"Structure","mult":2}
A3: detonator/0 | B3: detonator | C3: 0 | D3: Structure | G3: 0.5 | I3: Assets/MachineBrigade/Resources/Data/balance.json: weapons[72].bonuses[0] | J3: {"armor":"Structure","mult":0.5}
A4: dozer_blade/0 | B4: dozer_blade | C4: 0 | D4: Structure | G4: 3 | I4: Assets/MachineBrigade/Resources/Data/balance.json: weapons[104].bonuses[0] | J4: {"armor":"Structure","mult":3}
