Workbook

Sheet Boss
A1: id | B1: phan_loai | C1: ten_en | D1: ten_vi | E1: ten_ngan_vi | F1: lop | G1: nhanh | H1: ke_thua_tu | I1: base_cp | J1: mau_hp | K1: mau_trong_tran_hp | L1: giap_truoc | M1: giap_hong | N1: giap_sau | O1: giap_noc | P1: cong_trinh | Q1: toc_do_m_s | R1: xoay_than_deg_s | S1: xoay_thap_deg_s | T1: tam_nhin_m | U1: ban_kinh_m | V1: dai_m | W1: rong_m | X1: bay | Y1: do_cao_m | Z1: dung_yen | AA1: ban_khi_chay | AB1: toc_do_chiem | AC1: tha_du_s | AD1: he_so_sat_thuong_ra | AE1: vu_khi_chinh | AF1: vu_khi_phu | AG1: noi_tai | AH1: tu_ve | AI1: so_lan_tu_ve | AJ1: hoi_tu_ve_s | AK1: mo_hinh | AL1: so_voi_ban_goc | AM1: base_cp_truoc | AN1: base_cp_sau | AO1: mau_hp_truoc | AP1: mau_hp_sau | AQ1: giap_truoc_truoc | AR1: giap_truoc_sau | AS1: giap_hong_truoc | AT1: giap_hong_sau | AU1: giap_sau_truoc | AV1: giap_sau_sau | AW1: giap_noc_truoc | AX1: giap_noc_sau | AY1: toc_do_m_s_truoc | AZ1: toc_do_m_s_sau | BA1: tam_nhin_m_truoc | BB1: tam_nhin_m_sau | BC1: vu_khi_chinh_truoc | BD1: vu_khi_chinh_sau | BE1: vu_khi_phu_truoc | BF1: vu_khi_phu_sau | BG1: he_so_sat_thuong_ra_truoc | BH1: he_so_sat_thuong_ra_sau | BI1: khung | BJ1: kieu_duong_di | BK1: tuong | BL1: bien_the_cua | BM1: so_be | BN1: so_nong | BO1: sieu_vu_khi | BP1: sieu_vu_khi_chu_ky_s | BQ1: sieu_vu_khi_cach_nham | BR1: ho_tong | BS1: chuong | BT1: nhiem_vu | BU1: thoi_gian_ha_muc_tieu_s | BV1: air | BW1: altitude_m | BX1: arena | BY1: armour | BZ1: armour_front | CA1: armour_rear | CB1: armour_side | CC1: armour_top | CD1: big_attack | CE1: big_attack_scale_cooldown_s | CF1: big_attack_scale_damage | CG1: big_attack_scale_warn_s | CH1: boss | CI1: burrow_damage | CJ1: burrow_dive_s | CK1: burrow_exposed_s | CL1: burrow_exposed_taken | CM1: burrow_first | CN1: burrow_radius_m | CO1: burrow_speed_m_s | CP1: burrow_stop_phase | CQ1: burrow_stun_s | CR1: burrow_surface | CS1: burrow_surface_by_phase | CT1: burrow_under | CU1: burrow_under_by_phase | CV1: burrow_warn_s | CW1: capture_rate | CX1: cp | CY1: craft | CZ1: craft_carries | DA1: craft_every_s | DB1: craft_first | DC1: craft_max | DD1: craft_per | DE1: craft_phase | DF1: craft_unit | DG1: cruise_damage | DH1: cruise_every_s | DI1: cruise_final | DJ1: cruise_first | DK1: cruise_impact_tier | DL1: cruise_phase | DM1: cruise_radius_m | DN1: cruise_warn_s | DO1: cruise_warning | DP1: cruise_weapon | DQ1: crush_armour_cut | DR1: crush_dps | DS1: crush_min_speed | DT1: crush_reach_m | DU1: crush_structure | DV1: death_explosion_damage | DW1: death_explosion_delay_s | DX1: death_explosion_radius_m | DY1: death_explosion_tier | DZ1: drop_parts | EA1: duel_escorts | EB1: factory_cap | EC1: factory_doors | ED1: factory_every_s | EE1: factory_first | EF1: factory_grow | EG1: factory_max | EH1: factory_min | EI1: factory_units | EJ1: fire_trail_dps | EK1: fire_trail_every_s | EL1: fire_trail_radius_m | EM1: fire_trail_seconds_s | EN1: fires_while_moving | EO1: flying | EP1: frame | EQ1: general | ER1: guard | ES1: guard_count | ET1: guard_damage | EU1: guard_every_s | EV1: guard_pad_m | EW1: guard_radius_m | EX1: holds_to_fire | EY1: hp | EZ1: landing_every_s | FA1: landing_first | FB1: landing_landings | FC1: landing_max | FD1: landing_min | FE1: landing_ramp | FF1: landing_stop | FG1: landing_units | FH1: length_m | FI1: livery | FJ1: main_aim | FK1: main_model | FL1: main_slot | FM1: mines_damage | FN1: mines_interval_s | FO1: mines_life | FP1: mines_max | FQ1: mines_radius_m | FR1: mines_tier | FS1: mines_trigger | FT1: mines_turn_strip | FU1: model | FV1: model_size_height_m | FW1: model_size_length_m | FX1: model_size_width_m | FY1: mount_weapons_0 | FZ1: mount_weapons_1 | GA1: mount_weapons_10 | GB1: mount_weapons_2 | GC1: mount_weapons_3 | GD1: mount_weapons_4 | GE1: mount_weapons_5 | GF1: mount_weapons_6 | GG1: mount_weapons_7 | GH1: mount_weapons_8 | GI1: mount_weapons_9 | GJ1: naval_escape_phase | GK1: naval_escape_speed_m_s | GL1: naval_lanes | GM1: naval_role | GN1: outgoing_damage_mult | GO1: paint | GP1: paint_finish | GQ1: part_lock | GR1: part_lock_count | GS1: part_lock_kind | GT1: pods | GU1: pods_count | GV1: pods_damage | GW1: pods_every_by_phase | GX1: pods_every_s | GY1: pods_fall | GZ1: pods_first | HA1: pods_max | HB1: pods_min | HC1: pods_offset_m | HD1: pods_per_pod | HE1: pods_radius_m | HF1: pods_spread | HG1: pods_stun_s | HH1: pods_tiers | HI1: pods_unit | HJ1: pods_units | HK1: pods_warning | HL1: radio_spawn | HM1: radius_m | HN1: rank | HO1: route | HP1: salvo | HQ1: salvo_blind_scatter | HR1: salvo_damage | HS1: salvo_edge_m | HT1: salvo_every_s | HU1: salvo_first | HV1: salvo_radius_m | HW1: salvo_range_m | HX1: salvo_shells | HY1: salvo_spread | HZ1: salvo_sweep | IA1: salvo_warn_s | IB1: salvo_weapon | IC1: scale | ID1: scoot_max | IE1: scoot_min | IF1: scoot_shots | IG1: size | IH1: skills | II1: speed_m_s | IJ1: spot_aura | IK1: stealth | IL1: tiers_armour_belly | IM1: tiers_armour_grounded | IN1: tiers_armour_hull | IO1: tiers_crash | IP1: tiers_crash_at | IQ1: tiers_crash_damage | IR1: tiers_crash_debris | IS1: tiers_crash_debris_at | IT1: tiers_crash_fall | IU1: tiers_crash_form | IV1: tiers_crash_guns | IW1: tiers_crash_radius_m | IX1: tiers_crash_warning | IY1: tiers_descend_m_s | IZ1: tiers_halt_phase | JA1: tiers_heights_high | JB1: tiers_heights_low | JC1: tiers_heights_orbit | JD1: tiers_hijack | JE1: tiers_hijack_difficulties | JF1: tiers_hijack_every_s | JG1: tiers_hijack_first | JH1: tiers_hijack_seconds_s | JI1: tiers_hijack_warn_s | JJ1: tiers_marks | JK1: tiers_opening | JL1: tiers_radio_appear | JM1: tiers_radio_crash | JN1: tiers_radio_descend_m_s | JO1: tiers_radio_down | JP1: tiers_radio_hijack | JQ1: tiers_radio_hijack_warn | JR1: tiers_radio_phase2 | JS1: tiers_radio_phase3 | JT1: tiers_shift | JU1: turn_rate_deg_s | JV1: turret_turn_rate_deg_s | JW1: variant_drop | JX1: variant_keep | JY1: variant_mark | JZ1: variant_name | KA1: variant_of | KB1: variant_size | KC1: variant_tint_b | KD1: variant_tint_g | KE1: variant_tint_r | KF1: vision_m | KG1: wake | KH1: wake_mounts | KI1: wake_phase | KJ1: weapon | KK1: weapon_damage | KL1: width_m | KM1: nguon | KN1: raw_json
A2: argus | B2: mini | C2: Argus · Scout Airship | D2: Argus · Khí cầu trinh sát | E2: Argus | I2: 0 | J2: 94850 | K2: 80622.5 | L2: 2 | M2: 2 | N2: 2 | O2: 2 | P2: FALSE | Q2: 4.5 | R2: 8 | S2: 90 | T2: 80 | U2: 18 | X2: TRUE | Y2: 30 | Z2: FALSE | AA2: TRUE | AB2: 0 | AC2: 3.5 | AD2: 1.7892 | AE2: p26_roc_main_roc_bombs | AF2: p26_roc_main_roc_bombs | AH2: none | AK2: argus | AL2: doi | BG2: 1 | BH2: 1.7892 | BI2: aircraft | BJ2: aircraft | BK2: quaden | BL2: command_airship | BM2: 2 | BN2: 2 | BR2: FALSE | BS2: 10 | BT2: c10s2 | BU2: tuan:66;day_du:60 | EQ2: quaden | EY2: 94850 | GO2: #5d6a75 | GP2: 0.35;0.45 | HL2: radio.quaden.argus | IJ2: 0.5 | JX2: radar;engine_fl;engine_fr | JY2: argus | KA2: command_airship | KB2: 0.4375 | KC2: 0.8 | KD2: 0.9 | KE2: 0.92 | KK2: 1.44 | KM2: Assets/MachineBrigade/Resources/Data/balance.json: vehicles[169] | KN2: {"id":"argus","paint":"#5d6a75","paintFinish":[0.35,0.45],"wake":null,"variantOf":"command_airship","general":"quaden","radioSpawn":"radio.quaden.argus","hp":94850,"weaponDamage":1.44,"partLock":null,"spotAura":0.5,"skills":[],"variant":{"size":0.4375,"keep":["radar","engine_fl","engine_fr"],"tint":[0.92,0.9,0.8],"mark":"argus","tune":{"radar":{"hp":0.14,"stops":["spotaura"],"radio":"radio.part.radar","breakDamage":0.3},"engine_fl":{"hp":0.1,"breakDamage":0.3},"engine_fr":{"hp":0.1,"breakDamage":0.3}}}}
A3: armored_train | B3: mini | C3: Juggernaut · Armoured Train | D3: Juggernaut · Đoàn tàu bọc thép | E3: Juggernaut | I3: 0 | J3: 37750 | K3: 32087.5 | L3: 4 | M3: 3 | N3: 3 | O3: 2 | P3: FALSE | Q3: 0.32 | R3: 30 | S3: 45 | T3: 50 | U3: 3.6 | V3: 56.557 | W3: 3.91 | X3: FALSE | Y3: 0 | Z3: FALSE | AA3: TRUE | AB3: 0 | AC3: 3.5 | AD3: 0.8319 | AE3: train_gun | AF3: pt14_train_grad;boss_hmg;boss_flak;train_gun;boss_flak | AG3: train_patch | AH3: none | AK3: armored_train | AL3: doi | BE3: boss_rockets;boss_hmg;boss_flak;train_gun;boss_flak | BF3: pt14_train_grad;boss_hmg;boss_flak;train_gun;boss_flak | BG3: 1 | BH3: 0.8319 | BI3: train | BJ3: rail | BK3: kessler | BM3: 6 | BN3: 6 | BR3: TRUE | BS3: 4;7 | BT3: c4m05;c7m05 | BU3: tuan:66;day_du:60 | BX3: ironport | BZ3: 4 | CA3: 3 | CB3: 3 | CC3: 2 | CH3: TRUE | CW3: 0 | CX3: 0 | DV3: 380 | DW3: 2.6 | DX3: 16 | DY3: Ultimate | DZ3: mortar_car | EN3: TRUE | EP3: train | EQ3: kessler | EY3: 37750 | FH3: 49.18 | GN3: 0.8319 | GO3: #3f5a3c | GP3: 0.3;0.55 | HL3: radio.kessler.juggernaut | HM3: 3.6 | HN3: mini | HO3: rail | IC3: 1.15 | IG3: 0.85 | IH3: train_patch | II3: 0.32 | JU3: 30 | JV3: 45 | KF3: 50 | KJ3: train_gun | KK3: 1.859 | KL3: 3.4 | KM3: Assets/MachineBrigade/Resources/Data/balance.json: vehicles[140] | KN3: {"id":"armored_train","paint":"#3f5a3c","paintFinish":[0.3,0.55],"outgoingDamageMult":0.8319,"weaponDamage":1.859,"frame":"train","arena":"ironport","route":"rail","rank":"mini","general":"kessler","size":0.85,"dropParts":["mortar_car"],"radioSpawn":"radio.kessler.juggernaut","scale":1.15,"armour":[4,3,3,2],"hp":37750,"speed":0.32,"turnRate":30,"turretTurnRate":45,"radius":3.6,"length":49.18,"width":3.4,"cp":0,"vision":50,"firesWhileMoving":true,"weapon":"train_gun","captureRate":0,"boss":true,"skills":["train_patch"],"secondary":[{"weapon":"pt14_train_grad","slot":"rocket","aim":"Free"},{"weapon":"boss_hmg","slot":"mg","aim":"Free"},{"weapon":"boss_flak","slot":"mg","aim":"Free"},{"weapon":"train_gun","slot":"main","aim":"Free"},{"weapon":"train_mortar","slot":"mortar","aim":"Free"},{"weapon":"boss_flak","slot":"mg","aim":"Free"}],"parts":[{"id":"locomotive","kind":"locomotive","hp":0.12,"armour":4,"wreck":"wreck_stump","at":[0,14.67,2.5],"radius":3.5,"speed":0.5,"radio":"radio.part.locomotive"},{"id":"gun_car_front","kind":"maingun","hp":0.12,"armour":3,"node":"Main_cannon|Muzzle_brake","wreck":"wreck_barrel","at":[0,3.97,3.7],"radius":3.0,"mounts":[0],"radio":"radio.part.maingun"},{"id":"gun_car_rear","kind":"maingun","hp":0.12,"armour":3,"wreck":"wreck_stump","at":[0,9.17,3],"radius":2.5,"mounts":[4]},{"id":"rocket_car","kind":"rockets","hp":0.1,"armour":2,"node":"Mount_rocket","wreck":"wreck_launcher","at":[0,-1.13,3],"radius":2.2,"mounts":[1]},{"id":"flak_car","kind":"flak","hp":0.1,"armour":2,"wreck":"wreck_stump","at":[0,0.82,3.2],"radius":2.0,"mounts":[3]},{"id":"mortar_car","kind":"mortar","hp":0.1,"armour":2,"node":"Part_mortar","wreck":"wreck_launcher","at":[0,-5.33,2.6],"radius":2.4,"mounts":[5]}],"deathExplosion":{"damage":380,"radius":16,"delay":2.6,"tier":"Ultimate"}}
A4: bastion_mk0 | B4: mini | C4: Bastion Mk.0 · Prototype Fortress | D4: Bastion Mk.0 · Pháo đài nguyên mẫu | E4: Bastion Mk.0 | I4: 0 | J4: 19250 | K4: 16362.5 | L4: 4 | M4: 4 | N4: 4 | O4: 3 | P4: FALSE | Q4: 1.1 | R4: 18 | S4: 22 | T4: 64 | U4: 7.5 | V4: 19.884 | W4: 10.92 | X4: FALSE | Y4: 0 | Z4: FALSE | AA4: TRUE | AB4: 0 | AC4: 3.5 | AD4: 1.4708 | AE4: p26_bastion_sec_b240 | AF4: p26_bastion_direct_b100;p26_bastion_direct_b100 | AG4: train_patch;boss_bulwark;fortress_barrage | AH4: none | AK4: bastion_mk0 | AL4: doi | BG4: 1 | BH4: 1.4708 | BI4: tracked | BJ4: tracked | BK4: brandt | BL4: fortress_bastion | BM4: 3 | BN4: 5 | BR4: FALSE | BS4: 1 | BT4: c1m05 | BU4: tuan:66;day_du:60 | BZ4: 4 | CA4: 4 | CB4: 4 | CC4: 3 | EQ4: brandt | EY4: 19250 | FU4: bastion_mk0 | GN4: 1.4708 | GO4: #7d7766 | GP4: 0.2;0.65 | HL4: radio.brandt.bastion_mk0 | II4: 1.1 | JX4: mortar;turret_fl;turret_fr | JY4: mk0 | JZ4: mk0 | KA4: fortress_bastion | KB4: 0.6 | KC4: 0.72 | KD4: 0.86 | KE4: 0.8 | KK4: 1.51 | KM4: Assets/MachineBrigade/Resources/Data/balance.json: vehicles[163] | KN4: {"id":"bastion_mk0","paint":"#7d7766","paintFinish":[0.2,0.65],"outgoingDamageMult":1.4708,"guard":null,"armour":[4,4,4,3],"variantOf":"fortress_bastion","model":"bastion_mk0","hp":19250,"weaponDamage":1.51,"general":"brandt","radioSpawn":"radio.brandt.bastion_mk0","speed":1.1,"variant":{"size":0.6,"keep":["mortar","turret_fl","turret_fr"],"tint":[0.8,0.86,0.72],"mark":"mk0","name":"mk0","tune":{"mortar":{"hp":0.15,"at":[0,-0.83,9.66]},"turret_fl":{"hp":0.1},"turret_fr":{"hp":0.1}}}}
A5: behemoth | B5: main | C5: Behemoth · Steel Monster | D5: Behemoth · Quái vật thép | E5: Behemoth | I5: 0 | J5: 35787 | K5: 30418.95 | L5: 5 | M5: 3 | N5: 2 | O5: 2 | P5: FALSE | Q5: 2.4 | R5: 25 | S5: 30 | T5: 50 | U5: 6.4 | V5: 15.108 | W5: 7.8 | X5: FALSE | Y5: 0 | Z5: FALSE | AA5: TRUE | AB5: 0 | AC5: 3.5 | AD5: 1 | AE5: p26_behemoth_main_be152 | AF5: p26_behemoth_tiny_be120;p26_behemoth_close_boss_flak;p26_behemoth_close_boss_flak;p26_behemoth_tiny_boss_missiles;p26_behemoth_tiny_boss_missiles;p26_behemoth_tiny_kornet_twin;p26_behemoth_direct_be120;p26_behemoth_direct_be120;p26_behemoth_sec_be_rockets | AG5: boss_rage;boss_bulwark | AH5: aps | AI5: 2 | AJ5: 4 | AK5: behemoth | AL5: doi | AO5: 33550 | AP5: 35787 | BI5: tracked | BJ5: tracked | BK5: varga | BM5: 10 | BN5: 13 | BO5: behemoth_barrage | BP5: 45 | BQ5: group | BR5: TRUE | BS5: 2 | BU5: tuan:168;day_du:150 | BZ5: 5 | CA5: 2 | CB5: 3 | CC5: 2 | CD5: behemoth_barrage | CH5: TRUE | CW5: 0 | CX5: 0 | DV5: 400 | DW5: 2.6 | DX5: 18 | DY5: Ultimate | EN5: TRUE | EP5: tracked | EQ5: varga | ES5: 4 | ET5: 160 | EU5: 5 | EV5: 6 | EW5: 15 | EY5: 35787 | FH5: 12.59 | FY5: p26_behemoth_main_be152 | FZ5: p26_behemoth_tiny_be120 | GB5: p26_behemoth_close_boss_flak | GC5: p26_behemoth_close_boss_flak | GD5: p26_behemoth_tiny_boss_missiles | GE5: p26_behemoth_tiny_boss_missiles | GF5: p26_behemoth_tiny_kornet_twin | GG5: p26_behemoth_direct_be120 | GH5: p26_behemoth_direct_be120 | GI5: p26_behemoth_sec_be_rockets | GO5: #5a6340 | GP5: 0.3;0.55 | HL5: radio.varga.behemoth | HM5: 6.4 | HN5: main | IC5: 1.2 | IG5: 1.5712 | IH5: boss_rage;boss_bulwark | II5: 2.4 | JU5: 25 | JV5: 30 | KF5: 50 | KH5: 9 | KI5: 1 | KJ5: gun_behemoth | KK5: 1 | KL5: 6.5 | KM5: Assets/MachineBrigade/Resources/Data/balance.json: vehicles[138] | KN5: {"id":"behemoth","paint":"#5a6340","paintFinish":[0.3,0.55],"guard":{"radius":15,"count":4,"every":5,"damage":160,"pad":6},"wake":{"phase":1,"mounts":[9]},"mountWeapons":{"0":"p26_behemoth_main_be152","1":"p26_behemoth_tiny_be120","2":"p26_behemoth_close_boss_flak","3":"p26_behemoth_close_boss_flak","4":"p26_behemoth_tiny_boss_missiles","5":"p26_behemoth_tiny_boss_missiles","6":"p26_behemoth_tiny_kornet_twin","7":"p26_behemoth_direct_be120","8":"p26_behemoth_direct_be120","9":"p26_behemoth_sec_be_rockets"},"frame":"tracked","rank":"main","general":"varga","size":1.5712,"radioSpawn":"radio.varga.behemoth","scale":1.2,"armour":[5,3,2,2],"hp":35787,"weaponDamage":1,"speed":2.4,"turnRate":25,"turretTurnRate":30,"radius":6.4,"length":12.59,"width":6.5,"cp":0,"vision":50,"firesWhileMoving":true,"weapon":"gun_behemoth","captureRate":0,"boss":true,"bigAttack":"behemoth_barrage","skills":["boss_rage","boss_bulwark"],"aps":{"radius":11,"charges":2,"recharge":4},"secondary":[{"weapon":"gun_120mm","slot":"gun","aim":"Free"},{"weapon":"boss_flak","slot":"mg","aim":"Free"},{"weapon":"boss_flak","slot":"mg","aim":"Free"},{"weapon":"boss_missiles","slot":"missile","aim":"Hull"},{"weapon":"boss_missiles","slot":"missile","aim":"Hull"},{"weapon":"kornet_twin","slot":"missile","aim":"Free"}],"parts":[{"id":"main_gun","kind":"maingun","hp":0.07,"armour":3,"node":"Main_cannon|Main_cannon_2|Muzzle_brake|Muzzle_brake_2","wreck":"wreck_barrel","at":[0,3.5,4.1],"radius":3.2,"mounts":[0],"radio":"radio.part.maingun"},{"id":"gun_120","kind":"gun","hp":0.07,"armour":3,"node":"Mount_gun","wreck":"wreck_turret","at":[0,3.45,2.8],"radius":2.2,"mounts":[1,6]},{"id":"flak_r","kind":"flak","hp":0.07,"armour":2,"node":"Mount_mg","wreck":"wreck_turret","at":[0.9,-1.15,4.8],"radius":1.8,"mounts":[2]},{"id":"flak_l","kind":"flak","hp":0.07,"armour":2,"node":"Mount_mg.001","wreck":"wreck_turret","at":[-0.9,-1.15,4.8],"radius":1.8,"mounts":[3]},{"id":"missiles_r","kind":"missiles","hp":0.07,"armour":2,"wreck":"wreck_launcher","at":[2.6,-2.5,2.3],"radius":2.0,"mounts":[4]},{"id":"missiles_l","kind":"missiles","hp":0.07,"armour":2,"wreck":"wreck_launcher","at":[-2.6,-2.5,2.3],"radius":2.0,"mounts":[5]},{"id":"aps","kind":"aps","hp":0.07,"armour":1,"wreck":"wreck_stump","at":[0,0.6,5.2],"radius":1.6,"stops":["aps"]},{"use":"side_gun_120","id":"side_gun_l","node":"Mount_gun.001","at":[-3.4,1.0,2.6]},{"use":"side_gun_120","id":"side_gun_r","node":"Mount_gun.002","at":[3.4,1.0,2.6]},{"use":"rocket_pod","id":"rocket_pod","node":"Mount_rocket","at":[0,-3.8,4.4]}],"deathExplosion":{"damage":400,"radius":18,"delay":2.6,"tier":"Ultimate"}}
A6: behemoth_inferno | B6: mini | C6: Inferno · Flame Behemoth | D6: Inferno · Behemoth phun lửa | E6: Inferno | I6: 0 | J6: 24600 | K6: 20910 | L6: 4 | M6: 3 | N6: 2 | O6: 2 | P6: FALSE | Q6: 2.9 | R6: 28 | S6: 40 | T6: 46 | U6: 6.4 | V6: 15.108 | W6: 7.8 | X6: FALSE | Y6: 0 | Z6: FALSE | AA6: TRUE | AB6: 0 | AC6: 3.5 | AD6: 1 | AE6: boss_flamer | AF6: boss_thermo;boss_flamer | AG6: boss_rage | AH6: none | AK6: behemoth_inferno | AL6: giong | BI6: tracked | BJ6: tracked | BK6: varga | BM6: 3 | BN6: 3 | BR6: TRUE | BS6: 2;7 | BT6: c2m05;c7m13 | BU6: tuan:66;day_du:60 | BZ6: 4 | CA6: 2 | CB6: 3 | CC6: 2 | CH6: TRUE | CW6: 0 | CX6: 0 | DV6: 420 | DW6: 2.6 | DX6: 19 | DY6: Ultimate | DZ6: flak | EJ6: 18 | EK6: 4 | EL6: 3.5 | EM6: 10 | EN6: TRUE | EP6: tracked | EQ6: varga | EY6: 24600 | FH6: 12.59 | GO6: #7a3b26 | GP6: 0.3;0.55 | HL6: radio.varga.inferno | HM6: 6.4 | HN6: mini | IC6: 1.2 | IG6: 1.1252 | IH6: boss_rage | II6: 2.9 | JU6: 28 | JV6: 40 | KF6: 46 | KJ6: boss_flamer | KK6: 1.962 | KL6: 6.5 | KM6: Assets/MachineBrigade/Resources/Data/balance.json: vehicles[146] | KN6: {"id":"behemoth_inferno","paint":"#7a3b26","paintFinish":[0.3,0.55],"frame":"tracked","rank":"mini","general":"varga","size":1.1252,"dropParts":["flak"],"radioSpawn":"radio.varga.inferno","scale":1.2,"armour":[4,3,2,2],"hp":24600,"weaponDamage":1.962,"speed":2.9,"turnRate":28,"turretTurnRate":40,"radius":6.4,"length":12.59,"width":6.5,"cp":0,"vision":46,"firesWhileMoving":true,"weapon":"boss_flamer","captureRate":0,"boss":true,"skills":["boss_rage"],"fireTrail":{"every":4,"seconds":10,"radius":3.5,"dps":18},"secondary":[{"weapon":"boss_thermo","slot":"rocket","aim":"Free"},{"weapon":"boss_flak","slot":"mg","aim":"Free"},{"weapon":"boss_flamer","slot":"main","aim":"Turret"}],"parts":[{"id":"flamer_r","kind":"flamer","hp":0.12,"armour":2,"node":"Main_cannon|Main_cannon_hose|Main_cannon_jacket|Muzzle_brake|Muzzle_brake_glow|Muzzle_brake_pilot","wreck":"wreck_barrel","at":[0.62,3.4,4.1],"radius":2.2,"mounts":[0],"radio":"radio.part.maingun"},{"id":"flamer_l","kind":"flamer","hp":0.12,"armour":2,"node":"Main_cannon_2|Main_cannon_2_hose|Main_cannon_2_jacket|Muzzle_brake_2|Muzzle_brake_2_glow|Muzzle_brake_2_pilot","wreck":"wreck_barrel","at":[-0.62,3.4,4.1],"radius":2.2,"mounts":[3]},{"id":"thermo","kind":"thermo","hp":0.12,"armour":2,"node":"Mount_rocket","wreck":"wreck_turret","at":[0,3.45,2.8],"radius":2.2,"mounts":[1]},{"id":"flak","kind":"flak","hp":0.1,"armour":2,"node":"Mount_mg","wreck":"wreck_turret","at":[0.9,-1.15,4.8],"radius":1.8,"mounts":[2]},{"id":"fuel","kind":"fuel","hp":0.08,"armour":1,"node":"Fuel_tanks|Tank_straps|Tank_hazard","wreck":"wreck_stump","at":[0,-4.6,2.6],"radius":2.6,"stops":["trail"]}],"deathExplosion":{"damage":420,"radius":19,"delay":2.6,"tier":"Ultimate"}}
A7: behemoth_mk0 | B7: mini | C7: Behemoth Mk.0 · Prototype Behemoth | D7: Behemoth Mk.0 · Behemoth nguyên mẫu | E7: Behemoth Mk.0 | I7: 0 | J7: 33900 | K7: 28815 | L7: 3 | M7: 3 | N7: 2 | O7: 1 | P7: FALSE | Q7: 2.2 | R7: 25 | S7: 30 | T7: 50 | U7: 6.4 | V7: 15.108 | W7: 7.8 | X7: FALSE | Y7: 0 | Z7: FALSE | AA7: TRUE | AB7: 0 | AC7: 3.5 | AD7: 1 | AE7: p26_behemoth_main_be152 | AF7: p26_behemoth_direct_be120;p26_behemoth_direct_be120;p26_behemoth_sec_be_rockets | AG7: boss_bulwark | AH7: none | AK7: behemoth_mk0 | AL7: giong | BI7: tracked | BJ7: tracked | BK7: varga | BL7: behemoth | BM7: 4 | BN7: 7 | BR7: FALSE | BS7: 13 | BT7: i1m03 | BU7: tuan:66;day_du:60 | BZ7: 3 | CA7: 2 | CB7: 3 | CC7: 1 | EQ7: varga | EY7: 33900 | GO7: #6b6a4e | GP7: 0.25;0.6 | HL7: radio.varga.behemoth_mk0 | IH7: boss_bulwark | II7: 2.2 | JX7: main_gun;side_gun_l;side_gun_r;rocket_pod | JY7: mk0 | JZ7: mk0 | KA7: behemoth | KB7: 0.6538 | KC7: 0.66 | KD7: 0.82 | KE7: 0.94 | KK7: 0.884 | KM7: Assets/MachineBrigade/Resources/Data/balance.json: vehicles[170] | KN7: {"id":"behemoth_mk0","paint":"#6b6a4e","paintFinish":[0.25,0.6],"guard":null,"wake":null,"variantOf":"behemoth","hp":33900,"weaponDamage":0.884,"general":"varga","radioSpawn":"radio.varga.behemoth_mk0","armour":[3,3,2,1],"speed":2.2,"aps":null,"skills":["boss_bulwark"],"variant":{"size":0.6538,"keep":["main_gun","side_gun_l","side_gun_r","rocket_pod"],"tint":[0.94,0.82,0.66],"mark":"mk0","name":"mk0","tune":{"main_gun":{"hp":0.14},"side_gun_l":{"hp":0.12},"side_gun_r":{"hp":0.12},"rocket_pod":{"hp":0.12}}}}
A8: behemoth_mk2 | B8: mini | C8: Behemoth Mk.II · Upgraded Behemoth | D8: Behemoth Mk.II · Behemoth nâng cấp | E8: Behemoth Mk.II | I8: 0 | J8: 53500 | K8: 45475 | L8: 4 | M8: 3 | N8: 2 | O8: 2 | P8: FALSE | Q8: 2.4 | R8: 25 | S8: 30 | T8: 50 | U8: 6.4 | V8: 15.108 | W8: 7.8 | X8: FALSE | Y8: 0 | Z8: FALSE | AA8: TRUE | AB8: 0 | AC8: 3.5 | AD8: 1 | AE8: p26_behemoth_main_be152 | AF8: p26_behemoth_close_boss_flak;p26_behemoth_close_boss_flak | AG8: boss_rage;boss_bulwark | AH8: aps | AI8: 2 | AJ8: 4 | AK8: behemoth_mk2 | AL8: giong | BI8: tracked | BJ8: tracked | BK8: varga | BL8: behemoth | BM8: 3 | BN8: 4 | BR8: FALSE | BS8: 6;7;12 | BT8: c6m05 | BU8: tuan:66;day_du:60 | BZ8: 4 | CA8: 2 | CB8: 3 | CC8: 2 | EQ8: varga | EY8: 53500 | GO8: #3f4a3a | GP8: 0.35;0.5 | HL8: radio.varga.behemoth_mk2 | JX8: main_gun;flak_r;flak_l;aps | JY8: mk2 | JZ8: mk2 | KA8: behemoth | KB8: 0.6923 | KC8: 1.1 | KD8: 0.93 | KE8: 0.82 | KK8: 1.928 | KM8: Assets/MachineBrigade/Resources/Data/balance.json: vehicles[167] | KN8: {"id":"behemoth_mk2","paint":"#3f4a3a","paintFinish":[0.35,0.5],"guard":null,"wake":null,"variantOf":"behemoth","hp":53500,"weaponDamage":1.928,"general":"varga","radioSpawn":"radio.varga.behemoth_mk2","armour":[4,3,2,2],"variant":{"size":0.6923,"keep":["main_gun","flak_r","flak_l","aps"],"tint":[0.82,0.93,1.1],"mark":"mk2","name":"mk2","tune":{"main_gun":{"hp":0.13},"flak_r":{"hp":0.09},"flak_l":{"hp":0.09},"aps":{"hp":0.08}}}}
A9: behemoth_tempest | B9: mini | C9: Tempest · Railgun Behemoth | D9: Tempest · Behemoth pháo điện từ | E9: Tempest | I9: 0 | J9: 37750 | K9: 32087.5 | L9: 4 | M9: 3 | N9: 2 | O9: 2 | P9: FALSE | Q9: 2.6 | R9: 25 | S9: 28 | T9: 70 | U9: 6.4 | V9: 19.008 | W9: 7.8 | X9: FALSE | Y9: 0 | Z9: FALSE | AA9: TRUE | AB9: 0 | AC9: 3.5 | AD9: 1 | AE9: boss_railgun | AF9: coilgun;coilgun | AG9: mothership_shield;boss_bulwark;boss_emp | AH9: aps | AI9: 2 | AJ9: 1.6 | AK9: behemoth_tempest | AL9: giong | BI9: tracked | BJ9: tracked | BK9: kessler | BM9: 3 | BN9: 3 | BR9: TRUE | BS9: 4 | BU9: tuan:66;day_du:60 | BZ9: 4 | CA9: 2 | CB9: 3 | CC9: 2 | CH9: TRUE | CW9: 0 | CX9: 0 | DV9: 400 | DW9: 2.6 | DX9: 18 | DY9: Ultimate | EN9: TRUE | EP9: tracked | EQ9: kessler | EY9: 37750 | FH9: 15.84 | GO9: #3d5566 | GP9: 0.35;0.5 | HL9: radio.kessler.tempest | HM9: 6.4 | HN9: mini | IC9: 1.2 | IG9: 0.8944 | IH9: mothership_shield;boss_bulwark;boss_emp | II9: 2.6 | JU9: 25 | JV9: 28 | KF9: 70 | KJ9: boss_railgun | KK9: 1.74 | KL9: 6.5 | KM9: Assets/MachineBrigade/Resources/Data/balance.json: vehicles[147] | KN9: {"id":"behemoth_tempest","paint":"#3d5566","paintFinish":[0.35,0.5],"frame":"tracked","rank":"mini","general":"kessler","size":0.8944,"radioSpawn":"radio.kessler.tempest","scale":1.2,"armour":[4,3,2,2],"hp":37750,"weaponDamage":1.74,"speed":2.6,"turnRate":25,"turretTurnRate":28,"radius":6.4,"length":15.84,"width":6.5,"cp":0,"vision":70,"firesWhileMoving":true,"weapon":"boss_railgun","captureRate":0,"boss":true,"skills":["mothership_shield","boss_bulwark","boss_emp"],"aps":{"radius":26,"charges":2,"recharge":1.6,"rockets":true,"laser":true},"secondary":[{"weapon":"coilgun","slot":"gun","aim":"Free"},{"weapon":"coilgun","slot":"gun","aim":"Free"}],"parts":[{"id":"railgun","kind":"railgun","hp":0.15,"armour":3,"node":"Main_cannon*","wreck":"wreck_barrel","at":[0,5.5,4.1],"radius":3.2,"mounts":[0],"radio":"radio.part.maingun"},{"id":"coil_l","kind":"coilgun","hp":0.1,"armour":3,"node":"Mount_gun","wreck":"wreck_turret","at":[-0.9,3.3,2.9],"radius":1.8,"mounts":[1]},{"id":"coil_r","kind":"coilgun","hp":0.1,"armour":3,"node":"Mount_gun.001","wreck":"wreck_turret","at":[0.9,3.3,2.9],"radius":1.8,"mounts":[2]},{"id":"shield","kind":"shield","hp":0.12,"armour":2,"node":"Radar","wreck":"wreck_stump","at":[0,-3.3,5.9],"radius":2.0,"skills":["mothership_shield","boss_bulwark"],"radio":"radio.part.shield"},{"id":"interceptor","kind":"laser","hp":0.08,"armour":1,"node":"Aps_faces|Aps_tubes|Aps_tubes_bore","wreck":"wreck_stump","at":[0,-0.4,4.4],"radius":2.4,"stops":["aps"],"fx":"energy"}],"deathExplosion":{"damage":400,"radius":18,"delay":2.6,"tier":"Ultimate"}}
A10: coeus | B10: mini | C10: Coeus · Gunship Cruiser | D10: Coeus · Tuần dương hạm pháo kích | E10: Coeus | I10: 0 | J10: 94850 | K10: 80622.5 | L10: 4 | M10: 4 | N10: 4 | O10: 4 | P10: FALSE | Q10: 3.6 | R10: 10 | S10: 120 | T10: 80 | U10: 10 | V10: 34 | W10: 22 | X10: TRUE | Y10: 22 | Z10: FALSE | AA10: TRUE | AB10: 0 | AC10: 3.5 | AD10: 1 | AE10: pt14_co_203 | AF10: pt14_co_v76;pt14_co_v76;pt14_co_spike;pt14_co_spike | AG10: boss_rage | AH10: none | AK10: coeus | AL10: moi | BI10: spacecraft | BJ10: spacecraft | BK10: aurel | BL10: hyperion | BM10: 5 | BN10: 6 | BR10: FALSE | BU10: tuan:66;day_du:60 | EQ10: aurel | EY10: 94850 | FI10: own | FU10: coeus | FV10: 12.8 | FW10: 40.3 | FX10: 23.1 | FY10: pt14_co_203 | GO10: #6e7478 | GP10: 0.5;0.42 | HL10: radio.aurel.coeus | II10: 3.6 | JJ10: 0.45 | JK10: 0 | JR10: radio.aurel.coeus.phase2 | JX10: main_laser;main_engine;thruster_rl;thruster_rr | JY10: coeus | KA10: hyperion | KB10: 0.6 | KC10: 0.88 | KD10: 0.96 | KE10: 1.04 | KK10: 1 | KM10: Assets/MachineBrigade/Resources/Data/balance.json: vehicles[175] | KN10: {"id":"coeus","livery":"own","paint":"#6e7478","paintFinish":[0.5,0.42],"variantOf":"hyperion","model":"coeus","modelSize":[40.3,23.1,12.8],"general":"aurel","radioSpawn":"radio.aurel.coeus","hp":94850,"weaponDamage":1.0,"speed":3.6,"mountWeapons":{"0":"pt14_co_203"},"secondary":[{"weapon":"pt14_co_v76","slot":"gun","aim":"Free"},{"weapon":"pt14_co_v76","slot":"gun","aim":"Free"},{"weapon":"pt14_co_spike","slot":"rocket","aim":"Free"},{"weapon":"pt14_co_spike","slot":"rocket","aim":"Free"}],"aps":null,"pods":null,"tiers":{"opening":0,"marks":[0.45],"schedule":[{"steps":[{"tier":"high","seconds":24},{"tier":"low","seconds":10}]},{"steps":[{"tier":"high","seconds":18},{"tier":"low","seconds":12}]}],"radio":{"phase2":"radio.aurel.coeus.phase2"}},"variant":{"size":0.6,"keep":["main_laser","main_engine","thruster_rl","thruster_rr"],"tint":[1.04,0.96,0.88],"mark":"coeus","tune":{"main_laser":{"hp":0.12,"kind":"maingun","at":[0,9.0,20.5]},"main_engine":{"hp":0.1,"at":[0,-31.0,11.5]},"thruster_rl":{"hp":0.08,"at":[-16.5,-20.0,11.17]},"thruster_rr":{"hp":0.08,"at":[16.5,-20.0,11.17]}}}}
A11: command_airship | B11: main | C11: Roc · Flying Headquarters | D11: Roc · Khí cầu chỉ huy | E11: Roc | I11: 0 | J11: 205875 | K11: 174993.75 | L11: 2 | M11: 2 | N11: 2 | O11: 2 | P11: FALSE | Q11: 4.5 | R11: 8 | S11: 90 | T11: 80 | U11: 18 | X11: TRUE | Y11: 30 | Z11: FALSE | AA11: TRUE | AB11: 0 | AC11: 3.5 | AD11: 1.7892 | AE11: p26_roc_main_roc_bombs | AF11: p26_roc_main_roc_bombs;p26_roc_direct_roc_atgm;p26_roc_direct_roc_atgm;p26_roc_close_twin_30_bmpt;p26_roc_close_twin_30_bmpt;p26_roc_roc105;p26_roc_roc105 | AG11: airship_launch_l;airship_launch_r | AH11: none | AK11: command_airship | AL11: doi | AO11: 137250 | AP11: 205875 | BG11: 1 | BH11: 1.7892 | BI11: aircraft | BJ11: aircraft | BK11: quaden | BM11: 8 | BN11: 8 | BO11: airship_carpet | BP11: 50 | BQ11: group | BR11: TRUE | BS11: 10 | BT11: c10m08 | BU11: tuan:168;day_du:150 | BW11: 30 | BY11: 2 | CD11: airship_carpet | CH11: TRUE | CW11: 0 | CX11: 0 | DV11: 400 | DW11: 2.6 | DX11: 18 | DY11: Ultimate | EN11: TRUE | EO11: TRUE | EP11: aircraft | EQ11: quaden | EX11: TRUE | EY11: 205875 | FJ11: Free | FL11: gun | FY11: p26_roc_main_roc_bombs | FZ11: p26_roc_main_roc_bombs | GB11: p26_roc_direct_roc_atgm | GC11: p26_roc_direct_roc_atgm | GD11: p26_roc_close_twin_30_bmpt | GE11: p26_roc_close_twin_30_bmpt | GF11: p26_roc_roc105 | GG11: p26_roc_roc105 | GN11: 1.7892 | GO11: #8e9599 | GP11: 0.3;0.5 | GR11: 2 | GS11: engine | HL11: radio.quaden.airship | HM11: 18 | HN11: main | IC11: 1 | IG11: 1.7564 | IH11: airship_launch_l;airship_launch_r | II11: 4.5 | JU11: 8 | JV11: 90 | KF11: 80 | KH11: 6;7 | KI11: 1 | KJ11: airship_flak | KK11: 1 | KM11: Assets/MachineBrigade/Resources/Data/balance.json: vehicles[151] | KN11: {"id":"command_airship","paint":"#8e9599","paintFinish":[0.3,0.5],"outgoingDamageMult":1.7892,"wake":{"phase":1,"mounts":[6,7]},"mountWeapons":{"0":"p26_roc_main_roc_bombs","1":"p26_roc_main_roc_bombs","2":"p26_roc_direct_roc_atgm","3":"p26_roc_direct_roc_atgm","4":"p26_roc_close_twin_30_bmpt","5":"p26_roc_close_twin_30_bmpt","6":"p26_roc_roc105","7":"p26_roc_roc105"},"frame":"aircraft","rank":"main","size":1.7564,"boss":true,"bigAttack":"airship_carpet","general":"quaden","radioSpawn":"radio.quaden.airship","armour":2,"hp":205875,"weaponDamage":1,"speed":4.5,"turnRate":8,"holdsToFire":true,"turretTurnRate":90,"radius":18,"scale":1.0,"cp":0,"vision":80,"flying":true,"altitude":30,"captureRate":0,"firesWhileMoving":true,"weapon":"airship_flak","mainSlot":"gun","mainAim":"Free","secondary":[{"weapon":"airship_flak","slot":"gun","aim":"Free"},{"weapon":"airship_drones","slot":"door_l","aim":"Free"},{"weapon":"airship_drones","slot":"door_r","aim":"Free"},{"weapon":"twin_30_bmpt","slot":"gun","aim":"Free"},{"weapon":"twin_30_bmpt","slot":"gun","aim":"Free"}],"skills":["airship_launch_l","airship_launch_r"],"parts":[{"id":"engine_fl","breakDamage":0,"kind":"engine","hp":0.07,"armour":2,"node":"Part_engine","wreck":"wreck_engine","at":[-14.3,9,1],"radius":3.6,"speed":0.85},{"id":"engine_fr","breakDamage":0,"kind":"engine","hp":0.07,"armour":2,"node":"Part_engine.001","wreck":"wreck_engine","at":[14.3,9,1],"radius":3.6,"speed":0.85},{"id":"engine_rl","breakDamage":0,"kind":"engine","hp":0.07,"armour":2,"node":"Part_engine.002","wreck":"wreck_engine","at":[-14.3,-8,1],"radius":3.6,"speed":0.85},{"id":"engine_rr","breakDamage":0,"kind":"engine","hp":0.07,"armour":2,"node":"Part_engine.003","wreck":"wreck_engine","at":[14.3,-8,1],"radius":3.6,"speed":0.85},{"id":"hangar_l","breakDamage":0,"radio":"radio.part.bay","kind":"hangar","hp":0.07,"armour":2,"node":"Part_hangar","wreck":"wreck_launcher","at":[-1.3,-3,-2.2],"radius":3.2,"mounts":[2],"skills":["airship_launch_l"]},{"id":"hangar_r","breakDamage":0,"radio":"radio.part.bay","kind":"hangar","hp":0.07,"armour":2,"node":"Part_hangar.001","wreck":"wreck_launcher","at":[1.3,-3,-2.2],"radius":3.2,"mounts":[3],"skills":["airship_launch_r"]},{"id":"radar","breakDamage":0,"kind":"radar","hp":0.07,"armour":1,"node":"Part_radar","wreck":"wreck_stump","at":[0,3.2,6.7],"radius":2.6,"spread":3,"fail":0.5,"affects":[0,1]},{"id":"bomb_bay","mounts":[4,5],"breakDamage":0,"kind":"bombbay","hp":0.07,"armour":2,"wreck":"wreck_stump","at":[0,8.5,-3.0],"radius":3.2,"radio":"radio.part.bombbay"},{"use":"pod_105","id":"pod_105_l","breakDamage":0,"node":"Mount_gun.002","at":[-7.5,0,-3.0]},{"use":"pod_105","id":"pod_105_r","breakDamage":0,"node":"Mount_gun.003","at":[7.5,0,-3.0]}],"partLock":{"kind":"engine","count":2},"phases":[{"at":0.6,"transform":2.5,"damage":1.1,"radio":"radio.quaden.airship.phase2"},{"at":0.25,"transform":3,"damage":1.25,"radio":"radio.quaden.airship.half","fireRate":1.25}],"deathExplosion":{"damage":400,"radius":18,"delay":2.6,"tier":"Ultimate"}}
A12: daedalus | B12: main | C12: Daedalus · Orbital Lander | D12: Daedalus · Tàu đổ bộ quỹ đạo | E12: Daedalus | I12: 0 | J12: 240580 | K12: 204493 | L12: 3 | M12: 2 | N12: 1 | O12: 1 | P12: FALSE | Q12: 4.5 | R12: 10 | S12: 120 | T12: 80 | U12: 10 | V12: 36 | W12: 20 | X12: FALSE | Y12: 0 | Z12: FALSE | AA12: TRUE | AB12: 1 | AC12: 3.5 | AD12: 1 | AE12: p26_daedalus_direct_dae_laser | AF12: pt14_dd_v57;pt14_dd_v57;pt14_dd_v25;pt14_dd_v25;p26_daedalus_direct_dae_laser | AG12: boss_rage | AH12: aps | AI12: 2 | AJ12: 1.6 | AK12: daedalus | AL12: doi | AO12: 156900 | AP12: 240580 | BE12: p26_daedalus_sec_dae57;p26_daedalus_sec_dae57;p26_daedalus_direct_dae_laser | BF12: pt14_dd_v57;pt14_dd_v57;pt14_dd_v25;pt14_dd_v25;p26_daedalus_direct_dae_laser | BI12: spacecraft | BJ12: spacecraft | BK12: aurel | BM12: 6 | BN12: 8 | BO12: daedalus_mass_drop | BP12: 50 | BQ12: group | BR12: FALSE | BS12: 11 | BU12: tuan:168;day_du:150 | BY12: 3 | CD12: daedalus_mass_drop | CH12: TRUE | DV12: 420 | DW12: 2.6 | DX12: 18 | DY12: Ultimate | EP12: spacecraft | EQ12: aurel | EX12: TRUE | EY12: 240580 | FH12: 36 | FI12: own | FJ12: Free | FL12: gun | FU12: daedalus | FY12: p26_daedalus_direct_dae_laser | FZ12: pt14_dd_v57 | GB12: pt14_dd_v57 | GE12: p26_daedalus_direct_dae_laser | GO12: #c4c9cc | GP12: 0.35;0.42 | GU12: 3 | GV12: 1125 | GW12: 8;6.5;5 | GX12: 12 | GY12: 6 | GZ12: 6 | HA12: 8 | HB12: 1 | HC12: 30 | HD12: 2 | HE12: 6 | HF12: 12 | HG12: 1 | HH12: orbit;high;low | HI12: drop_pod | HJ12: main_battle_tank;ifv;heavy_tank;armored_car;main_battle_tank;ifv;tank_destroyer | HK12: pod_drop | HL12: radio.aurel.daedalus | HM12: 10 | HN12: main | IG12: 1.6183 | IH12: boss_rage | II12: 4.5 | IL12: 2 | IM12: 3 | IN12: 3 | IZ12: 2 | JJ12: 0.6;0.25 | JK12: 10 | JN12: radio.aurel.daedalus.descend | JR12: radio.aurel.daedalus.phase2 | JS12: radio.aurel.daedalus.phase3 | JU12: 10 | JV12: 120 | KF12: 80 | KJ12: autocannon_30 | KK12: 1 | KL12: 20 | KM12: Assets/MachineBrigade/Resources/Data/balance.json: vehicles[160] | KN12: {"id":"daedalus","livery":"own","paint":"#c4c9cc","paintFinish":[0.35,0.42],"mountWeapons":{"0":"p26_daedalus_direct_dae_laser","1":"pt14_dd_v57","2":"pt14_dd_v57","5":"p26_daedalus_direct_dae_laser"},"frame":"spacecraft","size":1.6183,"rank":"main","general":"aurel","boss":true,"bigAttack":"daedalus_mass_drop","radioSpawn":"radio.aurel.daedalus","model":"daedalus","armour":3,"hp":240580,"weaponDamage":1,"speed":4.5,"turnRate":10,"holdsToFire":true,"mainAim":"Free","turretTurnRate":120,"radius":10,"length":36,"width":20,"vision":80,"weapon":"autocannon_30","secondary":[{"weapon":"gun_57mm","slot":"gun","aim":"Free"},{"weapon":"gun_57mm","slot":"gun","aim":"Free"},{"weapon":"pt14_dd_v25","slot":"gun","aim":"Free"},{"weapon":"pt14_dd_v25","slot":"gun","aim":"Free"}],"mainSlot":"gun","skills":["boss_rage"],"aps":{"radius":31.6,"charges":2,"recharge":1.6,"rockets":true,"laser":true},"tiers":{"opening":10,"haltPhase":2,"marks":[0.6,0.25],"schedule":[{"steps":[{"tier":"high","seconds":20},{"tier":"low","seconds":14}]},{"steps":[{"tier":"high","seconds":14},{"tier":"low","seconds":20}]},{"steps":[{"tier":"low","seconds":60}]}],"armour":{"hull":3,"belly":2,"grounded":3},"radio":{"descend":"radio.aurel.daedalus.descend","phase2":"radio.aurel.daedalus.phase2","phase3":"radio.aurel.daedalus.phase3"}},"pods":{"unit":"drop_pod","first":6,"every":12,"everyByPhase":[8,6.5,5],"count":3,"min":1,"perPod":2,"fall":6,"max":8,"offset":30,"spread":12,"tiers":["orbit","high","low"],"warning":"pod_drop","units":["main_battle_tank","ifv","heavy_tank","armored_car","main_battle_tank","ifv","tank_destroyer"],"damage":1125,"radius":6,"stun":1},"parts":[{"id":"gun_l","kind":"gun","hp":0.08,"armour":2,"node":"Mount_gun","wreck":"wreck_turret","at":[-2.4,6.0,-2.7],"radius":1.6,"mounts":[0]},{"use":"gun_30","id":"gun_r","hp":0.08,"node":"Mount_gun.005","at":[2.4,6.0,-2.7]},{"use":"pd_laser","id":"pd_laser_l","node":"Pd_laser_l","at":[-3.4,4.0,2.8]},{"use":"pd_laser","id":"pd_laser_r","node":"Pd_laser_r","at":[3.4,4.0,2.8]},{"id":"engine","kind":"thruster","hp":0.08,"armour":2,"node":"Thruster_main","wreck":"wreck_stump","at":[0,-16.5,0.8],"radius":3.2,"speed":0.8,"radio":"radio.part.mainengine"},{"use":"pod_bay","id":"pod_bay_1","node":"Pod_bay_1","at":[-4.0,-2.0,-2.2]},{"use":"pod_bay","id":"pod_bay_2","node":"Pod_bay_2","at":[0,-5.0,-2.4]},{"use":"pod_bay","id":"pod_bay_3","node":"Pod_bay_3","at":[4.0,-2.0,-2.2]}],"deathExplosion":{"damage":420,"radius":18,"delay":2.6,"tier":"Ultimate"}}
A13: drone_mothership | B13: main | C13: Matriarch · Drone Mothership | D13: Matriarch · Tàu mẹ drone | E13: Matriarch | I13: 0 | J13: 77823 | K13: 66149.55 | L13: 2 | M13: 2 | N13: 2 | O13: 2 | P13: FALSE | Q13: 3.5 | R13: 20 | S13: 90 | T13: 70 | U13: 9 | X13: TRUE | Y13: 26 | Z13: FALSE | AA13: TRUE | AB13: 0 | AC13: 3.5 | AD13: 1 | AE13: p26_matriarch_tiny_mothership_cannon | AF13: p26_matriarch_ma_drones;p26_matriarch_close_boss_flak;p26_matriarch_close_boss_flak;p26_matriarch_tiny_mothership_cannon;p26_matriarch_direct_ma_atgm;p26_matriarch_sec_autocannon_30;p26_matriarch_sec_autocannon_30;p26_matriarch_direct_ma_atgm | AG13: mothership_launch;boss_flares;mothership_shield | AH13: none | AK13: drone_mothership | AL13: doi | AO13: 63100 | AP13: 77823 | BI13: aircraft | BJ13: aircraft | BK13: sen | BM13: 9 | BN13: 9 | BO13: carrier_heavy_bomb | BP13: 45 | BQ13: group | BR13: TRUE | BS13: 5 | BT13: c5m05 | BU13: tuan:168;day_du:150 | BW13: 26 | BY13: 2 | CD13: carrier_heavy_bomb | CH13: TRUE | CW13: 0 | CX13: 0 | DV13: 300 | DW13: 2.6 | DX13: 14 | DY13: Ultimate | EN13: TRUE | EO13: TRUE | EP13: aircraft | EQ13: sen | EY13: 77823 | FY13: p26_matriarch_tiny_mothership_cannon | FZ13: p26_matriarch_ma_drones | GB13: p26_matriarch_close_boss_flak | GC13: p26_matriarch_close_boss_flak | GD13: p26_matriarch_tiny_mothership_cannon | GE13: p26_matriarch_direct_ma_atgm | GF13: p26_matriarch_sec_autocannon_30 | GG13: p26_matriarch_sec_autocannon_30 | GH13: p26_matriarch_direct_ma_atgm | GO13: #4a5058 | GP13: 0.35;0.45 | HL13: radio.sen.matriarch | HM13: 9 | HN13: main | IC13: 1.15 | IG13: 1.6903 | IH13: mothership_launch;boss_flares;mothership_shield | II13: 3.5 | JU13: 20 | JV13: 90 | KF13: 70 | KH13: 4;6;7 | KI13: 1 | KJ13: mothership_cannon | KK13: 1 | KM13: Assets/MachineBrigade/Resources/Data/balance.json: vehicles[142] | KN13: {"id":"drone_mothership","paint":"#4a5058","paintFinish":[0.35,0.45],"wake":{"phase":1,"mounts":[4,6,7]},"mountWeapons":{"0":"p26_matriarch_tiny_mothership_cannon","1":"p26_matriarch_ma_drones","2":"p26_matriarch_close_boss_flak","3":"p26_matriarch_close_boss_flak","4":"p26_matriarch_tiny_mothership_cannon","5":"p26_matriarch_direct_ma_atgm","6":"p26_matriarch_sec_autocannon_30","7":"p26_matriarch_sec_autocannon_30","8":"p26_matriarch_direct_ma_atgm"},"frame":"aircraft","rank":"main","general":"sen","size":1.6903,"radioSpawn":"radio.sen.matriarch","scale":1.15,"boss":true,"bigAttack":"carrier_heavy_bomb","armour":2,"hp":77823,"weaponDamage":1,"speed":3.5,"turnRate":20,"turretTurnRate":90,"radius":9,"cp":0,"vision":70,"firesWhileMoving":true,"weapon":"mothership_cannon","flying":true,"altitude":26,"captureRate":0,"skills":["mothership_launch","boss_flares","mothership_shield"],"secondary":[{"weapon":"mothership_drones","slot":"missile","aim":"Free"},{"weapon":"boss_flak","slot":"mg","aim":"Free"},{"weapon":"boss_flak","slot":"mg","aim":"Free"},{"weapon":"mothership_cannon","slot":"main","aim":"Free"},{"weapon":"mothership_drones","slot":"missile","aim":"Free"}],"parts":[{"id":"cannon_bow","kind":"maingun","hp":0.06,"armour":2,"node":"Turret","wreck":"wreck_turret","at":[0,10.8,-3.6],"radius":2.0,"mounts":[0],"radio":"radio.part.maingun"},{"id":"cannon_gondola","kind":"gun","hp":0.06,"armour":2,"node":"Mount_main.001","wreck":"wreck_turret","at":[0,2.2,-5.4],"radius":2.0,"mounts":[4]},{"id":"drone_bay","kind":"bay","hp":0.06,"armour":2,"wreck":"wreck_stump","at":[0,-2.3,-4.6],"radius":3.0,"mounts":[1],"radio":"radio.part.bay"},{"id":"uav_bay","mounts":[5],"kind":"uav","hp":0.06,"armour":1,"wreck":"wreck_stump","at":[0,-8.5,-3.5],"radius":2.5,"skills":["mothership_launch"]},{"id":"flak_top","kind":"flak","hp":0.06,"armour":2,"node":"Mount_mg","wreck":"wreck_turret","at":[0,4.8,4.1],"radius":1.8,"mounts":[2]},{"id":"flak_rear","kind":"flak","hp":0.06,"armour":2,"node":"Mount_mg.001","wreck":"wreck_turret","at":[0,-3.4,3.9],"radius":1.8,"mounts":[3]},{"id":"shield","kind":"shield","hp":0.06,"armour":2,"wreck":"wreck_stump","at":[0,-2.35,5.2],"radius":2.5,"skills":["mothership_shield"],"radio":"radio.part.shield"},{"id":"bomb_bay","kind":"bombbay","hp":0.06,"armour":2,"wreck":"wreck_stump","at":[0,5.5,-4.8],"radius":2.8,"radio":"radio.part.bombbay"},{"use":"gun_30","id":"belly_gun_l","node":"Mount_gun","at":[-2.2,6.0,-5.8]},{"use":"gun_30","id":"belly_gun_r","node":"Mount_gun.001","at":[2.2,6.0,-5.8]},{"use":"drone_bay","id":"drone_bay_2","node":"Mount_missile.001","at":[0,-6.0,-4.4]}],"deathExplosion":{"damage":300,"radius":14,"delay":2.6,"tier":"Ultimate"}}
A14: earth_borer | B14: mini | C14: Tartarus · Tunnelling Machine | D14: Tartarus · Máy khoan | E14: Tartarus | I14: 0 | J14: 72000 | K14: 61200 | L14: 4 | M14: 3 | N14: 2 | O14: 2 | P14: FALSE | Q14: 3.2 | R14: 22 | S14: 40 | T14: 55 | U14: 6 | V14: 23.5 | W14: 5.8 | X14: FALSE | Y14: 0 | Z14: FALSE | AA14: TRUE | AB14: 0 | AC14: 3.5 | AD14: 1.0854 | AE14: borer_drill | AF14: borer_cannon;borer_cannon | AG14: boss_rage | AH14: none | AK14: earth_borer | AL14: doi | BG14: 1 | BH14: 1.0854 | BI14: tracked | BJ14: tracked | BK14: hung | BM14: 3 | BN14: 3 | BR14: TRUE | BS14: 8 | BT14: c8m05 | BU14: tuan:66;day_du:60 | BY14: 4 | CH14: TRUE | CI14: 350 | CJ14: 2 | CK14: 6 | CL14: 1.5 | CM14: 14 | CN14: 6 | CO14: 14 | CQ14: 3 | CR14: 22 | CV14: 2 | CW14: 0 | CX14: 0 | DV14: 420 | DW14: 2.6 | DX14: 18 | DY14: Ultimate | EN14: TRUE | EP14: tracked | EQ14: hung | EY14: 72000 | FH14: 23.5 | FJ14: Hull | GN14: 1.0854 | GO14: #b08a3a | GP14: 0.3;0.55 | HL14: radio.hung.borer | HM14: 6 | HN14: mini | IC14: 1 | IG14: 0.85 | IH14: boss_rage | II14: 3.2 | JU14: 22 | JV14: 40 | KF14: 55 | KJ14: borer_drill | KK14: 2.874 | KL14: 5.8 | KM14: Assets/MachineBrigade/Resources/Data/balance.json: vehicles[150] | KN14: {"id":"earth_borer","paint":"#b08a3a","paintFinish":[0.3,0.55],"outgoingDamageMult":1.0854,"frame":"tracked","rank":"mini","size":0.85,"boss":true,"general":"hung","radioSpawn":"radio.hung.borer","armour":4,"hp":72000,"weaponDamage":2.874,"speed":3.2,"turnRate":22,"turretTurnRate":40,"radius":6,"length":23.5,"width":5.8,"scale":1.0,"cp":0,"vision":55,"captureRate":0,"firesWhileMoving":true,"weapon":"borer_drill","mainAim":"Hull","secondary":[{"weapon":"borer_cannon","slot":"gun","aim":"Free"},{"weapon":"borer_cannon","slot":"gun","aim":"Free"}],"burrow":{"surface":22,"dive":2,"speed":14,"warn":2,"radius":6,"stun":3,"damage":350,"exposed":6,"exposedTaken":1.5,"first":14},"skills":["boss_rage"],"phases":[{"at":0.45,"transform":2.5,"speed":1.15,"radio":"radio.hung.borer.half"}],"parts":[{"id":"drill","kind":"drill","hp":0.14,"armour":4,"node":"Part_drill","wreck":"wreck_stump","at":[0,6.8,3.3],"radius":3.0,"mounts":[0],"stops":["burrow"],"radio":"radio.part.drill"},{"id":"gun_l","kind":"gun","hp":0.1,"armour":3,"node":"Part_gun","wreck":"wreck_turret","at":[-1.3,0.2,5.6],"radius":1.8,"mounts":[1]},{"id":"gun_r","kind":"gun","hp":0.1,"armour":3,"node":"Part_gun.001","wreck":"wreck_turret","at":[1.3,-3.2,5.6],"radius":1.8,"mounts":[2]},{"id":"engine","kind":"engine","hp":0.1,"armour":3,"node":"Part_engine","wreck":"wreck_engine","at":[0,-7.3,4.9],"radius":2.5,"speed":0.7}],"deathExplosion":{"damage":420,"radius":18,"delay":2.6,"tier":"Ultimate"}}
A15: fenrir | B15: mini | C15: Fenrir · Vanguard | D15: Fenrir · Xe tiên phong | E15: Fenrir | I15: 0 | J15: 29950 | K15: 25457.5 | L15: 4 | M15: 4 | N15: 3 | O15: 2 | P15: FALSE | Q15: 4.4 | R15: 34 | S15: 25 | T15: 60 | U15: 7.5 | V15: 19.308 | W15: 10.92 | X15: FALSE | Y15: 0 | Z15: FALSE | AA15: TRUE | AB15: 0 | AC15: 3.5 | AD15: 0.9508 | AE15: p26_jotunn_sec_jo_rockets | AF15: p26_jotunn_sec_jo_rockets;p26_jotunn_close_boss_flak | AG15: fortress_barrage;boss_emp | AH15: none | AK15: fenrir | AL15: doi | BG15: 1 | BH15: 0.9508 | BI15: tracked | BJ15: tracked | BK15: orlov | BL15: mobile_fortress | BM15: 3 | BN15: 3 | BR15: FALSE | BS15: 3 | BT15: c3s2 | BU15: tuan:66;day_du:60 | BZ15: 4 | CA15: 3 | CB15: 4 | CC15: 2 | EQ15: orlov | EY15: 29950 | FU15: fenrir | GO15: #5c6670 | GP15: 0.35;0.5 | HL15: radio.orlov.fenrir | ID15: 35 | IE15: 25 | IF15: 6 | II15: 4.4 | JU15: 34 | JX15: rockets_l;rockets_r;flak_l | JY15: frost | KA15: mobile_fortress | KB15: 0.5051 | KC15: 1.06 | KD15: 0.94 | KE15: 0.86 | KK15: 2.222 | KM15: Assets/MachineBrigade/Resources/Data/balance.json: vehicles[164] | KN15: {"id":"fenrir","paint":"#5c6670","paintFinish":[0.35,0.5],"guard":null,"wake":null,"armour":[4,4,3,2],"variantOf":"mobile_fortress","model":"fenrir","hp":29950,"weaponDamage":2.222,"general":"orlov","radioSpawn":"radio.orlov.fenrir","speed":4.4,"turnRate":34,"scoot":{"shots":6,"min":25,"max":35},"variant":{"size":0.5051,"keep":["rockets_l","rockets_r","flak_l"],"tint":[0.86,0.94,1.06],"mark":"frost","tune":{"rockets_l":{"hp":0.13,"at":[-2.02,-6.3,5.63]},"rockets_r":{"hp":0.13,"at":[2.02,-6.3,5.63]},"flak_l":{"hp":0.1,"at":[0,4.23,5.47]}}}}
A16: fortress_bastion | B16: main | C16: Bastion · Fortress | D16: Bastion · Pháo đài | E16: Bastion | I16: 0 | J16: 25900 | K16: 22015 | L16: 5 | M16: 3 | N16: 2 | O16: 3 | P16: FALSE | Q16: 1.5 | R16: 18 | S16: 22 | T16: 64 | U16: 7.5 | V16: 19.884 | W16: 10.92 | X16: FALSE | Y16: 0 | Z16: FALSE | AA16: TRUE | AB16: 0 | AC16: 3.5 | AD16: 1 | AE16: p26_bastion_sec_b240 | AF16: p26_bastion_direct_b100;p26_bastion_direct_b100;p26_bastion_tiny_autocannon_40;p26_bastion_tiny_autocannon_40;p26_bastion_tiny_kornet_twin;p26_bastion_close_boss_hmg;p26_bastion_close_boss_hmg;p26_bastion_main_b155;p26_bastion_tiny_zu23;p26_bastion_tiny_zu23 | AG16: train_patch;boss_bulwark;fortress_barrage | AH16: none | AK16: fortress_bastion | AL16: giong | BI16: tracked | BJ16: tracked | BK16: brandt | BM16: 11 | BN16: 15 | BO16: bastion_420_shell | BP16: 45 | BQ16: group | BR16: TRUE | BS16: 1 | BU16: tuan:168;day_du:150 | BZ16: 5 | CA16: 2 | CB16: 3 | CC16: 3 | CD16: bastion_420_shell | CH16: TRUE | CW16: 0 | CX16: 0 | DV16: 500 | DW16: 2.6 | DX16: 21 | DY16: Ultimate | EN16: TRUE | EP16: tracked | EQ16: brandt | ES16: 4 | ET16: 150 | EU16: 5 | EV16: 6 | EW16: 15 | EY16: 25900 | FH16: 16.57 | FY16: p26_bastion_sec_b240 | FZ16: p26_bastion_direct_b100 | GA16: p26_bastion_tiny_zu23 | GB16: p26_bastion_direct_b100 | GC16: p26_bastion_tiny_autocannon_40 | GD16: p26_bastion_tiny_autocannon_40 | GE16: p26_bastion_tiny_kornet_twin | GF16: p26_bastion_close_boss_hmg | GG16: p26_bastion_close_boss_hmg | GH16: p26_bastion_main_b155 | GI16: p26_bastion_tiny_zu23 | GO16: #6e6a5e | GP16: 0.25;0.6 | HL16: radio.brandt.bastion | HM16: 7.5 | HN16: main | IC16: 1.2 | IG16: 1.51 | IH16: train_patch;boss_bulwark;fortress_barrage | II16: 1.5 | JU16: 18 | JV16: 22 | KF16: 64 | KJ16: boss_mortar | KK16: 1 | KL16: 9.1 | KM16: Assets/MachineBrigade/Resources/Data/balance.json: vehicles[148] | KN16: {"id":"fortress_bastion","paint":"#6e6a5e","paintFinish":[0.25,0.6],"guard":{"radius":15,"count":4,"every":5,"damage":150,"pad":6},"mountWeapons":{"0":"p26_bastion_sec_b240","1":"p26_bastion_direct_b100","2":"p26_bastion_direct_b100","3":"p26_bastion_tiny_autocannon_40","4":"p26_bastion_tiny_autocannon_40","5":"p26_bastion_tiny_kornet_twin","6":"p26_bastion_close_boss_hmg","7":"p26_bastion_close_boss_hmg","8":"p26_bastion_main_b155","9":"p26_bastion_tiny_zu23","10":"p26_bastion_tiny_zu23"},"frame":"tracked","rank":"main","general":"brandt","size":1.51,"radioSpawn":"radio.brandt.bastion","scale":1.2,"armour":[5,3,2,3],"hp":25900,"weaponDamage":1,"speed":1.5,"turnRate":18,"turretTurnRate":22,"radius":7.5,"length":16.57,"width":9.1,"cp":0,"vision":64,"firesWhileMoving":true,"weapon":"boss_mortar","captureRate":0,"boss":true,"bigAttack":"bastion_420_shell","skills":["train_patch","boss_bulwark","fortress_barrage"],"secondary":[{"weapon":"autocannon_40","slot":"gun","aim":"Free","arc":[-45,80]},{"weapon":"autocannon_40","slot":"gun","aim":"Free","arc":[45,80]},{"weapon":"autocannon_40","slot":"gun","aim":"Free","arc":[-135,80]},{"weapon":"autocannon_40","slot":"gun","aim":"Free","arc":[135,80]},{"weapon":"kornet_twin","slot":"missile","aim":"Free"},{"weapon":"boss_hmg","slot":"mg","aim":"Free"},{"weapon":"boss_hmg","slot":"mg","aim":"Free"}],"parts":[{"id":"mortar","kind":"mortar","hp":0.1,"armour":3,"node":"Main_cannon*","wreck":"wreck_barrel","at":[0,-0.5,7.5],"radius":2.8,"mounts":[0],"skills":["fortress_barrage"],"radio":"radio.part.maingun"},{"id":"turret_fl","kind":"turret","hp":0.07,"armour":3,"node":"Mount_gun","wreck":"wreck_turret","at":[-4.1,4.35,3.3],"radius":1.8,"mounts":[1]},{"id":"turret_fr","kind":"turret","hp":0.07,"armour":3,"node":"Mount_gun.001","wreck":"wreck_turret","at":[4.1,4.35,3.3],"radius":1.8,"mounts":[2]},{"id":"turret_rl","kind":"turret","hp":0.07,"armour":3,"node":"Mount_gun.002","wreck":"wreck_turret","at":[-4.1,-4.25,3.3],"radius":1.8,"mounts":[3,6]},{"id":"turret_rr","kind":"turret","hp":0.07,"armour":3,"node":"Mount_gun.003","wreck":"wreck_turret","at":[4.1,-4.25,3.3],"radius":1.8,"mounts":[4,7]},{"id":"kornet","kind":"missiles","hp":0.07,"armour":2,"node":"Part_missile","wreck":"wreck_launcher","at":[-1.42,-2.75,6.4],"radius":1.8,"mounts":[5]},{"use":"casemate_155","id":"casemate","node":"Mount_gun.004","at":[0,8.7,3.2]},{"use":"zu23","id":"zu23_l","node":"Mount_mg","at":[-3.42,-1.25,5.4]},{"use":"zu23","id":"zu23_r","node":"Mount_mg.001","at":[3.42,-1.25,5.4]}],"deathExplosion":{"damage":500,"radius":21,"delay":2.6,"tier":"Ultimate"}}
A17: hydra | B17: mini | C17: Hydra · Attack Submarine | D17: Hydra · Tàu ngầm tấn công | E17: Hydra | I17: 0 | J17: 81300 | K17: 69105 | L17: 4 | M17: 3 | N17: 2 | O17: 2 | P17: FALSE | Q17: 4.5 | R17: 8 | S17: 40 | T17: 110 | U17: 11 | V17: 58 | W17: 12 | X17: FALSE | Y17: 0 | Z17: FALSE | AA17: TRUE | AB17: 1 | AC17: 3.5 | AD17: 1 | AE17: p26_typhon_sec_ty57 | AF17: p26_typhon_sec_ty57;p26_typhon_direct_ty100 | AH17: none | AK17: hydra_sub | AL17: giong | BI17: submarine | BJ17: submarine | BK17: hung | BL17: typhon | BM17: 3 | BN17: 5 | BR17: FALSE | BU17: tuan:66;day_du:60 | BZ17: 4 | CA17: 2 | CB17: 3 | CC17: 2 | CM17: 12 | CR17: 16 | CS17: 16;14 | CT17: 10 | CU17: 10;12 | DG17: 240 | DH17: 16 | DM17: 6.5 | DO17: kalibr_cruise_mark | DP17: hydra_club_s | EQ17: hung | EY17: 81300 | FI17: own | FU17: hydra_sub | FV17: 8 | FW17: 34.8 | FX17: 7.2 | GO17: #2b2f33 | GP17: 0.15;0.78 | HL17: radio.hung.hydra | II17: 4.5 | JX17: doors_l;doors_r;deck_gun;rudder | JY17: hydra | KA17: typhon | KB17: 0.5057 | KK17: 1.292 | KM17: Assets/MachineBrigade/Resources/Data/balance.json: vehicles[177] | KN17: {"id":"hydra","livery":"own","paint":"#2b2f33","paintFinish":[0.15,0.78],"armour":[4,3,2,2],"variantOf":"typhon","model":"hydra_sub","general":"hung","radioSpawn":"radio.hung.hydra","hp":81300,"weaponDamage":1.292,"speed":4.5,"modelSize":[34.8,7.2,8],"burrow":{"surface":16,"under":10,"first":12,"surfaceByPhase":[16,14],"underByPhase":[10,12]},"cruise":{"every":16,"damage":240,"weapon":"hydra_club_s","radius":6.5,"warning":"kalibr_cruise_mark"},"fleet":[{"unit":"missile_boat","count":1}],"wake":null,"secondary":[{"weapon":"p26_typhon_sec_ty57","slot":"gun","aim":"Free","arc":[180,150]},{"weapon":"p26_typhon_direct_ty100","slot":"gun","aim":"Free","arc":[0,150]}],"variant":{"size":0.5057,"keep":["doors_l","doors_r","deck_gun","rudder"],"mark":"hydra","tune":{"doors_l":{"hp":0.12,"at":[-0.95,-7.51,4.45]},"doors_r":{"hp":0.12,"at":[0.95,-7.51,4.45]},"deck_gun":{"hp":0.12,"node":"Mount_gun.002","at":[0,16.61,6.23]},"rudder":{"hp":0.1,"at":[0,-30.45,0.59]}}}}
A18: hyperion | B18: main | C18: Hyperion · Heavy Cruiser | D18: Hyperion · Tuần dương hạm hạng nặng | E18: Hyperion | I18: 0 | J18: 282320 | K18: 239972 | L18: 4 | M18: 4 | N18: 4 | O18: 4 | P18: FALSE | Q18: 3.5 | R18: 10 | S18: 120 | T18: 80 | U18: 10 | V18: 34 | W18: 22 | X18: TRUE | Y18: 22 | Z18: FALSE | AA18: TRUE | AB18: 0 | AC18: 3.5 | AD18: 1 | AE18: p26_icarus_sec_orbital_laser | AF18: pt14_hp_155;pt14_hp_155;pt14_hp_vlaser;pt14_hp_vlaser;pt14_hp_v127;pt14_hp_v127;pt14_hp_nsm;pt14_hp_nsm | AG18: boss_rage | AH18: aps | AI18: 3 | AJ18: 1.4 | AK18: hyperion | AL18: doi | AO18: 176450 | AP18: 282320 | BE18: p26_icarus_main_ic_coil;p26_icarus_main_ic_coil;p26_icarus_direct_ic_laser;p26_icarus_direct_ic_laser | BF18: pt14_hp_155;pt14_hp_155;pt14_hp_vlaser;pt14_hp_vlaser;pt14_hp_v127;pt14_hp_v127;pt14_hp_nsm;pt14_hp_nsm | BI18: spacecraft | BJ18: spacecraft | BK18: aurel | BL18: silver_bug | BM18: 9 | BN18: 9 | BO18: hyperion_sun_beam | BP18: 50 | BQ18: group | BR18: FALSE | BU18: tuan:168;day_du:150 | CD18: hyperion_sun_beam | EQ18: aurel | EY18: 282320 | FI18: own | FU18: hyperion | FV18: 21.3 | FW18: 67.2 | FX18: 33.4 | GO18: #98a4b2 | GP18: 0.5;0.4 | GU18: 2 | GX18: 60 | GZ18: 10 | HA18: 4 | HL18: radio.aurel.hyperion | HN18: main | II18: 3.5 | JR18: radio.aurel.hyperion.phase2 | JS18: radio.aurel.hyperion.phase3 | JW18: crash_turret_l;crash_turret_r;uplink | JY18: hyperion | KA18: silver_bug | KB18: 1.2 | KK18: 1.111 | KM18: Assets/MachineBrigade/Resources/Data/balance.json: vehicles[173] | KN18: {"id":"hyperion","livery":"own","paint":"#98a4b2","paintFinish":[0.5,0.4],"variantOf":"silver_bug","model":"hyperion","rank":"main","general":"aurel","radioSpawn":"radio.aurel.hyperion","hp":282320,"weaponDamage":1.111,"speed":3.5,"bigAttack":"hyperion_sun_beam","arena":null,"modelSize":[67.2,33.4,21.3],"secondary":[{"weapon":"pt14_hp_155","slot":"gun","aim":"Free"},{"weapon":"pt14_hp_155","slot":"gun","aim":"Free"},{"weapon":"pt14_hp_vlaser","slot":"gun","aim":"Free"},{"weapon":"pt14_hp_vlaser","slot":"gun","aim":"Free"},{"weapon":"pt14_hp_v127","slot":"gun","aim":"Free"},{"weapon":"pt14_hp_v127","slot":"gun","aim":"Free"},{"weapon":"pt14_hp_nsm","slot":"rocket","aim":"Free"},{"weapon":"pt14_hp_nsm","slot":"rocket","aim":"Free"}],"tiers":{"crash":null,"hijack":null,"schedule":[{"steps":[{"tier":"high","seconds":60}]},{"steps":[{"tier":"high","seconds":60}]},{"steps":[{"tier":"high","seconds":60}]}],"radio":{"phase2":"radio.aurel.hyperion.phase2","phase3":"radio.aurel.hyperion.phase3"}},"pods":{"first":10,"every":60,"count":2,"max":4},"variant":{"size":1.2,"drop":["crash_turret_l","crash_turret_r","uplink"],"mark":"hyperion","tune":{"main_laser":{"hp":0.07,"at":[0,21.17,3.33]},"main_engine":{"hp":0.07,"at":[0,-26.42,8.25]},"thruster_fl":{"hp":0.07,"at":[-10.38,22.0,8.33]},"thruster_fr":{"hp":0.07,"at":[10.38,22.0,8.33]},"thruster_rl":{"hp":0.07,"at":[-12.17,-18.33,8.0]},"thruster_rr":{"hp":0.07,"at":[12.17,-18.33,8.0]},"pd_laser_l":{"hp":0.07,"at":[-6.83,4.5,11.0]},"pd_laser_r":{"hp":0.07,"at":[6.83,4.5,11.0]},"pod_bay":{"hp":0.07,"at":[0,-12.67,2.92]}}}}
A19: icarus_mk0 | B19: mini | C19: Icarus Mk.0 · Prototype Spacecraft | D19: Icarus Mk.0 · Phi thuyền nguyên mẫu | E19: Icarus Mk.0 | I19: 0 | J19: 94850 | K19: 80622.5 | L19: 4 | M19: 4 | N19: 4 | O19: 4 | P19: FALSE | Q19: 3 | R19: 10 | S19: 120 | T19: 80 | U19: 10 | V19: 34 | W19: 22 | X19: TRUE | Y19: 22 | Z19: FALSE | AA19: TRUE | AB19: 0 | AC19: 3.5 | AD19: 1 | AE19: p26_icarus_sec_orbital_laser | AF19: pt14_mk0_v40;pt14_mk0_v40 | AG19: boss_rage | AH19: aps | AI19: 3 | AJ19: 1.4 | AK19: icarus_mk0 | AL19: doi | AY19: 5 | AZ19: 3 | BF19: pt14_mk0_v40;pt14_mk0_v40 | BI19: spacecraft | BJ19: spacecraft | BK19: aurel | BL19: silver_bug | BM19: 3 | BN19: 3 | BR19: FALSE | BS19: 10 | BT19: c10m05 | BU19: tuan:66;day_du:60 | EQ19: aurel | EY19: 94850 | FI19: own | FU19: icarus_mk0 | GO19: #a9aca6 | GP19: 0.7;0.4 | GU19: 1 | GX19: 18 | HA19: 4 | HL19: radio.aurel.icarus_mk0 | JJ19: 0.45 | JK19: 0 | JR19: radio.aurel.icarus_mk0.phase2 | JX19: main_laser;pod_bay;pd_laser_l | JY19: mk0 | JZ19: mk0 | KA19: silver_bug | KB19: 0.4 | KC19: 0.96 | KD19: 0.86 | KE19: 0.86 | KK19: 2.275 | KM19: Assets/MachineBrigade/Resources/Data/balance.json: vehicles[168] | KN19: {"id":"icarus_mk0","livery":"own","paint":"#a9aca6","paintFinish":[0.7,0.4],"interceptionMode":"PointDefense","variantOf":"silver_bug","model":"icarus_mk0","hp":94850,"weaponDamage":2.275,"general":"aurel","radioSpawn":"radio.aurel.icarus_mk0","secondary":[{"weapon":"pt14_mk0_v40","slot":"gun","aim":"Free"},{"weapon":"pt14_mk0_v40","slot":"gun","aim":"Free"}],"aps":{"radius":19.5,"charges":3,"recharge":1.4,"rockets":true,"laser":true},"arena":null,"tiers":{"opening":0,"crash":null,"hijack":null,"marks":[0.45],"schedule":[{"steps":[{"tier":"high","seconds":18},{"tier":"low","seconds":12}]},{"steps":[{"tier":"high","seconds":12},{"tier":"low","seconds":18}]}],"radio":{"phase2":"radio.aurel.icarus_mk0.phase2"}},"pods":{"count":1,"max":4,"every":18},"variant":{"size":0.4,"keep":["main_laser","pod_bay","pd_laser_l"],"tint":[0.86,0.86,0.96],"mark":"mk0","name":"mk0","tune":{"main_laser":{"hp":0.12},"pod_bay":{"hp":0.12},"pd_laser_l":{"hp":0.12}}}}
