Workbook

Sheet Thap
A1: id | B1: ten_en | C1: ten_vi | D1: ten_ngan_vi | E1: lop | F1: nhanh | G1: ke_thua_tu | H1: base_cp | I1: mau_hp | J1: mau_trong_tran_hp | K1: giap_truoc | L1: giap_hong | M1: giap_sau | N1: giap_noc | O1: cong_trinh | P1: toc_do_m_s | Q1: xoay_than_deg_s | R1: xoay_thap_deg_s | S1: tam_nhin_m | T1: ban_kinh_m | U1: dai_m | V1: rong_m | W1: bay | X1: do_cao_m | Y1: dung_yen | Z1: ban_khi_chay | AA1: toc_do_chiem | AB1: tha_du_s | AC1: he_so_sat_thuong_ra | AD1: vu_khi_chinh | AE1: vu_khi_phu | AF1: noi_tai | AG1: tu_ve | AH1: so_lan_tu_ve | AI1: hoi_tu_ve_s | AJ1: mo_hinh | AK1: so_voi_ban_goc | AL1: base_cp_truoc | AM1: base_cp_sau | AN1: mau_hp_truoc | AO1: mau_hp_sau | AP1: giap_truoc_truoc | AQ1: giap_truoc_sau | AR1: giap_hong_truoc | AS1: giap_hong_sau | AT1: giap_sau_truoc | AU1: giap_sau_sau | AV1: giap_noc_truoc | AW1: giap_noc_sau | AX1: toc_do_m_s_truoc | AY1: toc_do_m_s_sau | AZ1: tam_nhin_m_truoc | BA1: tam_nhin_m_sau | BB1: vu_khi_chinh_truoc | BC1: vu_khi_chinh_sau | BD1: vu_khi_phu_truoc | BE1: vu_khi_phu_sau | BF1: he_so_sat_thuong_ra_truoc | BG1: he_so_sat_thuong_ra_sau | BH1: the_goc | BI1: nhanh_ab | BJ1: co_o | BK1: vai_tro | BL1: trong_roster | BM1: base_rebuild_cp | BN1: runtime_rebuild_cp | BO1: xay_lai_cho_s | BP1: xay_lai_tha_s | BQ1: mo_khoa | BR1: the_cu_gop_vao | BS1: co_can_bang | BT1: armour | BU1: armour_front | BV1: armour_rear | BW1: armour_side | BX1: armour_top | BY1: art | BZ1: balloon_radius_m | CA1: balloon_scatter | CB1: blast_wall_cone | CC1: blast_wall_cut | CD1: blast_wall_radius_m | CE1: branch_of | CF1: branches | CG1: class | CH1: counter_battery_bonus | CI1: counter_battery_range_m | CJ1: counter_battery_seconds_s | CK1: cp | CL1: death_explosion_damage | CM1: death_explosion_delay_s | CN1: death_explosion_radius_m | CO1: death_explosion_tier | CP1: dome_hp | CQ1: dome_radius_m | CR1: dome_recharge_s | CS1: erect_seconds | CT1: fires_while_moving | CU1: fort_size | CV1: hangar_alive | CW1: hangar_budget | CX1: hangar_every_s | CY1: hangar_post | CZ1: hangar_units | DA1: hp | DB1: inherits | DC1: jammer | DD1: length_m | DE1: main_aim | DF1: main_slot | DG1: model | DH1: model_size_height_m | DI1: model_size_length_m | DJ1: model_size_width_m | DK1: naval_only | DL1: no_branch | DM1: outgoing_damage_mult | DN1: passable | DO1: radius_m | DP1: rebuild_cp | DQ1: relay_income | DR1: relay_quiet | DS1: relay_second | DT1: reveal_air | DU1: reveal_stealth | DV1: scale | DW1: secondary | DX1: shelter_cut | DY1: shelter_radius_m | DZ1: speed_m_s | EA1: static | EB1: tower_range_aura_radius_m | EC1: tower_range_aura_range_m | ED1: tower_role | EE1: turn_rate_deg_s | EF1: turret_turn_rate_deg_s | EG1: vision_m | EH1: wards_hp | EI1: wards_radius_m | EJ1: wards_recharge_s | EK1: weapon | EL1: width_m | EM1: nguon | EN1: raw_json
A2: aa_gun_tower | B2: 40 mm AA gun | C2: Pháo phòng không 40 mm | D2: Pháo PK 40 mm | H2: 0 | I2: 1273 | J2: 2800.6 | K2: 2 | L2: 2 | M2: 2 | N2: 2 | O2: TRUE | P2: 0 | Q2: 1 | R2: 120 | S2: 56 | T2: 2.4 | U2: 5 | V2: 5 | W2: FALSE | X2: 0 | Y2: TRUE | Z2: TRUE | AA2: 1 | AB2: 3.5 | AC2: 1 | AD2: bofors_l70 | AG2: none | AJ2: aa_gun_tower | AK2: giong | BJ2: Medium | BL2: FALSE | BM2: 4 | BN2: 4 | BO2: 40 | BP2: 3.5 | BQ2: Campaign | BR2: aa_gun_tower | BT2: 2 | CK2: 0 | CL2: 90 | CM2: 0.4 | CN2: 7 | CO2: Huge | CU2: Medium | DA2: 1273 | DD2: 5 | DH2: 3.2 | DI2: 5.5 | DJ2: 5.5 | DO2: 2.4 | DZ2: 0 | EA2: TRUE | EE2: 1 | EF2: 120 | EG2: 56 | EK2: bofors_l70 | EL2: 5 | EM2: Assets/MachineBrigade/Resources/Data/balance.json: vehicles[121] | EN2: {"id":"aa_gun_tower","modelSize":[5.5,5.5,3.2],"fort":{"size":"Medium"},"static":true,"armour":2,"hp":1273,"speed":0,"turnRate":1,"turretTurnRate":120,"radius":2.4,"length":5.0,"width":5.0,"cp":0,"vision":56,"weapon":"bofors_l70","secondary":[],"deathExplosion":{"damage":90,"radius":7,"delay":0.4,"tier":"Huge"}}
A3: aa_turret | B3: AA turret | C3: Tháp phòng không | D3: Tháp PK | H3: 0 | I3: 1100 | J3: 2420 | K3: 2 | L3: 2 | M3: 2 | N3: 2 | O3: TRUE | P3: 0 | Q3: 1 | R3: 200 | S3: 60 | T3: 2.3 | U3: 4.5 | V3: 4.5 | W3: FALSE | X3: 0 | Y3: TRUE | Z3: TRUE | AA3: 1 | AB3: 3.5 | AC3: 1 | AD3: tower_flak_30 | AE3: sam | AG3: none | AJ3: aa_turret | AK3: giong | BJ3: Small | BL3: TRUE | BM3: 6 | BN3: 6 | BO3: 25 | BP3: 2.5 | BQ3: Starter | BR3: aa_turret | BT3: 2 | CF3: aa_turret.flak;aa_turret.sam | CK3: 0 | CL3: 90 | CM3: 0.4 | CN3: 7 | CO3: Huge | CU3: Small | DA3: 1100 | DD3: 4.5 | DM3: 1 | DO3: 2.3 | DP3: 6 | DZ3: 0 | EA3: TRUE | EE3: 1 | EF3: 200 | EG3: 60 | EK3: tower_flak_30 | EL3: 4.5 | EM3: Assets/MachineBrigade/Resources/Data/balance.json: vehicles[70] | EN3: {"id":"aa_turret","outgoingDamageMult":1,"rebuildCp":6,"branches":["aa_turret.flak","aa_turret.sam"],"fort":{"size":"Small"},"static":true,"armour":2,"hp":1100,"speed":0,"turnRate":1,"turretTurnRate":200,"radius":2.3,"length":4.5,"width":4.5,"cp":0,"vision":60,"weapon":"tower_flak_30","secondary":[{"weapon":"sam","slot":"missile","aim":"Turret"}],"deathExplosion":{"damage":90,"radius":7,"delay":0.4,"tier":"Huge"}}
A4: aa_turret.flak | D4: Tháp cao xạ | G4: aa_turret | H4: 0 | I4: 1100 | J4: 2420 | K4: 2 | L4: 2 | M4: 2 | N4: 2 | O4: TRUE | P4: 0 | Q4: 1 | R4: 200 | S4: 60 | T4: 2.3 | U4: 4.5 | V4: 4.5 | W4: FALSE | X4: 0 | Y4: TRUE | Z4: TRUE | AA4: 1 | AB4: 3.5 | AC4: 0.7869 | AD4: flak_quad | AG4: none | AJ4: aa_turret | AK4: doi | BF4: 1 | BG4: 0.7869 | BH4: aa_turret | BI4: flak | BJ4: Small | BK4: aa_gun_23_drones_helis | BL4: FALSE | BM4: 6 | BN4: 6 | BO4: 25 | BP4: 2.5 | BQ4: Campaign | BR4: aa_turret | BS4: giam_dps_giu_mau | BY4: aa_turret_a | CE4: aa_turret | DB4: aa_turret | DM4: 0.7869 | DP4: 6 | ED4: aa_gun_23_drones_helis | EK4: flak_quad | EM4: Assets/MachineBrigade/Resources/Data/balance.json: vehicles[102] | EN4: {"id":"aa_turret.flak","outgoingDamageMult":0.7869,"rebuildCp":6,"towerRole":"aa_gun_23_drones_helis","art":"aa_turret_a","inherits":"aa_turret","branchOf":"aa_turret","weapon":"flak_quad","secondary":[]}
A5: aa_turret.sam | D5: Stinger | G5: aa_turret | H5: 0 | I5: 1100 | J5: 2420 | K5: 2 | L5: 2 | M5: 2 | N5: 2 | O5: TRUE | P5: 0 | Q5: 1 | R5: 200 | S5: 60 | T5: 2.3 | U5: 4.5 | V5: 4.5 | W5: FALSE | X5: 0 | Y5: TRUE | Z5: TRUE | AA5: 1 | AB5: 3.5 | AC5: 1 | AD5: stinger_post | AG5: none | AJ5: aa_turret | AK5: doi | AZ5: 64 | BA5: 60 | BB5: sam_post | BC5: stinger_post | BH5: aa_turret | BI5: sam | BJ5: Small | BK5: aa_manpads_aircraft | BL5: FALSE | BM5: 5 | BN5: 5 | BO5: 25 | BP5: 2.5 | BQ5: Campaign | BR5: aa_turret | BY5: aa_turret_b | CE5: aa_turret | DB5: aa_turret | DF5: missile | DM5: 1 | DP5: 5 | ED5: aa_manpads_aircraft | EG5: 60 | EK5: stinger_post | EM5: Assets/MachineBrigade/Resources/Data/balance.json: vehicles[103] | EN5: {"id":"aa_turret.sam","outgoingDamageMult":1,"rebuildCp":5,"towerRole":"aa_manpads_aircraft","art":"aa_turret_b","inherits":"aa_turret","branchOf":"aa_turret","weapon":"stinger_post","mainSlot":"missile","vision":60,"secondary":[]}
A6: aircraft_hangar | B6: Aircraft hangar | C6: Nhà chứa máy bay | D6: Nhà chứa máy bay | H6: 0 | I6: 1800 | J6: 3960 | K6: 2 | L6: 2 | M6: 2 | N6: 2 | O6: TRUE | P6: 0 | Q6: 1 | R6: 1 | S6: 50 | T6: 3.6 | U6: 8 | V6: 8 | W6: FALSE | X6: 0 | Y6: TRUE | Z6: TRUE | AA6: 1 | AB6: 3.5 | AC6: 1 | AD6: none | AG6: none | AJ6: aircraft_hangar | AK6: moi | BJ6: Medium | BL6: TRUE | BM6: 8 | BN6: 8 | BO6: 40 | BP6: 3.5 | BQ6: Campaign | BR6: aircraft_hangar | BT6: 2 | CK6: 0 | CL6: 120 | CM6: 0.4 | CN6: 8 | CO6: Huge | CU6: Medium | CV6: 2 | CW6: 12 | CX6: 60 | CY6: 30 | CZ6: scout_heli;recon_drone | DA6: 1800 | DD6: 8 | DG6: aircraft_hangar | DH6: 5.32 | DI6: 8 | DJ6: 7.72 | DO6: 3.6 | DP6: 8 | DZ6: 0 | EA6: TRUE | EE6: 1 | EF6: 1 | EG6: 50 | EK6: none | EL6: 8 | EM6: Assets/MachineBrigade/Resources/Data/balance.json: vehicles[75] | EN6: {"id":"aircraft_hangar","rebuildCp":8,"model":"aircraft_hangar","modelSize":[8.0,7.72,5.32],"fort":{"size":"Medium"},"static":true,"armour":2,"hp":1800,"speed":0,"turnRate":1,"turretTurnRate":1,"radius":3.6,"length":8,"width":8,"cp":0,"vision":50,"weapon":"none","hangar":{"units":["scout_heli","recon_drone"],"every":60,"alive":2,"budget":12,"post":30},"deathExplosion":{"damage":120,"radius":8,"delay":0.4,"tier":"Huge"}}
A7: atgm_tower | B7: ATGM tower | C7: Tháp tên lửa chống tăng | D7: Tháp ATGM | H7: 0 | I7: 900 | J7: 1980 | K7: 2 | L7: 2 | M7: 2 | N7: 2 | O7: TRUE | P7: 0 | Q7: 1 | R7: 90 | S7: 55 | T7: 2.3 | U7: 4.8 | V7: 4.8 | W7: FALSE | X7: 0 | Y7: TRUE | Z7: TRUE | AA7: 1 | AB7: 3.5 | AC7: 1 | AD7: tower_kornet | AG7: none | AJ7: atgm_tower | AK7: giong | BJ7: Medium | BL7: TRUE | BM7: 7 | BN7: 7 | BO7: 40 | BP7: 3.5 | BQ7: Campaign | BR7: atgm_tower | BT7: 2 | CF7: atgm_tower.top;atgm_tower.multi | CK7: 0 | CL7: 90 | CM7: 0.3 | CN7: 6 | CO7: Large | CU7: Medium | DA7: 900 | DD7: 4.8 | DF7: missile | DO7: 2.3 | DP7: 7 | DZ7: 0 | EA7: TRUE | EE7: 1 | EF7: 90 | EG7: 55 | EK7: tower_kornet | EL7: 4.8 | EM7: Assets/MachineBrigade/Resources/Data/balance.json: vehicles[68] | EN7: {"id":"atgm_tower","rebuildCp":7,"branches":["atgm_tower.top","atgm_tower.multi"],"fort":{"size":"Medium"},"static":true,"armour":2,"hp":900,"speed":0,"turnRate":1,"turretTurnRate":90,"radius":2.3,"length":4.8,"width":4.8,"cp":0,"vision":55,"weapon":"tower_kornet","mainSlot":"missile","deathExplosion":{"damage":90,"radius":6,"delay":0.3,"tier":"Large"}}
A8: atgm_tower.multi | D8: Đa năng | G8: atgm_tower | H8: 0 | I8: 900 | J8: 1980 | K8: 2 | L8: 2 | M8: 2 | N8: 2 | O8: TRUE | P8: 0 | Q8: 1 | R8: 90 | S8: 55 | T8: 2.3 | U8: 4.8 | V8: 4.8 | W8: FALSE | X8: 0 | Y8: TRUE | Z8: TRUE | AA8: 1 | AB8: 3.5 | AC8: 1 | AD8: kornet_multi | AG8: none | AJ8: atgm_tower | AK8: giong | BH8: atgm_tower | BI8: multi | BJ8: Medium | BK8: atgm_multi | BL8: FALSE | BM8: 6 | BN8: 6 | BO8: 40 | BP8: 3.5 | BQ8: Campaign | BR8: atgm_tower | BY8: atgm_tower_b | CE8: atgm_tower | DB8: atgm_tower | DP8: 6 | ED8: atgm_multi | EK8: kornet_multi | EM8: Assets/MachineBrigade/Resources/Data/balance.json: vehicles[88] | EN8: {"id":"atgm_tower.multi","rebuildCp":6,"towerRole":"atgm_multi","art":"atgm_tower_b","inherits":"atgm_tower","branchOf":"atgm_tower","weapon":"kornet_multi"}
A9: atgm_tower.top | D9: Đánh từ trên | G9: atgm_tower | H9: 0 | I9: 900 | J9: 1980 | K9: 2 | L9: 2 | M9: 2 | N9: 2 | O9: TRUE | P9: 0 | Q9: 1 | R9: 90 | S9: 55 | T9: 2.3 | U9: 4.8 | V9: 4.8 | W9: FALSE | X9: 0 | Y9: TRUE | Z9: TRUE | AA9: 1 | AB9: 3.5 | AC9: 1 | AD9: kornet_top | AG9: none | AJ9: atgm_tower | AK9: giong | BH9: atgm_tower | BI9: top | BJ9: Medium | BK9: atgm_top_attack | BL9: FALSE | BM9: 7 | BN9: 7 | BO9: 40 | BP9: 3.5 | BQ9: Campaign | BR9: atgm_tower | BY9: atgm_tower_a | CE9: atgm_tower | DB9: atgm_tower | DP9: 7 | ED9: atgm_top_attack | EK9: kornet_top | EM9: Assets/MachineBrigade/Resources/Data/balance.json: vehicles[87] | EN9: {"id":"atgm_tower.top","rebuildCp":7,"towerRole":"atgm_top_attack","art":"atgm_tower_a","inherits":"atgm_tower","branchOf":"atgm_tower","weapon":"kornet_top"}
A10: barrage_balloon | B10: Radar aerostat (JLENS) | C10: Khí cầu neo radar (JLENS) | D10: Khí cầu radar | H10: 0 | I10: 364 | J10: 800.8 | K10: 0 | L10: 0 | M10: 0 | N10: 0 | O10: TRUE | P10: 0 | Q10: 1 | R10: 1 | S10: 1 | T10: 2 | U10: 4 | V10: 4 | W10: FALSE | X10: 0 | Y10: TRUE | Z10: TRUE | AA10: 1 | AB10: 3.5 | AC10: 1 | AD10: none | AG10: none | AJ10: barrage_balloon | AK10: giong | BJ10: Small | BL10: FALSE | BM10: 2 | BN10: 2 | BO10: 25 | BP10: 2.5 | BQ10: Campaign | BR10: barrage_balloon | BT10: 0 | BZ10: 40 | CA10: 0.5 | CK10: 0 | CU10: Small | DA10: 364 | DD10: 4 | DH10: 16 | DI10: 9 | DJ10: 4 | DO10: 2 | DT10: 45 | DZ10: 0 | EA10: TRUE | EE10: 1 | EF10: 1 | EG10: 1 | EK10: none | EL10: 4 | EM10: Assets/MachineBrigade/Resources/Data/balance.json: vehicles[117] | EN10: {"id":"barrage_balloon","modelSize":[9.0,4.0,16.0],"fort":{"size":"Small"},"static":true,"armour":0,"hp":364,"speed":0,"turnRate":1,"turretTurnRate":1,"radius":2.0,"length":4.0,"width":4.0,"cp":0,"vision":1,"weapon":"none","balloon":{"radius":40,"scatter":0.5},"revealAir":45}
A11: blast_wall | B11: Gabion blast wall | C11: Tường chắn đạn | D11: Tường chắn đạn | H11: 0 | I11: 1364 | J11: 3000.8 | K11: 3 | L11: 3 | M11: 3 | N11: 3 | O11: TRUE | P11: 0 | Q11: 1 | R11: 1 | S11: 1 | T11: 2.2 | U11: 1.9 | V11: 4.8 | W11: FALSE | X11: 0 | Y11: TRUE | Z11: TRUE | AA11: 1 | AB11: 3.5 | AC11: 1 | AD11: none | AG11: none | AJ11: blast_wall | AK11: giong | BJ11: Small | BL11: FALSE | BM11: 2 | BN11: 2 | BO11: 25 | BP11: 2.5 | BQ11: Campaign | BR11: blast_wall | BT11: 3 | CB11: 50 | CC11: 0.3 | CD11: 10 | CK11: 0 | CU11: Small | DA11: 1364 | DD11: 1.9 | DH11: 2.4 | DI11: 1.9 | DJ11: 4.8 | DN11: TRUE | DO11: 2.2 | DZ11: 0 | EA11: TRUE | EE11: 1 | EF11: 1 | EG11: 1 | EK11: none | EL11: 4.8 | EM11: Assets/MachineBrigade/Resources/Data/balance.json: vehicles[115] | EN11: {"id":"blast_wall","modelSize":[1.9,4.8,2.4],"fort":{"size":"Small"},"static":true,"passable":true,"armour":3,"hp":1364,"speed":0,"turnRate":1,"turretTurnRate":1,"radius":2.2,"length":1.9,"width":4.8,"cp":0,"vision":1,"weapon":"none","blastWall":{"radius":10,"cut":0.3,"cone":50}}
A12: bulwark_post | B12: Field gun post | C12: Ụ súng dã chiến | D12: Ụ súng | E12: Defense | H12: 0 | I12: 500 | J12: 1100 | K12: 1 | L12: 1 | M12: 1 | N12: 1 | O12: TRUE | P12: 0 | Q12: 1 | R12: 160 | S12: 34 | T12: 1.6 | U12: 2.72 | V12: 2.72 | W12: FALSE | X12: 0 | Y12: TRUE | Z12: TRUE | AA12: 1 | AB12: 3.5 | AC12: 1 | AD12: bunker_hmg | AG12: none | AJ12: bulwark_post | AK12: giong | BL12: FALSE | BN12: 2 | BQ12: Campaign | BR12: bulwark_post | BT12: 1 | CG12: Defense | CK12: 0 | CL12: 40 | CM12: 0.2 | CN12: 4 | CO12: Large | DA12: 500 | DD12: 3.4 | DG12: bulwark_post | DO12: 1.6 | DV12: 0.8 | DZ12: 0 | EA12: TRUE | EE12: 1 | EF12: 160 | EG12: 34 | EK12: bunker_hmg | EL12: 3.4 | EM12: Assets/MachineBrigade/Resources/Data/balance.json: vehicles[106] | EN12: {"id":"bulwark_post","class":"Defense","static":true,"model":"bulwark_post","armour":1,"hp":500,"speed":0,"turnRate":1,"turretTurnRate":160,"radius":1.6,"length":3.4,"width":3.4,"scale":0.8,"cp":0,"vision":34,"weapon":"bunker_hmg","deathExplosion":{"damage":40,"radius":4,"delay":0.2,"tier":"Large"}}
A13: bunker_shelter_tower | B13: Bunker (medium slot) | C13: Hầm ngầm che quân | D13: Hầm ngầm | H13: 0 | I13: 1818 | J13: 3999.6 | K13: 3 | L13: 3 | M13: 3 | N13: 3 | O13: TRUE | P13: 0 | Q13: 1 | R13: 1 | S13: 30 | T13: 2.6 | U13: 6 | V13: 5 | W13: FALSE | X13: 0 | Y13: TRUE | Z13: TRUE | AA13: 1 | AB13: 3.5 | AC13: 1 | AD13: none | AG13: none | AJ13: bunker_shelter_tower | AK13: giong | BJ13: Medium | BL13: FALSE | BM13: 4 | BN13: 4 | BO13: 40 | BP13: 3.5 | BQ13: Campaign | BR13: bunker_shelter_tower | BT13: 3 | CK13: 0 | CU13: Medium | DA13: 1818 | DD13: 6 | DG13: bunker_shelter_tower | DH13: 2.2 | DI13: 6 | DJ13: 5 | DO13: 2.6 | DX13: 0.5 | DY13: 18 | DZ13: 0 | EA13: TRUE | EE13: 1 | EF13: 1 | EG13: 30 | EK13: none | EL13: 5 | EM13: Assets/MachineBrigade/Resources/Data/balance.json: vehicles[130] | EN13: {"id":"bunker_shelter_tower","model":"bunker_shelter_tower","modelSize":[6.0,5.0,2.2],"fort":{"size":"Medium"},"static":true,"armour":3,"hp":1818,"speed":0,"turnRate":1,"turretTurnRate":1,"radius":2.6,"length":6.0,"width":5.0,"cp":0,"vision":30,"weapon":"none","shelter":{"radius":18,"cut":0.5}}
A14: c_ram | B14: C-RAM interceptor | C14: Trạm đánh chặn C-RAM | D14: C-RAM | H14: 0 | I14: 1300 | J14: 2860 | K14: 1 | L14: 1 | M14: 1 | N14: 1 | O14: TRUE | P14: 0 | Q14: 1 | R14: 240 | S14: 60 | T14: 2.5 | U14: 5.5 | V14: 5.5 | W14: FALSE | X14: 0 | Y14: TRUE | Z14: TRUE | AA14: 1 | AB14: 3.5 | AC14: 1 | AD14: c_ram_gatling | AG14: aps | AH14: 4 | AI14: 0.6 | AJ14: c_ram | AK14: giong | BJ14: Medium | BL14: TRUE | BM14: 5 | BN14: 5 | BO14: 40 | BP14: 3.5 | BQ14: Campaign | BR14: c_ram | BT14: 1 | CF14: c_ram.centurion;c_ram.dome | CK14: 0 | CL14: 90 | CM14: 0.4 | CN14: 7 | CO14: Huge | CU14: Medium | DA14: 1300 | DD14: 5.5 | DO14: 2.5 | DP14: 5 | DZ14: 0 | EA14: TRUE | EE14: 1 | EF14: 240 | EG14: 60 | EK14: c_ram_gatling | EL14: 5.5 | EM14: Assets/MachineBrigade/Resources/Data/balance.json: vehicles[72] | EN14: {"id":"c_ram","rebuildCp":5,"branches":["c_ram.centurion","c_ram.dome"],"fort":{"size":"Medium"},"static":true,"armour":1,"hp":1300,"speed":0,"turnRate":1,"turretTurnRate":240,"radius":2.5,"length":5.5,"width":5.5,"cp":0,"vision":60,"weapon":"c_ram_gatling","aps":{"radius":35,"charges":4,"recharge":0.6,"rockets":true,"shells":0.3,"burst":0.5},"deathExplosion":{"damage":90,"radius":7,"delay":0.4,"tier":"Huge"}}
A15: c_ram.centurion | D15: Centurion | G15: c_ram | H15: 0 | I15: 1300 | J15: 2860 | K15: 1 | L15: 1 | M15: 1 | N15: 1 | O15: TRUE | P15: 0 | Q15: 1 | R15: 240 | S15: 60 | T15: 2.5 | U15: 5.5 | V15: 5.5 | W15: FALSE | X15: 0 | Y15: TRUE | Z15: TRUE | AA15: 1 | AB15: 3.5 | AC15: 1 | AD15: c_ram_gatling | AG15: aps | AH15: 5 | AI15: 0.35 | AJ15: c_ram | AK15: giong | BH15: c_ram | BI15: centurion | BJ15: Medium | BK15: intercept_close_fast | BL15: FALSE | BM15: 5 | BN15: 5 | BO15: 40 | BP15: 3.5 | BQ15: Campaign | BR15: c_ram | BY15: c_ram_a | CE15: c_ram | DB15: c_ram | DP15: 5 | ED15: intercept_close_fast | EM15: Assets/MachineBrigade/Resources/Data/balance.json: vehicles[91] | EN15: {"id":"c_ram.centurion","rebuildCp":5,"towerRole":"intercept_close_fast","art":"c_ram_a","inherits":"c_ram","branchOf":"c_ram","aps":{"radius":35,"charges":5,"recharge":0.35,"rockets":true,"shells":0.4,"burst":0.3}}
A16: c_ram.dome | D16: Vòm Sắt | G16: c_ram | H16: 0 | I16: 1300 | J16: 2860 | K16: 1 | L16: 1 | M16: 1 | N16: 1 | O16: TRUE | P16: 0 | Q16: 1 | R16: 240 | S16: 64 | T16: 2.5 | U16: 5.5 | V16: 5.5 | W16: FALSE | X16: 0 | Y16: TRUE | Z16: TRUE | AA16: 1 | AB16: 3.5 | AC16: 1 | AD16: tamir | AG16: aps | AH16: 6 | AJ16: c_ram | AK16: giong | BH16: c_ram | BI16: dome | BJ16: Medium | BK16: intercept_far_slow | BL16: FALSE | BM16: 5 | BN16: 5 | BO16: 40 | BP16: 3.5 | BQ16: Campaign | BR16: c_ram | BY16: c_ram_b | CE16: c_ram | DB16: c_ram | DP16: 5 | ED16: intercept_far_slow | EG16: 64 | EK16: tamir | EM16: Assets/MachineBrigade/Resources/Data/balance.json: vehicles[92] | EN16: {"id":"c_ram.dome","rebuildCp":5,"towerRole":"intercept_far_slow","art":"c_ram_b","inherits":"c_ram","branchOf":"c_ram","weapon":"tamir","vision":64,"aps":{"radius":60,"charges":6,"reload":12,"rockets":true,"shells":0.5,"direct":false,"missiles":true}}
A17: coastal_battery | B17: Coastal Battery | C17: Trận địa pháo bờ biển | D17: Pháo bờ biển | E17: Defense | H17: 0 | I17: 3000 | J17: 6600 | K17: 4 | L17: 3 | M17: 3 | N17: 3 | O17: TRUE | P17: 0 | Q17: 1 | R17: 18 | S17: 130 | T17: 3.8 | U17: 8 | V17: 8 | W17: FALSE | X17: 0 | Y17: TRUE | Z17: TRUE | AA17: 1 | AB17: 3.5 | AC17: 1 | AD17: gun_155_coastal | AG17: none | AJ17: coastal_battery | AK17: giong | BL17: FALSE | BN17: 2 | BQ17: Campaign | BR17: coastal_battery | BU17: 4 | BV17: 3 | BW17: 3 | BX17: 3 | CG17: Defense | CK17: 0 | CL17: 220 | CM17: 0.5 | CN17: 12 | CO17: Ultimate | DA17: 3000 | DD17: 8 | DG17: coastal_battery | DK17: TRUE | DO17: 3.8 | DZ17: 0 | EA17: TRUE | EE17: 1 | EF17: 18 | EG17: 130 | EK17: gun_155_coastal | EL17: 8 | EM17: Assets/MachineBrigade/Resources/Data/balance.json: vehicles[158] | EN17: {"id":"coastal_battery","class":"Defense","static":true,"model":"coastal_battery","armour":[4,3,3,3],"hp":3000,"speed":0,"turnRate":1,"turretTurnRate":18,"radius":3.8,"length":8,"width":8,"cp":0,"vision":130,"weapon":"gun_155_coastal","navalOnly":true,"deathExplosion":{"damage":220,"radius":12,"delay":0.5,"tier":"Ultimate"}}
A18: cp_relay | B18: CP relay | C18: Trạm tiếp tế CP | D18: Trạm CP | H18: 0 | I18: 600 | J18: 1320 | K18: 1 | L18: 1 | M18: 1 | N18: 1 | O18: TRUE | P18: 0 | Q18: 1 | R18: 1 | S18: 30 | T18: 1.8 | U18: 4 | V18: 4 | W18: FALSE | X18: 0 | Y18: TRUE | Z18: TRUE | AA18: 1 | AB18: 3.5 | AC18: 1 | AD18: none | AG18: none | AJ18: cp_relay | AK18: giong | BI18: noBranch | BJ18: Small | BK18: cp_income | BL18: TRUE | BM18: 6 | BN18: 6 | BO18: 25 | BP18: 2.5 | BQ18: Campaign | BR18: cp_relay | BT18: 1 | CK18: 0 | CL18: 50 | CM18: 0.3 | CN18: 5 | CO18: Large | CU18: Small | DA18: 600 | DD18: 4 | DL18: TRUE | DO18: 1.8 | DP18: 6 | DQ18: 0.1 | DR18: 5 | DS18: 0.06 | DZ18: 0 | EA18: TRUE | ED18: cp_income | EE18: 1 | EF18: 1 | EG18: 30 | EK18: none | EL18: 4 | EM18: Assets/MachineBrigade/Resources/Data/balance.json: vehicles[109] | EN18: {"id":"cp_relay","rebuildCp":6,"towerRole":"cp_income","noBranch":true,"fort":{"size":"Small"},"static":true,"armour":1,"hp":600,"speed":0,"turnRate":1,"turretTurnRate":1,"radius":1.8,"length":4,"width":4,"cp":0,"vision":30,"weapon":"none","relay":{"income":0.1,"second":0.06,"quiet":5},"deathExplosion":{"damage":50,"radius":5,"delay":0.3,"tier":"Large"}}
A19: drone_hangar | B19: Drone hangar | C19: Nhà chứa drone | D19: Nhà chứa drone | H19: 0 | I19: 2200 | J19: 4840 | K19: 2 | L19: 2 | M19: 2 | N19: 2 | O19: TRUE | P19: 0 | Q19: 1 | R19: 1 | S19: 60 | T19: 3.6 | U19: 8 | V19: 8 | W19: FALSE | X19: 0 | Y19: TRUE | Z19: TRUE | AA19: 1 | AB19: 3.5 | AC19: 1 | AD19: fpv_hangar | AG19: none | AJ19: drone_hangar | AK19: giong | BJ19: Large | BL19: TRUE | BM19: 12 | BN19: 12 | BO19: 60 | BP19: 5 | BQ19: Campaign | BR19: drone_hangar | BT19: 2 | CF19: drone_hangar.lancet;drone_hangar.swarm | CK19: 0 | CL19: 160 | CM19: 0.4 | CN19: 10 | CO19: Ultimate | CU19: Large | DA19: 2200 | DD19: 8 | DE19: Hull | DF19: door_l | DO19: 3.6 | DP19: 12 | DZ19: 0 | EA19: TRUE | EE19: 1 | EF19: 1 | EG19: 60 | EK19: fpv_hangar | EL19: 8 | EM19: Assets/MachineBrigade/Resources/Data/balance.json: vehicles[73] | EN19: {"id":"drone_hangar","rebuildCp":12,"branches":["drone_hangar.lancet","drone_hangar.swarm"],"fort":{"size":"Large"},"static":true,"armour":2,"hp":2200,"speed":0,"turnRate":1,"turretTurnRate":1,"radius":3.6,"length":8,"width":8,"cp":0,"vision":60,"weapon":"fpv_hangar","mainSlot":"door_l","mainAim":"Hull","deathExplosion":{"damage":160,"radius":10,"delay":0.4,"tier":"Ultimate"}}
A20: drone_hangar.lancet | D20: Lancet | G20: drone_hangar | H20: 0 | I20: 2200 | J20: 4840 | K20: 2 | L20: 2 | M20: 2 | N20: 2 | O20: TRUE | P20: 0 | Q20: 1 | R20: 1 | S20: 60 | T20: 3.6 | U20: 8 | V20: 8 | W20: FALSE | X20: 0 | Y20: TRUE | Z20: TRUE | AA20: 1 | AB20: 3.5 | AC20: 1 | AD20: lancet_hangar | AG20: none | AJ20: drone_hangar | AK20: giong | BH20: drone_hangar | BI20: lancet | BJ20: Large | BK20: drone_loitering | BL20: FALSE | BM20: 14 | BN20: 14 | BO20: 60 | BP20: 5 | BQ20: Campaign | BR20: drone_hangar | BY20: drone_hangar_a | CE20: drone_hangar | DB20: drone_hangar | DP20: 14 | ED20: drone_loitering | EK20: lancet_hangar | EM20: Assets/MachineBrigade/Resources/Data/balance.json: vehicles[95] | EN20: {"id":"drone_hangar.lancet","rebuildCp":14,"towerRole":"drone_loitering","art":"drone_hangar_a","inherits":"drone_hangar","branchOf":"drone_hangar","weapon":"lancet_hangar"}
A21: drone_hangar.swarm | D21: Bầy đàn | G21: drone_hangar | H21: 0 | I21: 2200 | J21: 4840 | K21: 2 | L21: 2 | M21: 2 | N21: 2 | O21: TRUE | P21: 0 | Q21: 1 | R21: 1 | S21: 60 | T21: 3.6 | U21: 8 | V21: 8 | W21: FALSE | X21: 0 | Y21: TRUE | Z21: TRUE | AA21: 1 | AB21: 3.5 | AC21: 1 | AD21: fpv_hangar_swarm | AG21: none | AJ21: drone_hangar | AK21: giong | BH21: drone_hangar | BI21: swarm | BJ21: Large | BK21: drone_fpv_swarm | BL21: FALSE | BM21: 14 | BN21: 14 | BO21: 60 | BP21: 5 | BQ21: Campaign | BR21: drone_hangar | BY21: drone_hangar_b | CE21: drone_hangar | DB21: drone_hangar | DP21: 14 | ED21: drone_fpv_swarm | EK21: fpv_hangar_swarm | EM21: Assets/MachineBrigade/Resources/Data/balance.json: vehicles[96] | EN21: {"id":"drone_hangar.swarm","rebuildCp":14,"towerRole":"drone_fpv_swarm","art":"drone_hangar_b","inherits":"drone_hangar","branchOf":"drone_hangar","weapon":"fpv_hangar_swarm"}
A22: drone_net_tower | B22: Drone net corridor | C22: Lưới chắn drone | D22: Lưới drone | H22: 0 | I22: 364 | J22: 800.8 | K22: 0 | L22: 0 | M22: 0 | N22: 0 | O22: TRUE | P22: 0 | Q22: 1 | R22: 1 | S22: 20 | T22: 1.6 | U22: 3 | V22: 8 | W22: FALSE | X22: 0 | Y22: TRUE | Z22: TRUE | AA22: 1 | AB22: 3.5 | AC22: 1 | AD22: net_zap | AG22: none | AJ22: drone_net_tower | AK22: giong | BJ22: Small | BL22: FALSE | BM22: 2 | BN22: 2 | BO22: 25 | BP22: 2.5 | BQ22: Campaign | BR22: drone_net_tower | BT22: 0 | CK22: 0 | CU22: Small | DA22: 364 | DD22: 3 | DG22: drone_net_tower | DH22: 4.6 | DI22: 6 | DJ22: 4 | DN22: TRUE | DO22: 1.6 | DZ22: 0 | EA22: TRUE | EE22: 1 | EF22: 1 | EG22: 20 | EK22: net_zap | EL22: 8 | EM22: Assets/MachineBrigade/Resources/Data/balance.json: vehicles[133] | EN22: {"id":"drone_net_tower","model":"drone_net_tower","modelSize":[6.0,4.0,4.6],"fort":{"size":"Small"},"static":true,"passable":true,"armour":0,"hp":364,"speed":0,"turnRate":1,"turretTurnRate":1,"radius":1.6,"length":3.0,"width":8.0,"cp":0,"vision":20,"weapon":"net_zap"}
A23: ew_tower | B23: EW tower | C23: Tháp gây nhiễu EW | D23: Tháp EW | H23: 0 | I23: 800 | J23: 1760 | K23: 1 | L23: 1 | M23: 1 | N23: 1 | O23: TRUE | P23: 0 | Q23: 1 | R23: 60 | S23: 50 | T23: 1.8 | U23: 4 | V23: 4 | W23: FALSE | X23: 0 | Y23: TRUE | Z23: TRUE | AA23: 1 | AB23: 3.5 | AC23: 1 | AD23: none | AG23: none | AJ23: ew_tower | AK23: giong | BJ23: Small | BL23: TRUE | BM23: 3 | BN23: 3 | BO23: 25 | BP23: 2.5 | BQ23: Campaign | BR23: ew_tower | BT23: 1 | CF23: ew_tower.drone;ew_tower.spoof | CK23: 0 | CL23: 60 | CM23: 0.3 | CN23: 5 | CO23: Large | CU23: Small | DA23: 800 | DC23: 30 | DD23: 4 | DO23: 1.8 | DP23: 3 | DZ23: 0 | EA23: TRUE | EE23: 1 | EF23: 60 | EG23: 50 | EK23: none | EL23: 4 | EM23: Assets/MachineBrigade/Resources/Data/balance.json: vehicles[71] | EN23: {"id":"ew_tower","rebuildCp":3,"branches":["ew_tower.drone","ew_tower.spoof"],"fort":{"size":"Small"},"static":true,"armour":1,"hp":800,"speed":0,"turnRate":1,"turretTurnRate":60,"radius":1.8,"length":4,"width":4,"cp":0,"vision":50,"weapon":"none","jammer":30,"deathExplosion":{"damage":60,"radius":5,"delay":0.3,"tier":"Large"}}
A24: ew_tower.drone | D24: Chống drone | G24: ew_tower | H24: 0 | I24: 800 | J24: 1760 | K24: 1 | L24: 1 | M24: 1 | N24: 1 | O24: TRUE | P24: 0 | Q24: 1 | R24: 60 | S24: 50 | T24: 1.8 | U24: 4 | V24: 4 | W24: FALSE | X24: 0 | Y24: TRUE | Z24: TRUE | AA24: 1 | AB24: 3.5 | AC24: 1 | AD24: none | AG24: none | AJ24: ew_tower | AK24: giong | BH24: ew_tower | BI24: drone | BJ24: Small | BK24: jam_drones_guided | BL24: FALSE | BM24: 3 | BN24: 3 | BO24: 25 | BP24: 2.5 | BQ24: Campaign | BR24: ew_tower | BY24: ew_tower_a | CE24: ew_tower | DB24: ew_tower | DC24: 45 | DP24: 3 | ED24: jam_drones_guided | EM24: Assets/MachineBrigade/Resources/Data/balance.json: vehicles[80] | EN24: {"id":"ew_tower.drone","rebuildCp":3,"towerRole":"jam_drones_guided","art":"ew_tower_a","inherits":"ew_tower","branchOf":"ew_tower","jammer":45}
A25: ew_tower.spoof | D25: Đánh lừa radar | G25: ew_tower | H25: 0 | I25: 800 | J25: 1760 | K25: 1 | L25: 1 | M25: 1 | N25: 1 | O25: TRUE | P25: 0 | Q25: 1 | R25: 60 | S25: 50 | T25: 1.8 | U25: 4 | V25: 4 | W25: FALSE | X25: 0 | Y25: TRUE | Z25: TRUE | AA25: 1 | AB25: 3.5 | AC25: 1 | AD25: none | AG25: none | AJ25: ew_tower | AK25: giong | BH25: ew_tower | BI25: spoof | BJ25: Small | BK25: radar_spoof_counterbattery | BL25: FALSE | BM25: 3 | BN25: 3 | BO25: 25 | BP25: 2.5 | BQ25: Campaign | BR25: ew_tower | BY25: ew_tower_b | CE25: ew_tower | CH25: 0 | CI25: 80 | CJ25: 6 | DB25: ew_tower | DP25: 3 | ED25: radar_spoof_counterbattery | EM25: Assets/MachineBrigade/Resources/Data/balance.json: vehicles[81] | EN25: {"id":"ew_tower.spoof","rebuildCp":3,"towerRole":"radar_spoof_counterbattery","art":"ew_tower_b","inherits":"ew_tower","branchOf":"ew_tower","counterBattery":{"range":80,"seconds":6,"bonus":0}}
A26: flare_searchlight_tower | B26: Flare tower (small slot) | C26: Tháp pháo sáng (ô nhỏ) | D26: Tháp pháo sáng | H26: 0 | I26: 455 | J26: 1001 | K26: 1 | L26: 1 | M26: 1 | N26: 1 | O26: TRUE | P26: 0 | Q26: 1 | R26: 90 | S26: 55 | T26: 1.8 | U26: 3.6 | V26: 3.6 | W26: FALSE | X26: 0 | Y26: TRUE | Z26: TRUE | AA26: 1 | AB26: 3.5 | AC26: 1 | AD26: illum_flare | AG26: flare | AH26: 0 | AI26: 0 | AJ26: flare_searchlight_tower | AK26: giong | BJ26: Small | BL26: FALSE | BM26: 2 | BN26: 2 | BO26: 25 | BP26: 2.5 | BQ26: Campaign | BR26: flare_searchlight_tower | BT26: 1 | CK26: 0 | CL26: 25 | CM26: 0.2 | CN26: 4 | CO26: Large | CU26: Small | DA26: 455 | DD26: 3.6 | DG26: flare_searchlight_tower | DH26: 5 | DI26: 3.6 | DJ26: 3.6 | DO26: 1.8 | DZ26: 0 | EA26: TRUE | EE26: 1 | EF26: 90 | EG26: 55 | EK26: illum_flare | EL26: 3.6 | EM26: Assets/MachineBrigade/Resources/Data/balance.json: vehicles[128] | EN26: {"id":"flare_searchlight_tower","model":"flare_searchlight_tower","modelSize":[3.6,3.6,5.0],"fort":{"size":"Small"},"static":true,"armour":1,"hp":455,"speed":0,"turnRate":1,"turretTurnRate":90,"radius":1.8,"length":3.6,"width":3.6,"cp":0,"vision":55,"weapon":"illum_flare","flares":{"every":15,"range":40,"radius":25,"seconds":15},"deathExplosion":{"damage":25,"radius":4,"delay":0.2,"tier":"Large"}}
A27: flare_tower | B27: Flare tower | C27: Tháp pháo sáng | D27: Tháp pháo sáng | H27: 0 | I27: 455 | J27: 1001 | K27: 1 | L27: 1 | M27: 1 | N27: 1 | O27: TRUE | P27: 0 | Q27: 1 | R27: 90 | S27: 60 | T27: 1.8 | U27: 3.6 | V27: 3.6 | W27: FALSE | X27: 0 | Y27: TRUE | Z27: TRUE | AA27: 1 | AB27: 3.5 | AC27: 1 | AD27: illum_flare | AG27: flare | AH27: 0 | AI27: 0 | AJ27: flare_tower | AK27: giong | BJ27: Small | BL27: FALSE | BM27: 2 | BN27: 2 | BO27: 25 | BP27: 2.5 | BQ27: Campaign | BR27: flare_tower | BT27: 1 | CK27: 0 | CL27: 30 | CM27: 0.2 | CN27: 4 | CO27: Large | CU27: Small | DA27: 455 | DD27: 3.6 | DH27: 5 | DI27: 3.6 | DJ27: 3.6 | DO27: 1.8 | DZ27: 0 | EA27: TRUE | EE27: 1 | EF27: 90 | EG27: 60 | EK27: illum_flare | EL27: 3.6 | EM27: Assets/MachineBrigade/Resources/Data/balance.json: vehicles[118] | EN27: {"id":"flare_tower","modelSize":[3.6,3.6,5.0],"fort":{"size":"Small"},"static":true,"armour":1,"hp":455,"speed":0,"turnRate":1,"turretTurnRate":90,"radius":1.8,"length":3.6,"width":3.6,"cp":0,"vision":60,"weapon":"illum_flare","flares":{"every":15,"range":40,"radius":30,"seconds":15},"deathExplosion":{"damage":30,"radius":4,"delay":0.2,"tier":"Large"}}
A28: guard_tower | B28: Guard tower | C28: Tháp canh | D28: Tháp canh | H28: 0 | I28: 700 | J28: 1540 | K28: 1 | L28: 1 | M28: 1 | N28: 1 | O28: TRUE | P28: 0 | Q28: 1 | R28: 200 | S28: 60 | T28: 1.8 | U28: 3.5 | V28: 3.5 | W28: FALSE | X28: 0 | Y28: TRUE | Z28: TRUE | AA28: 1 | AB28: 3.5 | AC28: 1 | AD28: tower_hmg | AG28: none | AJ28: guard_tower | AK28: giong | BJ28: Small | BL28: TRUE | BM28: 5 | BN28: 5 | BO28: 25 | BP28: 2.5 | BQ28: Starter | BR28: guard_tower | BT28: 1 | CF28: guard_tower.watch;guard_tower.nest | CK28: 0 | CL28: 60 | CM28: 0.3 | CN28: 5 | CO28: Large | CU28: Small | DA28: 700 | DD28: 3.5 | DO28: 1.8 | DP28: 5 | DU28: TRUE | DZ28: 0 | EA28: TRUE | EB28: 25 | EC28: 0.1 | EE28: 1 | EF28: 200 | EG28: 60 | EK28: tower_hmg | EL28: 3.5 | EM28: Assets/MachineBrigade/Resources/Data/balance.json: vehicles[107] | EN28: {"id":"guard_tower","rebuildCp":5,"branches":["guard_tower.watch","guard_tower.nest"],"fort":{"size":"Small"},"static":true,"armour":1,"hp":700,"speed":0,"turnRate":1,"turretTurnRate":200,"radius":1.8,"length":3.5,"width":3.5,"cp":0,"vision":60,"revealStealth":true,"towerRangeAura":{"radius":25,"range":0.1},"weapon":"tower_hmg","secondary":[],"deathExplosion":{"damage":60,"radius":5,"delay":0.3,"tier":"Large"}}
A29: guard_tower.nest | D29: Ổ súng | G29: guard_tower | H29: 0 | I29: 700 | J29: 1540 | K29: 1 | L29: 1 | M29: 1 | N29: 1 | O29: TRUE | P29: 0 | Q29: 1 | R29: 200 | S29: 48 | T29: 1.8 | U29: 3.5 | V29: 3.5 | W29: FALSE | X29: 0 | Y29: TRUE | Z29: TRUE | AA29: 1 | AB29: 3.5 | AC29: 1 | AD29: tower_ac25 | AG29: none | AJ29: guard_tower | AK29: giong | BH29: guard_tower | BI29: nest | BJ29: Small | BK29: autocannon_25 | BL29: FALSE | BM29: 5 | BN29: 5 | BO29: 25 | BP29: 2.5 | BQ29: Campaign | BR29: guard_tower | BY29: guard_tower_b | CE29: guard_tower | DB29: guard_tower | DP29: 5 | ED29: autocannon_25 | EG29: 48 | EK29: tower_ac25 | EM29: Assets/MachineBrigade/Resources/Data/balance.json: vehicles[77] | EN29: {"id":"guard_tower.nest","rebuildCp":5,"towerRole":"autocannon_25","art":"guard_tower_b","inherits":"guard_tower","branchOf":"guard_tower","weapon":"tower_ac25","vision":48}
A30: guard_tower.watch | D30: Tháp quan sát | G30: guard_tower | H30: 0 | I30: 700 | J30: 1540 | K30: 1 | L30: 1 | M30: 1 | N30: 1 | O30: TRUE | P30: 0 | Q30: 1 | R30: 200 | S30: 78 | T30: 1.8 | U30: 3.5 | V30: 3.5 | W30: FALSE | X30: 0 | Y30: TRUE | Z30: TRUE | AA30: 1 | AB30: 3.5 | AC30: 1 | AD30: tower_hmg | AG30: none | AJ30: guard_tower | AK30: giong | BH30: guard_tower | BI30: watch | BJ30: Small | BK30: observation_reach | BL30: FALSE | BM30: 5 | BN30: 5 | BO30: 25 | BP30: 2.5 | BQ30: Campaign | BR30: guard_tower | BY30: guard_tower_a | CE30: guard_tower | DB30: guard_tower | DP30: 5 | EB30: 35 | EC30: 0.15 | ED30: observation_reach | EG30: 78 | EM30: Assets/MachineBrigade/Resources/Data/balance.json: vehicles[76] | EN30: {"id":"guard_tower.watch","rebuildCp":5,"towerRole":"observation_reach","art":"guard_tower_a","inherits":"guard_tower","branchOf":"guard_tower","vision":78,"towerRangeAura":{"radius":35,"range":0.15}}
A31: gun_turret | B31: Gun turret | C31: Tháp pháo | D31: Tháp pháo | H31: 0 | I31: 1800 | J31: 3960 | K31: 3 | L31: 3 | M31: 3 | N31: 3 | O31: TRUE | P31: 0 | Q31: 1 | R31: 28 | S31: 42 | T31: 2.5 | U31: 5 | V31: 5 | W31: FALSE | X31: 0 | Y31: TRUE | Z31: TRUE | AA31: 1 | AB31: 3.5 | AC31: 1 | AD31: turret_gun_120 | AG31: none | AJ31: gun_turret | AK31: giong | BJ31: Medium | BL31: TRUE | BM31: 11 | BN31: 11 | BO31: 40 | BP31: 3.5 | BQ31: Starter | BR31: gun_turret | BT31: 3 | CF31: gun_turret.long;gun_turret.auto | CK31: 0 | CL31: 120 | CM31: 0.4 | CN31: 8 | CO31: Huge | CU31: Medium | DA31: 1800 | DD31: 5 | DO31: 2.5 | DP31: 11 | DZ31: 0 | EA31: TRUE | EE31: 1 | EF31: 28 | EG31: 42 | EK31: turret_gun_120 | EL31: 5 | EM31: Assets/MachineBrigade/Resources/Data/balance.json: vehicles[69] | EN31: {"id":"gun_turret","rebuildCp":11,"branches":["gun_turret.long","gun_turret.auto"],"fort":{"size":"Medium"},"static":true,"armour":3,"hp":1800,"speed":0,"turnRate":1,"turretTurnRate":28,"radius":2.5,"length":5,"width":5,"cp":0,"vision":42,"weapon":"turret_gun_120","secondary":[],"deathExplosion":{"damage":120,"radius":8,"delay":0.4,"tier":"Huge"}}
A32: gun_turret.auto | D32: Pháo 57 mm | G32: gun_turret | H32: 0 | I32: 1800 | J32: 3960 | K32: 3 | L32: 3 | M32: 3 | N32: 3 | O32: TRUE | P32: 0 | Q32: 1 | R32: 28 | S32: 42 | T32: 2.5 | U32: 5 | V32: 5 | W32: FALSE | X32: 0 | Y32: TRUE | Z32: TRUE | AA32: 1 | AB32: 3.5 | AC32: 1 | AD32: gun_57_auto | AG32: none | AJ32: gun_turret | AK32: giong | BH32: gun_turret | BI32: auto | BJ32: Medium | BK32: gun_57_light | BL32: FALSE | BM32: 11 | BN32: 11 | BO32: 40 | BP32: 3.5 | BQ32: Campaign | BR32: gun_turret | BY32: gun_turret_b | CE32: gun_turret | DB32: gun_turret | DP32: 11 | ED32: gun_57_light | EK32: gun_57_auto | EM32: Assets/MachineBrigade/Resources/Data/balance.json: vehicles[86] | EN32: {"id":"gun_turret.auto","rebuildCp":11,"towerRole":"gun_57_light","art":"gun_turret_b","inherits":"gun_turret","branchOf":"gun_turret","weapon":"gun_57_auto"}
A33: gun_turret.long | D33: Pháo bắn tỉa | G33: gun_turret | H33: 0 | I33: 1800 | J33: 3960 | K33: 3 | L33: 3 | M33: 3 | N33: 3 | O33: TRUE | P33: 0 | Q33: 1 | R33: 28 | S33: 42 | T33: 2.5 | U33: 5 | V33: 5 | W33: FALSE | X33: 0 | Y33: TRUE | Z33: TRUE | AA33: 1 | AB33: 3.5 | AC33: 1 | AD33: turret_gun_120_long | AG33: none | AJ33: gun_turret | AK33: giong | BH33: gun_turret | BI33: long | BJ33: Medium | BK33: gun_sniper_120 | BL33: FALSE | BM33: 11 | BN33: 11 | BO33: 40 | BP33: 3.5 | BQ33: Campaign | BR33: gun_turret | BY33: gun_turret_a | CE33: gun_turret | DB33: gun_turret | DP33: 11 | ED33: gun_sniper_120 | EK33: turret_gun_120_long | EM33: Assets/MachineBrigade/Resources/Data/balance.json: vehicles[85] | EN33: {"id":"gun_turret.long","rebuildCp":11,"towerRole":"gun_sniper_120","art":"gun_turret_a","inherits":"gun_turret","branchOf":"gun_turret","weapon":"turret_gun_120_long"}
A34: heavy_turret | B34: Heavy gun turret | C34: Tháp pháo hạng nặng | D34: Pháo hạng nặng | H34: 0 | I34: 2800 | J34: 6160 | K34: 4 | L34: 3 | M34: 3 | N34: 3 | O34: TRUE | P34: 0 | Q34: 1 | R34: 20 | S34: 60 | T34: 3.8 | U34: 8 | V34: 8 | W34: FALSE | X34: 0 | Y34: TRUE | Z34: TRUE | AA34: 1 | AB34: 3.5 | AC34: 1 | AD34: gun_155_twin_ap | AG34: none | AJ34: heavy_turret | AK34: giong | BJ34: Large | BL34: TRUE | BM34: 18 | BN34: 18 | BO34: 60 | BP34: 5 | BQ34: Campaign | BR34: heavy_turret | BU34: 4 | BV34: 3 | BW34: 3 | BX34: 3 | CF34: heavy_turret.coastal;heavy_turret.bastion | CK34: 0 | CL34: 220 | CM34: 0.5 | CN34: 12 | CO34: Ultimate | CU34: Large | DA34: 2800 | DD34: 8 | DO34: 3.8 | DP34: 18 | DZ34: 0 | EA34: TRUE | EE34: 1 | EF34: 20 | EG34: 60 | EK34: gun_155_twin_ap | EL34: 8 | EM34: Assets/MachineBrigade/Resources/Data/balance.json: vehicles[66] | EN34: {"id":"heavy_turret","rebuildCp":18,"branches":["heavy_turret.coastal","heavy_turret.bastion"],"fort":{"size":"Large"},"static":true,"armour":[4,3,3,3],"hp":2800,"speed":0,"turnRate":1,"turretTurnRate":20,"radius":3.8,"length":8,"width":8,"cp":0,"vision":60,"weapon":"gun_155_twin_ap","secondary":[],"deathExplosion":{"damage":220,"radius":12,"delay":0.5,"tier":"Ultimate"}}
A35: heavy_turret.bastion | D35: Pháo đài thép | G35: heavy_turret | H35: 0 | I35: 4340 | J35: 9548 | K35: 4 | L35: 3 | M35: 3 | N35: 3 | O35: TRUE | P35: 0 | Q35: 1 | R35: 20 | S35: 60 | T35: 3.8 | U35: 8 | V35: 8 | W35: FALSE | X35: 0 | Y35: TRUE | Z35: TRUE | AA35: 1 | AB35: 3.5 | AC35: 1 | AD35: gun_155_twin_ap | AE35: hmg_roof;hmg_roof | AG35: none | AJ35: heavy_turret | AK35: giong | BH35: heavy_turret | BI35: bastion | BJ35: Large | BK35: fortress_close_defence | BL35: FALSE | BM35: 18 | BN35: 18 | BO35: 60 | BP35: 5 | BQ35: Campaign | BR35: heavy_turret | BY35: heavy_turret_b | CE35: heavy_turret | DA35: 4340 | DB35: heavy_turret | DP35: 18 | ED35: fortress_close_defence | EM35: Assets/MachineBrigade/Resources/Data/balance.json: vehicles[98] | EN35: {"id":"heavy_turret.bastion","rebuildCp":18,"towerRole":"fortress_close_defence","art":"heavy_turret_b","secondary":[{"weapon":"hmg_roof","slot":"gun","aim":"Free"},{"weapon":"hmg_roof","slot":"gun","aim":"Free"}],"inherits":"heavy_turret","branchOf":"heavy_turret","hp":4340}
A36: heavy_turret.coastal | D36: Pháo bờ biển | G36: heavy_turret | H36: 0 | I36: 2800 | J36: 6160 | K36: 4 | L36: 3 | M36: 3 | N36: 3 | O36: TRUE | P36: 0 | Q36: 1 | R36: 20 | S36: 60 | T36: 3.8 | U36: 8 | V36: 8 | W36: FALSE | X36: 0 | Y36: TRUE | Z36: TRUE | AA36: 1 | AB36: 3.5 | AC36: 1 | AD36: gun_155_twin_coastlr | AG36: none | AJ36: heavy_turret | AK36: giong | BH36: heavy_turret | BI36: coastal | BJ36: Large | BK36: gun_coastal_long | BL36: FALSE | BM36: 18 | BN36: 18 | BO36: 60 | BP36: 5 | BQ36: Campaign | BR36: heavy_turret | BY36: heavy_turret_a | CE36: heavy_turret | DB36: heavy_turret | DP36: 18 | ED36: gun_coastal_long | EK36: gun_155_twin_coastlr | EM36: Assets/MachineBrigade/Resources/Data/balance.json: vehicles[97] | EN36: {"id":"heavy_turret.coastal","rebuildCp":18,"towerRole":"gun_coastal_long","art":"heavy_turret_a","inherits":"heavy_turret","branchOf":"heavy_turret","weapon":"gun_155_twin_coastlr"}
A37: laser_ad_station | B37: Laser Defence Tower | C37: Tháp la-de phòng thủ | D37: Tháp la-de | H37: 0 | I37: 1136 | J37: 2499.2 | K37: 1 | L37: 1 | M37: 1 | N37: 1 | O37: TRUE | P37: 0 | Q37: 1 | R37: 180 | S37: 56 | T37: 2.5 | U37: 5.5 | V37: 4 | W37: FALSE | X37: 0 | Y37: TRUE | Z37: TRUE | AA37: 1 | AB37: 3.5 | AC37: 1 | AD37: laser_50kw | AG37: aps | AH37: 1 | AI37: 0.8 | AJ37: laser_ad_station | AK37: giong | BJ37: Medium | BL37: TRUE | BM37: 5 | BN37: 5 | BO37: 40 | BP37: 3.5 | BQ37: Premium | BR37: laser_ad_station | BT37: 1 | CF37: laser_ad_station.laser | CK37: 0 | CL37: 80 | CM37: 0.4 | CN37: 7 | CO37: Huge | CU37: Medium | DA37: 1136 | DD37: 5.5 | DH37: 6.6 | DI37: 6 | DJ37: 3.85 | DO37: 2.5 | DP37: 5 | DZ37: 0 | EA37: TRUE | EE37: 1 | EF37: 180 | EG37: 56 | EK37: laser_50kw | EL37: 4 | EM37: Assets/MachineBrigade/Resources/Data/balance.json: vehicles[119] | EN37: {"id":"laser_ad_station","rebuildCp":5,"branches":["laser_ad_station.laser"],"modelSize":[6.0,3.85,6.6],"fort":{"size":"Medium"},"static":true,"armour":1,"hp":1136,"speed":0,"turnRate":1,"turretTurnRate":180,"radius":2.5,"length":5.5,"width":4.0,"cp":0,"vision":56,"weapon":"laser_50kw","aps":{"radius":40,"shells":0,"charges":1,"recharge":0.8,"rockets":true,"laser":true},"deathExplosion":{"damage":80,"radius":7,"delay":0.4,"tier":"Huge"}}
A38: laser_ad_station.laser | D38: La-de | G38: laser_ad_station | H38: 0 | I38: 1136 | J38: 2499.2 | K38: 1 | L38: 1 | M38: 1 | N38: 1 | O38: TRUE | P38: 0 | Q38: 1 | R38: 180 | S38: 56 | T38: 2.5 | U38: 5.5 | V38: 4 | W38: FALSE | X38: 0 | Y38: TRUE | Z38: TRUE | AA38: 1 | AB38: 3.5 | AC38: 1 | AD38: laser_50kw | AG38: aps | AH38: 1 | AI38: 0.8 | AJ38: laser_ad_station | AK38: moi | BH38: laser_ad_station | BI38: laser | BJ38: Medium | BK38: antidrone_laser | BL38: FALSE | BM38: 5 | BN38: 5 | BO38: 40 | BP38: 3.5 | BQ38: Campaign | BR38: laser_ad_station | CE38: laser_ad_station | DB38: laser_ad_station | DP38: 5 | ED38: antidrone_laser | EM38: Assets/MachineBrigade/Resources/Data/balance.json: vehicles[120] | EN38: {"id":"laser_ad_station.laser","rebuildCp":5,"inherits":"laser_ad_station","branchOf":"laser_ad_station","towerRole":"antidrone_laser"}
A39: manpads_tower | B39: MANPADS post | C39: Tổ tên lửa vác vai | D39: Tổ vác vai | H39: 0 | I39: 545 | J39: 1199 | K39: 1 | L39: 1 | M39: 1 | N39: 1 | O39: TRUE | P39: 0 | Q39: 1 | R39: 120 | S39: 40 | T39: 1.7 | U39: 3 | V39: 3 | W39: FALSE | X39: 0 | Y39: TRUE | Z39: TRUE | AA39: 1 | AB39: 3.5 | AC39: 1 | AD39: sam | AG39: none | AJ39: manpads_tower | AK39: giong | BJ39: Small | BL39: FALSE | BM39: 2 | BN39: 2 | BO39: 25 | BP39: 2.5 | BQ39: Campaign | BR39: manpads_tower | BT39: 1 | CK39: 0 | CU39: Small | DA39: 545 | DD39: 3 | DG39: manpads_tower | DH39: 2.4 | DI39: 3.2 | DJ39: 3.2 | DO39: 1.7 | DZ39: 0 | EA39: TRUE | EE39: 1 | EF39: 120 | EG39: 40 | EK39: sam | EL39: 3 | EM39: Assets/MachineBrigade/Resources/Data/balance.json: vehicles[135] | EN39: {"id":"manpads_tower","model":"manpads_tower","modelSize":[3.2,3.2,2.4],"fort":{"size":"Small"},"static":true,"armour":1,"hp":545,"speed":0,"turnRate":1,"turretTurnRate":120,"radius":1.7,"length":3.0,"width":3.0,"cp":0,"vision":40,"weapon":"sam"}
A40: mg_bunker | B40: MG bunker | C40: Lô cốt súng máy | D40: Lô cốt | H40: 0 | I40: 1500 | J40: 3300 | K40: 3 | L40: 2 | M40: 2 | N40: 2 | O40: TRUE | P40: 0 | Q40: 1 | R40: 120 | S40: 36 | T40: 2 | U40: 4 | V40: 4 | W40: FALSE | X40: 0 | Y40: TRUE | Z40: TRUE | AA40: 1 | AB40: 3.5 | AC40: 0.6086 | AD40: bunker_hmg | AE40: bunker_pkm;bunker_pkm;bunker_pkm;bunker_pkm | AG40: none | AJ40: mg_bunker | AK40: doi | BE40: bunker_pkm;bunker_pkm;bunker_pkm;bunker_pkm | BF40: 1 | BG40: 0.6086 | BJ40: Small | BL40: TRUE | BM40: 6 | BN40: 6 | BO40: 25 | BP40: 2.5 | BQ40: Starter | BR40: mg_bunker | BS40: giam_dps_giu_mau | BU40: 3 | BV40: 2 | BW40: 2 | BX40: 2 | CF40: mg_bunker.twin;mg_bunker.flame | CK40: 0 | CL40: 70 | CM40: 0.3 | CN40: 6 | CO40: Large | CU40: Small | DA40: 1500 | DD40: 4 | DM40: 0.6086 | DO40: 2 | DP40: 6 | DZ40: 0 | EA40: TRUE | EE40: 1 | EF40: 120 | EG40: 36 | EK40: bunker_hmg | EL40: 4 | EM40: Assets/MachineBrigade/Resources/Data/balance.json: vehicles[105] | EN40: {"id":"mg_bunker","outgoingDamageMult":0.6086,"rebuildCp":6,"branches":["mg_bunker.twin","mg_bunker.flame"],"fort":{"size":"Small"},"static":true,"armour":[3,2,2,2],"hp":1500,"speed":0,"turnRate":1,"turretTurnRate":120,"radius":2.0,"length":4,"width":4,"cp":0,"vision":36,"weapon":"bunker_hmg","deathExplosion":{"damage":70,"radius":6,"delay":0.3,"tier":"Large"},"secondary":[{"weapon":"bunker_pkm","slot":"mg","aim":"Free","arc":[-30,40]},{"weapon":"bunker_pkm","slot":"mg","aim":"Free","arc":[30,40]},{"weapon":"bunker_pkm","slot":"mg","aim":"Free","arc":[-90,40]},{"weapon":"bunker_pkm","slot":"mg","aim":"Free","arc":[90,40]}]}
...

Sheet Thap_vu_khi
A1: id | B1: thap_id | C1: thu_tu | D1: weapon | E1: aim | F1: arc_deg_center_deg | G1: arc_deg_half_deg | H1: slot | I1: nguon | J1: raw_json
A2: aa_turret/0 | B2: aa_turret | C2: 0 | D2: sam | E2: Turret | H2: missile | I2: Assets/MachineBrigade/Resources/Data/balance.json: vehicles[70].secondary[0] | J2: {"weapon":"sam","slot":"missile","aim":"Turret"}
A3: heavy_turret.bastion/0 | B3: heavy_turret.bastion | C3: 0 | D3: hmg_roof | E3: Free | H3: gun | I3: Assets/MachineBrigade/Resources/Data/balance.json: vehicles[98].secondary[0] | J3: {"weapon":"hmg_roof","slot":"gun","aim":"Free"}
A4: heavy_turret.bastion/1 | B4: heavy_turret.bastion | C4: 1 | D4: hmg_roof | E4: Free | H4: gun | I4: Assets/MachineBrigade/Resources/Data/balance.json: vehicles[98].secondary[1] | J4: {"weapon":"hmg_roof","slot":"gun","aim":"Free"}
A5: mg_bunker/0 | B5: mg_bunker | C5: 0 | D5: bunker_pkm | E5: Free | F5: -30 | G5: 40 | H5: mg | I5: Assets/MachineBrigade/Resources/Data/balance.json: vehicles[105].secondary[0] | J5: {"weapon":"bunker_pkm","slot":"mg","aim":"Free","arc":[-30,40]}
A6: mg_bunker/1 | B6: mg_bunker | C6: 1 | D6: bunker_pkm | E6: Free | F6: 30 | G6: 40 | H6: mg | I6: Assets/MachineBrigade/Resources/Data/balance.json: vehicles[105].secondary[1] | J6: {"weapon":"bunker_pkm","slot":"mg","aim":"Free","arc":[30,40]}
A7: mg_bunker/2 | B7: mg_bunker | C7: 2 | D7: bunker_pkm | E7: Free | F7: -90 | G7: 40 | H7: mg | I7: Assets/MachineBrigade/Resources/Data/balance.json: vehicles[105].secondary[2] | J7: {"weapon":"bunker_pkm","slot":"mg","aim":"Free","arc":[-90,40]}
A8: mg_bunker/3 | B8: mg_bunker | C8: 3 | D8: bunker_pkm | E8: Free | F8: 90 | G8: 40 | H8: mg | I8: Assets/MachineBrigade/Resources/Data/balance.json: vehicles[105].secondary[3] | J8: {"weapon":"bunker_pkm","slot":"mg","aim":"Free","arc":[90,40]}

Sheet Tuong
A1: id | B1: ten_en | C1: ten_vi | D1: ten_ngan_vi | E1: lop | F1: nhanh | G1: ke_thua_tu | H1: base_cp | I1: mau_hp | J1: mau_trong_tran_hp | K1: giap_truoc | L1: giap_hong | M1: giap_sau | N1: giap_noc | O1: cong_trinh | P1: toc_do_m_s | Q1: xoay_than_deg_s | R1: xoay_thap_deg_s | S1: tam_nhin_m | T1: ban_kinh_m | U1: dai_m | V1: rong_m | W1: bay | X1: do_cao_m | Y1: dung_yen | Z1: ban_khi_chay | AA1: toc_do_chiem | AB1: tha_du_s | AC1: he_so_sat_thuong_ra | AD1: vu_khi_chinh | AE1: vu_khi_phu | AF1: noi_tai | AG1: tu_ve | AH1: so_lan_tu_ve | AI1: hoi_tu_ve_s | AJ1: mo_hinh | AK1: so_voi_ban_goc | AL1: base_cp_truoc | AM1: base_cp_sau | AN1: mau_hp_truoc | AO1: mau_hp_sau | AP1: giap_truoc_truoc | AQ1: giap_truoc_sau | AR1: giap_hong_truoc | AS1: giap_hong_sau | AT1: giap_sau_truoc | AU1: giap_sau_sau | AV1: giap_noc_truoc | AW1: giap_noc_sau | AX1: toc_do_m_s_truoc | AY1: toc_do_m_s_sau | AZ1: tam_nhin_m_truoc | BA1: tam_nhin_m_sau | BB1: vu_khi_chinh_truoc | BC1: vu_khi_chinh_sau | BD1: vu_khi_phu_truoc | BE1: vu_khi_phu_sau | BF1: he_so_sat_thuong_ra_truoc | BG1: he_so_sat_thuong_ra_sau | BH1: loai | BI1: do_ben_tuong_doi | BJ1: tuong_them | BK1: co_sung | BL1: trang_thai_navmesh | BM1: armour | BN1: card | BO1: cp | BP1: hp | BQ1: length_m | BR1: obstacle | BS1: radius_m | BT1: speed_m_s | BU1: static | BV1: turn_rate_deg_s | BW1: turret_turn_rate_deg_s | BX1: vision_m | BY1: wall | BZ1: weapon | CA1: width_m | CB1: nguon | CC1: raw_json
A2: wall_gun | B2: Gun wall | C2: Tường gắn súng | D2: Tường súng | H2: 0 | I2: 2880 | J2: 6336 | K2: 3 | L2: 3 | M2: 3 | N2: 3 | O2: TRUE | P2: 0 | Q2: 1 | R2: 1 | S2: 1 | T2: 1.5 | U2: 2 | V2: 12 | W2: FALSE | X2: 0 | Y2: TRUE | Z2: TRUE | AA2: 1 | AB2: 3.5 | AC2: 1 | AD2: none | AG2: none | AJ2: wall_gun | AK2: moi | BH2: gun_wall | BI2: 1.2 | BK2: TRUE | BL2: obstacle | BM2: 3 | BN2: FALSE | BO2: 0 | BP2: 2880 | BQ2: 2 | BR2: TRUE | BS2: 1.5 | BT2: 0 | BU2: TRUE | BV2: 1 | BW2: 1 | BX2: 1 | BY2: TRUE | BZ2: none | CA2: 12 | CB2: Assets/MachineBrigade/Resources/Data/balance.json: vehicles[84] | CC2: {"id":"wall_gun","card":false,"wall":true,"static":true,"obstacle":true,"armour":3,"hp":2880,"speed":0,"turnRate":1,"turretTurnRate":1,"radius":1.5,"length":2,"width":12,"cp":0,"vision":1,"weapon":"none"}
A3: wall_hesco | B3: HESCO wall | C3: Tường HESCO | D3: HESCO | H3: 0 | I3: 2400 | J3: 5280 | K3: 3 | L3: 3 | M3: 3 | N3: 3 | O3: TRUE | P3: 0 | Q3: 1 | R3: 1 | S3: 1 | T3: 1.5 | U3: 2 | V3: 12 | W3: FALSE | X3: 0 | Y3: TRUE | Z3: TRUE | AA3: 1 | AB3: 3.5 | AC3: 1 | AD3: none | AG3: none | AJ3: wall_hesco | AK3: moi | BH3: hesco | BI3: 1 | BL3: obstacle | BM3: 3 | BN3: FALSE | BO3: 0 | BP3: 2400 | BQ3: 2 | BR3: TRUE | BS3: 1.5 | BT3: 0 | BU3: TRUE | BV3: 1 | BW3: 1 | BX3: 1 | BY3: TRUE | BZ3: none | CA3: 12 | CB3: Assets/MachineBrigade/Resources/Data/balance.json: vehicles[82] | CC3: {"id":"wall_hesco","card":false,"wall":true,"static":true,"obstacle":true,"armour":3,"hp":2400,"speed":0,"turnRate":1,"turretTurnRate":1,"radius":1.5,"length":2,"width":12,"cp":0,"vision":1,"weapon":"none"}
A4: wall_t | B4: T-wall | C4: Tường chữ T | D4: Tường T | H4: 0 | I4: 3840 | J4: 8448 | K4: 4 | L4: 4 | M4: 4 | N4: 4 | O4: TRUE | P4: 0 | Q4: 1 | R4: 1 | S4: 1 | T4: 1.5 | U4: 2 | V4: 12 | W4: FALSE | X4: 0 | Y4: TRUE | Z4: TRUE | AA4: 1 | AB4: 3.5 | AC4: 1 | AD4: none | AG4: none | AJ4: wall_t | AK4: moi | BH4: t_wall | BI4: 1.6 | BJ4: TRUE | BL4: obstacle | BM4: 4 | BN4: FALSE | BO4: 0 | BP4: 3840 | BQ4: 2 | BR4: TRUE | BS4: 1.5 | BT4: 0 | BU4: TRUE | BV4: 1 | BW4: 1 | BX4: 1 | BY4: TRUE | BZ4: none | CA4: 12 | CB4: Assets/MachineBrigade/Resources/Data/balance.json: vehicles[83] | CC4: {"id":"wall_t","card":false,"wall":true,"static":true,"obstacle":true,"armour":4,"hp":3840,"speed":0,"turnRate":1,"turretTurnRate":1,"radius":1.5,"length":2,"width":12,"cp":0,"vision":1,"weapon":"none"}

Sheet Tuong_luat
A1: id | B1: nhom | C1: khoa | D1: gia_tri_so | E1: gia_tri_chu | F1: don_vi | G1: nguon | H1: raw_json
A2: ai.brandt | B2: base.walls | C2: brandt | E2: t_wall | G2: Assets/MachineBrigade/Resources/Data/balance.json: base.walls.ai.brandt | H2: "t_wall"
A3: ai.default | B3: base.walls | C3: default | E3: hesco | G3: Assets/MachineBrigade/Resources/Data/balance.json: base.walls.ai.default | H3: "hesco"
A4: ai.kessler | B4: base.walls | C4: kessler | E4: t_wall | G4: Assets/MachineBrigade/Resources/Data/balance.json: base.walls.ai.kessler | H4: "t_wall"
A5: ai.varga | B5: base.walls | C5: varga | E5: gun_wall | G5: Assets/MachineBrigade/Resources/Data/balance.json: base.walls.ai.varga | H5: "gun_wall"
A6: breakerMultiplier | B6: base.walls | C6: breakerMultiplier | D6: 1.5 | G6: Assets/MachineBrigade/Resources/Data/balance.json: base.walls.breakerMultiplier | H6: 1.5
A7: breakers | B7: base.walls | C7: breakers | E7: armored_bulldozer;engineer_vehicle;demolition_line_vehicle | G7: Assets/MachineBrigade/Resources/Data/balance.json: base.walls.breakers | H7: ["armored_bulldozer","engineer_vehicle","demolition_line_vehicle"]
A8: campLines | B8: base.walls | C8: campLines | D8: 2 | G8: Assets/MachineBrigade/Resources/Data/balance.json: base.walls.campLines | H8: 2
A9: default | B9: base.walls | C9: default | E9: hesco | G9: Assets/MachineBrigade/Resources/Data/balance.json: base.walls.default | H9: "hesco"
A10: fortressLines | B10: base.walls | C10: fortressLines | D10: 3 | G10: Assets/MachineBrigade/Resources/Data/balance.json: base.walls.fortressLines | H10: 3
A11: rubbleSlow | B11: base.walls | C11: rubbleSlow | D11: 0.2 | G11: Assets/MachineBrigade/Resources/Data/balance.json: base.walls.rubbleSlow | H11: 0.2
A12: segmentHp | B12: base.walls | C12: segmentHp | D12: 2400 | G12: Assets/MachineBrigade/Resources/Data/balance.json: base.walls.segmentHp | H12: 2400

Sheet Nha_chinh
A1: id | B1: ten_en | C1: ten_vi | D1: ten_ngan_vi | E1: lop | F1: nhanh | G1: ke_thua_tu | H1: base_cp | I1: mau_hp | J1: mau_trong_tran_hp | K1: giap_truoc | L1: giap_hong | M1: giap_sau | N1: giap_noc | O1: cong_trinh | P1: toc_do_m_s | Q1: xoay_than_deg_s | R1: xoay_thap_deg_s | S1: tam_nhin_m | T1: ban_kinh_m | U1: dai_m | V1: rong_m | W1: bay | X1: do_cao_m | Y1: dung_yen | Z1: ban_khi_chay | AA1: toc_do_chiem | AB1: tha_du_s | AC1: he_so_sat_thuong_ra | AD1: vu_khi_chinh | AE1: vu_khi_phu | AF1: noi_tai | AG1: tu_ve | AH1: so_lan_tu_ve | AI1: hoi_tu_ve_s | AJ1: mo_hinh | AK1: so_voi_ban_goc | AL1: base_cp_truoc | AM1: base_cp_sau | AN1: mau_hp_truoc | AO1: mau_hp_sau | AP1: giap_truoc_truoc | AQ1: giap_truoc_sau | AR1: giap_hong_truoc | AS1: giap_hong_sau | AT1: giap_sau_truoc | AU1: giap_sau_sau | AV1: giap_noc_truoc | AW1: giap_noc_sau | AX1: toc_do_m_s_truoc | AY1: toc_do_m_s_sau | AZ1: tam_nhin_m_truoc | BA1: tam_nhin_m_sau | BB1: vu_khi_chinh_truoc | BC1: vu_khi_chinh_sau | BD1: vu_khi_phu_truoc | BE1: vu_khi_phu_sau | BF1: he_so_sat_thuong_ra_truoc | BG1: he_so_sat_thuong_ra_sau | BH1: armour | BI1: class | BJ1: cp | BK1: death_explosion_damage | BL1: death_explosion_delay_s | BM1: death_explosion_radius_m | BN1: death_explosion_tier | BO1: fires_while_moving | BP1: fort_kind | BQ1: fort_points | BR1: hp | BS1: inherits | BT1: length_m | BU1: model | BV1: radius_m | BW1: scale | BX1: speed_m_s | BY1: static | BZ1: turn_rate_deg_s | CA1: turret_turn_rate_deg_s | CB1: vision_m | CC1: weapon | CD1: width_m | CE1: nguon | CF1: raw_json
A2: headquarters | B2: Headquarters | C2: Sở chỉ huy | D2: Sở chỉ huy | E2: Defense | H2: 0 | I2: 9000 | J2: 19800 | K2: 4 | L2: 4 | M2: 4 | N2: 4 | O2: TRUE | P2: 0 | Q2: 1 | R2: 90 | S2: 50 | T2: 6.8 | U2: 12 | V2: 14 | W2: FALSE | X2: 0 | Y2: TRUE | Z2: TRUE | AA2: 1 | AB2: 3.5 | AC2: 1 | AD2: bastion_gun | AE2: hq_flak;hq_flak;mg_coax | AG2: none | AJ2: headquarters | AK2: giong | BH2: 4 | BI2: Defense | BJ2: 0 | BK2: 260 | BL2: 0.8 | BM2: 14 | BN2: Ultimate | BO2: TRUE | BP2: Hq | BQ2: 0 | BR2: 9000 | BT2: 12 | BU2: headquarters | BV2: 6.8 | BW2: 1 | BX2: 0 | BY2: TRUE | BZ2: 1 | CA2: 90 | CB2: 50 | CC2: bastion_gun | CD2: 14 | CE2: Assets/MachineBrigade/Resources/Data/balance.json: vehicles[60] | CF2: {"id":"headquarters","class":"Defense","static":true,"model":"headquarters","armour":4,"hp":9000,"speed":0,"turnRate":1,"turretTurnRate":90,"radius":6.8,"length":12,"width":14,"scale":1.0,"cp":0,"vision":50,"firesWhileMoving":true,"weapon":"bastion_gun","fort":{"points":0,"kind":"Hq"},"secondary":[{"weapon":"hq_flak","slot":"mg","aim":"Free"},{"weapon":"hq_flak","slot":"mg","aim":"Free"},{"weapon":"mg_coax","slot":"coax","aim":"Turret"}],"deathExplosion":{"damage":260,"radius":14,"delay":0.8,"tier":"Ultimate"}}
A3: headquarters.fortress_air | B3: Headquarters · AA Fortress | C3: Sở chỉ huy · Pháo đài phòng không | D3: Pháo đài PK | E3: Defense | G3: headquarters | H3: 0 | I3: 9000 | J3: 19800 | K3: 4 | L3: 4 | M3: 4 | N3: 4 | O3: TRUE | P3: 0 | Q3: 1 | R3: 90 | S3: 50 | T3: 6.8 | U3: 12 | V3: 14 | W3: FALSE | X3: 0 | Y3: TRUE | Z3: TRUE | AA3: 1 | AB3: 3.5 | AC3: 1 | AD3: bastion_gun | AE3: hq_flak;hq_flak;mg_coax;bofors_l70 | AG3: none | AJ3: headquarters | AK3: moi | BS3: headquarters | CE3: Assets/MachineBrigade/Resources/Data/balance.json: vehicles[62] | CF3: {"id":"headquarters.fortress_air","inherits":"headquarters","secondary":[{"weapon":"hq_flak","slot":"mg","aim":"Free"},{"weapon":"hq_flak","slot":"mg","aim":"Free"},{"weapon":"mg_coax","slot":"coax","aim":"Turret"},{"weapon":"bofors_l70","slot":"gun","aim":"Free"}]}
A4: headquarters.fortress_ground | B4: Headquarters · Fortress | C4: Sở chỉ huy · Pháo đài | D4: SCH Pháo đài | E4: Defense | G4: headquarters | H4: 0 | I4: 9000 | J4: 19800 | K4: 4 | L4: 4 | M4: 4 | N4: 4 | O4: TRUE | P4: 0 | Q4: 1 | R4: 90 | S4: 50 | T4: 6.8 | U4: 12 | V4: 14 | W4: FALSE | X4: 0 | Y4: TRUE | Z4: TRUE | AA4: 1 | AB4: 3.5 | AC4: 1 | AD4: bastion_gun | AE4: hq_flak;hq_flak;mg_coax;turret_gun_120_long | AG4: none | AJ4: headquarters | AK4: moi | BS4: headquarters | CE4: Assets/MachineBrigade/Resources/Data/balance.json: vehicles[61] | CF4: {"id":"headquarters.fortress_ground","inherits":"headquarters","secondary":[{"weapon":"hq_flak","slot":"mg","aim":"Free"},{"weapon":"hq_flak","slot":"mg","aim":"Free"},{"weapon":"mg_coax","slot":"coax","aim":"Turret"},{"weapon":"turret_gun_120_long","slot":"gun","aim":"Free"}]}
A5: headquarters.shield | B5: Headquarters · Shield | C5: Sở chỉ huy · Lá chắn | D5: SCH Lá chắn | E5: Defense | G5: headquarters | H5: 0 | I5: 9000 | J5: 19800 | K5: 4 | L5: 4 | M5: 4 | N5: 4 | O5: TRUE | P5: 0 | Q5: 1 | R5: 90 | S5: 50 | T5: 6.8 | U5: 12 | V5: 14 | W5: FALSE | X5: 0 | Y5: TRUE | Z5: TRUE | AA5: 1 | AB5: 3.5 | AC5: 1 | AD5: bastion_gun | AE5: hq_flak;hq_flak;mg_coax | AG5: aps | AH5: 6 | AI5: 0.6 | AJ5: headquarters | AK5: moi | BS5: headquarters | CE5: Assets/MachineBrigade/Resources/Data/balance.json: vehicles[63] | CF5: {"id":"headquarters.shield","inherits":"headquarters","aps":{"radius":45,"charges":6,"recharge":0.6,"rockets":true,"shells":0.3,"burst":0.5}}

Sheet Nha_chinh_vu_khi
A1: id | B1: nha_chinh_id | C1: thu_tu | D1: weapon | E1: aim | F1: slot | G1: nguon | H1: raw_json
A2: headquarters.fortress_air/0 | B2: headquarters.fortress_air | C2: 0 | D2: hq_flak | E2: Free | F2: mg | G2: Assets/MachineBrigade/Resources/Data/balance.json: vehicles[62].secondary[0] | H2: {"weapon":"hq_flak","slot":"mg","aim":"Free"}
A3: headquarters.fortress_air/1 | B3: headquarters.fortress_air | C3: 1 | D3: hq_flak | E3: Free | F3: mg | G3: Assets/MachineBrigade/Resources/Data/balance.json: vehicles[62].secondary[1] | H3: {"weapon":"hq_flak","slot":"mg","aim":"Free"}
A4: headquarters.fortress_air/2 | B4: headquarters.fortress_air | C4: 2 | D4: mg_coax | E4: Turret | F4: coax | G4: Assets/MachineBrigade/Resources/Data/balance.json: vehicles[62].secondary[2] | H4: {"weapon":"mg_coax","slot":"coax","aim":"Turret"}
A5: headquarters.fortress_air/3 | B5: headquarters.fortress_air | C5: 3 | D5: bofors_l70 | E5: Free | F5: gun | G5: Assets/MachineBrigade/Resources/Data/balance.json: vehicles[62].secondary[3] | H5: {"weapon":"bofors_l70","slot":"gun","aim":"Free"}
A6: headquarters.fortress_ground/0 | B6: headquarters.fortress_ground | C6: 0 | D6: hq_flak | E6: Free | F6: mg | G6: Assets/MachineBrigade/Resources/Data/balance.json: vehicles[61].secondary[0] | H6: {"weapon":"hq_flak","slot":"mg","aim":"Free"}
A7: headquarters.fortress_ground/1 | B7: headquarters.fortress_ground | C7: 1 | D7: hq_flak | E7: Free | F7: mg | G7: Assets/MachineBrigade/Resources/Data/balance.json: vehicles[61].secondary[1] | H7: {"weapon":"hq_flak","slot":"mg","aim":"Free"}
A8: headquarters.fortress_ground/2 | B8: headquarters.fortress_ground | C8: 2 | D8: mg_coax | E8: Turret | F8: coax | G8: Assets/MachineBrigade/Resources/Data/balance.json: vehicles[61].secondary[2] | H8: {"weapon":"mg_coax","slot":"coax","aim":"Turret"}
A9: headquarters.fortress_ground/3 | B9: headquarters.fortress_ground | C9: 3 | D9: turret_gun_120_long | E9: Free | F9: gun | G9: Assets/MachineBrigade/Resources/Data/balance.json: vehicles[61].secondary[3] | H9: {"weapon":"turret_gun_120_long","slot":"gun","aim":"Free"}
A10: headquarters/0 | B10: headquarters | C10: 0 | D10: hq_flak | E10: Free | F10: mg | G10: Assets/MachineBrigade/Resources/Data/balance.json: vehicles[60].secondary[0] | H10: {"weapon":"hq_flak","slot":"mg","aim":"Free"}
A11: headquarters/1 | B11: headquarters | C11: 1 | D11: hq_flak | E11: Free | F11: mg | G11: Assets/MachineBrigade/Resources/Data/balance.json: vehicles[60].secondary[1] | H11: {"weapon":"hq_flak","slot":"mg","aim":"Free"}
A12: headquarters/2 | B12: headquarters | C12: 2 | D12: mg_coax | E12: Turret | F12: coax | G12: Assets/MachineBrigade/Resources/Data/balance.json: vehicles[60].secondary[2] | H12: {"weapon":"mg_coax","slot":"coax","aim":"Turret"}

Sheet Nha_chinh_kieu
