Workbook

Sheet Che_do
A1: id | B1: ten_che_do | C1: kho_cp | D1: cp_khoi_dau_nhan_he_so | E1: ho_so_ai | F1: trung_lap | G1: lists_maps | H1: numbers | I1: numbers_anti_snipe_range | J1: numbers_anti_snipe_share | K1: numbers_base_radius | L1: numbers_bleed | M1: numbers_boss_wave | N1: numbers_bosses | O1: numbers_catch_up_max | P1: numbers_escalation_at | Q1: numbers_escalation_income | R1: numbers_final_phase | S1: numbers_final_scale | T1: numbers_kill_cap | U1: numbers_kill_ticket_factor | V1: numbers_losses | W1: numbers_losses_at_zero_cp | X1: numbers_max_bank | Y1: numbers_mini_boss_wave | Z1: numbers_neutrals_max | AA1: numbers_overtime | AB1: numbers_overtime_lead | AC1: numbers_per_second | AD1: numbers_points | AE1: numbers_rebuild_cutoff | AF1: numbers_sector_bonus | AG1: numbers_start | AH1: numbers_sudden_death | AI1: numbers_sudden_death_income | AJ1: numbers_target | AK1: numbers_time_limit_s | AL1: numbers_waves | AM1: text_anti_snipe_rule | AN1: text_breach_rule | AO1: text_catch_up_policy | AP1: text_draw_rule | AQ1: text_escalation | AR1: text_lose_condition | AS1: text_map_eligibility | AT1: text_overtime_rule | AU1: text_score_rule | AV1: text_time_limit | AW1: text_win_condition | AX1: nguon | AY1: raw_json
A2: assault | B2: Assault | C2: 30;45 | D2: TRUE | E2: assault | F2: ammo_depot | O2: 0.25 | X2: 300 | AA2: 60 | AF2: 150 | AG2: 240 | AO2: Như hiện có | AP2: Không có hòa | AR2: Hết quỹ thời gian | AT2: Hết giờ khi đang chiếm dở: kéo dài tới khi chiếm xong hoặc bị đẩy ra, tối đa 60 s | AU2: Không tính điểm; sao (nếu là màn chiến dịch) theo số khu | AV2: Bắt đầu 4:00; chiếm A +2:30; chiếm B +2:30; quỹ tối đa 5:00 | AW2: Chiếm A, B, C | AX2: Assets/MachineBrigade/Resources/Data/balance.json: matchRules.modes.assault | AY2: {"text":{"winCondition":"Chiếm A, B, C","loseCondition":"Hết quỹ thời gian","timeLimit":"Bắt đầu 4:00; chiếm A +2:30; chiếm B +2:30; quỹ tối đa 5:00","overtimeRule":"Hết giờ khi đang chiếm dở: kéo dài tới khi chiếm xong hoặc bị đẩy ra, tối đa 60 s","drawRule":"Không có hòa","scoreRule":"Không tính điểm; sao (nếu là màn chiến dịch) theo số khu","catchUpPolicy":"Như hiện có"},"numbers":{"start":240,"sectorBonus":150,"maxBank":300,"overtime":60,"catchUpMax":0.25}}
A3: bossrush | B3: BossRush | C3: 45;60 | D3: TRUE | E3: bossrush | N3: 10 | AK3: 1800 | AO3: Không áp | AP3: Không | AR3: Mất toàn bộ quân hoặc hết 30 phút | AT3: Không | AU3: Xếp hạng: số boss hạ (giảm dần) → thời gian hoàn thành (tăng dần) → số bộ phận phá (giảm dần). Thưởng CP mỗi bộ phận giữ nguyên | AV3: 30 phút | AW3: Hạ đủ 10 boss | AX3: Assets/MachineBrigade/Resources/Data/balance.json: matchRules.modes.bossrush | AY3: {"text":{"winCondition":"Hạ đủ 10 boss","loseCondition":"Mất toàn bộ quân hoặc hết 30 phút","timeLimit":"30 phút","overtimeRule":"Không","drawRule":"Không","scoreRule":"Xếp hạng: số boss hạ (giảm dần) → thời gian hoàn thành (tăng dần) → số bộ phận phá (giảm dần). Thưởng CP mỗi bộ phận giữ nguyên","catchUpPolicy":"Không áp"},"numbers":{"bosses":10,"timeLimit":1800}}
A4: conquest | B4: Conquest | C4: 30;45 | D4: TRUE | E4: conquest | F4: radar;workshop | L4: 0.8 | O4: 0.25 | R4: 120 | S4: 2 | U4: 0 | AA4: 60 | AD4: 500 | AK4: 600 | AO4: Giảm (tối đa +25%) | AP4: Hòa nếu hết hiệp phụ | AR4: Về 0 điểm, hoặc ít điểm hơn khi hết giờ | AT4: Bằng điểm khi hết giờ: tối đa 60 s, bên chiếm thêm cứ điểm trước thắng | AU4: 500 điểm mỗi bên; bên giữ ít cứ điểm hơn mất 0,8 × (chênh lệch số cứ điểm) điểm/s; 2 phút cuối ×2; giữ cả 3 không cộng thêm | AV4: 10 phút | AW4: Đối phương về 0 điểm, hoặc nhiều điểm hơn khi hết giờ | AX4: Assets/MachineBrigade/Resources/Data/balance.json: matchRules.modes.conquest | AY4: {"text":{"winCondition":"Đối phương về 0 điểm, hoặc nhiều điểm hơn khi hết giờ","loseCondition":"Về 0 điểm, hoặc ít điểm hơn khi hết giờ","timeLimit":"10 phút","overtimeRule":"Bằng điểm khi hết giờ: tối đa 60 s, bên chiếm thêm cứ điểm trước thắng","drawRule":"Hòa nếu hết hiệp phụ","scoreRule":"500 điểm mỗi bên; bên giữ ít cứ điểm hơn mất 0,8 × (chênh lệch số cứ điểm) điểm/s; 2 phút cuối ×2; giữ cả 3 không cộng thêm","catchUpPolicy":"Giảm (tối đa +25%)"},"numbers":{"points":500,"bleed":0.8,"killTicketFactor":0,"timeLimit":600,"finalPhase":120,"finalScale":2,"overtime":60,"catchUpMax":0.25}}
A5: deathmatch | B5: Deathmatch | C5: 30;45 | D5: TRUE | E5: deathmatch | F5: ammo_depot;aa_site | O5: 0.25 | T5: 18 | AA5: 60 | AJ5: 480 | AK5: 540 | AO5: Giảm (tối đa +25%) | AP5: Hòa nếu hết hiệp phụ | AR5: Đối phương đạt 480 trước, hoặc ít điểm hơn khi hết giờ | AT5: Bằng điểm: tối đa 60 s, xe bị hạ đầu tiên quyết định | AU5: Mỗi xe địch bị hạ: min(baseCP, 18) điểm. Dùng baseCP, không dùng giá sau giảm | AV5: 9 phút | AW5: Đạt 480 điểm, hoặc nhiều điểm hơn khi hết giờ | AX5: Assets/MachineBrigade/Resources/Data/balance.json: matchRules.modes.deathmatch | AY5: {"text":{"winCondition":"Đạt 480 điểm, hoặc nhiều điểm hơn khi hết giờ","loseCondition":"Đối phương đạt 480 trước, hoặc ít điểm hơn khi hết giờ","timeLimit":"9 phút","overtimeRule":"Bằng điểm: tối đa 60 s, xe bị hạ đầu tiên quyết định","drawRule":"Hòa nếu hết hiệp phụ","scoreRule":"Mỗi xe địch bị hạ: min(baseCP, 18) điểm. Dùng baseCP, không dùng giá sau giảm","catchUpPolicy":"Giảm (tối đa +25%)"},"numbers":{"target":480,"killCap":18,"timeLimit":540,"overtime":60,"catchUpMax":0.25}}
A6: defend | B6: Defend | C6: 30;45 | D6: TRUE | E6: defend | AK6: 720 | AO6: Không áp (đợt theo Sức mạnh căn cứ) | AP6: Không | AR6: Mất sở chỉ huy | AT6: Không | AU6: Không tính điểm; sao (nếu là màn chiến dịch) theo máu sở chỉ huy và số tuyến còn giữ; mất tuyến ngoài KHÔNG là thất bại | AV6: 12 phút | AW6: Sở chỉ huy còn đứng khi hết giờ | AX6: Assets/MachineBrigade/Resources/Data/balance.json: matchRules.modes.defend | AY6: {"text":{"winCondition":"Sở chỉ huy còn đứng khi hết giờ","loseCondition":"Mất sở chỉ huy","timeLimit":"12 phút","overtimeRule":"Không","drawRule":"Không","scoreRule":"Không tính điểm; sao (nếu là màn chiến dịch) theo máu sở chỉ huy và số tuyến còn giữ; mất tuyến ngoài KHÔNG là thất bại","catchUpPolicy":"Không áp (đợt theo Sức mạnh căn cứ)"},"numbers":{"timeLimit":720}}
A7: endless | B7: Endless | C7: 30;45 | D7: TRUE | E7: defend | AO7: Không áp | AP7: Không | AR7: Mất sở chỉ huy | AT7: Không | AU7: Xếp hạng theo thứ tự: đợt hoàn thành (giảm dần) → baseCP xe địch đã hạ (giảm dần) → thời gian sống (giảm dần) | AV7: Không giới hạn | AW7: Không có trạng thái thắng | AX7: Assets/MachineBrigade/Resources/Data/balance.json: matchRules.modes.endless | AY7: {"text":{"winCondition":"Không có trạng thái thắng","loseCondition":"Mất sở chỉ huy","timeLimit":"Không giới hạn","overtimeRule":"Không","drawRule":"Không","scoreRule":"Xếp hạng theo thứ tự: đợt hoàn thành (giảm dần) → baseCP xe địch đã hạ (giảm dần) → thời gian sống (giảm dần)","catchUpPolicy":"Không áp"},"numbers":{}}
A8: hill | B8: KingOfTheHill | C8: 30;45 | D8: TRUE | E8: hill | F8: workshop | O8: 0.25 | AA8: 60 | AC8: 1 | AJ8: 170 | AK8: 540 | AO8: Như hiện có | AP8: Hòa nếu hết hiệp phụ | AR8: Ngược lại | AT8: Bằng điểm hoặc đồi đang tranh khi hết giờ: tối đa 60 s; còn tranh thì kéo dài, một bên giữ riêng thì phân định | AU8: Một mình giữ đồi: +1 điểm/s; tranh chấp hoặc trống: 0 | AV8: 9 phút | AW8: Đạt 170 điểm, hoặc dẫn khi hết giờ | AX8: Assets/MachineBrigade/Resources/Data/balance.json: matchRules.modes.hill | AY8: {"text":{"winCondition":"Đạt 170 điểm, hoặc dẫn khi hết giờ","loseCondition":"Ngược lại","timeLimit":"9 phút","overtimeRule":"Bằng điểm hoặc đồi đang tranh khi hết giờ: tối đa 60 s; còn tranh thì kéo dài, một bên giữ riêng thì phân định","drawRule":"Hòa nếu hết hiệp phụ","scoreRule":"Một mình giữ đồi: +1 điểm/s; tranh chấp hoặc trống: 0","catchUpPolicy":"Như hiện có"},"numbers":{"target":170,"perSecond":1,"timeLimit":540,"overtime":60,"catchUpMax":0.25}}
A9: operations | B9: Operation | D9: FALSE | E9: operation | V9: 2000 | W9: 150 | AO9: Như màn gốc | AP9: Như màn gốc | AR9: Như màn gốc | AT9: Như màn gốc | AU9: Giữ công thức hiện có (5.000 + thời gian + tổn thất + máu sở chỉ huy, × hệ số cấp). Phần tổn thất đổi từ số xe sang baseCP đã mất: 2.000 khi mất 0, về 0 khi mất 150 baseCP | AV9: Như màn gốc | AW9: Như màn gốc | AX9: Assets/MachineBrigade/Resources/Data/balance.json: matchRules.modes.operations | AY9: {"text":{"winCondition":"Như màn gốc","loseCondition":"Như màn gốc","timeLimit":"Như màn gốc","overtimeRule":"Như màn gốc","drawRule":"Như màn gốc","scoreRule":"Giữ công thức hiện có (5.000 + thời gian + tổn thất + máu sở chỉ huy, × hệ số cấp). Phần tổn thất đổi từ số xe sang baseCP đã mất: 2.000 khi mất 0, về 0 khi mất 150 baseCP","catchUpPolicy":"Như màn gốc"},"numbers":{"losses":2000,"lossesAtZeroCp":150}}
A10: showdown | B10: Showdown | D10: TRUE | E10: showdown | F10: ammo_depot | G10: ashfield;capital;coralisles;dunebreak;foundry;frostpeak;greenvale;ironport;junglepass;landingbeach;launchsite;lighthousebay;metrocity;openpit;orbitalgate;redrock;rustyard;saltflat;skyhold;swamp;veyra_old_quarter;whiteout | I10: 60 | J10: 0.25 | K10: 46 | O10: 0.25 | P10: 360 | Q10: 1.5 | Z10: 2 | AB10: 0.05 | AE10: 600 | AH10: 90 | AI10: 2 | AK10: 720 | AM10: Nhà chính chỉ nhận 25% sát thương từ pháo binh, tên lửa và máy bay bắn từ ngoài 60 m, cho tới khi outerDefenseBreached | AN10: outerDefenseBreached khi quân mặt đất địch vào qua cổng chính (cổng trại là lối mở), hoặc một đoạn tường ngoài thành RUBBLE và mở được đường từ phía công vào trong căn cứ (kiểm bằng trạng thái NavGrid) | AO10: Chỉ bắt kịp thu nhập, trần +25%; không tiếp viện miễn phí | AP10: Bằng nhau sau đột tử → hòa | AQ10: Phút 6: thu nhập ×1,5 cho cả hai phe, trạm CP ngừng tạo CP; phút 10: tháp bị phá không xây lại (lần đã trừ CP thì hoàn tất) | AR10: Mất nhà chính | AS10: Chỉ bản đồ 300×300 đạt ngưỡng đối xứng của docs/checks/map_audit.md (không dùng 300×480) | AT10: Hết 12 phút: bên có nhà chính còn nhiều % máu hơn từ 5 điểm phần trăm trở lên thắng ngay; chênh dưới 5 điểm → đột tử 90 s (tắt chống bắn tỉa, không xây lại tháp, thu nhập ×2, không đặt lại hồi chiêu kỹ năng nhà chính): phá nhà chính thì thắng, hết 90 s thì bên gây nhiều sát thương lên nhà chính đối phương trong đột tử hơn thắng | AU10: Không có điểm phụ | AV10: 12 phút | AW10: Phá nhà chính đối phương | AX10: Assets/MachineBrigade/Resources/Data/balance.json: matchRules.modes.showdown | AY10: {"text":{"winCondition":"Phá nhà chính đối phương","loseCondition":"Mất nhà chính","timeLimit":"12 phút","overtimeRule":"Hết 12 phút: bên có nhà chính còn nhiều % máu hơn từ 5 điểm phần trăm trở lên thắng ngay; chênh dưới 5 điểm → đột tử 90 s (tắt chống bắn tỉa, không xây lại tháp, thu nhập ×2, không đặt lại hồi chiêu kỹ năng nhà chính): phá nhà chính thì thắng, hết 90 s thì bên gây nhiều sát thương lên nhà chính đối phương trong đột tử hơn thắng","drawRule":"Bằng nhau sau đột tử → hòa","scoreRule":"Không có điểm phụ","catchUpPolicy":"Chỉ bắt kịp thu nhập, trần +25%; không tiếp viện miễn phí","antiSnipeRule":"Nhà chính chỉ nhận 25% sát thương từ pháo binh, tên lửa và máy bay bắn từ ngoài 60 m, cho tới khi outerDefenseBreached","breachRule":"outerDefenseBreached khi quân mặt đất địch vào qua cổng chính (cổng trại là lối mở), hoặc một đoạn tường ngoài thành RUBBLE và mở được đường từ phía công vào trong căn cứ (kiểm bằng trạng thái NavGrid)","escalation":"Phút 6: thu nhập ×1,5 cho cả hai phe, trạm CP ngừng tạo CP; phút 10: tháp bị phá không xây lại (lần đã trừ CP thì hoàn tất)","mapEligibility":"Chỉ bản đồ 300×300 đạt ngưỡng đối xứng của docs/checks/map_audit.md (không dùng 300×480)"},"numbers":{"timeLimit":720,"antiSnipeShare":0.25,"antiSnipeRange":60,"escalationAt":360,"escalationIncome":1.5,"rebuildCutoff":600,"overtimeLead":0.05,"suddenDeath":90,"suddenDeathIncome":2,"catchUpMax":0.25,"baseRadius":46,"neutralsMax":2},"lists":{"maps":["ashfield","capital","coralisles","dunebreak","foundry","frostpeak","greenvale","ironport","junglepass","landingbeach","launchsite","lighthousebay","metrocity","openpit","orbitalgate","redrock","rustyard","saltflat","skyhold","swamp","veyra_old_quarter","whiteout"]}}
A11: siege | B11: Siege | C11: 40;55 | D11: TRUE | E11: siege | F11: aa_site | AA11: 60 | AK11: 1080 | AO11: Như hiện có | AP11: Không có hòa | AR11: Hết giờ | AT11: Mục tiêu cuối đang bị tấn công khi hết giờ: tối đa 60 s | AU11: Không tính điểm | AV11: 18 phút mặc định; màn chiến dịch dùng giới hạn thời gian riêng | AW11: Hạ sở chỉ huy pháo đài | AX11: Assets/MachineBrigade/Resources/Data/balance.json: matchRules.modes.siege | AY11: {"text":{"winCondition":"Hạ sở chỉ huy pháo đài","loseCondition":"Hết giờ","timeLimit":"18 phút mặc định; màn chiến dịch dùng giới hạn thời gian riêng","overtimeRule":"Mục tiêu cuối đang bị tấn công khi hết giờ: tối đa 60 s","drawRule":"Không có hòa","scoreRule":"Không tính điểm","catchUpPolicy":"Như hiện có"},"numbers":{"timeLimit":1080,"overtime":60}}
A12: survival | B12: Survival | C12: 30;40 | D12: TRUE | E12: survival | F12: workshop | M12: 10 | Y12: 5 | AL12: 10 | AO12: Không áp | AP12: Không | AR12: Mất toàn bộ quân hoặc địch chiếm bãi thả | AT12: Không | AU12: Số đợt đã qua | AV12: 10 đợt; nhịp mục tiêu khoảng 60 giây/đợt, tổng khoảng 10 phút | AW12: Qua hết đợt 10 (đợt 5 có mini boss, đợt 10 có boss chủ lực) | AX12: Assets/MachineBrigade/Resources/Data/balance.json: matchRules.modes.survival | AY12: {"text":{"winCondition":"Qua hết đợt 10 (đợt 5 có mini boss, đợt 10 có boss chủ lực)","loseCondition":"Mất toàn bộ quân hoặc địch chiếm bãi thả","timeLimit":"10 đợt; nhịp mục tiêu khoảng 60 giây/đợt, tổng khoảng 10 phút","overtimeRule":"Không","drawRule":"Không","scoreRule":"Số đợt đã qua","catchUpPolicy":"Không áp"},"numbers":{"waves":10,"miniBossWave":5,"bossWave":10}}
A13: weekly | B13: Weekly | D13: TRUE | E13: siege | F13: ammo_depot | AA13: 60 | AO13: Như Công thành | AP13: Không | AR13: Mỗi lần đánh có thể dừng giữa chừng; lớp đã phá được giữ | AT13: Như Công thành | AU13: Xếp hạng: đã phá xong? → số lần đánh (tăng dần) → tổng thời gian giao chiến (tăng dần) | AV13: Theo lần đánh (như Công thành) + chu kỳ tuần | AW13: Hạ sở chỉ huy trước khi tuần kết thúc | AX13: Assets/MachineBrigade/Resources/Data/balance.json: matchRules.modes.weekly | AY13: {"text":{"winCondition":"Hạ sở chỉ huy trước khi tuần kết thúc","loseCondition":"Mỗi lần đánh có thể dừng giữa chừng; lớp đã phá được giữ","timeLimit":"Theo lần đánh (như Công thành) + chu kỳ tuần","overtimeRule":"Như Công thành","drawRule":"Không","scoreRule":"Xếp hạng: đã phá xong? → số lần đánh (tăng dần) → tổng thời gian giao chiến (tăng dần)","catchUpPolicy":"Như Công thành"},"numbers":{"overtime":60}}

Sheet Sao_chien_dich
A1: id | B1: sao2_kind | C1: sao2_value | D1: sao3_kind | E1: sao3_value | F1: nguon | G1: raw_json
A2: Boss | B2: BossParts | C2: 2 | D2: NoAircraft | F2: Assets/MachineBrigade/Resources/Data/balance.json: matchRules.starMastery.Boss
A3: Capture | B3: LossShare | C3: 0.4 | D3: Kills | E3: 10 | F3: Assets/MachineBrigade/Resources/Data/balance.json: matchRules.starMastery.Capture
A4: Destroy | B4: LossShare | C4: 0.4 | D4: NoStrikes | F4: Assets/MachineBrigade/Resources/Data/balance.json: matchRules.starMastery.Destroy
A5: Duel | B5: HqShare | C5: 0.5 | D5: Kills | E5: 15 | F5: Assets/MachineBrigade/Resources/Data/balance.json: matchRules.starMastery.Duel
A6: Escort | B6: ConvoyShare | C6: 0.8 | D6: Kills | E6: 10 | F6: Assets/MachineBrigade/Resources/Data/balance.json: matchRules.starMastery.Escort
A7: Evacuate | B7: ConvoyShare | C7: 0.8 | D7: Kills | E7: 10 | F7: Assets/MachineBrigade/Resources/Data/balance.json: matchRules.starMastery.Evacuate
A8: Hold | B8: HoldShare | C8: 0.8 | D8: Kills | E8: 15 | F8: Assets/MachineBrigade/Resources/Data/balance.json: matchRules.starMastery.Hold
A9: Hunt | B9: LossShare | C9: 0.4 | D9: Kills | E9: 10 | F9: Assets/MachineBrigade/Resources/Data/balance.json: matchRules.starMastery.Hunt
A10: Intercept | B10: LossShare | C10: 0.4 | D10: NoStrikes | F10: Assets/MachineBrigade/Resources/Data/balance.json: matchRules.starMastery.Intercept
A11: Outpost | B11: HoldShare | C11: 0.8 | D11: Kills | E11: 12 | F11: Assets/MachineBrigade/Resources/Data/balance.json: matchRules.starMastery.Outpost
A12: Protect | B12: ProtectShare | C12: 0.75 | D12: Kills | E12: 15 | F12: Assets/MachineBrigade/Resources/Data/balance.json: matchRules.starMastery.Protect
A13: Recon | B13: ReconQuiet | C13: 0.67 | D13: NoStrikes | F13: Assets/MachineBrigade/Resources/Data/balance.json: matchRules.starMastery.Recon
A14: Relieve | B14: LossShare | C14: 0.4 | D14: Kills | E14: 12 | F14: Assets/MachineBrigade/Resources/Data/balance.json: matchRules.starMastery.Relieve
A15: ShootDown | B15: LossShare | C15: 0.4 | D15: Kills | E15: 12 | F15: Assets/MachineBrigade/Resources/Data/balance.json: matchRules.starMastery.ShootDown
A16: Survive | B16: HqShare | C16: 0.5 | D16: Kills | E16: 20 | F16: Assets/MachineBrigade/Resources/Data/balance.json: matchRules.starMastery.Survive

Sheet Vo_han
A1: id | B1: thu_tu_xep_hang | C1: he_so_tang_thuong | D1: nguon | E1: raw_json
A2: bossrush | B2: -bosses;+seconds;-parts | C2: 0.9 | D2: Assets/MachineBrigade/Resources/Data/balance.json: matchRules.leaderboards.bossrush | E2: ["-bosses","+seconds","-parts"]
A3: bossrushEndless | B3: -bosses;+seconds;-parts | C3: 0.9 | D3: Assets/MachineBrigade/Resources/Data/balance.json: matchRules.leaderboards.bossrushEndless | E3: ["-bosses","+seconds","-parts"]
A4: defendEndless | B4: -waves;-killedBaseCp;-seconds | C4: 0.9 | D4: Assets/MachineBrigade/Resources/Data/balance.json: matchRules.leaderboards.defendEndless | E4: ["-waves","-killedBaseCp","-seconds"]
A5: endless | B5: -waves;-killedBaseCp;-seconds | C5: 0.9 | D5: Assets/MachineBrigade/Resources/Data/balance.json: matchRules.leaderboards.endless | E5: ["-waves","-killedBaseCp","-seconds"]
A6: survivalEndless | B6: -waves;-killedBaseCp;-seconds | C6: 0.9 | D6: Assets/MachineBrigade/Resources/Data/balance.json: matchRules.leaderboards.survivalEndless | E6: ["-waves","-killedBaseCp","-seconds"]
A7: weekly | B7: -cleared;+attempts;+seconds | C7: 0.9 | D7: Assets/MachineBrigade/Resources/Data/balance.json: matchRules.leaderboards.weekly | E7: ["-cleared","+attempts","+seconds"]

Sheet Kinh_te
A1: id | B1: nhom | C1: khoa | D1: gia_tri_so | E1: gia_tri_chu | F1: don_vi | G1: nguon | H1: raw_json
A2: campaign.economy.payScale["2"] | B2: economy | C2: 2 | D2: 1.66 | G2: Assets/MachineBrigade/Resources/Data/campaign.json: economy.payScale["2"] | H2: 1.66
A3: campaign.economy.payScale["3"] | B3: economy | C3: 3 | D3: 1 | G3: Assets/MachineBrigade/Resources/Data/campaign.json: economy.payScale["3"] | H3: 1.0
A4: economy.armyCap.Campaign | B4: economy | C4: Campaign | D4: 24 | G4: Assets/MachineBrigade/Resources/Data/balance.json: economy.armyCap.Campaign | H4: 24
A5: economy.armyCap.Survival | B5: economy | C5: Survival | D5: 30 | G5: Assets/MachineBrigade/Resources/Data/balance.json: economy.armyCap.Survival | H5: 30
A6: economy.armyCap.default | B6: economy | C6: default | D6: 40 | G6: Assets/MachineBrigade/Resources/Data/balance.json: economy.armyCap.default | H6: 40
A7: economy.enemyScaling | B7: economy | C7: enemyScaling | D7: 0.55 | G7: Assets/MachineBrigade/Resources/Data/balance.json: economy.enemyScaling | H7: 0.55
A8: economy.enemyScalingModes.Weekly | B8: economy | C8: Weekly | D8: 0.5 | G8: Assets/MachineBrigade/Resources/Data/balance.json: economy.enemyScalingModes.Weekly | H8: 0.5
A9: economy.income | B9: economy | C9: income | D9: 0.9 | G9: Assets/MachineBrigade/Resources/Data/balance.json: economy.income | H9: 0.9
A10: economy.startCp.modes | B10: economy | C10: modes | E10: Conquest;Deathmatch;KingOfTheHill;Assault;Siege;Weekly;Defend;Endless;Survival;BossRush;Campaign;Showdown | G10: Assets/MachineBrigade/Resources/Data/balance.json: economy.startCp.modes | H10: ["Conquest","Deathmatch","KingOfTheHill","Assault","Siege","Weekly","Defend","Endless","Survival","BossRush","Campaign","Showdown"]
A11: economy.startCp.scale | B11: economy | C11: scale | D11: 1.16 | G11: Assets/MachineBrigade/Resources/Data/balance.json: economy.startCp.scale | H11: 1.16
A12: economy.supply | B12: economy | C12: supply | D12: 1.05 | G12: Assets/MachineBrigade/Resources/Data/balance.json: economy.supply | H12: 1.05
A13: economy.vehicleCap.Defend | B13: economy | C13: Defend | D13: 48 | G13: Assets/MachineBrigade/Resources/Data/balance.json: economy.vehicleCap.Defend | H13: 48
A14: economy.vehicleCap.Endless | B14: economy | C14: Endless | D14: 48 | G14: Assets/MachineBrigade/Resources/Data/balance.json: economy.vehicleCap.Endless | H14: 48
A15: economy.vehicleCap.Operation | B15: economy | C15: Operation | D15: 48 | G15: Assets/MachineBrigade/Resources/Data/balance.json: economy.vehicleCap.Operation | H15: 48
A16: economy.vehicleCap.Siege | B16: economy | C16: Siege | D16: 48 | G16: Assets/MachineBrigade/Resources/Data/balance.json: economy.vehicleCap.Siege | H16: 48
A17: economy.vehicleCap.default | B17: economy | C17: default | D17: 32 | G17: Assets/MachineBrigade/Resources/Data/balance.json: economy.vehicleCap.default | H17: 32
A18: ma.hoan_cp_khi_ha | B18: ma | C18: hoàn CP khi hạ, bắt kịp, thưởng rút lui, thưởng bộ phận boss, thứ tự áp | E18: kill_share 0.25; tran_hoan_khi_ha 0.45; tran_hoan_khi_mat 0.15; duong_bat_kip (ban/doi_thu:tang_thu_nhap) 1:1;0.75:1;0.6:1.1364;0.5:1.2273;0.4:1.3182;0.3:1.4091;0.2:1.5;0.1:1.5; duong_phat_tiep_te (quan/tiep_te:thu_nhap_giu) 1:1;1.25:0.875;1.5:0.75;2:0.5;2.5:0.25;3:0.25 | G18: Assets/MachineBrigade/Scripts/Sim (mã kinh tế)
A19: ma.tiep_te_cong_thuc | B19: ma | C19: tiếp tế: công thức, ngưỡng, đường phạt, tối đa -75 % | E19: armyCap = round((economy.armyCap[mode] x supplyPriceScale + bonus) x economy.supply x commander); supply = floor(armyCap x supplyPerArmyCap); income kept = max(upkeepFloor, 1 - upkeepSlope x (army - supply) / supply) above the supply | G19: Assets/MachineBrigade/Scripts/Sim (mã kinh tế)

Sheet Do_kho
A1: id | B1: he_so_dich_tran_nhanh | C1: thu_tu | D1: bien_co_ally | E1: bien_co_ally_waves | F1: bien_co_directions | G1: bien_co_elites | H1: bien_co_escorts | I1: bien_co_step | J1: bien_co_warning | K1: bien_co_wave_scale | L1: nguon | M1: raw_json
A2: Easy | B2: 0.4 | C2: 0 | D2: 0.7 | E2: -1 | F2: 1;2 | G2: FALSE | H2: 2 | I2: 0 | J2: 15 | K2: 0.7 | L2: Assets/MachineBrigade/Resources/Data/balance.json: economy.enemyScalingQuick.Easy
A3: Hard | B3: 0.85 | C3: 2 | D3: 0.3 | E3: -1 | F3: 2;3 | G3: FALSE | H3: 4 | I3: 2 | J3: 8 | K3: 1.15 | L3: Assets/MachineBrigade/Resources/Data/balance.json: economy.enemyScalingQuick.Hard
A4: Normal | B4: 0.75 | C4: 1 | D4: 0.5 | E4: -1 | F4: 2;2 | G4: FALSE | H4: 3 | I4: 1 | J4: 10 | K4: 1 | L4: Assets/MachineBrigade/Resources/Data/balance.json: economy.enemyScalingQuick.Normal
A5: VeryHard | B5: 1.08 | C5: 3 | D5: 0.15 | E5: 1 | F5: 3;4 | G5: TRUE | H5: 5 | I5: 3 | J5: 6 | K5: 1.3 | L5: Assets/MachineBrigade/Resources/Data/balance.json: economy.enemyScalingQuick.VeryHard

Sheet Diem_tac_chien
A1: id | B1: nhom | C1: khoa | D1: gia_tri_so | E1: gia_tri_chu | F1: don_vi | G1: nguon | H1: raw_json
A2: score.hq | C2: hq | D2: 2000 | G2: Assets/MachineBrigade/Resources/Data/operations.json: score.hq | H2: 2000
A3: score.losses | C3: losses | D3: 2000 | G3: Assets/MachineBrigade/Resources/Data/operations.json: score.losses | H3: 2000
A4: score.lossesAtZeroCp | C4: lossesAtZeroCp | D4: 150 | G4: Assets/MachineBrigade/Resources/Data/operations.json: score.lossesAtZeroCp | H4: 150
A5: score.par | C5: par | D5: 1500 | G5: Assets/MachineBrigade/Resources/Data/operations.json: score.par | H5: 1500
A6: score.time | C6: time | D6: 3000 | G6: Assets/MachineBrigade/Resources/Data/operations.json: score.time | H6: 3000
A7: score.win | C7: win | D7: 5000 | G7: Assets/MachineBrigade/Resources/Data/operations.json: score.win | H7: 5000
A8: weekly.fortress | C8: fortress | D8: 600 | G8: Assets/MachineBrigade/Resources/Data/operations.json: weekly.fortress | H8: 600
A9: weekly.operation | C9: operation | D9: 800 | G9: Assets/MachineBrigade/Resources/Data/operations.json: weekly.operation | H9: 800

Sheet Tac_chien_bac
A1: id | B1: enemy | C1: player_income | D1: score | E1: supports | F1: nguon | G1: raw_json
A2: heroic | B2: 1.3 | C2: 1 | D2: 1.3 | E2: TRUE | F2: Assets/MachineBrigade/Resources/Data/operations.json: tiers[1] | G2: {"id":"heroic","enemy":1.3,"playerIncome":1.0,"supports":true,"score":1.3}
A3: iron | B3: 1.3 | C3: 0.8 | D3: 1.6 | E3: FALSE | F3: Assets/MachineBrigade/Resources/Data/operations.json: tiers[2] | G3: {"id":"iron","enemy":1.3,"playerIncome":0.8,"supports":false,"score":1.6}
A4: legend | B4: 1.6 | C4: 0.75 | D4: 2 | E4: FALSE | F4: Assets/MachineBrigade/Resources/Data/operations.json: tiers[3] | G4: {"id":"legend","enemy":1.6,"playerIncome":0.75,"supports":false,"score":2.0}
A5: normal | B5: 1 | C5: 1 | D5: 1 | E5: TRUE | F5: Assets/MachineBrigade/Resources/Data/operations.json: tiers[0] | G5: {"id":"normal","enemy":1.0,"playerIncome":1.0,"supports":true,"score":1.0}

Sheet Mutator
A1: id | B1: excludes | C1: class | D1: both_damage | E1: both_hp | F1: empty_base | G1: enemy_air | H1: enemy_cp | I1: enemy_hp | J1: enemy_income | K1: extra_boss | L1: extra_escorts | M1: extra_raiders | N1: no_air | O1: no_repair | P1: no_supports | Q1: player_heavy | R1: player_income | S1: player_max_cp | T1: raids | U1: score | V1: sea_sight | W1: swarm | X1: time_scale | Y1: tower_damage | Z1: tower_hp | AA1: weather | AB1: nguon | AC1: raw_json
A2: armour_only | B2: light_deck;enemy_air | C2: rule | Q2: TRUE | U2: 0.15 | AB2: Assets/MachineBrigade/Resources/Data/operations.json: mutators[8] | AC2: {"id":"armour_only","class":"rule","score":0.15,"playerHeavy":true,"excludes":["light_deck","enemy_air"]}
A3: empty_base | B3: towers_x2 | C3: pressure | F3: TRUE | U3: 0.25 | AB3: Assets/MachineBrigade/Resources/Data/operations.json: mutators[16] | AC3: {"id":"empty_base","class":"pressure","score":0.25,"emptyBase":true,"excludes":["towers_x2"]}
A4: enemy_air | B4: no_air;armour_only;light_deck | C4: pressure | G4: TRUE | U4: 0.25 | AB4: Assets/MachineBrigade/Resources/Data/operations.json: mutators[1] | AC4: {"id":"enemy_air","class":"pressure","score":0.25,"enemyAir":true,"excludes":["no_air","armour_only","light_deck"]}
A5: fleet | C5: pressure | J5: 1.1 | L5: 1 | M5: 2 | U5: 0.2 | AB5: Assets/MachineBrigade/Resources/Data/operations.json: mutators[19] | AC5: {"id":"fleet","class":"pressure","score":0.2,"extraEscorts":1,"extraRaiders":2,"enemyIncome":1.1}
A6: general_boost | B6: veterans | C6: pressure | H6: 1.5 | J6: 1.3 | U6: 0.25 | AB6: Assets/MachineBrigade/Resources/Data/operations.json: mutators[6] | AC6: {"id":"general_boost","class":"pressure","score":0.25,"enemyCp":1.5,"enemyIncome":1.3,"excludes":["veterans"]}
A7: glass_cannon | C7: rule | D7: 1.5 | E7: 0.75 | U7: 0.1 | AB7: Assets/MachineBrigade/Resources/Data/operations.json: mutators[10] | AC7: {"id":"glass_cannon","class":"rule","score":0.1,"bothDamage":1.5,"bothHp":0.75}
A8: iron_rain | C8: rule | T8: TRUE | U8: 0.1 | AB8: Assets/MachineBrigade/Resources/Data/operations.json: mutators[14] | AC8: {"id":"iron_rain","class":"rule","score":0.1,"raids":true}
A9: lean_logistics | C9: pressure | R9: 0.75 | U9: 0.2 | AB9: Assets/MachineBrigade/Resources/Data/operations.json: mutators[13] | AC9: {"id":"lean_logistics","class":"pressure","score":0.2,"playerIncome":0.75}
A10: light_deck | B10: armour_only | C10: rule | S10: 8 | U10: 0.2 | AB10: Assets/MachineBrigade/Resources/Data/operations.json: mutators[7] | AC10: {"id":"light_deck","class":"rule","score":0.2,"playerMaxCp":8,"excludes":["armour_only"]}
A11: night_ops | B11: storm | C11: rule | U11: 0.05 | AA11: Night | AB11: Assets/MachineBrigade/Resources/Data/operations.json: mutators[17] | AC11: {"id":"night_ops","class":"rule","score":0.05,"weather":"Night","excludes":["storm"]}
A12: no_air | B12: enemy_air | C12: rule | N12: TRUE | U12: 0.1 | AB12: Assets/MachineBrigade/Resources/Data/operations.json: mutators[9] | AC12: {"id":"no_air","class":"rule","score":0.1,"noAir":true,"excludes":["enemy_air"]}
A13: no_repair | C13: rule | O13: TRUE | U13: 0.15 | AB13: Assets/MachineBrigade/Resources/Data/operations.json: mutators[5] | AC13: {"id":"no_repair","class":"rule","score":0.15,"noRepair":true}
A14: no_support | C14: rule | P14: TRUE | U14: 0.2 | AB14: Assets/MachineBrigade/Resources/Data/operations.json: mutators[2] | AC14: {"id":"no_support","class":"rule","score":0.2,"noSupports":true}
A15: sea_storm | B15: storm | C15: rule | U15: 0.15 | V15: 0.55 | AA15: Storm | AB15: Assets/MachineBrigade/Resources/Data/operations.json: mutators[18] | AC15: {"id":"sea_storm","class":"rule","score":0.15,"weather":"Storm","seaSight":0.55,"excludes":["storm"]}
A16: storm | C16: rule | U16: 0.05 | AA16: Storm | AB16: Assets/MachineBrigade/Resources/Data/operations.json: mutators[0] | AC16: {"id":"storm","class":"rule","score":0.05,"weather":"Storm"}
A17: swarm | C17: pressure | U17: 0.2 | W17: TRUE | AB17: Assets/MachineBrigade/Resources/Data/operations.json: mutators[15] | AC17: {"id":"swarm","class":"pressure","score":0.2,"swarm":true}
A18: time_attack | B18: two_bosses | C18: pressure | U18: 0.2 | X18: 0.7 | AB18: Assets/MachineBrigade/Resources/Data/operations.json: mutators[12] | AC18: {"id":"time_attack","class":"pressure","score":0.2,"timeScale":0.7,"excludes":["two_bosses"]}
A19: towers_x2 | C19: pressure | U19: 0.2 | Y19: 1.5 | Z19: 2 | AB19: Assets/MachineBrigade/Resources/Data/operations.json: mutators[4] | AC19: {"id":"towers_x2","class":"pressure","score":0.2,"towerHp":2.0,"towerDamage":1.5}
A20: two_bosses | B20: time_attack | C20: pressure | K20: TRUE | U20: 0.3 | AB20: Assets/MachineBrigade/Resources/Data/operations.json: mutators[3] | AC20: {"id":"two_bosses","class":"pressure","score":0.3,"extraBoss":true,"excludes":["time_attack"]}
A21: veterans | B21: general_boost | C21: pressure | I21: 1.25 | U21: 0.2 | AB21: Assets/MachineBrigade/Resources/Data/operations.json: mutators[11] | AC21: {"id":"veterans","class":"pressure","score":0.2,"enemyHp":1.25,"excludes":["general_boost"]}

Sheet Che_do_thoi_luong
A1: id | B1: doc_gio_du_lieu | C1: gio_bat_dau_ma_s | D1: thuong_giai_doan_s | E1: tran_quy_ma_s | F1: dot_dau_s | G1: cach_dot_s | H1: nguon_ma | I1: gio_du_lieu_s | J1: hiep_phu_s | K1: gio_vao_tran_s | L1: quy_cong_them_s | M1: thoi_luong_toi_da_s | N1: thang_som_nhat_s | O1: so_ha_toi_thieu | P1: dot_cuoi_bat_dau_s | Q1: thoi_luong_tham_chieu_s | R1: lech_gio_du_lieu_s | S1: nguon | T1: raw_json
A2: assault | B2: FALSE | C2: 300 | H2: Game/Match/ModeSessions.cs:602 | I2: =IF(ISNUMBER(Che_do!$AK$2),Che_do!$AK$2,"") | J2: =IF(ISNUMBER(Che_do!$AA$2),Che_do!$AA$2,0)+IF(ISNUMBER(Che_do!$AH$2),Che_do!$AH$2,0) | K2: =IF(AND($B$2,ISNUMBER($I$2)),$I$2,IF(ISNUMBER(Che_do!$AG$2),Che_do!$AG$2*$C$2/300,IF(ISNUMBER($C$2),$C$2,""))) | L2: =IF(ISNUMBER(Che_do!$AF$2),2*MIN(Che_do!$AF$2,Che_do!$X$2),IF(ISNUMBER($D$2),MIN($D$2,2*$E$2),0)) | M2: =IF(ISNUMBER($K$2),$K$2+$L$2+$J$2,"") | N2: =IF(ISNUMBER(Che_do!$L$2),IF(Che_do!$AD$2/(Che_do!$L$2*3)<=Che_do!$AK$2-Che_do!$R$2,Che_do!$AD$2/(Che_do!$L$2*3),Che_do!$AK$2-Che_do!$R$2+(Che_do!$AD$2-Che_do!$L$2*3*(Che_do!$AK$2-Che_do!$R$2))/(Che_do!$L$2*3*Che_do!$S$2)),IF(ISNUMBER(Che_do!$AC$2),Che_do!$AJ$2/Che_do!$AC$2,"")) | O2: =IF(ISNUMBER(Che_do!$T$2),CEILING(Che_do!$AJ$2/Che_do!$T$2,1),"") | P2: =IF(ISNUMBER($F$2),$F$2+(Che_do!$AL$2-1)*$G$2,"") | Q2: =IF(ISNUMBER($M$2),$M$2,IF(ISNUMBER($P$2),$P$2,"")) | R2: =IF(AND(ISNUMBER($I$2),ISNUMBER($C$2),NOT($B$2)),$I$2-($C$2+$L$2),"") | S2: 04_che_do_kinh_te_ai/Che_do (assault) + C# của chế độ
A3: bossrush | B3: FALSE | C3: 1800 | H3: tunables.json: bosses.bossHunts.weeklyMinutes.value | I3: =IF(ISNUMBER(Che_do!$AK$3),Che_do!$AK$3,"") | J3: =IF(ISNUMBER(Che_do!$AA$3),Che_do!$AA$3,0)+IF(ISNUMBER(Che_do!$AH$3),Che_do!$AH$3,0) | K3: =IF(AND($B$3,ISNUMBER($I$3)),$I$3,IF(ISNUMBER(Che_do!$AG$3),Che_do!$AG$3*$C$3/300,IF(ISNUMBER($C$3),$C$3,""))) | L3: =IF(ISNUMBER(Che_do!$AF$3),2*MIN(Che_do!$AF$3,Che_do!$X$3),IF(ISNUMBER($D$3),MIN($D$3,2*$E$3),0)) | M3: =IF(ISNUMBER($K$3),$K$3+$L$3+$J$3,"") | N3: =IF(ISNUMBER(Che_do!$L$3),IF(Che_do!$AD$3/(Che_do!$L$3*3)<=Che_do!$AK$3-Che_do!$R$3,Che_do!$AD$3/(Che_do!$L$3*3),Che_do!$AK$3-Che_do!$R$3+(Che_do!$AD$3-Che_do!$L$3*3*(Che_do!$AK$3-Che_do!$R$3))/(Che_do!$L$3*3*Che_do!$S$3)),IF(ISNUMBER(Che_do!$AC$3),Che_do!$AJ$3/Che_do!$AC$3,"")) | O3: =IF(ISNUMBER(Che_do!$T$3),CEILING(Che_do!$AJ$3/Che_do!$T$3,1),"") | P3: =IF(ISNUMBER($F$3),$F$3+(Che_do!$AL$3-1)*$G$3,"") | Q3: =IF(ISNUMBER($M$3),$M$3,IF(ISNUMBER($P$3),$P$3,"")) | R3: =IF(AND(ISNUMBER($I$3),ISNUMBER($C$3),NOT($B$3)),$I$3-($C$3+$L$3),"") | S3: 04_che_do_kinh_te_ai/Che_do (bossrush) + C# của chế độ
A4: conquest | B4: TRUE | I4: =IF(ISNUMBER(Che_do!$AK$4),Che_do!$AK$4,"") | J4: =IF(ISNUMBER(Che_do!$AA$4),Che_do!$AA$4,0)+IF(ISNUMBER(Che_do!$AH$4),Che_do!$AH$4,0) | K4: =IF(AND($B$4,ISNUMBER($I$4)),$I$4,IF(ISNUMBER(Che_do!$AG$4),Che_do!$AG$4*$C$4/300,IF(ISNUMBER($C$4),$C$4,""))) | L4: =IF(ISNUMBER(Che_do!$AF$4),2*MIN(Che_do!$AF$4,Che_do!$X$4),IF(ISNUMBER($D$4),MIN($D$4,2*$E$4),0)) | M4: =IF(ISNUMBER($K$4),$K$4+$L$4+$J$4,"") | N4: =IF(ISNUMBER(Che_do!$L$4),IF(Che_do!$AD$4/(Che_do!$L$4*3)<=Che_do!$AK$4-Che_do!$R$4,Che_do!$AD$4/(Che_do!$L$4*3),Che_do!$AK$4-Che_do!$R$4+(Che_do!$AD$4-Che_do!$L$4*3*(Che_do!$AK$4-Che_do!$R$4))/(Che_do!$L$4*3*Che_do!$S$4)),IF(ISNUMBER(Che_do!$AC$4),Che_do!$AJ$4/Che_do!$AC$4,"")) | O4: =IF(ISNUMBER(Che_do!$T$4),CEILING(Che_do!$AJ$4/Che_do!$T$4,1),"") | P4: =IF(ISNUMBER($F$4),$F$4+(Che_do!$AL$4-1)*$G$4,"") | Q4: =IF(ISNUMBER($M$4),$M$4,IF(ISNUMBER($P$4),$P$4,"")) | R4: =IF(AND(ISNUMBER($I$4),ISNUMBER($C$4),NOT($B$4)),$I$4-($C$4+$L$4),"") | S4: 04_che_do_kinh_te_ai/Che_do (conquest) + C# của chế độ
A5: deathmatch | B5: TRUE | I5: =IF(ISNUMBER(Che_do!$AK$5),Che_do!$AK$5,"") | J5: =IF(ISNUMBER(Che_do!$AA$5),Che_do!$AA$5,0)+IF(ISNUMBER(Che_do!$AH$5),Che_do!$AH$5,0) | K5: =IF(AND($B$5,ISNUMBER($I$5)),$I$5,IF(ISNUMBER(Che_do!$AG$5),Che_do!$AG$5*$C$5/300,IF(ISNUMBER($C$5),$C$5,""))) | L5: =IF(ISNUMBER(Che_do!$AF$5),2*MIN(Che_do!$AF$5,Che_do!$X$5),IF(ISNUMBER($D$5),MIN($D$5,2*$E$5),0)) | M5: =IF(ISNUMBER($K$5),$K$5+$L$5+$J$5,"") | N5: =IF(ISNUMBER(Che_do!$L$5),IF(Che_do!$AD$5/(Che_do!$L$5*3)<=Che_do!$AK$5-Che_do!$R$5,Che_do!$AD$5/(Che_do!$L$5*3),Che_do!$AK$5-Che_do!$R$5+(Che_do!$AD$5-Che_do!$L$5*3*(Che_do!$AK$5-Che_do!$R$5))/(Che_do!$L$5*3*Che_do!$S$5)),IF(ISNUMBER(Che_do!$AC$5),Che_do!$AJ$5/Che_do!$AC$5,"")) | O5: =IF(ISNUMBER(Che_do!$T$5),CEILING(Che_do!$AJ$5/Che_do!$T$5,1),"") | P5: =IF(ISNUMBER($F$5),$F$5+(Che_do!$AL$5-1)*$G$5,"") | Q5: =IF(ISNUMBER($M$5),$M$5,IF(ISNUMBER($P$5),$P$5,"")) | R5: =IF(AND(ISNUMBER($I$5),ISNUMBER($C$5),NOT($B$5)),$I$5-($C$5+$L$5),"") | S5: 04_che_do_kinh_te_ai/Che_do (deathmatch) + C# của chế độ
A6: defend | B6: TRUE | C6: 480 | D6: 150 | E6: 900 | H6: Game/Match/ModeSessions.cs:691 | I6: =IF(ISNUMBER(Che_do!$AK$6),Che_do!$AK$6,"") | J6: =IF(ISNUMBER(Che_do!$AA$6),Che_do!$AA$6,0)+IF(ISNUMBER(Che_do!$AH$6),Che_do!$AH$6,0) | K6: =IF(AND($B$6,ISNUMBER($I$6)),$I$6,IF(ISNUMBER(Che_do!$AG$6),Che_do!$AG$6*$C$6/300,IF(ISNUMBER($C$6),$C$6,""))) | L6: =IF(ISNUMBER(Che_do!$AF$6),2*MIN(Che_do!$AF$6,Che_do!$X$6),IF(ISNUMBER($D$6),MIN($D$6,2*$E$6),0)) | M6: =IF(ISNUMBER($K$6),$K$6+$L$6+$J$6,"") | N6: =IF(ISNUMBER(Che_do!$L$6),IF(Che_do!$AD$6/(Che_do!$L$6*3)<=Che_do!$AK$6-Che_do!$R$6,Che_do!$AD$6/(Che_do!$L$6*3),Che_do!$AK$6-Che_do!$R$6+(Che_do!$AD$6-Che_do!$L$6*3*(Che_do!$AK$6-Che_do!$R$6))/(Che_do!$L$6*3*Che_do!$S$6)),IF(ISNUMBER(Che_do!$AC$6),Che_do!$AJ$6/Che_do!$AC$6,"")) | O6: =IF(ISNUMBER(Che_do!$T$6),CEILING(Che_do!$AJ$6/Che_do!$T$6,1),"") | P6: =IF(ISNUMBER($F$6),$F$6+(Che_do!$AL$6-1)*$G$6,"") | Q6: =IF(ISNUMBER($M$6),$M$6,IF(ISNUMBER($P$6),$P$6,"")) | R6: =IF(AND(ISNUMBER($I$6),ISNUMBER($C$6),NOT($B$6)),$I$6-($C$6+$L$6),"") | S6: 04_che_do_kinh_te_ai/Che_do (defend) + C# của chế độ
A7: endless | B7: FALSE | I7: =IF(ISNUMBER(Che_do!$AK$7),Che_do!$AK$7,"") | J7: =IF(ISNUMBER(Che_do!$AA$7),Che_do!$AA$7,0)+IF(ISNUMBER(Che_do!$AH$7),Che_do!$AH$7,0) | K7: =IF(AND($B$7,ISNUMBER($I$7)),$I$7,IF(ISNUMBER(Che_do!$AG$7),Che_do!$AG$7*$C$7/300,IF(ISNUMBER($C$7),$C$7,""))) | L7: =IF(ISNUMBER(Che_do!$AF$7),2*MIN(Che_do!$AF$7,Che_do!$X$7),IF(ISNUMBER($D$7),MIN($D$7,2*$E$7),0)) | M7: =IF(ISNUMBER($K$7),$K$7+$L$7+$J$7,"") | N7: =IF(ISNUMBER(Che_do!$L$7),IF(Che_do!$AD$7/(Che_do!$L$7*3)<=Che_do!$AK$7-Che_do!$R$7,Che_do!$AD$7/(Che_do!$L$7*3),Che_do!$AK$7-Che_do!$R$7+(Che_do!$AD$7-Che_do!$L$7*3*(Che_do!$AK$7-Che_do!$R$7))/(Che_do!$L$7*3*Che_do!$S$7)),IF(ISNUMBER(Che_do!$AC$7),Che_do!$AJ$7/Che_do!$AC$7,"")) | O7: =IF(ISNUMBER(Che_do!$T$7),CEILING(Che_do!$AJ$7/Che_do!$T$7,1),"") | P7: =IF(ISNUMBER($F$7),$F$7+(Che_do!$AL$7-1)*$G$7,"") | Q7: =IF(ISNUMBER($M$7),$M$7,IF(ISNUMBER($P$7),$P$7,"")) | R7: =IF(AND(ISNUMBER($I$7),ISNUMBER($C$7),NOT($B$7)),$I$7-($C$7+$L$7),"") | S7: 04_che_do_kinh_te_ai/Che_do (endless) + C# của chế độ
A8: hill | B8: TRUE | I8: =IF(ISNUMBER(Che_do!$AK$8),Che_do!$AK$8,"") | J8: =IF(ISNUMBER(Che_do!$AA$8),Che_do!$AA$8,0)+IF(ISNUMBER(Che_do!$AH$8),Che_do!$AH$8,0) | K8: =IF(AND($B$8,ISNUMBER($I$8)),$I$8,IF(ISNUMBER(Che_do!$AG$8),Che_do!$AG$8*$C$8/300,IF(ISNUMBER($C$8),$C$8,""))) | L8: =IF(ISNUMBER(Che_do!$AF$8),2*MIN(Che_do!$AF$8,Che_do!$X$8),IF(ISNUMBER($D$8),MIN($D$8,2*$E$8),0)) | M8: =IF(ISNUMBER($K$8),$K$8+$L$8+$J$8,"") | N8: =IF(ISNUMBER(Che_do!$L$8),IF(Che_do!$AD$8/(Che_do!$L$8*3)<=Che_do!$AK$8-Che_do!$R$8,Che_do!$AD$8/(Che_do!$L$8*3),Che_do!$AK$8-Che_do!$R$8+(Che_do!$AD$8-Che_do!$L$8*3*(Che_do!$AK$8-Che_do!$R$8))/(Che_do!$L$8*3*Che_do!$S$8)),IF(ISNUMBER(Che_do!$AC$8),Che_do!$AJ$8/Che_do!$AC$8,"")) | O8: =IF(ISNUMBER(Che_do!$T$8),CEILING(Che_do!$AJ$8/Che_do!$T$8,1),"") | P8: =IF(ISNUMBER($F$8),$F$8+(Che_do!$AL$8-1)*$G$8,"") | Q8: =IF(ISNUMBER($M$8),$M$8,IF(ISNUMBER($P$8),$P$8,"")) | R8: =IF(AND(ISNUMBER($I$8),ISNUMBER($C$8),NOT($B$8)),$I$8-($C$8+$L$8),"") | S8: 04_che_do_kinh_te_ai/Che_do (hill) + C# của chế độ
A9: operations | B9: FALSE | I9: =IF(ISNUMBER(Che_do!$AK$9),Che_do!$AK$9,"") | J9: =IF(ISNUMBER(Che_do!$AA$9),Che_do!$AA$9,0)+IF(ISNUMBER(Che_do!$AH$9),Che_do!$AH$9,0) | K9: =IF(AND($B$9,ISNUMBER($I$9)),$I$9,IF(ISNUMBER(Che_do!$AG$9),Che_do!$AG$9*$C$9/300,IF(ISNUMBER($C$9),$C$9,""))) | L9: =IF(ISNUMBER(Che_do!$AF$9),2*MIN(Che_do!$AF$9,Che_do!$X$9),IF(ISNUMBER($D$9),MIN($D$9,2*$E$9),0)) | M9: =IF(ISNUMBER($K$9),$K$9+$L$9+$J$9,"") | N9: =IF(ISNUMBER(Che_do!$L$9),IF(Che_do!$AD$9/(Che_do!$L$9*3)<=Che_do!$AK$9-Che_do!$R$9,Che_do!$AD$9/(Che_do!$L$9*3),Che_do!$AK$9-Che_do!$R$9+(Che_do!$AD$9-Che_do!$L$9*3*(Che_do!$AK$9-Che_do!$R$9))/(Che_do!$L$9*3*Che_do!$S$9)),IF(ISNUMBER(Che_do!$AC$9),Che_do!$AJ$9/Che_do!$AC$9,"")) | O9: =IF(ISNUMBER(Che_do!$T$9),CEILING(Che_do!$AJ$9/Che_do!$T$9,1),"") | P9: =IF(ISNUMBER($F$9),$F$9+(Che_do!$AL$9-1)*$G$9,"") | Q9: =IF(ISNUMBER($M$9),$M$9,IF(ISNUMBER($P$9),$P$9,"")) | R9: =IF(AND(ISNUMBER($I$9),ISNUMBER($C$9),NOT($B$9)),$I$9-($C$9+$L$9),"") | S9: 04_che_do_kinh_te_ai/Che_do (operations) + C# của chế độ
A10: showdown | B10: TRUE | I10: =IF(ISNUMBER(Che_do!$AK$10),Che_do!$AK$10,"") | J10: =IF(ISNUMBER(Che_do!$AA$10),Che_do!$AA$10,0)+IF(ISNUMBER(Che_do!$AH$10),Che_do!$AH$10,0) | K10: =IF(AND($B$10,ISNUMBER($I$10)),$I$10,IF(ISNUMBER(Che_do!$AG$10),Che_do!$AG$10*$C$10/300,IF(ISNUMBER($C$10),$C$10,""))) | L10: =IF(ISNUMBER(Che_do!$AF$10),2*MIN(Che_do!$AF$10,Che_do!$X$10),IF(ISNUMBER($D$10),MIN($D$10,2*$E$10),0)) | M10: =IF(ISNUMBER($K$10),$K$10+$L$10+$J$10,"") | N10: =IF(ISNUMBER(Che_do!$L$10),IF(Che_do!$AD$10/(Che_do!$L$10*3)<=Che_do!$AK$10-Che_do!$R$10,Che_do!$AD$10/(Che_do!$L$10*3),Che_do!$AK$10-Che_do!$R$10+(Che_do!$AD$10-Che_do!$L$10*3*(Che_do!$AK$10-Che_do!$R$10))/(Che_do!$L$10*3*Che_do!$S$10)),IF(ISNUMBER(Che_do!$AC$10),Che_do!$AJ$10/Che_do!$AC$10,"")) | O10: =IF(ISNUMBER(Che_do!$T$10),CEILING(Che_do!$AJ$10/Che_do!$T$10,1),"") | P10: =IF(ISNUMBER($F$10),$F$10+(Che_do!$AL$10-1)*$G$10,"") | Q10: =IF(ISNUMBER($M$10),$M$10,IF(ISNUMBER($P$10),$P$10,"")) | R10: =IF(AND(ISNUMBER($I$10),ISNUMBER($C$10),NOT($B$10)),$I$10-($C$10+$L$10),"") | S10: 04_che_do_kinh_te_ai/Che_do (showdown) + C# của chế độ
A11: siege | B11: TRUE | C11: 480 | D11: 600 | E11: 900 | H11: Game/Match/ModeSessions.cs:874, 879 | I11: =IF(ISNUMBER(Che_do!$AK$11),Che_do!$AK$11,"") | J11: =IF(ISNUMBER(Che_do!$AA$11),Che_do!$AA$11,0)+IF(ISNUMBER(Che_do!$AH$11),Che_do!$AH$11,0) | K11: =IF(AND($B$11,ISNUMBER($I$11)),$I$11,IF(ISNUMBER(Che_do!$AG$11),Che_do!$AG$11*$C$11/300,IF(ISNUMBER($C$11),$C$11,""))) | L11: =IF(ISNUMBER(Che_do!$AF$11),2*MIN(Che_do!$AF$11,Che_do!$X$11),IF(ISNUMBER($D$11),MIN($D$11,2*$E$11),0)) | M11: =IF(ISNUMBER($K$11),$K$11+$L$11+$J$11,"") | N11: =IF(ISNUMBER(Che_do!$L$11),IF(Che_do!$AD$11/(Che_do!$L$11*3)<=Che_do!$AK$11-Che_do!$R$11,Che_do!$AD$11/(Che_do!$L$11*3),Che_do!$AK$11-Che_do!$R$11+(Che_do!$AD$11-Che_do!$L$11*3*(Che_do!$AK$11-Che_do!$R$11))/(Che_do!$L$11*3*Che_do!$S$11)),IF(ISNUMBER(Che_do!$AC$11),Che_do!$AJ$11/Che_do!$AC$11,"")) | O11: =IF(ISNUMBER(Che_do!$T$11),CEILING(Che_do!$AJ$11/Che_do!$T$11,1),"") | P11: =IF(ISNUMBER($F$11),$F$11+(Che_do!$AL$11-1)*$G$11,"") | Q11: =IF(ISNUMBER($M$11),$M$11,IF(ISNUMBER($P$11),$P$11,"")) | R11: =IF(AND(ISNUMBER($I$11),ISNUMBER($C$11),NOT($B$11)),$I$11-($C$11+$L$11),"") | S11: 04_che_do_kinh_te_ai/Che_do (siege) + C# của chế độ
A12: survival | B12: FALSE | F12: 20 | G12: 30 | H12: tunables.json: modes.sandboxMode.firstWaveDelay.value, tunables.json: modes.sandboxMode.waveInterval.value | I12: =IF(ISNUMBER(Che_do!$AK$12),Che_do!$AK$12,"") | J12: =IF(ISNUMBER(Che_do!$AA$12),Che_do!$AA$12,0)+IF(ISNUMBER(Che_do!$AH$12),Che_do!$AH$12,0) | K12: =IF(AND($B$12,ISNUMBER($I$12)),$I$12,IF(ISNUMBER(Che_do!$AG$12),Che_do!$AG$12*$C$12/300,IF(ISNUMBER($C$12),$C$12,""))) | L12: =IF(ISNUMBER(Che_do!$AF$12),2*MIN(Che_do!$AF$12,Che_do!$X$12),IF(ISNUMBER($D$12),MIN($D$12,2*$E$12),0)) | M12: =IF(ISNUMBER($K$12),$K$12+$L$12+$J$12,"") | N12: =IF(ISNUMBER(Che_do!$L$12),IF(Che_do!$AD$12/(Che_do!$L$12*3)<=Che_do!$AK$12-Che_do!$R$12,Che_do!$AD$12/(Che_do!$L$12*3),Che_do!$AK$12-Che_do!$R$12+(Che_do!$AD$12-Che_do!$L$12*3*(Che_do!$AK$12-Che_do!$R$12))/(Che_do!$L$12*3*Che_do!$S$12)),IF(ISNUMBER(Che_do!$AC$12),Che_do!$AJ$12/Che_do!$AC$12,"")) | O12: =IF(ISNUMBER(Che_do!$T$12),CEILING(Che_do!$AJ$12/Che_do!$T$12,1),"") | P12: =IF(ISNUMBER($F$12),$F$12+(Che_do!$AL$12-1)*$G$12,"") | Q12: =IF(ISNUMBER($M$12),$M$12,IF(ISNUMBER($P$12),$P$12,"")) | R12: =IF(AND(ISNUMBER($I$12),ISNUMBER($C$12),NOT($B$12)),$I$12-($C$12+$L$12),"") | S12: 04_che_do_kinh_te_ai/Che_do (survival) + C# của chế độ
A13: weekly | B13: TRUE | C13: 300 | D13: 540 | E13: 600 | H13: Game/Match/ModeSessions.cs:797, Sim/Modes/SiegeModes.cs:56 | I13: =IF(ISNUMBER(Che_do!$AK$13),Che_do!$AK$13,"") | J13: =IF(ISNUMBER(Che_do!$AA$13),Che_do!$AA$13,0)+IF(ISNUMBER(Che_do!$AH$13),Che_do!$AH$13,0) | K13: =IF(AND($B$13,ISNUMBER($I$13)),$I$13,IF(ISNUMBER(Che_do!$AG$13),Che_do!$AG$13*$C$13/300,IF(ISNUMBER($C$13),$C$13,""))) | L13: =IF(ISNUMBER(Che_do!$AF$13),2*MIN(Che_do!$AF$13,Che_do!$X$13),IF(ISNUMBER($D$13),MIN($D$13,2*$E$13),0)) | M13: =IF(ISNUMBER($K$13),$K$13+$L$13+$J$13,"") | N13: =IF(ISNUMBER(Che_do!$L$13),IF(Che_do!$AD$13/(Che_do!$L$13*3)<=Che_do!$AK$13-Che_do!$R$13,Che_do!$AD$13/(Che_do!$L$13*3),Che_do!$AK$13-Che_do!$R$13+(Che_do!$AD$13-Che_do!$L$13*3*(Che_do!$AK$13-Che_do!$R$13))/(Che_do!$L$13*3*Che_do!$S$13)),IF(ISNUMBER(Che_do!$AC$13),Che_do!$AJ$13/Che_do!$AC$13,"")) | O13: =IF(ISNUMBER(Che_do!$T$13),CEILING(Che_do!$AJ$13/Che_do!$T$13,1),"") | P13: =IF(ISNUMBER($F$13),$F$13+(Che_do!$AL$13-1)*$G$13,"") | Q13: =IF(ISNUMBER($M$13),$M$13,IF(ISNUMBER($P$13),$P$13,"")) | R13: =IF(AND(ISNUMBER($I$13),ISNUMBER($C$13),NOT($B$13)),$I$13-($C$13+$L$13),"") | S13: 04_che_do_kinh_te_ai/Che_do (weekly) + C# của chế độ

Sheet Kinh_te_suy_ra
A1: id | B1: che_do | C1: do_kho | D1: cp_khoi_dau_nguoi_choi_ma | E1: thu_nhap_nguoi_choi_ma_cp_s | F1: cp_khoi_dau_dich_ma | G1: thu_nhap_dich_ma_cp_s | H1: he_so_dich_che_do | I1: he_so_dich_do_kho | J1: thuong_muc_tieu_cp_s | K1: ghi_chu | L1: nguon_ma | M1: cp_khoi_dau_nguoi_choi | N1: cp_khoi_dau_nguoi_choi_game | O1: cp_khoi_dau_dich | P1: cp_khoi_dau_dich_game | Q1: thu_nhap_nguoi_choi_cp_s | R1: thu_nhap_nguoi_choi_cp_s_game | S1: thu_nhap_dich_cp_s | T1: thu_nhap_dich_cp_s_game | U1: thoi_luong_tham_chieu_s | V1: cp_nguoi_choi_25 | W1: cp_nguoi_choi_50 | X1: cp_nguoi_choi_75 | Y1: cp_nguoi_choi_100 | Z1: cp_dich_25 | AA1: cp_dich_50 | AB1: cp_dich_75 | AC1: cp_dich_100 | AD1: ty_le_dich_nguoi_choi_100 | AE1: nguon | AF1: raw_json
A2: assault/Easy | B2: assault | C2: Easy | D2: 20 | E2: 1.45 | F2: 32 | G2: 1.3 | H2: 1 | I2: 0.8 | J2: 0 | K2: thưởng khu (8 CP, +0,25 CP/s mỗi khu) không tính | L2: Game/Match/ModeSessions.cs:606; Sim/AI/ConquestAi.cs:65 | M2: =IF(ISNUMBER($D$2),IF(AND(ISNUMBER(FIND(";"&Che_do!$B$2&";",";"&Kinh_te!$E$10&";")),$D$2>0,Kinh_te!$D$11<>1),ROUND($D$2*Kinh_te!$D$11,0),$D$2),"") | N2: 23 | O2: =IF(ISNUMBER($F$2),IF(AND(ISNUMBER(FIND(";"&Che_do!$B$2&";",";"&Kinh_te!$E$10&";")),$F$2>0,Kinh_te!$D$11<>1),ROUND($F$2*Kinh_te!$D$11,0),$F$2),"") | P2: 37 | Q2: =($E$2+$J$2)*Kinh_te!$D$9 | R2: 1.305 | S2: =IF(ISNUMBER($G$2),($G$2+$J$2)*Kinh_te!$D$9*$H$2*$I$2,"") | T2: 0.936 | U2: =Che_do_thoi_luong!$Q$2 | V2: =IF(AND(ISNUMBER($U$2),ISNUMBER($M$2)),$M$2+$Q$2*0.25*$U$2,"") | W2: =IF(AND(ISNUMBER($U$2),ISNUMBER($M$2)),$M$2+$Q$2*0.5*$U$2,"") | X2: =IF(AND(ISNUMBER($U$2),ISNUMBER($M$2)),$M$2+$Q$2*0.75*$U$2,"") | Y2: =IF(AND(ISNUMBER($U$2),ISNUMBER($M$2)),$M$2+$Q$2*1.0*$U$2,"") | Z2: =IF(AND(ISNUMBER($U$2),ISNUMBER($O$2)),$O$2+$S$2*0.25*$U$2,"") | AA2: =IF(AND(ISNUMBER($U$2),ISNUMBER($O$2)),$O$2+$S$2*0.5*$U$2,"") | AB2: =IF(AND(ISNUMBER($U$2),ISNUMBER($O$2)),$O$2+$S$2*0.75*$U$2,"") | AC2: =IF(AND(ISNUMBER($U$2),ISNUMBER($O$2)),$O$2+$S$2*1.0*$U$2,"") | AD2: =IF(AND(ISNUMBER($AC$2),ISNUMBER($Y$2)),$AC$2/$Y$2,"") | AE2: C#: Game/Match/ModeSessions.cs:606; Sim/AI/ConquestAi.cs:65
A3: assault/Hard | B3: assault | C3: Hard | D3: 20 | E3: 1.45 | F3: 32 | G3: 1.3 | H3: 1 | I3: 1.2 | J3: 0 | K3: thưởng khu (8 CP, +0,25 CP/s mỗi khu) không tính | L3: Game/Match/ModeSessions.cs:606; Sim/AI/ConquestAi.cs:68 | M3: =IF(ISNUMBER($D$3),IF(AND(ISNUMBER(FIND(";"&Che_do!$B$2&";",";"&Kinh_te!$E$10&";")),$D$3>0,Kinh_te!$D$11<>1),ROUND($D$3*Kinh_te!$D$11,0),$D$3),"") | N3: 23 | O3: =IF(ISNUMBER($F$3),IF(AND(ISNUMBER(FIND(";"&Che_do!$B$2&";",";"&Kinh_te!$E$10&";")),$F$3>0,Kinh_te!$D$11<>1),ROUND($F$3*Kinh_te!$D$11,0),$F$3),"") | P3: 37 | Q3: =($E$3+$J$3)*Kinh_te!$D$9 | R3: 1.305 | S3: =IF(ISNUMBER($G$3),($G$3+$J$3)*Kinh_te!$D$9*$H$3*$I$3,"") | T3: 1.404 | U3: =Che_do_thoi_luong!$Q$2 | V3: =IF(AND(ISNUMBER($U$3),ISNUMBER($M$3)),$M$3+$Q$3*0.25*$U$3,"") | W3: =IF(AND(ISNUMBER($U$3),ISNUMBER($M$3)),$M$3+$Q$3*0.5*$U$3,"") | X3: =IF(AND(ISNUMBER($U$3),ISNUMBER($M$3)),$M$3+$Q$3*0.75*$U$3,"") | Y3: =IF(AND(ISNUMBER($U$3),ISNUMBER($M$3)),$M$3+$Q$3*1.0*$U$3,"") | Z3: =IF(AND(ISNUMBER($U$3),ISNUMBER($O$3)),$O$3+$S$3*0.25*$U$3,"") | AA3: =IF(AND(ISNUMBER($U$3),ISNUMBER($O$3)),$O$3+$S$3*0.5*$U$3,"") | AB3: =IF(AND(ISNUMBER($U$3),ISNUMBER($O$3)),$O$3+$S$3*0.75*$U$3,"") | AC3: =IF(AND(ISNUMBER($U$3),ISNUMBER($O$3)),$O$3+$S$3*1.0*$U$3,"") | AD3: =IF(AND(ISNUMBER($AC$3),ISNUMBER($Y$3)),$AC$3/$Y$3,"") | AE3: C#: Game/Match/ModeSessions.cs:606; Sim/AI/ConquestAi.cs:68
A4: assault/Normal | B4: assault | C4: Normal | D4: 20 | E4: 1.45 | F4: 32 | G4: 1.3 | H4: 1 | I4: 0.7 | J4: 0 | K4: thưởng khu (8 CP, +0,25 CP/s mỗi khu) không tính | L4: Game/Match/ModeSessions.cs:606; Sim/AI/ConquestAi.cs:67 | M4: =IF(ISNUMBER($D$4),IF(AND(ISNUMBER(FIND(";"&Che_do!$B$2&";",";"&Kinh_te!$E$10&";")),$D$4>0,Kinh_te!$D$11<>1),ROUND($D$4*Kinh_te!$D$11,0),$D$4),"") | N4: 23 | O4: =IF(ISNUMBER($F$4),IF(AND(ISNUMBER(FIND(";"&Che_do!$B$2&";",";"&Kinh_te!$E$10&";")),$F$4>0,Kinh_te!$D$11<>1),ROUND($F$4*Kinh_te!$D$11,0),$F$4),"") | P4: 37 | Q4: =($E$4+$J$4)*Kinh_te!$D$9 | R4: 1.305 | S4: =IF(ISNUMBER($G$4),($G$4+$J$4)*Kinh_te!$D$9*$H$4*$I$4,"") | T4: 0.819 | U4: =Che_do_thoi_luong!$Q$2 | V4: =IF(AND(ISNUMBER($U$4),ISNUMBER($M$4)),$M$4+$Q$4*0.25*$U$4,"") | W4: =IF(AND(ISNUMBER($U$4),ISNUMBER($M$4)),$M$4+$Q$4*0.5*$U$4,"") | X4: =IF(AND(ISNUMBER($U$4),ISNUMBER($M$4)),$M$4+$Q$4*0.75*$U$4,"") | Y4: =IF(AND(ISNUMBER($U$4),ISNUMBER($M$4)),$M$4+$Q$4*1.0*$U$4,"") | Z4: =IF(AND(ISNUMBER($U$4),ISNUMBER($O$4)),$O$4+$S$4*0.25*$U$4,"") | AA4: =IF(AND(ISNUMBER($U$4),ISNUMBER($O$4)),$O$4+$S$4*0.5*$U$4,"") | AB4: =IF(AND(ISNUMBER($U$4),ISNUMBER($O$4)),$O$4+$S$4*0.75*$U$4,"") | AC4: =IF(AND(ISNUMBER($U$4),ISNUMBER($O$4)),$O$4+$S$4*1.0*$U$4,"") | AD4: =IF(AND(ISNUMBER($AC$4),ISNUMBER($Y$4)),$AC$4/$Y$4,"") | AE4: C#: Game/Match/ModeSessions.cs:606; Sim/AI/ConquestAi.cs:67
A5: assault/VeryHard | B5: assault | C5: VeryHard | D5: 20 | E5: 1.45 | F5: 32 | G5: 1.3 | H5: 1 | I5: 1.4 | J5: 0 | K5: thưởng khu (8 CP, +0,25 CP/s mỗi khu) không tính | L5: Game/Match/ModeSessions.cs:606; Sim/AI/ConquestAi.cs:69 | M5: =IF(ISNUMBER($D$5),IF(AND(ISNUMBER(FIND(";"&Che_do!$B$2&";",";"&Kinh_te!$E$10&";")),$D$5>0,Kinh_te!$D$11<>1),ROUND($D$5*Kinh_te!$D$11,0),$D$5),"") | N5: 23 | O5: =IF(ISNUMBER($F$5),IF(AND(ISNUMBER(FIND(";"&Che_do!$B$2&";",";"&Kinh_te!$E$10&";")),$F$5>0,Kinh_te!$D$11<>1),ROUND($F$5*Kinh_te!$D$11,0),$F$5),"") | P5: 37 | Q5: =($E$5+$J$5)*Kinh_te!$D$9 | R5: 1.305 | S5: =IF(ISNUMBER($G$5),($G$5+$J$5)*Kinh_te!$D$9*$H$5*$I$5,"") | T5: 1.638 | U5: =Che_do_thoi_luong!$Q$2 | V5: =IF(AND(ISNUMBER($U$5),ISNUMBER($M$5)),$M$5+$Q$5*0.25*$U$5,"") | W5: =IF(AND(ISNUMBER($U$5),ISNUMBER($M$5)),$M$5+$Q$5*0.5*$U$5,"") | X5: =IF(AND(ISNUMBER($U$5),ISNUMBER($M$5)),$M$5+$Q$5*0.75*$U$5,"") | Y5: =IF(AND(ISNUMBER($U$5),ISNUMBER($M$5)),$M$5+$Q$5*1.0*$U$5,"") | Z5: =IF(AND(ISNUMBER($U$5),ISNUMBER($O$5)),$O$5+$S$5*0.25*$U$5,"") | AA5: =IF(AND(ISNUMBER($U$5),ISNUMBER($O$5)),$O$5+$S$5*0.5*$U$5,"") | AB5: =IF(AND(ISNUMBER($U$5),ISNUMBER($O$5)),$O$5+$S$5*0.75*$U$5,"") | AC5: =IF(AND(ISNUMBER($U$5),ISNUMBER($O$5)),$O$5+$S$5*1.0*$U$5,"") | AD5: =IF(AND(ISNUMBER($AC$5),ISNUMBER($Y$5)),$AC$5/$Y$5,"") | AE5: C#: Game/Match/ModeSessions.cs:606; Sim/AI/ConquestAi.cs:69
A6: bossrush/Easy | B6: bossrush | C6: Easy | D6: 40 | E6: 1.8 | J6: 0 | K6: thưởng boss (8 CP mỗi 25 % máu, 12 khi hạ) không tính | L6: Game/Match/ModeSessions.cs:979 | M6: =IF(ISNUMBER($D$6),IF(AND(ISNUMBER(FIND(";"&Che_do!$B$3&";",";"&Kinh_te!$E$10&";")),$D$6>0,Kinh_te!$D$11<>1),ROUND($D$6*Kinh_te!$D$11,0),$D$6),"") | N6: 46 | O6: =IF(ISNUMBER($F$6),IF(AND(ISNUMBER(FIND(";"&Che_do!$B$3&";",";"&Kinh_te!$E$10&";")),$F$6>0,Kinh_te!$D$11<>1),ROUND($F$6*Kinh_te!$D$11,0),$F$6),"") | Q6: =($E$6+$J$6)*Kinh_te!$D$9 | R6: 1.62 | S6: =IF(ISNUMBER($G$6),($G$6+$J$6)*Kinh_te!$D$9*$H$6*$I$6,"") | U6: =Che_do_thoi_luong!$Q$3 | V6: =IF(AND(ISNUMBER($U$6),ISNUMBER($M$6)),$M$6+$Q$6*0.25*$U$6,"") | W6: =IF(AND(ISNUMBER($U$6),ISNUMBER($M$6)),$M$6+$Q$6*0.5*$U$6,"") | X6: =IF(AND(ISNUMBER($U$6),ISNUMBER($M$6)),$M$6+$Q$6*0.75*$U$6,"") | Y6: =IF(AND(ISNUMBER($U$6),ISNUMBER($M$6)),$M$6+$Q$6*1.0*$U$6,"") | Z6: =IF(AND(ISNUMBER($U$6),ISNUMBER($O$6)),$O$6+$S$6*0.25*$U$6,"") | AA6: =IF(AND(ISNUMBER($U$6),ISNUMBER($O$6)),$O$6+$S$6*0.5*$U$6,"") | AB6: =IF(AND(ISNUMBER($U$6),ISNUMBER($O$6)),$O$6+$S$6*0.75*$U$6,"") | AC6: =IF(AND(ISNUMBER($U$6),ISNUMBER($O$6)),$O$6+$S$6*1.0*$U$6,"") | AD6: =IF(AND(ISNUMBER($AC$6),ISNUMBER($Y$6)),$AC$6/$Y$6,"") | AE6: C#: Game/Match/ModeSessions.cs:979; Sim/AI/ConquestAi.cs:65
A7: bossrush/Hard | B7: bossrush | C7: Hard | D7: 40 | E7: 1.6 | J7: 0 | K7: thưởng boss (8 CP mỗi 25 % máu, 12 khi hạ) không tính | L7: Game/Match/ModeSessions.cs:979 | M7: =IF(ISNUMBER($D$7),IF(AND(ISNUMBER(FIND(";"&Che_do!$B$3&";",";"&Kinh_te!$E$10&";")),$D$7>0,Kinh_te!$D$11<>1),ROUND($D$7*Kinh_te!$D$11,0),$D$7),"") | N7: 46 | O7: =IF(ISNUMBER($F$7),IF(AND(ISNUMBER(FIND(";"&Che_do!$B$3&";",";"&Kinh_te!$E$10&";")),$F$7>0,Kinh_te!$D$11<>1),ROUND($F$7*Kinh_te!$D$11,0),$F$7),"") | Q7: =($E$7+$J$7)*Kinh_te!$D$9 | R7: 1.44 | S7: =IF(ISNUMBER($G$7),($G$7+$J$7)*Kinh_te!$D$9*$H$7*$I$7,"") | U7: =Che_do_thoi_luong!$Q$3 | V7: =IF(AND(ISNUMBER($U$7),ISNUMBER($M$7)),$M$7+$Q$7*0.25*$U$7,"") | W7: =IF(AND(ISNUMBER($U$7),ISNUMBER($M$7)),$M$7+$Q$7*0.5*$U$7,"") | X7: =IF(AND(ISNUMBER($U$7),ISNUMBER($M$7)),$M$7+$Q$7*0.75*$U$7,"") | Y7: =IF(AND(ISNUMBER($U$7),ISNUMBER($M$7)),$M$7+$Q$7*1.0*$U$7,"") | Z7: =IF(AND(ISNUMBER($U$7),ISNUMBER($O$7)),$O$7+$S$7*0.25*$U$7,"") | AA7: =IF(AND(ISNUMBER($U$7),ISNUMBER($O$7)),$O$7+$S$7*0.5*$U$7,"") | AB7: =IF(AND(ISNUMBER($U$7),ISNUMBER($O$7)),$O$7+$S$7*0.75*$U$7,"") | AC7: =IF(AND(ISNUMBER($U$7),ISNUMBER($O$7)),$O$7+$S$7*1.0*$U$7,"") | AD7: =IF(AND(ISNUMBER($AC$7),ISNUMBER($Y$7)),$AC$7/$Y$7,"") | AE7: C#: Game/Match/ModeSessions.cs:979; Sim/AI/ConquestAi.cs:68
A8: bossrush/Normal | B8: bossrush | C8: Normal | D8: 40 | E8: 1.8 | J8: 0 | K8: thưởng boss (8 CP mỗi 25 % máu, 12 khi hạ) không tính | L8: Game/Match/ModeSessions.cs:979 | M8: =IF(ISNUMBER($D$8),IF(AND(ISNUMBER(FIND(";"&Che_do!$B$3&";",";"&Kinh_te!$E$10&";")),$D$8>0,Kinh_te!$D$11<>1),ROUND($D$8*Kinh_te!$D$11,0),$D$8),"") | N8: 46 | O8: =IF(ISNUMBER($F$8),IF(AND(ISNUMBER(FIND(";"&Che_do!$B$3&";",";"&Kinh_te!$E$10&";")),$F$8>0,Kinh_te!$D$11<>1),ROUND($F$8*Kinh_te!$D$11,0),$F$8),"") | Q8: =($E$8+$J$8)*Kinh_te!$D$9 | R8: 1.62 | S8: =IF(ISNUMBER($G$8),($G$8+$J$8)*Kinh_te!$D$9*$H$8*$I$8,"") | U8: =Che_do_thoi_luong!$Q$3 | V8: =IF(AND(ISNUMBER($U$8),ISNUMBER($M$8)),$M$8+$Q$8*0.25*$U$8,"") | W8: =IF(AND(ISNUMBER($U$8),ISNUMBER($M$8)),$M$8+$Q$8*0.5*$U$8,"") | X8: =IF(AND(ISNUMBER($U$8),ISNUMBER($M$8)),$M$8+$Q$8*0.75*$U$8,"") | Y8: =IF(AND(ISNUMBER($U$8),ISNUMBER($M$8)),$M$8+$Q$8*1.0*$U$8,"") | Z8: =IF(AND(ISNUMBER($U$8),ISNUMBER($O$8)),$O$8+$S$8*0.25*$U$8,"") | AA8: =IF(AND(ISNUMBER($U$8),ISNUMBER($O$8)),$O$8+$S$8*0.5*$U$8,"") | AB8: =IF(AND(ISNUMBER($U$8),ISNUMBER($O$8)),$O$8+$S$8*0.75*$U$8,"") | AC8: =IF(AND(ISNUMBER($U$8),ISNUMBER($O$8)),$O$8+$S$8*1.0*$U$8,"") | AD8: =IF(AND(ISNUMBER($AC$8),ISNUMBER($Y$8)),$AC$8/$Y$8,"") | AE8: C#: Game/Match/ModeSessions.cs:979; Sim/AI/ConquestAi.cs:67
A9: bossrush/VeryHard | B9: bossrush | C9: VeryHard | D9: 40 | E9: 1.45 | J9: 0 | K9: thưởng boss (8 CP mỗi 25 % máu, 12 khi hạ) không tính | L9: Game/Match/ModeSessions.cs:979 | M9: =IF(ISNUMBER($D$9),IF(AND(ISNUMBER(FIND(";"&Che_do!$B$3&";",";"&Kinh_te!$E$10&";")),$D$9>0,Kinh_te!$D$11<>1),ROUND($D$9*Kinh_te!$D$11,0),$D$9),"") | N9: 46 | O9: =IF(ISNUMBER($F$9),IF(AND(ISNUMBER(FIND(";"&Che_do!$B$3&";",";"&Kinh_te!$E$10&";")),$F$9>0,Kinh_te!$D$11<>1),ROUND($F$9*Kinh_te!$D$11,0),$F$9),"") | Q9: =($E$9+$J$9)*Kinh_te!$D$9 | R9: 1.305 | S9: =IF(ISNUMBER($G$9),($G$9+$J$9)*Kinh_te!$D$9*$H$9*$I$9,"") | U9: =Che_do_thoi_luong!$Q$3 | V9: =IF(AND(ISNUMBER($U$9),ISNUMBER($M$9)),$M$9+$Q$9*0.25*$U$9,"") | W9: =IF(AND(ISNUMBER($U$9),ISNUMBER($M$9)),$M$9+$Q$9*0.5*$U$9,"") | X9: =IF(AND(ISNUMBER($U$9),ISNUMBER($M$9)),$M$9+$Q$9*0.75*$U$9,"") | Y9: =IF(AND(ISNUMBER($U$9),ISNUMBER($M$9)),$M$9+$Q$9*1.0*$U$9,"") | Z9: =IF(AND(ISNUMBER($U$9),ISNUMBER($O$9)),$O$9+$S$9*0.25*$U$9,"") | AA9: =IF(AND(ISNUMBER($U$9),ISNUMBER($O$9)),$O$9+$S$9*0.5*$U$9,"") | AB9: =IF(AND(ISNUMBER($U$9),ISNUMBER($O$9)),$O$9+$S$9*0.75*$U$9,"") | AC9: =IF(AND(ISNUMBER($U$9),ISNUMBER($O$9)),$O$9+$S$9*1.0*$U$9,"") | AD9: =IF(AND(ISNUMBER($AC$9),ISNUMBER($Y$9)),$AC$9/$Y$9,"") | AE9: C#: Game/Match/ModeSessions.cs:979; Sim/AI/ConquestAi.cs:69
A10: conquest/Easy | B10: conquest | C10: Easy | D10: 14 | E10: 1 | F10: 14 | G10: 1 | H10: 1.18 | I10: 0.8 | J10: 0.225 | K10: PointIncome x 1,5 cứ điểm (chia đều 3 cứ điểm) | L10: Sim/Modes/ConquestMode.cs:64; Sim/Economy/EconomySystem.cs:27; Game/Match/ModeSessions.cs:480; Game/Match/ModeSessions.cs:473; Sim/AI/ConquestAi.cs:65 | M10: =IF(ISNUMBER($D$10),IF(AND(ISNUMBER(FIND(";"&Che_do!$B$4&";",";"&Kinh_te!$E$10&";")),$D$10>0,Kinh_te!$D$11<>1),ROUND($D$10*Kinh_te!$D$11,0),$D$10),"") | N10: 16 | O10: =IF(ISNUMBER($F$10),IF(AND(ISNUMBER(FIND(";"&Che_do!$B$4&";",";"&Kinh_te!$E$10&";")),$F$10>0,Kinh_te!$D$11<>1),ROUND($F$10*Kinh_te!$D$11,0),$F$10),"") | P10: 16 | Q10: =($E$10+$J$10)*Kinh_te!$D$9 | R10: 1.1025 | S10: =IF(ISNUMBER($G$10),($G$10+$J$10)*Kinh_te!$D$9*$H$10*$I$10,"") | T10: 1.04076 | U10: =Che_do_thoi_luong!$Q$4 | V10: =IF(AND(ISNUMBER($U$10),ISNUMBER($M$10)),$M$10+$Q$10*0.25*$U$10,"") | W10: =IF(AND(ISNUMBER($U$10),ISNUMBER($M$10)),$M$10+$Q$10*0.5*$U$10,"") | X10: =IF(AND(ISNUMBER($U$10),ISNUMBER($M$10)),$M$10+$Q$10*0.75*$U$10,"") | Y10: =IF(AND(ISNUMBER($U$10),ISNUMBER($M$10)),$M$10+$Q$10*1.0*$U$10,"") | Z10: =IF(AND(ISNUMBER($U$10),ISNUMBER($O$10)),$O$10+$S$10*0.25*$U$10,"") | AA10: =IF(AND(ISNUMBER($U$10),ISNUMBER($O$10)),$O$10+$S$10*0.5*$U$10,"") | AB10: =IF(AND(ISNUMBER($U$10),ISNUMBER($O$10)),$O$10+$S$10*0.75*$U$10,"") | AC10: =IF(AND(ISNUMBER($U$10),ISNUMBER($O$10)),$O$10+$S$10*1.0*$U$10,"") | AD10: =IF(AND(ISNUMBER($AC$10),ISNUMBER($Y$10)),$AC$10/$Y$10,"") | AE10: C#: Sim/Modes/ConquestMode.cs:64; Sim/Economy/EconomySystem.cs:27; Game/Match/ModeSessions.cs:480; Game/Match/ModeSessions.cs:473; Sim/AI/ConquestAi.cs:65
A11: conquest/Hard | B11: conquest | C11: Hard | D11: 14 | E11: 1 | F11: 14 | G11: 1 | H11: 1.18 | I11: 1.2 | J11: 0.225 | K11: PointIncome x 1,5 cứ điểm (chia đều 3 cứ điểm) | L11: Sim/Modes/ConquestMode.cs:64; Sim/Economy/EconomySystem.cs:27; Game/Match/ModeSessions.cs:480; Game/Match/ModeSessions.cs:473; Sim/AI/ConquestAi.cs:68 | M11: =IF(ISNUMBER($D$11),IF(AND(ISNUMBER(FIND(";"&Che_do!$B$4&";",";"&Kinh_te!$E$10&";")),$D$11>0,Kinh_te!$D$11<>1),ROUND($D$11*Kinh_te!$D$11,0),$D$11),"") | N11: 16 | O11: =IF(ISNUMBER($F$11),IF(AND(ISNUMBER(FIND(";"&Che_do!$B$4&";",";"&Kinh_te!$E$10&";")),$F$11>0,Kinh_te!$D$11<>1),ROUND($F$11*Kinh_te!$D$11,0),$F$11),"") | P11: 16 | Q11: =($E$11+$J$11)*Kinh_te!$D$9 | R11: 1.1025 | S11: =IF(ISNUMBER($G$11),($G$11+$J$11)*Kinh_te!$D$9*$H$11*$I$11,"") | T11: 1.56114 | U11: =Che_do_thoi_luong!$Q$4 | V11: =IF(AND(ISNUMBER($U$11),ISNUMBER($M$11)),$M$11+$Q$11*0.25*$U$11,"") | W11: =IF(AND(ISNUMBER($U$11),ISNUMBER($M$11)),$M$11+$Q$11*0.5*$U$11,"") | X11: =IF(AND(ISNUMBER($U$11),ISNUMBER($M$11)),$M$11+$Q$11*0.75*$U$11,"") | Y11: =IF(AND(ISNUMBER($U$11),ISNUMBER($M$11)),$M$11+$Q$11*1.0*$U$11,"") | Z11: =IF(AND(ISNUMBER($U$11),ISNUMBER($O$11)),$O$11+$S$11*0.25*$U$11,"") | AA11: =IF(AND(ISNUMBER($U$11),ISNUMBER($O$11)),$O$11+$S$11*0.5*$U$11,"") | AB11: =IF(AND(ISNUMBER($U$11),ISNUMBER($O$11)),$O$11+$S$11*0.75*$U$11,"") | AC11: =IF(AND(ISNUMBER($U$11),ISNUMBER($O$11)),$O$11+$S$11*1.0*$U$11,"") | AD11: =IF(AND(ISNUMBER($AC$11),ISNUMBER($Y$11)),$AC$11/$Y$11,"") | AE11: C#: Sim/Modes/ConquestMode.cs:64; Sim/Economy/EconomySystem.cs:27; Game/Match/ModeSessions.cs:480; Game/Match/ModeSessions.cs:473; Sim/AI/ConquestAi.cs:68
