Workbook

Sheet Chuong
A1: id | B1: maps | C1: main | D1: minis | E1: general | F1: tep_thoai_chuong | G1: tep_thoai | H1: so_cau_thoai | I1: act | J1: comic | K1: interlude | L1: number | M1: nguon | N1: raw_json
A2: 1 | B2: landingbeach;greenvale;ashfield | C2: fortress_bastion | D2: bastion_mk0 | E2: brandt | F2: 1 | G2: ch01.json | H2: 82 | I2: 1 | J2: comic.1 | L2: 1 | M2: Assets/MachineBrigade/Resources/Data/campaign.json: chapters[0] | N2: {"number":1,"act":1,"maps":["landingbeach","greenvale","ashfield"],"general":"brandt","main":"fortress_bastion","minis":["bastion_mk0"],"comic":"comic.1"}
A3: 2 | B3: dunebreak;redrock | C3: behemoth | D3: behemoth_inferno | E3: varga | F3: 2 | G3: ch02.json | H3: 108 | I3: 1 | J3: comic.2 | L3: 2 | M3: Assets/MachineBrigade/Resources/Data/campaign.json: chapters[1] | N3: {"number":2,"act":1,"maps":["dunebreak","redrock"],"general":"varga","main":"behemoth","minis":["behemoth_inferno"],"comic":"comic.2"}
A4: 3 | B4: whiteout;frostpeak | C4: mobile_fortress | D4: mega_gunship;fenrir | E4: orlov | F4: 3 | G4: ch03.json | H4: 111 | I4: 1 | J4: comic.3 | L4: 3 | M4: Assets/MachineBrigade/Resources/Data/campaign.json: chapters[2] | N4: {"number":3,"act":1,"maps":["whiteout","frostpeak"],"general":"orlov","main":"mobile_fortress","minis":["mega_gunship","fenrir"],"comic":"comic.3"}
A5: 4 | B5: rustyard;ironport;lighthousebay | C5: leviathan | D5: behemoth_tempest;armored_train;scylla | E5: kessler | F5: 4 | G5: ch04.json | H5: 164 | I5: 2 | J5: comic.4 | L5: 4 | M5: Assets/MachineBrigade/Resources/Data/campaign.json: chapters[4] | N5: {"number":4,"act":2,"maps":["rustyard","ironport","lighthousebay"],"general":"kessler","main":"leviathan","minis":["behemoth_tempest","armored_train","scylla"],"comic":"comic.4"}
A6: 5 | B6: junglepass;emberridge | C6: drone_mothership | D6: locust | E6: sen | F6: 5 | G6: ch05.json | H6: 121 | I6: 2 | J6: comic.5 | L6: 5 | M6: Assets/MachineBrigade/Resources/Data/campaign.json: chapters[5] | N6: {"number":5,"act":2,"maps":["junglepass","emberridge"],"general":"sen","main":"drone_mothership","minis":["locust"],"comic":"comic.5"}
A7: 6 | B7: ashfield;whiteout;greenvale;landingbeach;hydrodam | C7: moloch | D7: landing_hovercraft;behemoth_mk2 | E7: varga | F7: 6 | G7: ch06.json | H7: 153 | I7: 2 | J7: comic.6 | L7: 6 | M7: Assets/MachineBrigade/Resources/Data/campaign.json: chapters[6] | N7: {"number":6,"act":2,"maps":["ashfield","whiteout","greenvale","landingbeach","hydrodam"],"general":"varga","main":"moloch","minis":["landing_hovercraft","behemoth_mk2"],"comic":"comic.6"}
A8: 7 | B8: metrocity;veyra_old_quarter;capital | C8: nuke_train | D8: behemoth_mk2;behemoth_inferno;armored_train | E8: hung | F8: 7 | G8: ch07.json | H8: 149 | I8: 3 | J8: comic.7 | L8: 7 | M8: Assets/MachineBrigade/Resources/Data/campaign.json: chapters[8] | N8: {"number":7,"act":3,"maps":["metrocity","veyra_old_quarter","capital"],"general":"hung","main":"nuke_train","minis":["behemoth_mk2","behemoth_inferno","armored_train"],"comic":"comic.7"}
A9: 8 | B9: redrock;openpit;hydrodam;dunebreak | C9: moloch | D9: ixion;earth_borer | E9: hung | F9: 8 | G9: ch08.json | H9: 129 | I9: 3 | J9: comic.8 | L9: 8 | M9: Assets/MachineBrigade/Resources/Data/campaign.json: chapters[9] | N9: {"number":8,"act":3,"maps":["redrock","openpit","hydrodam","dunebreak"],"general":"hung","main":"moloch","minis":["ixion","earth_borer"],"comic":"comic.8"}
A10: 9 | B10: ironport;landingbeach;lighthousebay;coralisles | C10: typhon | D10: landing_hovercraft;scylla | E10: hung | F10: 9 | G10: ch09.json | H10: 131 | I10: 3 | J10: comic.9 | L10: 9 | M10: Assets/MachineBrigade/Resources/Data/campaign.json: chapters[10] | N10: {"number":9,"act":3,"maps":["ironport","landingbeach","lighthousebay","coralisles"],"general":"hung","main":"typhon","minis":["landing_hovercraft","scylla"],"comic":"comic.9"}
A11: 10 | B11: frostpeak;skyhold;whiteout | C11: command_airship | D11: icarus_mk0;argus;mega_gunship | E11: quaden | F11: 10 | G11: ch10.json | H11: 134 | I11: 4 | J11: comic.10 | L11: 10 | M11: Assets/MachineBrigade/Resources/Data/campaign.json: chapters[12] | N11: {"number":10,"act":4,"maps":["frostpeak","skyhold","whiteout"],"general":"quaden","main":"command_airship","minis":["icarus_mk0","argus","mega_gunship"],"comic":"comic.10"}
A12: 11 | B12: rustyard;skyhold;frostpeak;orbitalgate | C12: daedalus | D12: monster;locust | E12: aurel | F12: 11 | G12: ch11.json | H12: 120 | I12: 4 | J12: comic.11 | L12: 11 | M12: Assets/MachineBrigade/Resources/Data/campaign.json: chapters[13] | N12: {"number":11,"act":4,"maps":["rustyard","skyhold","frostpeak","orbitalgate"],"general":"aurel","main":"daedalus","minis":["monster","locust"],"comic":"comic.11"}
A13: 12 | B13: launchsite;saltflat;dunebreak;lighthousebay | C13: silver_bug | D13: behemoth_mk2;scylla;locust | E13: aurel | F13: 12 | G13: ch12.json | H13: 93 | I13: 4 | J13: comic.12 | L13: 12 | M13: Assets/MachineBrigade/Resources/Data/campaign.json: chapters[14] | N13: {"number":12,"act":4,"maps":["launchsite","saltflat","dunebreak","lighthousebay"],"general":"aurel","main":"silver_bug","minis":["behemoth_mk2","scylla","locust"],"comic":"comic.12"}
A14: 13 | B14: foundry | D14: behemoth_mk0 | E14: varga | F14: 13 | G14: ch13.json | H14: 35 | I14: 1 | J14: comic.13 | K14: 1 | L14: 13 | M14: Assets/MachineBrigade/Resources/Data/campaign.json: chapters[3] | N14: {"number":13,"act":1,"interlude":1,"maps":["foundry"],"general":"varga","minis":["behemoth_mk0"],"comic":"comic.13"}
A15: 14 | B15: swamp;borderbridge | D15: locust | F15: 14 | G15: ch14.json | H15: 44 | I15: 2 | J15: comic.14 | K15: 2 | L15: 14 | M15: Assets/MachineBrigade/Resources/Data/campaign.json: chapters[7] | N15: {"number":14,"act":2,"interlude":2,"maps":["swamp","borderbridge"],"minis":["locust"],"comic":"comic.14"}
A16: 15 | B16: frostpeak;junglepass | D16: mega_gunship | E16: quaden | F16: 15 | G16: ch15.json | H16: 40 | I16: 3 | J16: comic.15 | K16: 3 | L16: 15 | M16: Assets/MachineBrigade/Resources/Data/campaign.json: chapters[11] | N16: {"number":15,"act":3,"interlude":3,"maps":["frostpeak","junglepass"],"general":"quaden","minis":["mega_gunship"],"comic":"comic.15"}

Sheet Nhiem_vu
A1: id | B1: chapter | C1: map | D1: general | E1: enemy_deck | F1: unlocks | G1: after | H1: boss_def | I1: nguoi_noi_chinh | J1: bo_bai_game | K1: so_cau_thoai | L1: trang_thai_kich_ban | M1: ally_heading_deg | N1: ally_hq | O1: ally_x_m | P1: ally_z_m | Q1: awaits | R1: boss_fallback | S1: boss_fallback_health | T1: boss_flee_at | U1: boss_heading_deg | V1: boss_health | W1: boss_name | X1: boss_route | Y1: boss_x_m | Z1: boss_z_m | AA1: branch | AB1: challenge_kind | AC1: challenge_value | AD1: coins | AE1: commander | AF1: convoy_count | AG1: convoy_def | AH1: convoy_heading_deg | AI1: convoy_health | AJ1: convoy_interval_s | AK1: convoy_needed | AL1: convoy_route | AM1: convoy_x_m | AN1: convoy_z_m | AO1: difficulty | AP1: enemy_ai | AQ1: enemy_base | AR1: enemy_cp | AS1: enemy_hq | AT1: enemy_income | AU1: enemy_owns | AV1: enemy_stance | AW1: goal | AX1: hold_seconds_s | AY1: hq_level | AZ1: kills_needed | BA1: launch_seconds_s | BB1: legacy | BC1: operation | BD1: option | BE1: outposts | BF1: play_area_max_x | BG1: play_area_max_z | BH1: play_area_min_x | BI1: play_area_min_z | BJ1: player_base | BK1: player_cap | BL1: player_cp | BM1: player_income | BN1: points | BO1: prints | BP1: protect_needed | BQ1: rare_prints | BR1: reinforcements | BS1: replay | BT1: reversed | BU1: set_piece | BV1: side | BW1: speaker | BX1: star_losses | BY1: star_time_s | BZ1: story_choice | CA1: survive_seconds_s | CB1: target_health | CC1: target_radius | CD1: target_x | CE1: target_z | CF1: targets | CG1: time_limit_s | CH1: tower_gear | CI1: variant | CJ1: waves_first | CK1: waves_grow | CL1: waves_interval_s | CM1: waves_max_alive | CN1: waves_max_size | CO1: waves_roster | CP1: waves_size | CQ1: waves_spawns | CR1: weather | CS1: xp | CT1: nguon | CU1: raw_json
A2: c1m01 | B2: 1 | C2: landingbeach | E2: scout_jeep;armored_car | F2: rocket_technical | I2: khai | J2: TRUE | K2: 8 | L2: co_kich_ban | AB2: Kills | AC2: 8 | AD2: 100 | AO2: Easy | AP2: commander | AR2: 8 | AT2: 0.45 | AV2: Defend | AW2: Capture | BL2: 22 | BM2: 1.3 | BN2: east;town | BO2: 1 | BR2: 0 | BU2: TRUE | BX2: 4 | BY2: 300 | CR2: Clear | CS2: 80 | CT2: Assets/MachineBrigade/Resources/Data/campaign.json: missions[0] | CU2: {"id":"c1m01","chapter":1,"map":"landingbeach","weather":"Clear","goal":"Capture","points":["east","town"],"reinforcements":0,"enemyAi":"commander","enemyStance":"Defend","difficulty":"Easy","enemyCp":8,"enemyIncome":0.45,"enemyDeck":["scout_jeep","armored_car"],"playerCp":22,"playerIncome":1.3,"tips":[{"at":2,"key":"tip.auto"},{"at":9,"key":"tip.deploy"},{"at":16,"key":"tip.points"},{"at":24,"key":"tip.strike"},{"at":33,"key":"tip.select"},{"at":43,"key":"tip.counters"},{"at":54,"key":"tip.items"}],"starTime":300,"starLosses":4,"challenge":{"kind":"Kills","value":8},"radio":[{"key":"radio.khai.c1m01.1","on":"Start"},{"key":"radio.dieuhau.c1m01.2","on":"Capture","arg":"east"},{"key":"radio.khai.c1m01.3","on":"Win"}],"unlocks":["rocket_technical"],"setPiece":true,"missionEvents":[{"id":"landing_assault","params":{"size":4}},"accord_landing",{"id":"enemy_barrage","trigger":{"at":90,"every":80,"times":4},"params":{"salvos":2,"radius":16}},"tide_turn"],"fixedDeck":{"vehicleIds":["recoilless_jeep","light_tank","armored_car","rocket_technical","mortar_carrier","ifv","main_battle_tank","scout_jeep"],"supportIds":["repair_drop","artillery_barrage"],"placedAllies":[],"loanedCards":["recoilless_jeep","light_tank","rocket_technical","mortar_carrier"],"specialRules":["noBaseStart","beachLanding","coastalGuns"],"status":"MAKE_FIRST"},"navStates":[{"id":"shoal","initial":"low","states":[{"name":"low"},{"name":"high","blocks":[{"x":66,"z":-130,"w":152,"d":12}]}]}],"coins":100,"xp":80,"prints":1}
A3: c1m02 | B3: 1 | C3: landingbeach | E3: scout_jeep;armored_car;light_tank;rocket_technical;ifv | F3: mortar_carrier | I3: linh | J3: FALSE | K3: 7 | L3: co_kich_ban | AB3: NoStrikes | AD3: 105 | AO3: Easy | AP3: commander | AR3: 10 | AT3: 0.7 | AV3: Defend | AW3: Destroy | BL3: 20 | BM3: 1.3 | BO3: 1 | BR3: 1 | BY3: 420 | CB3: 3 | CF3: radar_station_prop | CG3: 900 | CR3: Overcast | CS3: 85 | CT3: Assets/MachineBrigade/Resources/Data/campaign.json: missions[1] | CU3: {"id":"c1m02","chapter":1,"map":"landingbeach","weather":"Overcast","goal":"Destroy","targets":["radar_station_prop"],"targetHealth":3,"timeLimit":900,"reinforcements":1,"enemyAi":"commander","enemyStance":"Defend","difficulty":"Easy","enemyCp":10,"enemyIncome":0.7,"enemyDeck":["scout_jeep","armored_car","light_tank","rocket_technical","ifv"],"playerCp":20,"playerIncome":1.3,"starTime":420,"challenge":{"kind":"NoStrikes"},"radio":[{"key":"radio.linh.c1m02.1","on":"Start"},{"key":"radio.khai.c1m02.2","on":"Win"}],"unlocks":["mortar_carrier"],"missionEvents":["landing_assault","nadia_intel","rain_sets_in"],"coins":105,"xp":85,"prints":1}
A4: c1m03 | B4: 1 | C4: greenvale | E4: scout_jeep;armored_car;light_tank | F4: light_tank | I4: linh | J4: FALSE | K4: 7 | L4: co_kich_ban | AD4: 105 | AO4: Easy | AP4: commander | AR4: 9 | AT4: 0.55 | AV4: Defend | AW4: Capture | BB4: m00 | BL4: 22 | BM4: 1.3 | BN4: west;town;east | BO4: 1 | BR4: 0 | BX4: 5 | BY4: 360 | CR4: Clear | CS4: 85 | CT4: Assets/MachineBrigade/Resources/Data/campaign.json: missions[2] | CU4: {"id":"c1m03","chapter":1,"map":"greenvale","weather":"Clear","goal":"Capture","legacy":"m00","points":["west","town","east"],"reinforcements":0,"enemyAi":"commander","enemyStance":"Defend","difficulty":"Easy","enemyCp":9,"enemyIncome":0.55,"enemyDeck":["scout_jeep","armored_car","light_tank"],"playerCp":22,"playerIncome":1.3,"starTime":360,"starLosses":5,"radio":[{"key":"radio.khai.c1m03.1","on":"Start"},{"key":"radio.linh.c1m03.2","on":"Capture","arg":"town"},{"key":"radio.khai.c1m03.q1","on":"Win"}],"unlocks":["light_tank"],"missionEvents":["enemy_wave","loot_drop","accord_wave"],"coins":105,"xp":85,"prints":1}
A5: c1m04 | B5: 1 | C5: greenvale | E5: scout_jeep;armored_car;light_tank;rocket_technical;ifv | F5: rocket_turret;repair_bay | I5: mai | J5: FALSE | K5: 7 | L5: co_kich_ban | AD5: 110 | AO5: Easy | AP5: both | AR5: 8 | AT5: 0.6 | AV5: Attack | AW5: Outpost | AX5: 150 | AY5: 1 | BL5: 24 | BM5: 1.4 | BN5: town | BO5: 1 | BR5: 1 | BW5: mai | BX5: 6 | BY5: 480 | CG5: 1000 | CJ5: 60 | CK5: 0.3 | CL5: 55 | CM5: 10 | CN5: 4 | CO5: armored_car;light_tank;rocket_technical | CP5: 2 | CQ5: 90;60;60;95;100;20 | CR5: Overcast | CS5: 90 | CT5: Assets/MachineBrigade/Resources/Data/campaign.json: missions[3] | CU5: {"id":"c1m04","chapter":1,"map":"greenvale","weather":"Overcast","goal":"Outpost","points":["town"],"holdSeconds":150,"speaker":"mai","reinforcements":1,"timeLimit":1000,"enemyAi":"both","enemyStance":"Attack","difficulty":"Easy","enemyCp":8,"enemyIncome":0.6,"enemyDeck":["scout_jeep","armored_car","light_tank","rocket_technical","ifv"],"playerCp":24,"playerIncome":1.4,"waves":{"first":60,"interval":55,"size":2,"grow":0.3,"maxSize":4,"maxAlive":10,"roster":["armored_car","light_tank","rocket_technical"],"spawns":[90,60,60,95,100,20]},"starTime":480,"starLosses":6,"radio":[{"key":"radio.mai.c1m04.1","on":"Start"},{"key":"radio.mai.c1m04.2","on":"Capture","arg":"town"},{"key":"radio.mai.c1m04.3","on":"Win"}],"unlocks":["rocket_turret","repair_bay"],"hqLevel":1,"missionEvents":["enemy_wave_late","supply_drop","rain_sets_in"],"coins":110,"xp":90,"prints":1}
A6: c1m05 | B6: 1 | C6: greenvale | E6: armored_car;light_tank;ifv;main_battle_tank;mortar_carrier;rocket_technical | F6: engineer_vehicle | H6: bastion_mk0 | I6: mai | J6: FALSE | K6: 13 | L6: co_kich_ban | R6: fortress_bastion | S6: 0.55 | U6: 225 | W6: bastion_mk0 | X6: 55;55;20;25;-15;-5 | Y6: 84 | Z6: 84 | AD6: 170 | AO6: Normal | AP6: commander | AR6: 10 | AT6: 0.8 | AV6: Attack | AW6: Boss | BJ6: Anchor | BL6: 24 | BM6: 1.4 | BO6: 1 | BR6: 2 | BX6: 8 | BY6: 600 | CG6: 1140 | CR6: Night | CS6: 135 | CT6: Assets/MachineBrigade/Resources/Data/campaign.json: missions[4] | CU6: {"id":"c1m05","chapter":1,"map":"greenvale","weather":"Night","goal":"Boss","timeLimit":1140,"reinforcements":2,"boss":{"def":"bastion_mk0","x":84,"z":84,"heading":225,"route":[55,55,20,25,-15,-5],"fallback":"fortress_bastion","fallbackHealth":0.55,"name":"bastion_mk0"},"enemyAi":"commander","enemyStance":"Attack","difficulty":"Normal","enemyCp":10,"enemyIncome":0.8,"enemyDeck":["armored_car","light_tank","ifv","main_battle_tank","mortar_carrier","rocket_technical"],"playerCp":24,"playerIncome":1.4,"playerBase":"Anchor","starTime":600,"starLosses":8,"radio":[{"key":"radio.linh.c1m05.1","on":"Start"},{"key":"radio.khai.c1m05.2","on":"Win"}],"missionEvents":["accord_artillery","loot_repair"],"unlocks":["engineer_vehicle"],"coins":170,"xp":135,"prints":1}
A7: c1m06 | B7: 1 | C7: greenvale | F7: zu23_technical | I7: khai | J7: FALSE | K7: 7 | L7: co_kich_ban | AB7: Kills | AC7: 15 | AD7: 115 | AF7: 5 | AG7: supply_truck | AH7: 45 | AK7: 3 | AL7: -78.75;-78.75;-78.75;0;0;0;0;86.25;-60;86.25 | AM7: -100 | AN7: -100 | AO7: Easy | AP7: waves | AW7: Escort | BJ7: Anchor | BO7: 1 | BR7: 1 | BX7: 5 | BY7: 300 | CG7: 1000 | CJ7: 15 | CK7: 0.4 | CL7: 28 | CM7: 11 | CN7: 5 | CO7: armored_car;rocket_technical;light_tank;ifv | CP7: 2 | CQ7: 20;110;95;40;60;90;-10;60 | CR7: Rain | CS7: 95 | CT7: Assets/MachineBrigade/Resources/Data/campaign.json: missions[5] | CU7: {"id":"c1m06","chapter":1,"map":"greenvale","weather":"Rain","goal":"Escort","convoyCount":5,"convoyNeeded":3,"reinforcements":1,"timeLimit":1000,"convoy":{"def":"supply_truck","x":-100,"z":-100,"heading":45,"route":[-78.75,-78.75,-78.75,0,0,0,0,86.25,-60,86.25]},"units":[{"def":"light_tank","team":0,"x":-85.0,"z":-88.0,"heading":45},{"def":"ifv","team":0,"x":-92.5,"z":-83.67,"heading":45},{"def":"main_battle_tank","team":0,"x":-92.5,"z":-92.33,"heading":45}],"enemyAi":"waves","difficulty":"Easy","waves":{"first":15,"interval":28,"size":2,"grow":0.4,"maxSize":5,"maxAlive":11,"roster":["armored_car","rocket_technical","light_tank","ifv"],"spawns":[20,110,95,40,60,90,-10,60]},"playerBase":"Anchor","starTime":300,"starLosses":5,"challenge":{"kind":"Kills","value":15},"radio":[{"key":"radio.khai.c1m06.1","on":"Start"},{"key":"radio.linh.c1m06.2","at":60}],"unlocks":["zu23_technical"],"missionEvents":["enemy_barrage","accord_relief","skies_clear"],"coins":115,"xp":95,"prints":1}
A8: c1m08 | B8: 1 | C8: ashfield | E8: armored_car;light_tank;ifv;main_battle_tank;mortar_carrier;rocket_technical | I8: linh | J8: FALSE | K8: 7 | L8: co_kich_ban | AB8: NoStrikes | AD8: 120 | AO8: Normal | AP8: commander | AR8: 11 | AT8: 0.8 | AV8: Attack | AW8: Capture | BB8: m01 | BJ8: Anchor | BL8: 22 | BM8: 1.3 | BN8: west;town;east | BO8: 1 | BR8: 1 | BX8: 6 | BY8: 480 | CR8: Clear | CS8: 95 | CT8: Assets/MachineBrigade/Resources/Data/campaign.json: missions[6] | CU8: {"id":"c1m08","chapter":1,"map":"ashfield","weather":"Clear","goal":"Capture","legacy":"m01","points":["west","town","east"],"reinforcements":1,"enemyAi":"commander","enemyStance":"Attack","difficulty":"Normal","enemyCp":11,"enemyIncome":0.8,"enemyDeck":["armored_car","light_tank","ifv","main_battle_tank","mortar_carrier","rocket_technical"],"playerCp":22,"playerIncome":1.3,"playerBase":"Anchor","starTime":480,"starLosses":6,"challenge":{"kind":"NoStrikes"},"radio":[{"key":"radio.khai.c1m08.1","on":"Start"},{"key":"radio.linh.c1m08.2","on":"Lost"}],"missionEvents":[{"id":"general_field","params":{"general":"brandt"}},{"id":"intercept_files","reward":{"intel":"c1.inspection"}},"enemy_wave"],"coins":120,"xp":95,"prints":1}
A9: c1m09 | B9: 1 | C9: ashfield | I9: khai | J9: FALSE | K9: 7 | L9: co_kich_ban | AB9: Kills | AC9: 18 | AD9: 125 | AF9: 5 | AG9: supply_truck | AH9: 45 | AK9: 3 | AL9: -78.75;-78.75;0;-78.75;78.75;-78.75;78.75;0;31.8;0;7.5;0 | AM9: -105 | AN9: -105 | AO9: Normal | AP9: waves | AW9: Escort | BB9: m02 | BJ9: Anchor | BO9: 1 | BR9: 1 | BX9: 5 | BY9: 300 | CG9: 1000 | CJ9: 12 | CK9: 0.45 | CL9: 26 | CM9: 11 | CN9: 5 | CO9: scout_jeep;armored_car;rocket_technical;light_tank;mortar_carrier | CP9: 2 | CQ9: 15;-108;93;-45;93;30;45;45;-45;21 | CR9: Overcast | CS9: 100 | CT9: Assets/MachineBrigade/Resources/Data/campaign.json: missions[7] | CU9: {"id":"c1m09","chapter":1,"map":"ashfield","weather":"Overcast","goal":"Escort","legacy":"m02","convoyCount":5,"convoyNeeded":3,"reinforcements":1,"timeLimit":1000,"convoy":{"def":"supply_truck","x":-105,"z":-105,"heading":45,"route":[-78.75,-78.75,0,-78.75,78.75,-78.75,78.75,0,31.8,0,7.5,0]},"units":[{"def":"light_tank","team":0,"x":-84.0,"z":-90.0,"heading":45},{"def":"light_tank","team":0,"x":-93.0,"z":-84.8,"heading":45},{"def":"ifv","team":0,"x":-93.0,"z":-95.2,"heading":45}],"enemyAi":"waves","difficulty":"Normal","waves":{"first":12,"interval":26,"size":2,"grow":0.45,"maxSize":5,"maxAlive":11,"roster":["scout_jeep","armored_car","rocket_technical","light_tank","mortar_carrier"],"spawns":[15,-108,93,-45,93,30,45,45,-45,21]},"playerBase":"Anchor","starTime":300,"starLosses":5,"challenge":{"kind":"Kills","value":18},"radio":[{"key":"radio.khai.c1m09.1","on":"Start"}],"missionEvents":["enemy_air_raid","accord_wave","sea_fog"],"coins":125,"xp":100,"prints":1}
A10: c1m10 | B10: 1 | C10: ashfield | E10: armored_car;light_tank;ifv;main_battle_tank;mortar_carrier;rocket_technical | I10: khai | J10: FALSE | K10: 14 | L10: co_kich_ban | AD10: 305 | AO10: Normal | AP10: both | AR10: 12 | AS10: 2 | AT10: 0.85 | AV10: Defend | AW10: Destroy | BC10: TRUE | BJ10: Anchor | BK10: 42 | BL10: 30 | BM10: 2 | BO10: 2 | BR10: 2 | BX10: 16 | BY10: 1320 | CI10: siege | CJ10: 70 | CK10: 0.3 | CL10: 60 | CM10: 12 | CN10: 5 | CO10: light_tank;main_battle_tank;ifv;mortar_carrier;rocket_technical | CP10: 2 | CQ10: 100;60;60;100;80;80 | CR10: Fog | CS10: 245 | CT10: Assets/MachineBrigade/Resources/Data/campaign.json: missions[8] | CU10: {"id":"c1m10","chapter":1,"map":"ashfield","variant":"siege","weather":"Fog","goal":"Destroy","operation":true,"reinforcements":2,"enemyAi":"both","enemyStance":"Defend","difficulty":"Normal","enemyCp":12,"enemyIncome":0.85,"enemyDeck":["armored_car","light_tank","ifv","main_battle_tank","mortar_carrier","rocket_technical"],"playerCp":30,"playerIncome":2.0,"playerCap":42,"playerBase":"Anchor","enemyHq":2,"stages":[{"stage":"depot","goal":"Destroy","targets":["fuel_tank"],"targetX":56.25,"targetZ":-97,"targetRadius":25,"targetHealth":2,"cp":8,"events":[{"at":"start","kind":"Radio","key":"radio.khai.c1m10.s1"}],"choices":[{"key":"dump","next":"dump"},{"key":"radar","next":"radar"}],"missionEvents":["enemy_wave"]},{"stage":"dump","goal":"Destroy","targets":["ammo_dump"],"targetHealth":2,"cp":6,"next":"bastion","events":[{"at":"end","kind":"Income","team":1,"amount":0.7},{"at":"end","kind":"Radio","key":"radio.enemyWeakened"}]},{"stage":"radar","goal":"Destroy","targets":["radar_station_prop"],"targetHealth":2,"cp":6,"next":"bastion","events":[{"at":"end","kind":"Strike","team":0,"support":"airstrike","every":55},{"at":"end","kind":"Radio","key":"radio.alliedStrikes"}]},{"stage":"bastion","goal":"Boss","boss":{"def":"fortress_bastion","x":92,"z":92,"heading":225,"health":0.55},"cp":10,"events":[{"at":"start","kind":"Radio","key":"radio.mai.c1m10.s3"}],"missionEvents":["accord_artillery"]},{"stage":"counter","goal":"Survive","surviveSeconds":240,"cp":8,"events":[{"at":"start","kind":"Radio","key":"radio.khai.c1m10.s4"},{"at":"30","kind":"Reinforce","team":1,"units":["main_battle_tank","ifv","mortar_carrier","light_tank"]},{"at":"140","kind":"Reinforce","team":1,"units":["main_battle_tank","rocket_technical","ifv"]}],"missionEvents":["enemy_counterattack","accord_landing"]},{"stage":"hq","goal":"Destroy","targets":["command_hq"],"targetHealth":0.8,"events":[{"at":"start","kind":"Reinforce","team":1,"units":["main_battle_tank","ifv","mortar_carrier"]}]}],"waves":{"first":70,"interval":60,"size":2,"grow":0.3,"maxSize":5,"maxAlive":12,"roster":["light_tank","main_battle_tank","ifv","mortar_carrier","rocket_technical"],"spawns":[100,60,60,100,80,80]},"starTime":1320,"starLosses":16,"radio":[{"key":"radio.khai.c1m10.1","on":"Start"},{"key":"radio.khai.c1m10.2","on":"Win"},{"key":"radio.brandt.c1m10.q1","on":"Win"},{"key":"radio.linh.c1m10.q2","on":"Win"}],"missionEvents":["hawk_strike","supply_drop"],"coins":305,"xp":245,"prints":2}
A11: c1s1 | B11: 1 | C11: greenvale | E11: scout_jeep;armored_car;light_tank;rocket_technical;ifv | G11: c1m03 | I11: linh | J11: FALSE | K11: 5 | L11: co_kich_ban | AD11: 350 | AO11: Easy | AP11: commander | AR11: 10 | AT11: 0.7 | AV11: Defend | AW11: Recon | BL11: 22 | BM11: 1.3 | BN11: west;town;east | BO11: 1 | BQ11: 18 | BR11: 1 | BV11: TRUE | BW11: linh | BX11: 5 | BY11: 360 | CG11: 840 | CR11: Fog | CS11: 280 | CT11: Assets/MachineBrigade/Resources/Data/campaign.json: missions[9] | CU11: {"id":"c1s1","chapter":1,"side":true,"after":"c1m03","map":"greenvale","weather":"Fog","goal":"Recon","speaker":"linh","points":["west","town","east"],"timeLimit":840,"reinforcements":1,"enemyAi":"commander","enemyStance":"Defend","difficulty":"Easy","enemyCp":10,"enemyIncome":0.7,"enemyDeck":["scout_jeep","armored_car","light_tank","rocket_technical","ifv"],"playerCp":22,"playerIncome":1.3,"rarePrints":18,"starTime":360,"starLosses":5,"radio":[{"key":"radio.linh.c1s1.1","on":"Start"}],"missionEvents":["nadia_intel","skies_clear"],"coins":350,"xp":280,"prints":1}
A12: c2m01 | B12: 2 | C12: dunebreak | D12: varga | F12: aa_vehicle | I12: khai | J12: FALSE | K12: 8 | L12: co_kich_ban | AB12: NoAircraft | AD12: 130 | AO12: Normal | AP12: waves | AW12: Survive | BB12: m04 | BJ12: Anchor | BL12: 20 | BM12: 1.3 | BN12: east | BO12: 1 | BX12: 8 | BY12: 0 | CA12: 300 | CJ12: 18 | CK12: 0.6 | CL12: 30 | CM12: 16 | CN12: 8 | CO12: rocket_technical;armored_car;light_tank;mortar_carrier;ifv | CP12: 3 | CQ12: 93;-15;75;33;27;-114 | CR12: Clear | CS12: 105 | CT12: Assets/MachineBrigade/Resources/Data/campaign.json: missions[10] | CU12: {"id":"c2m01","chapter":2,"map":"dunebreak","weather":"Clear","goal":"Survive","legacy":"m04","surviveSeconds":300,"points":["east"],"general":"varga","enemyAi":"waves","difficulty":"Normal","playerCp":20,"playerIncome":1.3,"waves":{"first":18,"interval":30,"size":3,"grow":0.6,"maxSize":8,"maxAlive":16,"roster":["rocket_technical","armored_car","light_tank","mortar_carrier","ifv"],"spawns":[93,-15,75,33,27,-114]},"playerBase":"Anchor","starTime":0,"starLosses":8,"challenge":{"kind":"NoAircraft"},"radio":[{"key":"radio.khai.c2m01.1","on":"Start"},{"key":"radio.varga.c2m01.q1","at":15}],"missionEvents":["oil_convoy","enemy_wave","sandstorm"],"unlocks":["aa_vehicle"],"coins":130,"xp":105,"prints":1}
A13: c2m02 | B13: 2 | C13: redrock | D13: varga | E13: armored_car;light_tank;main_battle_tank;ifv;tank_destroyer;mortar_carrier | F13: artillery | I13: linh | J13: FALSE | K13: 7 | L13: co_kich_ban | AD13: 135 | AO13: Normal | AP13: commander | AR13: 13 | AT13: 0.85 | AU13: town | AV13: Defend | AW13: Capture | BJ13: Anchor | BL13: 24 | BM13: 1.4 | BN13: west;town;east | BO13: 1 | BR13: 2 | BX13: 8 | BY13: 540 | CR13: Clear | CS13: 105 | CT13: Assets/MachineBrigade/Resources/Data/campaign.json: missions[11] | CU13: {"id":"c2m02","chapter":2,"map":"redrock","weather":"Clear","goal":"Capture","points":["west","town","east"],"enemyOwns":["town"],"general":"varga","reinforcements":2,"enemyAi":"commander","enemyStance":"Defend","difficulty":"Normal","enemyCp":13,"enemyIncome":0.85,"enemyDeck":["armored_car","light_tank","main_battle_tank","ifv","tank_destroyer","mortar_carrier"],"playerCp":24,"playerIncome":1.4,"playerBase":"Anchor","starTime":540,"starLosses":8,"radio":[{"key":"radio.linh.c2m02.1","on":"Start"},{"key":"radio.varga.c2m02.2","on":"Capture","arg":"town"}],"missionEvents":["enemy_wave_late","loot_drop","accord_wave"],"unlocks":["artillery"],"coins":135,"xp":105,"prints":1}
A14: c2m03 | B14: 2 | C14: redrock | F14: flame_tank | I14: khai | J14: FALSE | K14: 7 | L14: co_kich_ban | AB14: Kills | AC14: 18 | AD14: 135 | AF14: 5 | AG14: supply_truck | AH14: 45 | AK14: 3 | AL14: -78;-65;-34;-45;-20;-20;0;0;-30;40;-56.25;86.25 | AM14: -100 | AN14: -100 | AO14: Normal | AP14: waves | AW14: Escort | BO14: 1 | BR14: 1 | BX14: 6 | BY14: 360 | CG14: 1000 | CJ14: 20 | CK14: 0.5 | CL14: 28 | CM14: 13 | CN14: 6 | CO14: armored_car;rocket_technical;light_tank;tank_destroyer;mortar_carrier | CP14: 2 | CQ14: 60;80;90;20;20;110;-60;110 | CR14: Night | CS14: 110 | CT14: Assets/MachineBrigade/Resources/Data/campaign.json: missions[12] | CU14: {"id":"c2m03","chapter":2,"map":"redrock","weather":"Night","goal":"Escort","convoyCount":5,"convoyNeeded":3,"reinforcements":1,"timeLimit":1000,"convoy":{"def":"supply_truck","x":-100,"z":-100,"heading":45,"route":[-78,-65,-34,-45,-20,-20,0,0,-30,40,-56.25,86.25]},"units":[{"def":"main_battle_tank","team":0,"x":-82.0,"z":-92.0,"heading":45},{"def":"ifv","team":0,"x":-91.0,"z":-86.8,"heading":45},{"def":"aa_vehicle","team":0,"x":-91.0,"z":-97.2,"heading":45}],"enemyAi":"waves","difficulty":"Normal","waves":{"first":20,"interval":28,"size":2,"grow":0.5,"maxSize":6,"maxAlive":13,"roster":["armored_car","rocket_technical","light_tank","tank_destroyer","mortar_carrier"],"spawns":[60,80,90,20,20,110,-60,110]},"starTime":360,"starLosses":6,"challenge":{"kind":"Kills","value":18},"radio":[{"key":"radio.khai.c2m03.1","on":"Start"}],"unlocks":["flame_tank"],"missionEvents":["neutral_convoy","enemy_barrage"],"coins":135,"xp":110,"prints":1}
A15: c2m04 | B15: 2 | C15: dunebreak | D15: varga | E15: armored_car;light_tank;main_battle_tank;ifv;tank_destroyer;mortar_carrier | F15: airstrike | I15: khai | J15: TRUE | K15: 8 | L15: co_kich_ban | AB15: NoStrikes | AD15: 140 | AO15: Normal | AP15: commander | AR15: 14 | AT15: 0.85 | AV15: Defend | AW15: Destroy | BL15: 24 | BM15: 1.4 | BO15: 1 | BR15: 2 | BX15: 8 | BY15: 480 | CB15: 2.5 | CF15: pipeline | CG15: 900 | CR15: Overcast | CS15: 110 | CT15: Assets/MachineBrigade/Resources/Data/campaign.json: missions[13] | CU15: {"id":"c2m04","chapter":2,"map":"dunebreak","weather":"Overcast","goal":"Destroy","targets":["pipeline"],"targetHealth":2.5,"timeLimit":900,"general":"varga","reinforcements":2,"units":[{"def":"main_battle_tank","team":1,"x":6.0,"z":30.0,"heading":225},{"def":"tank_destroyer","team":1,"x":-6.0,"z":30.0,"heading":225},{"def":"light_tank","team":1,"x":106.0,"z":-50.0,"heading":225},{"def":"ifv","team":1,"x":94.0,"z":-50.0,"heading":225}],"enemyAi":"commander","enemyStance":"Defend","difficulty":"Normal","enemyCp":14,"enemyIncome":0.85,"enemyDeck":["armored_car","light_tank","main_battle_tank","ifv","tank_destroyer","mortar_carrier"],"playerCp":24,"playerIncome":1.4,"starTime":480,"starLosses":8,"challenge":{"kind":"NoStrikes"},"radio":[{"key":"radio.khai.c2m04.1","on":"Start"},{"key":"radio.varga.c2m04.2","at":150}],"unlocks":["airstrike"],"missionEvents":["general_field",{"id":"intercept_files","reward":{"intel":"c2.order"}},"oil_convoy"],"fixedDeck":{"vehicleIds":["armored_car","scout_jeep","vbied","rocket_technical","ifv","light_tank","zu23_technical","demolition_line_vehicle"],"supportIds":["artillery_barrage","repair_drop"],"placedAllies":[],"loanedCards":["vbied","demolition_line_vehicle"],"specialRules":["raidNoBase"],"status":"MAKE_FIRST"},"coins":140,"xp":110,"prints":1}
A16: c2m05 | B16: 2 | C16: dunebreak | D16: varga | E16: armored_car;light_tank;main_battle_tank;ifv;tank_destroyer;mortar_carrier | F16: ammo_carrier | H16: behemoth_inferno | I16: mai | J16: FALSE | K16: 13 | L16: co_kich_ban | T16: 0.5 | U16: 225 | V16: 1.6 | W16: behemoth_inferno | Y16: 75 | Z16: 75 | AD16: 215 | AO16: Normal | AP16: commander | AR16: 11 | AT16: 0.85 | AV16: Attack | AW16: Boss | BB16: m06 | BJ16: Anchor | BK16: 36 | BL16: 26 | BM16: 1.45 | BO16: 2 | BR16: 3 | BX16: 10 | BY16: 720 | CG16: 1200 | CR16: Sandstorm | CS16: 170 | CT16: Assets/MachineBrigade/Resources/Data/campaign.json: missions[14] | CU16: {"id":"c2m05","chapter":2,"map":"dunebreak","weather":"Sandstorm","goal":"Boss","legacy":"m06","timeLimit":1200,"general":"varga","reinforcements":3,"boss":{"def":"behemoth_inferno","x":75,"z":75,"heading":225,"health":1.6,"name":"behemoth_inferno","fleeAt":0.5},"enemyAi":"commander","enemyStance":"Attack","difficulty":"Normal","enemyCp":11,"enemyIncome":0.85,"enemyDeck":["armored_car","light_tank","main_battle_tank","ifv","tank_destroyer","mortar_carrier"],"playerCp":26,"playerIncome":1.45,"playerCap":36,"playerBase":"Anchor","starTime":720,"starLosses":10,"radio":[{"key":"radio.varga.c2m05.q1","on":"Start"},{"key":"radio.mai.c2m05.q2","on":"Boss"},{"key":"radio.khai.c2m05.q3","on":"Win"}],"missionEvents":["hawk_strike","skies_clear"],"unlocks":["ammo_carrier"],"coins":215,"xp":170,"prints":2}
A17: c2m06 | B17: 2 | C17: redrock | D17: varga | E17: main_battle_tank;aa_vehicle;tank_destroyer;ifv;heavy_tank;mortar_carrier | F17: atgm_tower | I17: linh | J17: FALSE | K17: 7 | L17: co_kich_ban | AB17: Kills | AC17: 25 | AD17: 145 | AO17: Normal | AP17: commander | AR17: 14 | AT17: 0.85 | AV17: Defend | AW17: Hunt | BB17: m17 | BJ17: Anchor | BK17: 36 | BL17: 26 | BM17: 1.4 | BO17: 1 | BR17: 2 | BX17: 12 | BY17: 660 | CB17: 2.5 | CG17: 1100 | CR17: Sandstorm | CS17: 115 | CT17: Assets/MachineBrigade/Resources/Data/campaign.json: missions[15] | CU17: {"id":"c2m06","chapter":2,"map":"redrock","weather":"Sandstorm","goal":"Hunt","legacy":"m17","timeLimit":1100,"targetHealth":2.5,"general":"varga","reinforcements":2,"hunt":[{"def":"elite_mlrs","x":90,"z":45,"heading":225,"route":[60,82.5,22.5,60,52.5,22.5,90,45]},{"def":"elite_grad","x":-15,"z":105,"heading":180,"route":[-60,120,-37.5,75,-15,105]},{"def":"sam_launcher","x":105,"z":0,"heading":225,"route":[82.5,-37.5,120,-45,105,0]}],"units":[{"def":"tank_destroyer","team":1,"x":75,"z":52.5,"heading":225},{"def":"aa_vehicle","team":1,"x":82.5,"z":63,"heading":225},{"def":"main_battle_tank","team":1,"x":-7.5,"z":90,"heading":200},{"def":"tank_destroyer","team":1,"x":-27,"z":99,"heading":200},{"def":"heavy_tank","team":1,"x":93,"z":-12,"heading":225},{"def":"main_battle_tank","team":1,"x":108,"z":-21,"heading":225}],"enemyAi":"commander","enemyStance":"Defend","difficulty":"Normal","enemyCp":14,"enemyIncome":0.85,"enemyDeck":["main_battle_tank","aa_vehicle","tank_destroyer","ifv","heavy_tank","mortar_carrier"],"playerCp":26,"playerIncome":1.4,"playerCap":36,"playerBase":"Anchor","starTime":660,"starLosses":12,"challenge":{"kind":"Kills","value":25},"radio":[{"key":"radio.linh.c2m06.1","on":"Start"}],"unlocks":["atgm_tower"],"missionEvents":["thorne_support","enemy_wave","nadia_intel",{"id":"sandstorm_turn","params":{"sight":0.65,"clear":1.25}}],"coins":145,"xp":115,"prints":1}
A18: c2m07 | B18: 2 | C18: redrock | E18: armored_car;light_tank;main_battle_tank;ifv;tank_destroyer;mortar_carrier | F18: vbied | I18: khai | J18: FALSE | K18: 7 | L18: co_kich_ban | N18: headquarters | O18: 0 | P18: 0 | AD18: 150 | AO18: Normal | AP18: both | AR18: 10 | AT18: 0.75 | AV18: Attack | AW18: Relieve | BJ18: Anchor | BK18: 36 | BL18: 26 | BM18: 1.45 | BO18: 1 | BR18: 2 | BX18: 8 | BY18: 480 | CB18: 3 | CG18: 1000 | CJ18: 70 | CK18: 0.3 | CL18: 60 | CM18: 12 | CN18: 4 | CO18: light_tank;ifv;mortar_carrier;tank_destroyer | CP18: 2 | CQ18: 60;80;80;30 | CR18: Night | CS18: 120 | CT18: Assets/MachineBrigade/Resources/Data/campaign.json: missions[16] | CU18: {"id":"c2m07","chapter":2,"map":"redrock","weather":"Night","goal":"Relieve","targetHealth":3.0,"reinforcements":2,"timeLimit":1000,"ally":{"x":0,"z":0,"hq":"headquarters","structures":[{"def":"mg_bunker","team":0,"x":14.0,"z":0.0,"heading":45},{"def":"gun_turret","team":0,"x":-7.0,"z":12.12,"heading":45},{"def":"guard_tower","team":0,"x":-7.0,"z":-12.12,"heading":45}],"units":[{"def":"ifv","team":0,"x":-2.0,"z":-6.0,"heading":45},{"def":"light_tank","team":0,"x":-10.0,"z":-6.0,"heading":45}]},"hunt":[{"def":"main_battle_tank","x":36.3,"z":11.23,"heading":225},{"def":"tank_destroyer","x":8.43,"z":37.05,"heading":225},{"def":"light_tank","x":-27.88,"z":25.82,"heading":225},{"def":"mortar_carrier","x":-36.3,"z":-11.23,"heading":225},{"def":"ifv","x":-8.43,"z":-37.05,"heading":225},{"def":"main_battle_tank","x":27.88,"z":-25.82,"heading":225}],"enemyAi":"both","enemyStance":"Attack","difficulty":"Normal","enemyCp":10,"enemyIncome":0.75,"enemyDeck":["armored_car","light_tank","main_battle_tank","ifv","tank_destroyer","mortar_carrier"],"playerCp":26,"playerIncome":1.45,"playerCap":36,"playerBase":"Anchor","waves":{"first":70,"interval":60,"size":2,"grow":0.3,"maxSize":4,"maxAlive":12,"roster":["light_tank","ifv","mortar_carrier","tank_destroyer"],"spawns":[60,80,80,30]},"starTime":480,"starLosses":8,"radio":[{"key":"radio.khai.c2m07.1","on":"Start"},{"key":"radio.linh.c2m07.2","at":120}],"missionEvents":["enemy_counterattack","supply_drop"],"unlocks":["vbied"],"coins":150,"xp":120,"prints":1}
A19: c2m08 | B19: 2 | C19: dunebreak | D19: varga | E19: light_tank;main_battle_tank;ifv;tank_destroyer;flame_tank;heavy_tank | I19: khai | J19: FALSE | K19: 7 | L19: co_kich_ban | AD19: 155 | AO19: Normal | AP19: both | AR19: 10 | AT19: 0.8 | AV19: Attack | AW19: Hold | AX19: 240 | BJ19: Anchor | BK19: 40 | BL19: 24 | BM19: 1.3 | BN19: town | BO19: 1 | BR19: 2 | BX19: 10 | BY19: 0 | CJ19: 40 | CK19: 0.35 | CL19: 48 | CM19: 12 | CN19: 5 | CO19: light_tank;main_battle_tank;ifv;mortar_carrier;flame_tank | CP19: 2 | CR19: Night | CS19: 125 | CT19: Assets/MachineBrigade/Resources/Data/campaign.json: missions[17] | CU19: {"id":"c2m08","chapter":2,"map":"dunebreak","weather":"Night","goal":"Hold","points":["town"],"holdSeconds":240,"general":"varga","reinforcements":2,"units":[{"def":"main_battle_tank","team":0,"x":0.0,"z":-8.0,"heading":45},{"def":"main_battle_tank","team":0,"x":-5.53,"z":-0.39,"heading":45},{"def":"ifv","team":0,"x":-14.47,"z":-3.3,"heading":45},{"def":"aa_vehicle","team":0,"x":-14.47,"z":-12.7,"heading":45},{"def":"tank_destroyer","team":0,"x":-5.53,"z":-15.61,"heading":45}],"enemyAi":"both","enemyStance":"Attack","difficulty":"Normal","enemyCp":10,"enemyIncome":0.8,"enemyDeck":["light_tank","main_battle_tank","ifv","tank_destroyer","flame_tank","heavy_tank"],"playerCp":24,"playerIncome":1.3,"playerCap":40,"playerBase":"Anchor","waves":{"first":40,"interval":48,"size":2,"grow":0.35,"maxSize":5,"maxAlive":12,"roster":["light_tank","main_battle_tank","ifv","mortar_carrier","flame_tank"]},"starTime":0,"starLosses":10,"radio":[{"key":"radio.khai.c2m08.1","on":"Start"},{"key":"radio.varga.c2m08.2","at":100}],"missionEvents":["enemy_wave","thorne_support","supply_raid"],"coins":155,"xp":125,"prints":1}
A20: c2m09 | B20: 2 | C20: redrock | D20: varga | I20: khai | J20: FALSE | K20: 9 | L20: co_kich_ban | AD20: 155 | AO20: Normal | AP20: commander | AQ20: Target | AR20: 10 | AS20: 3 | AT20: 0.54 | AV20: Defend | AW20: Duel | BJ20: Anchor | BK20: 38 | BL20: 26 | BM20: 1.9 | BO20: 1 | BR20: 3 | BS20: TRUE | BX20: 12 | BY20: 780 | CB20: 0.4 | CG20: 1500 | CR20: Sandstorm | CS20: 125 | CT20: Assets/MachineBrigade/Resources/Data/campaign.json: missions[18] | CU20: {"id":"c2m09","chapter":2,"map":"redrock","weather":"Sandstorm","goal":"Duel","targetHealth":0.4,"general":"varga","enemyBase":"Target","enemyHq":3,"replay":true,"reinforcements":3,"timeLimit":1500,"enemyAi":"commander","enemyStance":"Defend","difficulty":"Normal","enemyCp":10,"enemyIncome":0.54,"playerCp":26,"playerIncome":1.9,"playerCap":38,"playerBase":"Anchor","starTime":780,"starLosses":12,"radio":[{"key":"radio.varga.c2m09.1","on":"Start"},{"key":"radio.khai.c2m09.2","on":"Start"},{"key":"radio.varga.c2m09.3","on":"Win"}],"missionEvents":["enemy_barrage","accord_artillery","loot_drop"],"coins":155,"xp":125,"prints":1}
A21: c2m10 | B21: 2 | C21: dunebreak | D21: varga | E21: light_tank;main_battle_tank;ifv;tank_destroyer;flame_tank;heavy_tank | I21: khai | J21: FALSE | K21: 7 | L21: co_kich_ban | AD21: 290 | AO21: Normal | AP21: both | AR21: 14 | AT21: 0.9 | AV21: Defend | AW21: Capture | BB21: m05 | BJ21: Anchor | BK21: 40 | BL21: 28 | BM21: 1.6 | BO21: 2 | BR21: 3 | BS21: TRUE | BU21: TRUE | BX21: 16 | BY21: 1320 | CJ21: 80 | CK21: 0.3 | CL21: 60 | CM21: 12 | CN21: 5 | CO21: light_tank;main_battle_tank;ifv;flame_tank;tank_destroyer | CP21: 2 | CR21: Overcast | CS21: 230 | CT21: Assets/MachineBrigade/Resources/Data/campaign.json: missions[19] | CU21: {"id":"c2m10","chapter":2,"map":"dunebreak","weather":"Overcast","goal":"Capture","legacy":"m05","general":"varga","reinforcements":3,"enemyAi":"both","enemyStance":"Defend","difficulty":"Normal","enemyCp":14,"enemyIncome":0.9,"enemyDeck":["light_tank","main_battle_tank","ifv","tank_destroyer","flame_tank","heavy_tank"],"playerCp":28,"playerIncome":1.6,"playerCap":40,"playerBase":"Anchor","waves":{"first":80,"interval":60,"size":2,"grow":0.3,"maxSize":5,"maxAlive":12,"roster":["light_tank","main_battle_tank","ifv","flame_tank","tank_destroyer"]},"stages":[{"stage":"fields","goal":"Capture","points":["east","west"],"enemyOwns":["east","west"],"cp":8,"events":[{"at":"start","kind":"Radio","key":"radio.khai.c2m10.s1"}],"choices":[{"key":"tanks","next":"tanks"},{"key":"oasis","next":"oasis"}],"missionEvents":["oil_convoy"]},{"stage":"tanks","goal":"Destroy","targets":["fuel_tank"],"targetX":65,"targetZ":29,"targetRadius":20,"targetHealth":2,"cp":6,"next":"wells","events":[{"at":"end","kind":"Income","team":1,"amount":0.7},{"at":"end","kind":"Radio","key":"radio.enemyWeakened"}]},{"stage":"oasis","goal":"Survive","points":["west"],"surviveSeconds":90,"cp":6,"next":"wells","events":[{"at":"end","kind":"Strike","team":0,"support":"airstrike","every":55},{"at":"end","kind":"Radio","key":"radio.alliedStrikes"}]},{"stage":"wells","goal":"Destroy","targets":["oil_pump"],"targetX":56,"targetZ":-86,"targetRadius":40,"targetHealth":2,"cp":6},{"stage":"refinery","goal":"Destroy","targets":["refinery_tower","storage_tank"],"targetX":0,"targetZ":0,"targetRadius":40,"targetHealth":2,"cp":10,"events":[{"at":"start","kind":"Reinforce","team":1,"units":["main_battle_tank","tank_destroyer","flame_tank"]}]},{"stage":"yard","goal":"Survive","points":["town"],"surviveSeconds":240,"cp":8,"events":[{"at":"30","kind":"Reinforce","team":1,"units":["main_battle_tank","ifv","flame_tank"]}]},{"stage":"inferno","goal":"Boss","boss":{"def":"behemoth_inferno","x":30,"z":30,"heading":225,"health":1.2,"name":"behemoth_inferno"},"cp":8,"events":[{"at":"start","kind":"Radio","key":"radio.varga.c2m10.s5"}]},{"stage":"counter","goal":"Survive","surviveSeconds":480,"events":[{"at":"start","kind":"Radio","key":"radio.varga.c2m10.s6"},{"at":"40","kind":"Reinforce","team":1,"units":["heavy_tank","tank_destroyer","ifv","mlrs"]},{"at":"200","kind":"Reinforce","team":1,"units":["main_battle_tank","flame_tank","heavy_tank"]}],"missionEvents":["accord_wave"]}],"towerGear":null,"starTime":1320,"starLosses":16,"radio":[{"key":"radio.khai.c2m10.1","on":"Start"},{"key":"radio.khai.c2m10.2","on":"Win"}],"replay":true,"setPiece":true,"missionEvents":["sandstorm"],"coins":290,"xp":230,"prints":2}
A22: c2m11 | B22: 2 | C22: redrock | D22: varga | E22: light_tank;main_battle_tank;ifv;tank_destroyer;flame_tank;heavy_tank | I22: mai | J22: FALSE | K22: 16 | L22: co_kich_ban | M22: 45 | O22: -96 | P22: -80 | AD22: 390 | AO22: Normal | AP22: both | AR22: 14 | AT22: 0.9 | AV22: Defend | AW22: Capture | BC22: TRUE | BF22: 146 | BG22: 146 | BH22: -146 | BI22: -146 | BJ22: Anchor | BK22: 40 | BL22: 28 | BM22: 1.6 | BO22: 3 | BR22: 3 | BS22: TRUE | BX22: 16 | BY22: 1320 | CJ22: 80 | CK22: 0.3 | CL22: 60 | CM22: 12 | CN22: 5 | CO22: light_tank;main_battle_tank;ifv;flame_tank;tank_destroyer | CP22: 2 | CR22: Sandstorm | CS22: 315 | CT22: Assets/MachineBrigade/Resources/Data/campaign.json: missions[20] | CU22: {"id":"c2m11","chapter":2,"map":"redrock","weather":"Sandstorm","goal":"Capture","general":"varga","reinforcements":3,"enemyAi":"both","enemyStance":"Defend","difficulty":"Normal","enemyCp":14,"enemyIncome":0.9,"enemyDeck":["light_tank","main_battle_tank","ifv","tank_destroyer","flame_tank","heavy_tank"],"playerCp":28,"playerIncome":1.6,"playerCap":40,"playerBase":"Anchor","waves":{"first":80,"interval":60,"size":2,"grow":0.3,"maxSize":5,"maxAlive":12,"roster":["light_tank","main_battle_tank","ifv","flame_tank","tank_destroyer"]},"stages":[{"stage":"wells","goal":"Capture","points":["west"],"enemyOwns":["west","town","east"],"cp":8,"choices":[{"key":"pumps","next":"pumps"},{"key":"guns","next":"guns"}],"events":[{"at":"start","kind":"Radio","key":"radio.khai.c2m11.s1"}],"missionEvents":["oil_convoy"]},{"stage":"pumps","goal":"Destroy","targets":["oil_pump"],"targetX":-56,"targetZ":92,"targetRadius":30,"targetHealth":2,"cp":6,"next":"oasis","events":[{"at":"end","kind":"Income","team":1,"amount":0.7},{"at":"end","kind":"Radio","key":"radio.enemyWeakened"}]},{"stage":"guns","goal":"Survive","points":["west"],"surviveSeconds":150,"cp":6,"next":"oasis","events":[{"at":"end","kind":"Strike","team":0,"support":"artillery_barrage","every":55},{"at":"end","kind":"Radio","key":"radio.hung.c2m11.s2"}]},{"stage":"oasis","goal":"Capture","points":["town"],"enemyOwns":["town"],"cp":8,"events":[{"at":"start","kind":"Reinforce","team":1,"units":["heavy_tank","tank_destroyer","ifv"]}],"missionEvents":["enemy_wave"]},{"stage":"caravan","goal":"Survive","points":["town"],"surviveSeconds":180,"cp":6,"events":[{"at":"30","kind":"Reinforce","team":1,"units":["main_battle_tank","flame_tank","ifv"]}],"missionEvents":["enemy_barrage"]},{"stage":"behemoth","goal":"Boss","boss":{"def":"behemoth","name":"behemoth","x":84,"z":84,"heading":225,"health":1.8},"cp":0,"events":[{"at":"start","kind":"Radio","key":"radio.varga.c2m11.s5"}],"missionEvents":["skies_clear"]}],"starTime":1320,"starLosses":16,"operation":true,"replay":true,"playArea":{"minX":-146,"minZ":-146,"maxX":146,"maxZ":146},"ally":{"x":-96,"z":-80,"heading":45,"units":[{"def":"main_battle_tank","team":0,"x":-89.0,"z":-80.0,"heading":45},{"def":"main_battle_tank","team":0,"x":-93.84,"z":-73.34,"heading":45},{"def":"ifv","team":0,"x":-101.66,"z":-75.89,"heading":45},{"def":"aa_vehicle","team":0,"x":-101.66,"z":-84.11,"heading":45},{"def":"mlrs","team":0,"x":-93.84,"z":-86.66,"heading":45}],"reinforcements":[{"at":240,"units":["heavy_tank","ifv","tank_destroyer"]}]},"radio":[{"key":"radio.khai.c2m11.1","on":"Start"},{"key":"radio.hung.c2m11.2","at":12},{"key":"radio.mai.c2m11.3","on":"Win"}],"missionEvents":["thorne_support","hawk_strike"],"coins":390,"xp":315,"prints":3}
A23: c2s1 | B23: 2 | C23: dunebreak | E23: armored_car;light_tank;main_battle_tank;ifv;tank_destroyer;mortar_carrier | G23: c2m03 | I23: linh | J23: FALSE | K23: 5 | L23: co_kich_ban | AB23: NoAircraft | AD23: 450 | AO23: Normal | AP23: commander | AR23: 12 | AT23: 0.8 | AV23: Defend | AW23: Recon | BL23: 24 | BM23: 1.4 | BN23: west;town;east | BO23: 2 | BQ23: 22 | BR23: 1 | BV23: TRUE | BW23: linh | BX23: 6 | BY23: 420 | CG23: 840 | CR23: Night | CS23: 360 | CT23: Assets/MachineBrigade/Resources/Data/campaign.json: missions[21] | CU23: {"id":"c2s1","chapter":2,"side":true,"after":"c2m03","map":"dunebreak","weather":"Night","goal":"Recon","speaker":"linh","points":["west","town","east"],"timeLimit":840,"reinforcements":1,"enemyAi":"commander","enemyStance":"Defend","difficulty":"Normal","enemyCp":12,"enemyIncome":0.8,"enemyDeck":["armored_car","light_tank","main_battle_tank","ifv","tank_destroyer","mortar_carrier"],"playerCp":24,"playerIncome":1.4,"rarePrints":22,"starTime":420,"starLosses":6,"challenge":{"kind":"NoAircraft"},"radio":[{"key":"radio.linh.c2s1.1","on":"Start"}],"missionEvents":["nadia_intel","loot_drop"],"coins":450,"xp":360,"prints":2}
A24: c2s2 | B24: 2 | C24: redrock | G24: c2m07 | I24: dieuhau | J24: TRUE | K24: 7 | L24: co_kich_ban | AD24: 450 | AO24: Normal | AP24: waves | AW24: ShootDown | AZ24: 10 | BK24: 34 | BL24: 24 | BM24: 1.4 | BO24: 2 | BV24: TRUE | BW24: dieuhau | BX24: 8 | BY24: 540 | CG24: 1100 | CH24: Rare | CJ24: 30 | CK24: 0.35 | CL24: 40 | CM24: 12 | CN24: 5 | CO24: attack_helicopter;attack_helicopter;scout_heli;armored_car;light_tank | CP24: 2 | CR24: Clear | CS24: 360 | CT24: Assets/MachineBrigade/Resources/Data/campaign.json: missions[22] | CU24: {"id":"c2s2","chapter":2,"side":true,"after":"c2m07","map":"redrock","weather":"Clear","goal":"ShootDown","speaker":"dieuhau","killsNeeded":10,"timeLimit":1100,"enemyAi":"waves","difficulty":"Normal","playerCp":24,"playerIncome":1.4,"playerCap":34,"waves":{"first":30,"interval":40,"size":2,"grow":0.35,"maxSize":5,"maxAlive":12,"roster":["attack_helicopter","attack_helicopter","scout_heli","armored_car","light_tank"]},"towerGear":"Rare","starTime":540,"starLosses":8,"radio":[{"key":"radio.dieuhau.c2s2.1","on":"Start"}],"missionEvents":["air_wave","loot_repair"],"fixedDeck":{"vehicleIds":["zu23_technical","aa_vehicle","heavy_aa","aa_gun_vehicle","armored_car","ifv","engineer_vehicle","ammo_carrier"],"supportIds":["artillery_barrage","repair_drop"],"placedAllies":[],"loanedCards":["heavy_aa","aa_gun_vehicle"],"specialRules":["warnedAirWaves"],"status":"MAKE_FIRST"},"coins":450,"xp":360,"prints":2}
A25: c3m01 | B25: 3 | C25: whiteout | D25: orlov | E25: main_battle_tank;ifv;mlrs;artillery;mortar_carrier;sam_launcher;aa_vehicle;attack_helicopter | F25: sam_launcher | I25: khai | J25: FALSE | K25: 7 | L25: co_kich_ban | AD25: 165 | AO25: Normal | AP25: commander | AR25: 14 | AT25: 0.85 | AV25: Defend | AW25: Capture | BJ25: Anchor | BL25: 24 | BM25: 1.4 | BN25: west;town;east | BO25: 1 | BR25: 2 | BX25: 8 | BY25: 540 | CR25: Snow | CS25: 135 | CT25: Assets/MachineBrigade/Resources/Data/campaign.json: missions[23] | CU25: {"id":"c3m01","chapter":3,"map":"whiteout","weather":"Snow","goal":"Capture","points":["west","town","east"],"general":"orlov","reinforcements":2,"enemyAi":"commander","enemyStance":"Defend","difficulty":"Normal","enemyCp":14,"enemyIncome":0.85,"enemyDeck":["main_battle_tank","ifv","mlrs","artillery","mortar_carrier","sam_launcher","aa_vehicle","attack_helicopter"],"playerCp":24,"playerIncome":1.4,"playerBase":"Anchor","starTime":540,"starLosses":8,"radio":[{"key":"radio.orlov.c3m01.1","on":"Start"},{"key":"radio.khai.c3m01.2","on":"Start"}],"missionEvents":["orlov_barrage","accord_wave"],"unlocks":["sam_launcher"],"coins":165,"xp":135,"prints":1}
A26: c3m02 | B26: 3 | C26: frostpeak | D26: orlov | E26: main_battle_tank;ifv;mlrs;artillery;mortar_carrier;sam_launcher;aa_vehicle;attack_helicopter | F26: attack_helicopter | I26: linh | J26: FALSE | K26: 7 | L26: co_kich_ban | AB26: NoStrikes | AD26: 170 | AO26: Normal | AP26: both | AR26: 15 | AT26: 0.9 | AV26: Defend | AW26: Destroy | BB26: m07 | BJ26: Anchor | BL26: 24 | BM26: 1.4 | BO26: 1 | BR26: 2 | BX26: 8 | BY26: 480 | CB26: 5 | CF26: radar_station_prop | CG26: 840 | CJ26: 60 | CK26: 0.4 | CL26: 55 | CM26: 16 | CN26: 5 | CO26: scout_heli;attack_helicopter;armored_car | CP26: 2 | CR26: Snow | CS26: 135 | CT26: Assets/MachineBrigade/Resources/Data/campaign.json: missions[24] | CU26: {"id":"c3m02","chapter":3,"map":"frostpeak","weather":"Snow","goal":"Destroy","legacy":"m07","targets":["radar_station_prop"],"timeLimit":840,"targetHealth":5,"general":"orlov","reinforcements":2,"units":[{"def":"heavy_tank","team":1,"x":-56.25,"z":93.75,"heading":225},{"def":"sam_launcher","team":1,"x":-75,"z":116.25,"heading":225},{"def":"aa_vehicle","team":1,"x":-37.5,"z":112.5,"heading":225},{"def":"main_battle_tank","team":1,"x":-41.25,"z":97.5,"heading":225},{"def":"mortar_carrier","team":1,"x":-60,"z":128,"heading":225}],"enemyAi":"both","enemyStance":"Defend","difficulty":"Normal","enemyCp":15,"enemyIncome":0.9,"enemyDeck":["main_battle_tank","ifv","mlrs","artillery","mortar_carrier","sam_launcher","aa_vehicle","attack_helicopter"],"waves":{"first":60,"interval":55,"size":2,"grow":0.4,"maxSize":5,"maxAlive":16,"roster":["scout_heli","attack_helicopter","armored_car"]},"playerCp":24,"playerIncome":1.4,"playerBase":"Anchor","starTime":480,"starLosses":8,"challenge":{"kind":"NoStrikes"},"radio":[{"key":"radio.linh.c3m02.1","on":"Start"}],"unlocks":["attack_helicopter"],"missionEvents":["counter_battery","enemy_wave","nadia_intel"],"coins":170,"xp":135,"prints":1}
A27: c3m03 | B27: 3 | C27: frostpeak | D27: orlov | E27: light_tank;ifv;main_battle_tank;heavy_tank;mortar_carrier;flame_tank;attack_helicopter | F27: scout_heli | I27: khai | J27: FALSE | K27: 7 | L27: co_kich_ban | AD27: 175 | AO27: Normal | AP27: both | AR27: 9 | AT27: 0.85 | AV27: Attack | AW27: Hold | AX27: 210 | BB27: m08 | BJ27: Anchor | BK27: 40 | BL27: 24 | BM27: 1.2 | BN27: town | BO27: 2 | BR27: 2 | BX27: 10 | BY27: 0 | CJ27: 45 | CK27: 0.3 | CL27: 50 | CM27: 10 | CN27: 4 | CO27: light_tank;main_battle_tank;ifv;mortar_carrier;attack_helicopter;flame_tank | CP27: 2 | CR27: Fog | CS27: 140 | CT27: Assets/MachineBrigade/Resources/Data/campaign.json: missions[26] | CU27: {"id":"c3m03","chapter":3,"map":"frostpeak","weather":"Fog","goal":"Hold","legacy":"m08","points":["town"],"holdSeconds":210,"general":"orlov","reinforcements":2,"units":[{"def":"main_battle_tank","team":0,"x":12.0,"z":0.0,"heading":45},{"def":"main_battle_tank","team":0,"x":7.48,"z":9.38,"heading":45},{"def":"aa_vehicle","team":0,"x":-2.67,"z":11.7,"heading":45},{"def":"light_tank","team":0,"x":-10.81,"z":5.21,"heading":45},{"def":"tank_destroyer","team":0,"x":-10.81,"z":-5.21,"heading":45},{"def":"heavy_tank","team":0,"x":-2.67,"z":-11.7,"heading":45},{"def":"mlrs","team":0,"x":7.48,"z":-9.38,"heading":45}],"enemyAi":"both","enemyStance":"Attack","difficulty":"Normal","enemyCp":9,"enemyIncome":0.85,"enemyDeck":["light_tank","ifv","main_battle_tank","heavy_tank","mortar_carrier","flame_tank","attack_helicopter"],"playerCp":24,"playerIncome":1.2,"playerCap":40,"playerBase":"Anchor","waves":{"first":45,"interval":50,"size":2,"grow":0.3,"maxSize":4,"maxAlive":10,"roster":["light_tank","main_battle_tank","ifv","mortar_carrier","attack_helicopter","flame_tank"]},"starTime":0,"starLosses":10,"tips":[{"at":20,"key":"tip.ammoIcons"}],"radio":[{"key":"radio.khai.c3m03.1","on":"Start"}],"missionEvents":["snowstorm","enemy_wave_late","supply_drop"],"unlocks":["scout_heli"],"coins":175,"xp":140,"prints":2}
A28: c3m04 | B28: 3 | C28: whiteout | D28: orlov | E28: main_battle_tank;ifv;mlrs;artillery;mortar_carrier;sam_launcher;aa_vehicle;attack_helicopter | F28: vehicle_hangar | I28: mai | J28: FALSE | K28: 7 | L28: co_kich_ban | AD28: 180 | AO28: Normal | AP28: both | AR28: 12 | AT28: 0.85 | AV28: Attack | AW28: Outpost | AX28: 180 | BJ28: Anchor | BK28: 36 | BL28: 26 | BM28: 1.45 | BN28: town | BO28: 2 | BR28: 2 | BW28: mai | BX28: 8 | BY28: 600 | CG28: 1100 | CJ28: 70 | CK28: 0.3 | CL28: 55 | CM28: 12 | CN28: 4 | CO28: light_tank;ifv;mortar_carrier;main_battle_tank | CP28: 2 | CR28: Night | CS28: 145 | CT28: Assets/MachineBrigade/Resources/Data/campaign.json: missions[27] | CU28: {"id":"c3m04","chapter":3,"map":"whiteout","weather":"Night","goal":"Outpost","points":["town"],"holdSeconds":180,"speaker":"mai","general":"orlov","reinforcements":2,"timeLimit":1100,"enemyAi":"both","enemyStance":"Attack","difficulty":"Normal","enemyCp":12,"enemyIncome":0.85,"enemyDeck":["main_battle_tank","ifv","mlrs","artillery","mortar_carrier","sam_launcher","aa_vehicle","attack_helicopter"],"playerCp":26,"playerIncome":1.45,"playerCap":36,"playerBase":"Anchor","waves":{"first":70,"interval":55,"size":2,"grow":0.3,"maxSize":4,"maxAlive":12,"roster":["light_tank","ifv","mortar_carrier","main_battle_tank"]},"starTime":600,"starLosses":8,"radio":[{"key":"radio.mai.c3m04.1","on":"Start"},{"key":"radio.orlov.c3m04.2","at":120}],"unlocks":["vehicle_hangar"],"missionEvents":["orlov_barrage","accord_relief","snowstorm","ice_crack"],"coins":180,"xp":145,"prints":2}
A29: c3m05 | B29: 3 | C29: whiteout | D29: orlov | E29: light_tank;main_battle_tank;ifv;mortar_carrier;aa_vehicle;attack_helicopter | F29: recon_drone | H29: mega_gunship | I29: dieuhau | J29: FALSE | K29: 14 | L29: co_kich_ban | U29: 225 | V29: 1.6 | X29: 60;60;-20;60;-40;-10;30;-30 | Y29: 84 | Z29: 84 | AB29: NoStrikes | AD29: 275 | AO29: Normal | AP29: commander | AR29: 12 | AT29: 0.85 | AV29: Attack | AW29: Boss | AY29: 2 | BB29: m03 | BJ29: Anchor | BK29: 36 | BL29: 26 | BM29: 1.45 | BO29: 2 | BR29: 2 | BU29: TRUE | BX29: 10 | BY29: 660 | CG29: 1140 | CR29: Clear | CS29: 220 | CT29: Assets/MachineBrigade/Resources/Data/campaign.json: missions[28] | CU29: {"id":"c3m05","chapter":3,"map":"whiteout","weather":"Clear","goal":"Boss","legacy":"m03","general":"orlov","timeLimit":1140,"reinforcements":2,"boss":{"def":"mega_gunship","x":84,"z":84,"heading":225,"route":[60,60,-20,60,-40,-10,30,-30],"health":1.6},"enemyAi":"commander","enemyStance":"Attack","difficulty":"Normal","enemyCp":12,"enemyIncome":0.85,"enemyDeck":["light_tank","main_battle_tank","ifv","mortar_carrier","aa_vehicle","attack_helicopter"],"playerCp":26,"playerIncome":1.45,"playerCap":36,"playerBase":"Anchor","starTime":660,"starLosses":10,"challenge":{"kind":"NoStrikes"},"radio":[{"key":"radio.dieuhau.c3m05.1","on":"Start"},{"key":"radio.orlov.c3m05.2","on":"Boss"},{"key":"radio.dieuhau.c3m05.3","on":"Win"},{"key":"radio.quaden.c3m05.q1","on":"Boss"},{"key":"radio.dieuhau.c3m05.q2","on":"Boss"}],"unlocks":["recon_drone"],"hqLevel":2,"setPiece":true,"missionEvents":["snowstorm","hawk_strike"],"coins":275,"xp":220,"prints":2}
A30: c3m06 | B30: 3 | C30: frostpeak | D30: orlov | E30: main_battle_tank;ifv;mlrs;artillery;mortar_carrier;sam_launcher;aa_vehicle;attack_helicopter | F30: mine_layer | I30: linh | J30: TRUE | K30: 8 | L30: co_kich_ban | AB30: Kills | AC30: 25 | AD30: 185 | AO30: Normal | AP30: commander | AR30: 14 | AT30: 0.9 | AV30: Defend | AW30: Hunt | BJ30: Anchor | BK30: 36 | BL30: 26 | BM30: 1.45 | BO30: 2 | BR30: 2 | BX30: 10 | BY30: 660 | CB30: 2.5 | CG30: 1100 | CR30: Night | CS30: 150 | CT30: Assets/MachineBrigade/Resources/Data/campaign.json: missions[29] | CU30: {"id":"c3m06","chapter":3,"map":"frostpeak","weather":"Night","goal":"Hunt","general":"orlov","timeLimit":1100,"targetHealth":2.5,"reinforcements":2,"hunt":[{"def":"mlrs","x":60,"z":70,"heading":225,"route":[80,90,40,60,70,40]},{"def":"artillery","x":-20,"z":100,"heading":225,"route":[-40,120,0,90,-30,80]},{"def":"mlrs","x":100,"z":20,"heading":225,"route":[110,-10,90,40,120,30]}],"units":[{"def":"main_battle_tank","team":1,"x":67.0,"z":70.0,"heading":225},{"def":"aa_vehicle","team":1,"x":56.5,"z":76.06,"heading":225},{"def":"tank_destroyer","team":1,"x":56.5,"z":63.94,"heading":225},{"def":"ifv","team":1,"x":-14.0,"z":100.0,"heading":225},{"def":"sam_launcher","team":1,"x":-26.0,"z":100.0,"heading":225},{"def":"heavy_tank","team":1,"x":106.0,"z":20.0,"heading":225},{"def":"mortar_carrier","team":1,"x":94.0,"z":20.0,"heading":225}],"enemyAi":"commander","enemyStance":"Defend","difficulty":"Normal","enemyCp":14,"enemyIncome":0.9,"enemyDeck":["main_battle_tank","ifv","mlrs","artillery","mortar_carrier","sam_launcher","aa_vehicle","attack_helicopter"],"playerCp":26,"playerIncome":1.45,"playerCap":36,"playerBase":"Anchor","starTime":660,"starLosses":10,"challenge":{"kind":"Kills","value":25},"radio":[{"key":"radio.linh.c3m06.1","on":"Start"},{"key":"radio.orlov.c3m06.2","at":150}],"missionEvents":["counter_battery",{"id":"intercept_files","reward":{"intel":"c3.tables"}},"enemy_wave"],"unlocks":["mine_layer"],"fixedDeck":{"vehicleIds":["scout_jeep","rocket_technical","command_vehicle","mortar_carrier","artillery","attack_helicopter","recon_drone","armored_car"],"supportIds":["artillery_barrage","airstrike"],"placedAllies":[],"loanedCards":["command_vehicle"],"specialRules":["nightGuns"],"status":"MAKE_FIRST"},"coins":185,"xp":150,"prints":2}
A31: c3m07 | B31: 3 | C31: whiteout | D31: orlov | E31: main_battle_tank;ifv;mlrs;artillery;mortar_carrier;sam_launcher;aa_vehicle;attack_helicopter | I31: khai | J31: FALSE | K31: 8 | L31: co_kich_ban | AB31: NoAircraft | AD31: 195 | AO31: Normal | AP31: both | AR31: 10 | AT31: 0.8 | AV31: Attack | AW31: Protect | BJ31: Anchor | BK31: 36 | BL31: 26 | BM31: 1.4 | BO31: 2 | BP31: 1 | BR31: 2 | BX31: 10 | BY31: 0 | CA31: 390 | CB31: 22 | CF31: log_cabin;barn | CJ31: 90 | CK31: 0.3 | CL31: 65 | CM31: 10 | CN31: 4 | CO31: light_tank;ifv;mortar_carrier;main_battle_tank;attack_helicopter | CP31: 2 | CR31: Fog | CS31: 155 | CT31: Assets/MachineBrigade/Resources/Data/campaign.json: missions[31] | CU31: {"id":"c3m07","chapter":3,"map":"whiteout","weather":"Fog","goal":"Protect","targets":["log_cabin","barn"],"protectNeeded":1,"targetHealth":22,"surviveSeconds":390,"general":"orlov","reinforcements":2,"enemyAi":"both","enemyStance":"Attack","difficulty":"Normal","enemyCp":10,"enemyIncome":0.8,"enemyDeck":["main_battle_tank","ifv","mlrs","artillery","mortar_carrier","sam_launcher","aa_vehicle","attack_helicopter"],"playerCp":26,"playerIncome":1.4,"playerCap":36,"playerBase":"Anchor","waves":{"first":90,"interval":65,"size":2,"grow":0.3,"maxSize":4,"maxAlive":10,"roster":["light_tank","ifv","mortar_carrier","main_battle_tank","attack_helicopter"]},"starTime":0,"starLosses":10,"challenge":{"kind":"NoAircraft"},"radio":[{"key":"radio.khai.c3m07.1","on":"Start"}],"missionEvents":["orlov_barrage","protect_civilians","snowstorm"],"coins":195,"xp":155,"prints":2}
