Workbook

Sheet Am_thanh
A1: id | B1: bank | C1: nhom | D1: bac_co | E1: duong_dan | F1: do_dai_s | G1: kenh | H1: tan_so_mau_hz | I1: nen | J1: tac_gia | K1: nguon_goc | L1: giay_phep | M1: nguon | N1: raw_json
A2: Music/battle_1 | C2: Music | E2: Assets/MachineBrigade/Resources/Audio/Music/battle_1.ogg | F2: 135 | G2: 2 | H2: 44100 | I2: ogg | J2: Armored Advance | K2: Assets/MachineBrigade/Resources/Audio/Music/MUSIC_CREDITS.md | M2: Assets/MachineBrigade/Resources/Audio/Music/battle_1.ogg
A3: Music/battle_2 | C3: Music | E3: Assets/MachineBrigade/Resources/Audio/Music/battle_2.ogg | F3: 132.414 | G3: 2 | H3: 44100 | I3: ogg | J3: Iron Rain | K3: Assets/MachineBrigade/Resources/Audio/Music/MUSIC_CREDITS.md | M3: Assets/MachineBrigade/Resources/Audio/Music/battle_2.ogg
A4: Music/battle_3 | C4: Music | E4: Assets/MachineBrigade/Resources/Audio/Music/battle_3.ogg | F4: 139.13 | G4: 2 | H4: 44100 | I4: ogg | J4: Air Superiority | K4: Assets/MachineBrigade/Resources/Audio/Music/MUSIC_CREDITS.md | M4: Assets/MachineBrigade/Resources/Audio/Music/battle_3.ogg
A5: Music/boss | C5: Music | E5: Assets/MachineBrigade/Resources/Audio/Music/boss.ogg | F5: 125.217 | G5: 2 | H5: 44100 | I5: ogg | J5: Colossus | K5: Assets/MachineBrigade/Resources/Audio/Music/MUSIC_CREDITS.md | M5: Assets/MachineBrigade/Resources/Audio/Music/boss.ogg
A6: Music/defeat | C6: Music | E6: Assets/MachineBrigade/Resources/Audio/Music/defeat.ogg | F6: 9.5 | G6: 2 | H6: 44100 | I6: ogg | J6: Defeat (stinger) | K6: Assets/MachineBrigade/Resources/Audio/Music/MUSIC_CREDITS.md | M6: Assets/MachineBrigade/Resources/Audio/Music/defeat.ogg
A7: Music/menu | C7: Music | E7: Assets/MachineBrigade/Resources/Audio/Music/menu.ogg | F7: 108 | G7: 2 | H7: 44100 | I7: ogg | J7: Command Briefing | K7: Assets/MachineBrigade/Resources/Audio/Music/MUSIC_CREDITS.md | M7: Assets/MachineBrigade/Resources/Audio/Music/menu.ogg
A8: Music/siege | C8: Music | E8: Assets/MachineBrigade/Resources/Audio/Music/siege.ogg | F8: 115.556 | G8: 2 | H8: 44100 | I8: ogg | J8: Hold the Line | K8: Assets/MachineBrigade/Resources/Audio/Music/MUSIC_CREDITS.md | M8: Assets/MachineBrigade/Resources/Audio/Music/siege.ogg
A9: Music/victory | C9: Music | E9: Assets/MachineBrigade/Resources/Audio/Music/victory.ogg | F9: 8.621 | G9: 2 | H9: 44100 | I9: ogg | J9: Victory (stinger) | K9: Assets/MachineBrigade/Resources/Audio/Music/MUSIC_CREDITS.md | M9: Assets/MachineBrigade/Resources/Audio/Music/victory.ogg
A10: autocannon/autocannon_1 | B10: autocannon | C10: shot | E10: Assets/MachineBrigade/Resources/Audio/autocannon/autocannon_1.ogg | F10: 0.695 | G10: 1 | H10: 44100 | I10: ogg | J10: Fascinated Sound | K10: The Gun Locker SFX Pack: "Automatic Cannon - MK44 - 03 - Single Shot with Report 03.wav" | L10: Sonniss GDC licence (no attribution) | M10: Assets/MachineBrigade/Resources/Audio/autocannon/autocannon_1.ogg
A11: autocannon/autocannon_2 | B11: autocannon | C11: shot | E11: Assets/MachineBrigade/Resources/Audio/autocannon/autocannon_2.ogg | F11: 0.695 | G11: 1 | H11: 44100 | I11: ogg | J11: Fascinated Sound | K11: The Gun Locker SFX Pack: "Automatic Cannon - MK44 - 03 - Single Shot with Report 03.wav" | L11: Sonniss GDC licence (no attribution) | M11: Assets/MachineBrigade/Resources/Audio/autocannon/autocannon_2.ogg
A12: autocannon/autocannon_3 | B12: autocannon | C12: shot | E12: Assets/MachineBrigade/Resources/Audio/autocannon/autocannon_3.ogg | F12: 0.682 | G12: 1 | H12: 44100 | I12: ogg | J12: Fascinated Sound | K12: The Gun Locker SFX Pack: "Automatic Cannon - MK44 - 03 - Single Shot with Report 03.wav" | L12: Sonniss GDC licence (no attribution) | M12: Assets/MachineBrigade/Resources/Audio/autocannon/autocannon_3.ogg
A13: cannon/cannon_1 | B13: cannon | C13: shot | E13: Assets/MachineBrigade/Resources/Audio/cannon/cannon_1.ogg | F13: 1.5 | G13: 1 | H13: 44100 | I13: ogg | J13: Bluezone Corporation | K13: Tank - Explosion Sound Effects: "Bluezone_BC0271_tank_artillery_cannon_shot_012.wav" | L13: Sonniss GDC licence (no attribution) | M13: Assets/MachineBrigade/Resources/Audio/cannon/cannon_1.ogg
A14: cannon/cannon_2 | B14: cannon | C14: shot | E14: Assets/MachineBrigade/Resources/Audio/cannon/cannon_2.ogg | F14: 1.5 | G14: 1 | H14: 44100 | I14: ogg | J14: Pole Position Production | K14: The Warfare Library: "warfare_t1b_cannon_firing_forest_distant_MKH8060_2.wav" | L14: Sonniss GDC licence (no attribution) | M14: Assets/MachineBrigade/Resources/Audio/cannon/cannon_2.ogg
A15: cannon/cannon_3 | B15: cannon | C15: shot | E15: Assets/MachineBrigade/Resources/Audio/cannon/cannon_3.ogg | F15: 1.384 | G15: 1 | H15: 44100 | I15: ogg | J15: Pole Position Production | K15: The Warfare Library: "warfare_t1b_cannon_firing_forest_distant_MKH8060_2.wav" | L15: Sonniss GDC licence (no attribution) | M15: Assets/MachineBrigade/Resources/Audio/cannon/cannon_3.ogg
A16: click/click_1 | C16: click | E16: Assets/MachineBrigade/Resources/Audio/click/click_1.ogg | F16: 0.092 | G16: 1 | H16: 44100 | I16: ogg | J16: Kenney (www.kenney.nl) | K16: UI Audio pack ("click1.ogg") | L16: CC0 1.0 | M16: Assets/MachineBrigade/Resources/Audio/click/click_1.ogg
A17: click/click_2 | C17: click | E17: Assets/MachineBrigade/Resources/Audio/click/click_2.ogg | F17: 0.065 | G17: 1 | H17: 44100 | I17: ogg | J17: Kenney (www.kenney.nl) | K17: UI Audio pack ("click3.ogg") | L17: CC0 1.0 | M17: Assets/MachineBrigade/Resources/Audio/click/click_2.ogg
A18: collapse/collapse_1 | B18: collapse | C18: wreck | E18: Assets/MachineBrigade/Resources/Audio/collapse/collapse_1.ogg | F18: 3.697 | G18: 1 | H18: 44100 | I18: ogg | J18: Alexander Kopeikin | K18: Rocks: "rocks stream down heavy 02.wav" | L18: Sonniss GDC licence (no attribution) | M18: Assets/MachineBrigade/Resources/Audio/collapse/collapse_1.ogg
A19: collapse/collapse_2 | B19: collapse | C19: wreck | E19: Assets/MachineBrigade/Resources/Audio/collapse/collapse_2.ogg | F19: 3.853 | G19: 1 | H19: 44100 | I19: ogg | J19: Alexander Kopeikin | K19: Rocks: "rock tumble down debris long 06.wav" | L19: Sonniss GDC licence (no attribution) | M19: Assets/MachineBrigade/Resources/Audio/collapse/collapse_2.ogg
A20: debris/debris_1 | B20: debris | C20: wreck | E20: Assets/MachineBrigade/Resources/Audio/debris/debris_1.ogg | F20: 0.805 | G20: 1 | H20: 44100 | I20: ogg | J20: Mechanical Wave | K20: Undoing-Computer: "Drop Fall Metal Rattle Scrap Debris_UC 10.wav" | L20: Sonniss GDC licence (no attribution) | M20: Assets/MachineBrigade/Resources/Audio/debris/debris_1.ogg
A21: debris/debris_2 | B21: debris | C21: wreck | E21: Assets/MachineBrigade/Resources/Audio/debris/debris_2.ogg | F21: 0.853 | G21: 1 | H21: 44100 | I21: ogg | J21: Mechanical Wave | K21: Undoing-Computer: "Hit Impact Metal Scrap Debris_UC 06.wav" | L21: Sonniss GDC licence (no attribution) | M21: Assets/MachineBrigade/Resources/Audio/debris/debris_2.ogg
A22: debris/debris_3 | B22: debris | C22: wreck | E22: Assets/MachineBrigade/Resources/Audio/debris/debris_3.ogg | F22: 0.954 | G22: 1 | H22: 44100 | I22: ogg | J22: Mechanical Wave | K22: Rock Brick and Dirt: "Hit Rock Debris_RBD 02.wav" | L22: Sonniss GDC licence (no attribution) | M22: Assets/MachineBrigade/Resources/Audio/debris/debris_3.ogg
A23: drums_loop/drums_loop_1 | C23: drums_loop | E23: Assets/MachineBrigade/Resources/Audio/drums_loop/drums_loop_1.ogg | F23: 7.385 | G23: 1 | H23: 44100 | I23: ogg | J23: William Hector | K23: Horde War Drums loop (OpenGameArt) ("horde_war_drums_by_william_hector.wav") | L23: CC0 1.0 | M23: Assets/MachineBrigade/Resources/Audio/drums_loop/drums_loop_1.ogg
A24: explosion_huge/explosion_huge_1 | B24: explosion_huge | C24: blast | E24: Assets/MachineBrigade/Resources/Audio/explosion_huge/explosion_huge_1.ogg | F24: 5 | G24: 1 | H24: 44100 | I24: ogg | J24: Stefano Cremona | K24: Explosions: "BigExplosion02.wav" | L24: Sonniss GDC licence (no attribution) | M24: Assets/MachineBrigade/Resources/Audio/explosion_huge/explosion_huge_1.ogg
A25: explosion_huge/explosion_huge_2 | B25: explosion_huge | C25: blast | E25: Assets/MachineBrigade/Resources/Audio/explosion_huge/explosion_huge_2.ogg | F25: 4.975 | G25: 1 | H25: 44100 | I25: ogg | J25: David Dumais Audio | K25: Explosion SFX Pack: "EXPLDsgn_Nuclear Explosion 07_DDUMAIS_NONE.wav" | L25: Sonniss GDC licence (no attribution) | M25: Assets/MachineBrigade/Resources/Audio/explosion_huge/explosion_huge_2.ogg
A26: explosion_huge/explosion_huge_3 | B26: explosion_huge | C26: blast | E26: Assets/MachineBrigade/Resources/Audio/explosion_huge/explosion_huge_3.ogg | F26: 4.964 | G26: 1 | H26: 44100 | I26: ogg | J26: MatiasMacSD | K26: Eradication - Small Pack: "Planet_Explosion_High-12.wav" | L26: Sonniss GDC licence (no attribution) | M26: Assets/MachineBrigade/Resources/Audio/explosion_huge/explosion_huge_3.ogg
A27: explosion_large/explosion_large_1 | B27: explosion_large | C27: blast | E27: Assets/MachineBrigade/Resources/Audio/explosion_large/explosion_large_1.ogg | F27: 3 | G27: 1 | H27: 44100 | I27: ogg | J27: Bluezone Corporation | K27: Tank - Explosion Sound Effects: "Bluezone_BC0271_explosion_outdoors_large_005.wav" | L27: Sonniss GDC licence (no attribution) | M27: Assets/MachineBrigade/Resources/Audio/explosion_large/explosion_large_1.ogg
A28: explosion_large/explosion_large_2 | B28: explosion_large | C28: blast | E28: Assets/MachineBrigade/Resources/Audio/explosion_large/explosion_large_2.ogg | F28: 2.511 | G28: 1 | H28: 44100 | I28: ogg | J28: Gamemaster Audio | K28: Guns, Bullets and Explosions: "explosion_large_07.wav" | L28: Sonniss GDC licence (no attribution) | M28: Assets/MachineBrigade/Resources/Audio/explosion_large/explosion_large_2.ogg
A29: explosion_large/explosion_large_3 | B29: explosion_large | C29: blast | E29: Assets/MachineBrigade/Resources/Audio/explosion_large/explosion_large_3.ogg | F29: 3 | G29: 1 | H29: 44100 | I29: ogg | J29: Gamemaster Audio | K29: Explosion Sound Pack: "explosion_large_08.wav" | L29: Sonniss GDC licence (no attribution) | M29: Assets/MachineBrigade/Resources/Audio/explosion_large/explosion_large_3.ogg
A30: explosion_large/explosion_large_4 | B30: explosion_large | C30: blast | E30: Assets/MachineBrigade/Resources/Audio/explosion_large/explosion_large_4.ogg | F30: 2.688 | G30: 1 | H30: 44100 | I30: ogg | J30: Bluezone Corporation | K30: Combat Drone: "Bluezone_BC0288_combat_drone_weapon_explosion_004.wav" | L30: Sonniss GDC licence (no attribution) | M30: Assets/MachineBrigade/Resources/Audio/explosion_large/explosion_large_4.ogg
A31: explosion_medium/explosion_medium_1 | B31: explosion_medium | C31: blast | E31: Assets/MachineBrigade/Resources/Audio/explosion_medium/explosion_medium_1.ogg | F31: 2 | G31: 1 | H31: 44100 | I31: ogg | J31: Gamemaster Audio | K31: Explosion Sound Pack: "explosion_med_long_tail_01.wav" | L31: Sonniss GDC licence (no attribution) | M31: Assets/MachineBrigade/Resources/Audio/explosion_medium/explosion_medium_1.ogg
A32: explosion_medium/explosion_medium_2 | B32: explosion_medium | C32: blast | E32: Assets/MachineBrigade/Resources/Audio/explosion_medium/explosion_medium_2.ogg | F32: 1.989 | G32: 1 | H32: 44100 | I32: ogg | J32: David Dumais Audio | K32: Explosion SFX Pack: "EXPLReal_Medium Realistic Explosion 15_DDUMAIS_NONE.wav" | L32: Sonniss GDC licence (no attribution) | M32: Assets/MachineBrigade/Resources/Audio/explosion_medium/explosion_medium_2.ogg
A33: explosion_medium/explosion_medium_3 | B33: explosion_medium | C33: blast | E33: Assets/MachineBrigade/Resources/Audio/explosion_medium/explosion_medium_3.ogg | F33: 2 | G33: 1 | H33: 44100 | I33: ogg | J33: Bluezone Corporation | K33: Detonation - Explosion: "Bluezone_BC0277_explosion_urban_004_02.wav" | L33: Sonniss GDC licence (no attribution) | M33: Assets/MachineBrigade/Resources/Audio/explosion_medium/explosion_medium_3.ogg
A34: explosion_medium/explosion_medium_4 | B34: explosion_medium | C34: blast | E34: Assets/MachineBrigade/Resources/Audio/explosion_medium/explosion_medium_4.ogg | F34: 1.998 | G34: 1 | H34: 44100 | I34: ogg | J34: Stefano Cremona | K34: Explosions: "DeepExplosion02.wav" | L34: Sonniss GDC licence (no attribution) | M34: Assets/MachineBrigade/Resources/Audio/explosion_medium/explosion_medium_4.ogg
A35: explosion_small/explosion_small_1 | B35: explosion_small | C35: blast | E35: Assets/MachineBrigade/Resources/Audio/explosion_small/explosion_small_1.ogg | F35: 0.95 | G35: 1 | H35: 44100 | I35: ogg | J35: Bluezone Corporation | K35: Detonation - Explosion: "Bluezone_BC0277_explosion_mortar_002_01.wav" | L35: Sonniss GDC licence (no attribution) | M35: Assets/MachineBrigade/Resources/Audio/explosion_small/explosion_small_1.ogg
... A47: heavy_cannon/heavy_cannon_3 | B47: heavy_cannon | C47: shot | E47: Assets/MachineBrigade/Resources/Audio/heavy_cannon/heavy_cannon_3.ogg | F47: 1.981 | G47: 1 | H47: 44100 | I47: ogg | J47: Airborne Sound | K47: Battlefield Howitzers: "Howitzer,M101,C3,105 mm,Medium Distant,Right Side,Shot,Firm,Heavy,EQ Version,Soft Attack.wav" | L47: Sonniss GDC licence (no attribution) | M47: Assets/MachineBrigade/Resources/Audio/heavy_cannon/heavy_cannon_3.ogg
A48: impact_metal/impact_metal_1 | C48: impact_metal | E48: Assets/MachineBrigade/Resources/Audio/impact_metal/impact_metal_1.ogg | F48: 0.453 | G48: 1 | H48: 44100 | I48: ogg | J48: Mechanical Wave | K48: Undoing-Computer: "Hit Impact Hard Metal Scrap Debris_UC 01.wav" | L48: Sonniss GDC licence (no attribution) | M48: Assets/MachineBrigade/Resources/Audio/impact_metal/impact_metal_1.ogg
A49: impact_metal/impact_metal_2 | C49: impact_metal | E49: Assets/MachineBrigade/Resources/Audio/impact_metal/impact_metal_2.ogg | F49: 0.468 | G49: 1 | H49: 44100 | I49: ogg | J49: Mechanical Wave | K49: Undoing-Computer: "Hit Impact Hard Metal Scrap Debris_UC 01.wav" | L49: Sonniss GDC licence (no attribution) | M49: Assets/MachineBrigade/Resources/Audio/impact_metal/impact_metal_2.ogg
A50: impact_metal/impact_metal_3 | C50: impact_metal | E50: Assets/MachineBrigade/Resources/Audio/impact_metal/impact_metal_3.ogg | F50: 0.442 | G50: 1 | H50: 44100 | I50: ogg | J50: Gamemaster Audio | K50: Bullet Impact Sounds: "bullet_impact_metal_heavy_08.wav" | L50: Sonniss GDC licence (no attribution) | M50: Assets/MachineBrigade/Resources/Audio/impact_metal/impact_metal_3.ogg
A51: jet_loop/jet_loop_1 | B51: jet_loop | C51: aircraft | E51: Assets/MachineBrigade/Resources/Audio/jet_loop/jet_loop_1.ogg | F51: 5 | G51: 1 | H51: 44100 | I51: ogg | J51: Airborne Sound | K51: Attack Aircraft Maneuvers: "Jet,Fighter,FA-18C,Hornet,Medium Distant,Climb,Right to High,Crest and Hold,Kill Engine,191.wav" | L51: Sonniss GDC licence (no attribution) | M51: Assets/MachineBrigade/Resources/Audio/jet_loop/jet_loop_1.ogg
...

Sheet Am_thanh_bank
A1: id | B1: so_clip | C1: group | D1: kept | E1: row | F1: size | G1: variants | H1: nguon | I1: raw_json
A2: autocannon | B2: 3 | C2: shot | D2: TRUE | H2: Tools/sfx/library.json: banks.autocannon | I2: {"group":"shot","size":null,"row":null,"kept":true}
A3: blast_air_s1 | B3: 2 | C3: blast_air | F3: s1 | G3: 2 | H3: Tools/sfx/library.json: banks.blast_air_s1 | I3: {"group":"blast_air","size":"s1","row":null,"variants":2}
A4: blast_air_s2 | B4: 2 | C4: blast_air | F4: s2 | G4: 2 | H4: Tools/sfx/library.json: banks.blast_air_s2 | I4: {"group":"blast_air","size":"s2","row":null,"variants":2}
A5: blast_air_s3 | B5: 2 | C5: blast_air | F5: s3 | G5: 2 | H5: Tools/sfx/library.json: banks.blast_air_s3 | I5: {"group":"blast_air","size":"s3","row":null,"variants":2}
A6: blast_bomb | B6: 3 | C6: blast | E6: blast | F6: bomb | G6: 3 | H6: Tools/sfx/library.json: banks.blast_bomb | I6: {"group":"blast","size":"bomb","row":"blast","variants":3}
A7: blast_he_s1 | B7: 3 | C7: blast | E7: blast | F7: s1 | G7: 3 | H7: Tools/sfx/library.json: banks.blast_he_s1 | I7: {"group":"blast","size":"s1","row":"blast","variants":3}
A8: blast_he_s2 | B8: 3 | C8: blast | E8: blast | F8: s2 | G8: 3 | H8: Tools/sfx/library.json: banks.blast_he_s2 | I8: {"group":"blast","size":"s2","row":"blast","variants":3}
A9: blast_he_s3 | B9: 3 | C9: blast | E9: blast | F9: s3 | G9: 3 | H9: Tools/sfx/library.json: banks.blast_he_s3 | I9: {"group":"blast","size":"s3","row":"blast","variants":3}
A10: blast_he_s4 | B10: 3 | C10: blast | E10: blast | F10: s4 | G10: 3 | H10: Tools/sfx/library.json: banks.blast_he_s4 | I10: {"group":"blast","size":"s4","row":"blast","variants":3}
A11: blast_he_s406 | B11: 2 | C11: blast | E11: blast | F11: s406 | G11: 2 | H11: Tools/sfx/library.json: banks.blast_he_s406 | I11: {"group":"blast","size":"s406","row":"blast","variants":2}
A12: blast_heat_s2 | B12: 2 | C12: blast_heat | F12: s2 | G12: 2 | H12: Tools/sfx/library.json: banks.blast_heat_s2 | I12: {"group":"blast_heat","size":"s2","row":null,"variants":2}
A13: blast_heat_s3 | B13: 2 | C13: blast_heat | F13: s3 | G13: 2 | H13: Tools/sfx/library.json: banks.blast_heat_s3 | I13: {"group":"blast_heat","size":"s3","row":null,"variants":2}
A14: blast_super | B14: 2 | C14: blast | E14: blast | F14: super | G14: 2 | H14: Tools/sfx/library.json: banks.blast_super | I14: {"group":"blast","size":"super","row":"blast","variants":2}
A15: blast_thermo_s3 | B15: 2 | C15: blast_thermo | F15: s3 | G15: 2 | H15: Tools/sfx/library.json: banks.blast_thermo_s3 | I15: {"group":"blast_thermo","size":"s3","row":null,"variants":2}
A16: blast_thermo_s4 | B16: 2 | C16: blast_thermo | F16: s4 | G16: 2 | H16: Tools/sfx/library.json: banks.blast_thermo_s4 | I16: {"group":"blast_thermo","size":"s4","row":null,"variants":2}
A17: burst_s0_10 | B17: 3 | C17: shot | F17: s0 | G17: 3 | H17: Tools/sfx/library.json: banks.burst_s0_10 | I17: {"group":"shot","size":"s0","row":null,"variants":3}
A18: burst_s0_16 | B18: 3 | C18: shot | F18: s0 | G18: 3 | H18: Tools/sfx/library.json: banks.burst_s0_16 | I18: {"group":"shot","size":"s0","row":null,"variants":3}
A19: burst_s0_55 | B19: 3 | C19: shot | F19: s0 | G19: 3 | H19: Tools/sfx/library.json: banks.burst_s0_55 | I19: {"group":"shot","size":"s0","row":null,"variants":3}
A20: burst_s1_10 | B20: 3 | C20: shot | F20: s1 | G20: 3 | H20: Tools/sfx/library.json: banks.burst_s1_10 | I20: {"group":"shot","size":"s1","row":null,"variants":3}
A21: burst_s1_22 | B21: 3 | C21: shot | F21: s1 | G21: 3 | H21: Tools/sfx/library.json: banks.burst_s1_22 | I21: {"group":"shot","size":"s1","row":null,"variants":3}
A22: burst_s1_35 | B22: 3 | C22: shot | F22: s1 | G22: 3 | H22: Tools/sfx/library.json: banks.burst_s1_35 | I22: {"group":"shot","size":"s1","row":null,"variants":3}
A23: burst_s1_55 | B23: 3 | C23: shot | F23: s1 | G23: 3 | H23: Tools/sfx/library.json: banks.burst_s1_55 | I23: {"group":"shot","size":"s1","row":null,"variants":3}
A24: cannon | B24: 3 | C24: shot | D24: TRUE | H24: Tools/sfx/library.json: banks.cannon | I24: {"group":"shot","size":null,"row":null,"kept":true}
A25: collapse | B25: 2 | C25: wreck | D25: TRUE | H25: Tools/sfx/library.json: banks.collapse | I25: {"group":"wreck","size":null,"row":null,"kept":true}
A26: crash_fall | B26: 2 | C26: aircraft | G26: 2 | H26: Tools/sfx/library.json: banks.crash_fall | I26: {"group":"aircraft","size":null,"row":null,"variants":2}
A27: crash_impact | B27: 2 | C27: aircraft | G27: 2 | H27: Tools/sfx/library.json: banks.crash_impact | I27: {"group":"aircraft","size":null,"row":null,"variants":2}
A28: debris | B28: 3 | C28: wreck | D28: TRUE | H28: Tools/sfx/library.json: banks.debris | I28: {"group":"wreck","size":null,"row":null,"kept":true}
A29: engine_heavy | B29: 1 | C29: engine | G29: 1 | H29: Tools/sfx/library.json: banks.engine_heavy | I29: {"group":"engine","size":null,"row":null,"variants":1}
A30: engine_tracked | B30: 1 | C30: engine | G30: 1 | H30: Tools/sfx/library.json: banks.engine_tracked | I30: {"group":"engine","size":null,"row":null,"variants":1}
A31: engine_wheeled | B31: 1 | C31: engine | G31: 1 | H31: Tools/sfx/library.json: banks.engine_wheeled | I31: {"group":"engine","size":null,"row":null,"variants":1}
A32: explosion_huge | B32: 3 | C32: blast | D32: TRUE | H32: Tools/sfx/library.json: banks.explosion_huge | I32: {"group":"blast","size":null,"row":null,"kept":true}
A33: explosion_large | B33: 4 | C33: blast | D33: TRUE | H33: Tools/sfx/library.json: banks.explosion_large | I33: {"group":"blast","size":null,"row":null,"kept":true}
A34: explosion_medium | B34: 4 | C34: blast | D34: TRUE | H34: Tools/sfx/library.json: banks.explosion_medium | I34: {"group":"blast","size":null,"row":null,"kept":true}
A35: explosion_small | B35: 4 | C35: blast | D35: TRUE | H35: Tools/sfx/library.json: banks.explosion_small | I35: {"group":"blast","size":null,"row":null,"kept":true}
A36: fire_loop | B36: 1 | C36: ambience | D36: TRUE | H36: Tools/sfx/library.json: banks.fire_loop | I36: {"group":"ambience","size":null,"row":null,"kept":true}
A37: flak | B37: 3 | C37: blast_air | D37: TRUE | H37: Tools/sfx/library.json: banks.flak | I37: {"group":"blast_air","size":null,"row":null,"kept":true}
A38: flame | B38: 2 | C38: shot | D38: TRUE | H38: Tools/sfx/library.json: banks.flame | I38: {"group":"shot","size":null,"row":null,"kept":true}
A39: flare_pop | B39: 2 | C39: flare | G39: 2 | H39: Tools/sfx/library.json: banks.flare_pop | I39: {"group":"flare","size":null,"row":null,"variants":2}
A40: heavy_cannon | B40: 3 | C40: shot | D40: TRUE | H40: Tools/sfx/library.json: banks.heavy_cannon | I40: {"group":"shot","size":null,"row":null,"kept":true}
...

Sheet Am_thanh_thu_vien
A1: id | B1: nhom | C1: khoa | D1: gia_tri_so | E1: gia_tri_chu | F1: don_vi | G1: nguon | H1: raw_json
A2: note | C2: note | E2: Fix pass L7: the sound library (Tools/sfx/build_sfx.py); sizes s0 = <= 14.5 mm, s1 = 20-40 mm, s2 = 57-105 mm, s3 = 120-155 mm, s4 = 203-240 mm, bomb = bombs, s406 = big rockets / >= 406 mm, super = super weapons | G2: Tools/sfx/library.json: note | H2: "Fix pass L7: the sound library (Tools/sfx/build_sfx.py); sizes s0 = <= 14.5 mm, s1 = 20-40 mm, s2 = 57-105 mm, s3 = 120-155 mm, s4 = 203-240 mm, bomb = bombs, s406 = big rockets / >= 406 mm, super = super weapons"

Sheet Am_thanh_loat
A1: id | B1: bank | C1: co | D1: nhip_phat_s | E1: so_phat | F1: nguon | G1: raw_json
A2: burst_s0_10 | B2: burst_s0_10 | C2: S0 | D2: 10 | E2: 3 | F2: Assets/MachineBrigade/Scripts/Game/Audio/SoundLibrary.cs:164 (Bursts[0]) | G2: ["burst_s0_10","S0",10,3]
A3: burst_s0_16 | B3: burst_s0_16 | C3: S0 | D3: 16 | E3: 5 | F3: Assets/MachineBrigade/Scripts/Game/Audio/SoundLibrary.cs:164 (Bursts[1]) | G3: ["burst_s0_16","S0",16,5]
A4: burst_s0_55 | B4: burst_s0_55 | C4: S0 | D4: 55 | E4: 18 | F4: Assets/MachineBrigade/Scripts/Game/Audio/SoundLibrary.cs:164 (Bursts[2]) | G4: ["burst_s0_55","S0",55,18]
A5: burst_s1_10 | B5: burst_s1_10 | C5: S1 | D5: 10 | E5: 3 | F5: Assets/MachineBrigade/Scripts/Game/Audio/SoundLibrary.cs:165 (Bursts[3]) | G5: ["burst_s1_10","S1",10,3]
A6: burst_s1_22 | B6: burst_s1_22 | C6: S1 | D6: 22 | E6: 7 | F6: Assets/MachineBrigade/Scripts/Game/Audio/SoundLibrary.cs:165 (Bursts[4]) | G6: ["burst_s1_22","S1",22,7]
A7: burst_s1_35 | B7: burst_s1_35 | C7: S1 | D7: 35 | E7: 12 | F7: Assets/MachineBrigade/Scripts/Game/Audio/SoundLibrary.cs:165 (Bursts[5]) | G7: ["burst_s1_35","S1",35,12]
A8: burst_s1_55 | B8: burst_s1_55 | C8: S1 | D8: 55 | E8: 18 | F8: Assets/MachineBrigade/Scripts/Game/Audio/SoundLibrary.cs:166 (Bursts[6]) | G8: ["burst_s1_55","S1",55,18]

Sheet VFX_bac
A1: id | B1: bac | C1: rung_camera_dong_thoi | D1: ban_dust_ring | E1: ban_flash | F1: ban_flash_life | G1: ban_light | H1: ban_pressure | I1: ban_puff_life | J1: ban_puff_life_arg0 | K1: ban_puff_life_arg1 | L1: ban_puff_size | M1: ban_puffs | N1: ban_squat | O1: ban_water | P1: doi_crater | Q1: doi_fireball | R1: doi_smoke_max | S1: doi_smoke_min | T1: nguon | U1: raw_json
A2: T0 | B2: 0 | C2: XEM_VFX_ngan_sach | D2: 0 | E2: 0 | F2: 0 | G2: 0 | H2: 0 | I2: zero | L2: 0 | M2: 0 | N2: 0 | O2: 0 | P2: 0 | Q2: 0.2 | R2: 0.5 | S2: 0.5 | T2: Assets/MachineBrigade/Scripts/Game/Effects/TierFx.cs (Fire), Assets/MachineBrigade/Scripts/Game/Effects/EffectLife.cs (Bands)
A3: T1 | B3: 1 | C3: XEM_VFX_ngan_sach | D3: 0 | E3: 0 | F3: 0 | G3: 0 | H3: 0 | J3: 1.2 | K3: 1.8 | L3: 0.6 | M3: 2 | N3: 0 | O3: 0 | P3: 10 | Q3: 0.3 | R3: 1 | S3: 0.5 | T3: Assets/MachineBrigade/Scripts/Game/Effects/TierFx.cs (Fire), Assets/MachineBrigade/Scripts/Game/Effects/EffectLife.cs (Bands)
A4: T2 | B4: 2 | C4: XEM_VFX_ngan_sach | D4: 0 | E4: 1.2 | F4: 0.1 | G4: 0 | H4: 0 | J4: 1.8 | K4: 2.6 | L4: 1.1 | M4: 4 | N4: 0 | O4: 0 | P4: 20 | Q4: 0.5 | R4: 2.5 | S4: 1.5 | T4: Assets/MachineBrigade/Scripts/Game/Effects/TierFx.cs (Fire), Assets/MachineBrigade/Scripts/Game/Effects/EffectLife.cs (Bands)
A5: T3 | B5: 3 | C5: XEM_VFX_ngan_sach | D5: 8 | E5: 2.4 | F5: 0.16 | G5: 9 | H5: 0 | J5: 3.5 | K5: 5 | L5: 1.7 | M5: 10 | N5: 1.6 | O5: 0 | P5: 30 | Q5: 0.8 | R5: 5 | S5: 3 | T5: Assets/MachineBrigade/Scripts/Game/Effects/TierFx.cs (Fire), Assets/MachineBrigade/Scripts/Game/Effects/EffectLife.cs (Bands)
A6: T4 | B6: 4 | C6: XEM_VFX_ngan_sach | D6: 16 | E6: 3.6 | F6: 0.24 | G6: 16 | H6: 7 | J6: 5 | K6: 7 | L6: 2.4 | M6: 16 | N6: 2.4 | O6: 12 | P6: 45 | Q6: 1.2 | R6: 10 | S6: 6 | T6: Assets/MachineBrigade/Scripts/Game/Effects/TierFx.cs (Fire), Assets/MachineBrigade/Scripts/Game/Effects/EffectLife.cs (Bands)
A7: T5 | B7: 5 | C7: XEM_VFX_ngan_sach | D7: 26 | E7: 5 | F7: 0.34 | G7: 28 | H7: 12 | J7: 7 | K7: 10 | L7: 3.2 | M7: 24 | N7: 3.2 | O7: 22 | P7: 60 | Q7: 1.8 | R7: 15 | S7: 10 | T7: Assets/MachineBrigade/Scripts/Game/Effects/TierFx.cs (Fire), Assets/MachineBrigade/Scripts/Game/Effects/EffectLife.cs (Bands)

Sheet VFX_chay_than_xe
A1: id | B1: bodies | C1: embers | D1: low_tongues | E1: power | F1: reach_m | G1: size | H1: smoke_alpha | I1: smoke_shade | J1: smoke_size | K1: sparks | L1: tongues | M1: nguon | N1: raw_json
A2: 0 | B2: 1 | C2: 0.5 | D2: 1 | E2: 2.8 | F2: 4.5 | G2: 1 | H2: 0.6 | I2: 0.34 | J2: 1 | K2: 0.25 | L2: 1 | M2: Assets/MachineBrigade/Scripts/Game/Effects/HullFire.cs:63 (Looks[0]) | N2: {"bodies":1,"tongues":1,"lowTongues":1,"size":1,"smokeShade":0.34,"smokeAlpha":0.6,"smokeSize":1,"embers":0.5,"sparks":0.25,"reach":4.5,"power":2.8}
A3: 1 | B3: 1 | C3: 1.1 | D3: 1 | E3: 4 | F3: 6 | G3: 1.2 | H3: 0.74 | I3: 0.16 | J3: 1.15 | K3: 0.7 | L3: 2 | M3: Assets/MachineBrigade/Scripts/Game/Effects/HullFire.cs:66 (Looks[1]) | N3: {"bodies":1,"tongues":2,"lowTongues":1,"size":1.2,"smokeShade":0.16,"smokeAlpha":0.74,"smokeSize":1.15,"embers":1.1,"sparks":0.7,"reach":6,"power":4}
A4: 2 | B4: 2 | C4: 1.8 | D4: 2 | E4: 5.2 | F4: 7.5 | G4: 1.45 | H4: 0.8 | I4: 0.06 | J4: 1.35 | K4: 1.2 | L4: 2 | M4: Assets/MachineBrigade/Scripts/Game/Effects/HullFire.cs:69 (Looks[2]) | N4: {"bodies":2,"tongues":2,"lowTongues":2,"size":1.45,"smokeShade":0.06,"smokeAlpha":0.8,"smokeSize":1.35,"embers":1.8,"sparks":1.2,"reach":7.5,"power":5.2}

Sheet Hau_ky_hinh_anh
A1: id | B1: hieu_ung | C1: thiet_lap | D1: ghi_de | E1: gia_tri | F1: dimension | G1: nguon | H1: raw_json
A2: BattlefieldProfile.m_Enabled | B2: BattlefieldProfile | C2: m_Enabled | E2: 1 | G2: Assets/MachineBrigade/Settings/BattlefieldProfile.asset: docs[3].MonoBehaviour.m_Enabled | H2: "1"
A3: BattlefieldProfile.m_Name | B3: BattlefieldProfile | C3: m_Name | E3: BattlefieldProfile | G3: Assets/MachineBrigade/Settings/BattlefieldProfile.asset: docs[3].MonoBehaviour.m_Name | H3: "BattlefieldProfile"
A4: Bloom.active | B4: Bloom | C4: active | E4: 1 | G4: Assets/MachineBrigade/Settings/BattlefieldProfile.asset: docs[0].MonoBehaviour.active | H4: "1"
A5: Bloom.clamp | B5: Bloom | C5: clamp | D5: 1 | E5: 6 | G5: Assets/MachineBrigade/Settings/BattlefieldProfile.asset: docs[0].MonoBehaviour.clamp | H5: {"m_OverrideState":"1","m_Value":"6"}
A6: Bloom.dirtIntensity | B6: Bloom | C6: dirtIntensity | D6: 0 | E6: 0 | G6: Assets/MachineBrigade/Settings/BattlefieldProfile.asset: docs[0].MonoBehaviour.dirtIntensity | H6: {"m_OverrideState":"0","m_Value":"0"}
A7: Bloom.dirtTexture | B7: Bloom | C7: dirtTexture | D7: 0 | E7: {fileID: 0} | F7: 1 | G7: Assets/MachineBrigade/Settings/BattlefieldProfile.asset: docs[0].MonoBehaviour.dirtTexture | H7: {"m_OverrideState":"0","m_Value":"{fileID: 0}","dimension":"1"}
A8: Bloom.downscale | B8: Bloom | C8: downscale | D8: 0 | E8: 0 | G8: Assets/MachineBrigade/Settings/BattlefieldProfile.asset: docs[0].MonoBehaviour.downscale | H8: {"m_OverrideState":"0","m_Value":"0"}
A9: Bloom.filter | B9: Bloom | C9: filter | D9: 0 | E9: 0 | G9: Assets/MachineBrigade/Settings/BattlefieldProfile.asset: docs[0].MonoBehaviour.filter | H9: {"m_OverrideState":"0","m_Value":"0"}
A10: Bloom.highQualityFiltering | B10: Bloom | C10: highQualityFiltering | D10: 1 | E10: 1 | G10: Assets/MachineBrigade/Settings/BattlefieldProfile.asset: docs[0].MonoBehaviour.highQualityFiltering | H10: {"m_OverrideState":"1","m_Value":"1"}
A11: Bloom.intensity | B11: Bloom | C11: intensity | D11: 1 | E11: 0.45 | G11: Assets/MachineBrigade/Settings/BattlefieldProfile.asset: docs[0].MonoBehaviour.intensity | H11: {"m_OverrideState":"1","m_Value":"0.45"}
A12: Bloom.m_Enabled | B12: Bloom | C12: m_Enabled | E12: 1 | G12: Assets/MachineBrigade/Settings/BattlefieldProfile.asset: docs[0].MonoBehaviour.m_Enabled | H12: "1"
A13: Bloom.m_Name | B13: Bloom | C13: m_Name | E13: Bloom | G13: Assets/MachineBrigade/Settings/BattlefieldProfile.asset: docs[0].MonoBehaviour.m_Name | H13: "Bloom"
A14: Bloom.maxIterations | B14: Bloom | C14: maxIterations | D14: 0 | E14: 6 | G14: Assets/MachineBrigade/Settings/BattlefieldProfile.asset: docs[0].MonoBehaviour.maxIterations | H14: {"m_OverrideState":"0","m_Value":"6"}
A15: Bloom.scatter | B15: Bloom | C15: scatter | D15: 1 | E15: 0.6 | G15: Assets/MachineBrigade/Settings/BattlefieldProfile.asset: docs[0].MonoBehaviour.scatter | H15: {"m_OverrideState":"1","m_Value":"0.6"}
A16: Bloom.skipIterations | B16: Bloom | C16: skipIterations | D16: 1 | E16: 0 | G16: Assets/MachineBrigade/Settings/BattlefieldProfile.asset: docs[0].MonoBehaviour.skipIterations | H16: {"m_OverrideState":"1","m_Value":"0"}
A17: Bloom.threshold | B17: Bloom | C17: threshold | D17: 1 | E17: 1 | G17: Assets/MachineBrigade/Settings/BattlefieldProfile.asset: docs[0].MonoBehaviour.threshold | H17: {"m_OverrideState":"1","m_Value":"1"}
A18: Bloom.tint | B18: Bloom | C18: tint | D18: 0 | E18: {r: 1, g: 1, b: 1, a: 1} | G18: Assets/MachineBrigade/Settings/BattlefieldProfile.asset: docs[0].MonoBehaviour.tint | H18: {"m_OverrideState":"0","m_Value":"{r: 1, g: 1, b: 1, a: 1}"}
A19: ColorAdjustments.active | B19: ColorAdjustments | C19: active | E19: 1 | G19: Assets/MachineBrigade/Settings/BattlefieldProfile.asset: docs[1].MonoBehaviour.active | H19: "1"
A20: ColorAdjustments.colorFilter | B20: ColorAdjustments | C20: colorFilter | D20: 1 | E20: {r: 1, g: 1, b: 1, a: 1} | G20: Assets/MachineBrigade/Settings/BattlefieldProfile.asset: docs[1].MonoBehaviour.colorFilter | H20: {"m_OverrideState":"1","m_Value":"{r: 1, g: 1, b: 1, a: 1}"}
A21: ColorAdjustments.contrast | B21: ColorAdjustments | C21: contrast | D21: 1 | E21: 10 | G21: Assets/MachineBrigade/Settings/BattlefieldProfile.asset: docs[1].MonoBehaviour.contrast | H21: {"m_OverrideState":"1","m_Value":"10"}
A22: ColorAdjustments.hueShift | B22: ColorAdjustments | C22: hueShift | D22: 1 | E22: 0 | G22: Assets/MachineBrigade/Settings/BattlefieldProfile.asset: docs[1].MonoBehaviour.hueShift | H22: {"m_OverrideState":"1","m_Value":"0"}
A23: ColorAdjustments.m_Enabled | B23: ColorAdjustments | C23: m_Enabled | E23: 1 | G23: Assets/MachineBrigade/Settings/BattlefieldProfile.asset: docs[1].MonoBehaviour.m_Enabled | H23: "1"
A24: ColorAdjustments.m_Name | B24: ColorAdjustments | C24: m_Name | E24: ColorAdjustments | G24: Assets/MachineBrigade/Settings/BattlefieldProfile.asset: docs[1].MonoBehaviour.m_Name | H24: "ColorAdjustments"
A25: ColorAdjustments.postExposure | B25: ColorAdjustments | C25: postExposure | D25: 1 | E25: 0.35 | G25: Assets/MachineBrigade/Settings/BattlefieldProfile.asset: docs[1].MonoBehaviour.postExposure | H25: {"m_OverrideState":"1","m_Value":"0.35"}
A26: ColorAdjustments.saturation | B26: ColorAdjustments | C26: saturation | D26: 1 | E26: 0 | G26: Assets/MachineBrigade/Settings/BattlefieldProfile.asset: docs[1].MonoBehaviour.saturation | H26: {"m_OverrideState":"1","m_Value":"0"}
A27: MotionBlur.active | B27: MotionBlur | C27: active | E27: 0 | G27: Assets/MachineBrigade/Settings/BattlefieldProfile.asset: docs[5].MonoBehaviour.active | H27: "0"
A28: MotionBlur.clamp | B28: MotionBlur | C28: clamp | D28: 0 | E28: 0.05 | G28: Assets/MachineBrigade/Settings/BattlefieldProfile.asset: docs[5].MonoBehaviour.clamp | H28: {"m_OverrideState":"0","m_Value":"0.05"}
A29: MotionBlur.intensity | B29: MotionBlur | C29: intensity | D29: 1 | E29: 0.6 | G29: Assets/MachineBrigade/Settings/BattlefieldProfile.asset: docs[5].MonoBehaviour.intensity | H29: {"m_OverrideState":"1","m_Value":"0.6"}
A30: MotionBlur.m_Enabled | B30: MotionBlur | C30: m_Enabled | E30: 1 | G30: Assets/MachineBrigade/Settings/BattlefieldProfile.asset: docs[5].MonoBehaviour.m_Enabled | H30: "1"
A31: MotionBlur.m_Name | B31: MotionBlur | C31: m_Name | E31: MotionBlur | G31: Assets/MachineBrigade/Settings/BattlefieldProfile.asset: docs[5].MonoBehaviour.m_Name | H31: "MotionBlur"
A32: MotionBlur.mode | B32: MotionBlur | C32: mode | D32: 0 | E32: 0 | G32: Assets/MachineBrigade/Settings/BattlefieldProfile.asset: docs[5].MonoBehaviour.mode | H32: {"m_OverrideState":"0","m_Value":"0"}
A33: MotionBlur.quality | B33: MotionBlur | C33: quality | D33: 1 | E33: 2 | G33: Assets/MachineBrigade/Settings/BattlefieldProfile.asset: docs[5].MonoBehaviour.quality | H33: {"m_OverrideState":"1","m_Value":"2"}
A34: Tonemapping.acesPreset | B34: Tonemapping | C34: acesPreset | D34: 0 | E34: 3 | G34: Assets/MachineBrigade/Settings/BattlefieldProfile.asset: docs[4].MonoBehaviour.acesPreset | H34: {"m_OverrideState":"0","m_Value":"3"}
A35: Tonemapping.active | B35: Tonemapping | C35: active | E35: 1 | G35: Assets/MachineBrigade/Settings/BattlefieldProfile.asset: docs[4].MonoBehaviour.active | H35: "1"
A36: Tonemapping.detectBrightnessLimits | B36: Tonemapping | C36: detectBrightnessLimits | D36: 1 | E36: 1 | G36: Assets/MachineBrigade/Settings/BattlefieldProfile.asset: docs[4].MonoBehaviour.detectBrightnessLimits | H36: {"m_OverrideState":"1","m_Value":"1"}
A37: Tonemapping.detectPaperWhite | B37: Tonemapping | C37: detectPaperWhite | D37: 1 | E37: 0 | G37: Assets/MachineBrigade/Settings/BattlefieldProfile.asset: docs[4].MonoBehaviour.detectPaperWhite | H37: {"m_OverrideState":"1","m_Value":"0"}
A38: Tonemapping.hueShiftAmount | B38: Tonemapping | C38: hueShiftAmount | D38: 0 | E38: 0 | G38: Assets/MachineBrigade/Settings/BattlefieldProfile.asset: docs[4].MonoBehaviour.hueShiftAmount | H38: {"m_OverrideState":"0","m_Value":"0"}
A39: Tonemapping.m_Enabled | B39: Tonemapping | C39: m_Enabled | E39: 1 | G39: Assets/MachineBrigade/Settings/BattlefieldProfile.asset: docs[4].MonoBehaviour.m_Enabled | H39: "1"
A40: Tonemapping.m_Name | B40: Tonemapping | C40: m_Name | E40: Tonemapping | G40: Assets/MachineBrigade/Settings/BattlefieldProfile.asset: docs[4].MonoBehaviour.m_Name | H40: "Tonemapping"
...

Sheet Xac_vo
A1: id | B1: tran_day_du | C1: song_toi_thieu_s | D1: song_toi_da_s | E1: song_boss_s | F1: nguon | G1: raw_json
A2: High | B2: 12 | C2: 30 | D2: 45 | E2: 90 | F2: game.json balancePack.wrecks
A3: Low | B3: 6 | C3: 20.1 | D3: 30.15 | E3: 60.3 | F3: game.json balancePack.wrecks
A4: Medium | B4: 9 | C4: 30 | D4: 45 | E4: 90 | F4: game.json balancePack.wrecks

Sheet Am_thanh_mixer
A1: id | B1: loai | C1: gia_tri | D1: nguon | E1: raw_json
A2: am_luong.dialogue | B2: am_luong_mac_dinh | C2: 1 | D2: game.json balancePack.audio
A3: am_luong.effects | B3: am_luong_mac_dinh | C3: 1 | D3: game.json balancePack.audio
A4: am_luong.master | B4: am_luong_mac_dinh | C4: 0.8 | D4: game.json balancePack.audio
A5: am_luong.music | B5: am_luong_mac_dinh | C5: 0.7 | D5: game.json balancePack.audio
A6: nhom.Dialogue | B6: nhom_kenh | D6: game.json balancePack.audio
A7: nhom.Effects | B7: nhom_kenh | D7: game.json balancePack.audio
A8: nhom.Music | B8: nhom_kenh | D8: game.json balancePack.audio
A9: nhom.UI | B9: nhom_kenh | D9: game.json balancePack.audio

Sheet Am_thanh_mau
A1: id | B1: tep | C1: do_dai_s | D1: kenh | E1: tan_so_mau_hz | F1: lufs_mmax_tinh | G1: so_moc | H1: events | I1: played | J1: cooldown | K1: out_of_reach | L1: cut_for_priority | M1: dropped_no_voice | N1: clustered_shots | O1: metal_played | P1: metal_capped | Q1: max_busy | R1: bursts | S1: burst_events | T1: burst_dropped_at_cap | U1: limiter_min_gain_db | V1: compressor_min_gain_db | W1: do_dai_tron_s | X1: lufs | Y1: lufs_mmax | Z1: peak_db | AA1: sub150 | AB1: nguon | AC1: raw_json
A2: boss_battle | B2: Docs/audio/samples/boss_battle.ogg | C2: 48 | D2: 2 | E2: 44100 | F2: -13.9 | G2: 8 | H2: 1288 | I2: 972 | J2: 261 | K2: 0 | L2: 8 | M2: 1 | N2: 172 | O2: 24 | P2: 0 | Q2: 24 | R2: 298 | S2: 1003 | T2: 54 | U2: -0.5 | V2: -4.5 | W2: 48 | X2: -18.4 | Y2: -13.8 | Z2: -1 | AA2: 65.8 | AB2: Docs/audio/samples/boss_battle.ogg; Docs/audio/samples/mixes.json[boss_battle] | AC2: {"events":1288,"played":972,"cooldown":261,"out_of_reach":0,"cut_for_priority":8,"dropped_no_voice":1,"clustered_shots":172,"metal_played":24,"metal_capped":0,"max_busy":24,"bursts":298,"burst_events":1003,"burst_dropped_at_cap":54,"limiter_min_gain_db":-0.5,"compressor_min_gain_db":-4.5,"seconds":48.0,"lufs":-18.4,"lufs_mmax":-13.8,"peak_db":-1.0,"sub150":65.8}
A3: crowded_battle | B3: Docs/audio/samples/crowded_battle.ogg | C3: 43 | D3: 2 | E3: 44100 | F3: -15 | G3: 8 | H3: 5930 | I3: 1830 | J3: 2802 | K3: 0 | L3: 350 | M3: 228 | N3: 568 | O3: 97 | P3: 333 | Q3: 25 | R3: 1802 | S3: 6387 | T3: 1070 | U3: 0 | V3: -1 | W3: 43 | X3: -17.7 | Y3: -14.8 | Z3: -1 | AA3: 32.1 | AB3: Docs/audio/samples/crowded_battle.ogg; Docs/audio/samples/mixes.json[crowded_battle] | AC3: {"events":5930,"played":1830,"cooldown":2802,"out_of_reach":0,"cut_for_priority":350,"dropped_no_voice":228,"clustered_shots":568,"metal_played":97,"metal_capped":333,"max_busy":25,"bursts":1802,"burst_events":6387,"burst_dropped_at_cap":1070,"limiter_min_gain_db":-0.0,"compressor_min_gain_db":-1.0,"seconds":43.0,"lufs":-17.7,"lufs_mmax":-14.8,"peak_db":-1.0,"sub150":32.1}
A4: normal_battle | B4: Docs/audio/samples/normal_battle.ogg | C4: 43 | D4: 2 | E4: 44100 | F4: -15.6 | G4: 8 | H4: 1150 | I4: 739 | J4: 251 | K4: 0 | L4: 0 | M4: 0 | N4: 0 | O4: 28 | P4: 1 | Q4: 20 | R4: 349 | S4: 1065 | T4: 160 | U4: 0 | V4: -0.8 | W4: 43 | X4: -22 | Y4: -15.5 | Z4: -2.2 | AA4: 39 | AB4: Docs/audio/samples/normal_battle.ogg; Docs/audio/samples/mixes.json[normal_battle] | AC4: {"events":1150,"played":739,"cooldown":251,"out_of_reach":0,"cut_for_priority":0,"dropped_no_voice":0,"clustered_shots":0,"metal_played":28,"metal_capped":1,"max_busy":20,"bursts":349,"burst_events":1065,"burst_dropped_at_cap":160,"limiter_min_gain_db":0.0,"compressor_min_gain_db":-0.8,"seconds":43.0,"lufs":-22.0,"lufs_mmax":-15.5,"peak_db":-2.2,"sub150":39.0}

Sheet Am_thanh_mau_moc
A1: id | B1: am_thanh_mau_id | C1: thu_tu | D1: thoi_diem_s | E1: lufs_400ms | F1: duoi_to_nhat_lu | G1: dinh_dbfs | H1: hang | I1: nguon | J1: raw_json
A2: boss_battle/1 | B2: boss_battle | C2: 0 | D2: 9.7 | E2: -15.7 | F2: 1.8 | G2: -3.5 | H2: 5 | I2: Docs/audio/samples/boss_battle.ogg @ 9.7 s
A3: boss_battle/2 | B3: boss_battle | C3: 1 | D3: 13.2 | E3: -15.1 | F3: 1.2 | G3: -1.2 | H3: 2 | I3: Docs/audio/samples/boss_battle.ogg @ 13.2 s
A4: boss_battle/3 | B4: boss_battle | C4: 2 | D4: 21.4 | E4: -15.7 | F4: 1.8 | G4: -2.2 | H4: 6 | I4: Docs/audio/samples/boss_battle.ogg @ 21.4 s
A5: boss_battle/4 | B5: boss_battle | C5: 3 | D5: 29.4 | E5: -15.5 | F5: 1.6 | G5: -2.6 | H5: 4 | I5: Docs/audio/samples/boss_battle.ogg @ 29.4 s
A6: boss_battle/5 | B6: boss_battle | C6: 4 | D6: 31.7 | E6: -16.6 | F6: 2.7 | G6: -2.2 | H6: 8 | I6: Docs/audio/samples/boss_battle.ogg @ 31.7 s
A7: boss_battle/6 | B7: boss_battle | C7: 5 | D7: 33.7 | E7: -13.9 | F7: 0 | G7: -1 | H7: 1 | I7: Docs/audio/samples/boss_battle.ogg @ 33.7 s
A8: boss_battle/7 | B8: boss_battle | C8: 6 | D8: 36.2 | E8: -15.1 | F8: 1.2 | G8: -1.7 | H8: 3 | I8: Docs/audio/samples/boss_battle.ogg @ 36.2 s
A9: boss_battle/8 | B9: boss_battle | C9: 7 | D9: 43.1 | E9: -16 | F9: 2.1 | G9: -1.6 | H9: 7 | I9: Docs/audio/samples/boss_battle.ogg @ 43.1 s
A10: crowded_battle/1 | B10: crowded_battle | C10: 0 | D10: 1.9 | E10: -16.1 | F10: 1.1 | G10: -2.8 | H10: 4 | I10: Docs/audio/samples/crowded_battle.ogg @ 1.9 s
A11: crowded_battle/2 | B11: crowded_battle | C11: 1 | D11: 10.7 | E11: -15.3 | F11: 0.3 | G11: -1 | H11: 2 | I11: Docs/audio/samples/crowded_battle.ogg @ 10.7 s
A12: crowded_battle/3 | B12: crowded_battle | C12: 2 | D12: 15.3 | E12: -16.5 | F12: 1.5 | G12: -4.1 | H12: 6 | I12: Docs/audio/samples/crowded_battle.ogg @ 15.3 s
A13: crowded_battle/4 | B13: crowded_battle | C13: 3 | D13: 18.7 | E13: -15.8 | F13: 0.8 | G13: -3.2 | H13: 3 | I13: Docs/audio/samples/crowded_battle.ogg @ 18.7 s
... A25: normal_battle/8 | B25: normal_battle | C25: 7 | D25: 39.5 | E25: -18.2 | F25: 2.6 | G25: -5 | H25: 7 | I25: Docs/audio/samples/normal_battle.ogg @ 39.5 s

Sheet VFX_vu_khi
A1: id | B1: loai | C1: vu_khi | D1: bac | E1: co_mm | F1: so_nong | G1: loat | H1: don_vi_mang | I1: thu_muc | J1: so_anh | K1: so_anh_co | L1: trang_thai | M1: nguon | N1: raw_json
A2: amos_120 | B2: vu_khi | C2: amos_120 | D2: 3 | E2: 120 | F2: 1 | G2: FALSE | H2: sp_mortar | I2: Builds/effect_shots/amos_120/ | J2: 8 | K2: 0 | L2: pending | M2: EffectShots.FxJobs (01_chien_dau/Vu_khi); Builds/effect_shots/amos_120/
A3: bastion_gun | B3: vu_khi | C3: bastion_gun | D3: 3 | E3: 152 | F3: 2 | G3: TRUE | H3: headquarters;headquarters.fortress_air;headquarters.fortress_ground;headquarters.shield;spawn_bastion | I3: Builds/effect_shots/bastion_gun/ | J3: 10 | K3: 0 | L3: pending | M3: EffectShots.FxJobs (01_chien_dau/Vu_khi); Builds/effect_shots/bastion_gun/
A4: boss_howitzer | B4: vu_khi | C4: boss_howitzer | D4: 4 | E4: 203 | F4: 1 | G4: FALSE | H4: howitzer_203 | I4: Builds/effect_shots/boss_howitzer/ | J4: 8 | K4: 0 | L4: pending | M4: EffectShots.FxJobs (01_chien_dau/Vu_khi); Builds/effect_shots/boss_howitzer/
A5: boss_rockets | B5: vu_khi | C5: boss_rockets | D5: 3 | E5: 122 | F5: 1 | G5: FALSE | H5: rocket_pod | I5: Builds/effect_shots/boss_rockets/ | J5: 8 | K5: 0 | L5: pending | M5: EffectShots.FxJobs (01_chien_dau/Vu_khi); Builds/effect_shots/boss_rockets/
A6: boss_thermo | B6: vu_khi | C6: boss_thermo | D6: 3 | E6: 125 | F6: 1 | G6: FALSE | H6: behemoth_inferno | I6: Builds/effect_shots/boss_thermo/ | J6: 8 | K6: 0 | L6: pending | M6: EffectShots.FxJobs (01_chien_dau/Vu_khi); Builds/effect_shots/boss_thermo/
A7: casemate_155 | B7: vu_khi | C7: casemate_155 | D7: 3 | E7: 155 | F7: 1 | G7: FALSE | H7: casemate_155 | I7: Builds/effect_shots/casemate_155/ | J7: 8 | K7: 0 | L7: pending | M7: EffectShots.FxJobs (01_chien_dau/Vu_khi); Builds/effect_shots/casemate_155/
A8: cruiser_203 | B8: vu_khi | C8: cruiser_203 | D8: 4 | E8: 203 | F8: 2 | G8: TRUE | H8: sea_cruiser | I8: Builds/effect_shots/cruiser_203/ | J8: 10 | K8: 0 | L8: pending | M8: EffectShots.FxJobs (01_chien_dau/Vu_khi); Builds/effect_shots/cruiser_203/
A9: grad_cluster | B9: vu_khi | C9: grad_cluster | D9: 3 | E9: 122 | F9: 1 | G9: FALSE | H9: elite_grad | I9: Builds/effect_shots/grad_cluster/ | J9: 8 | K9: 0 | L9: pending | M9: EffectShots.FxJobs (01_chien_dau/Vu_khi); Builds/effect_shots/grad_cluster/
A10: gun_105_apfsds | B10: vu_khi | C10: gun_105_apfsds | D10: 3 | E10: 125 | F10: 1 | G10: FALSE | H10: elite_tank_destroyer | I10: Builds/effect_shots/gun_105_apfsds/ | J10: 8 | K10: 0 | L10: pending | M10: EffectShots.FxJobs (01_chien_dau/Vu_khi); Builds/effect_shots/gun_105_apfsds/
A11: gun_105_long | B11: vu_khi | C11: gun_105_long | D11: 3 | E11: 125 | F11: 1 | G11: FALSE | H11: tank_destroyer | I11: Builds/effect_shots/gun_105_long/ | J11: 8 | K11: 0 | L11: pending | M11: EffectShots.FxJobs (01_chien_dau/Vu_khi); Builds/effect_shots/gun_105_long/
A12: gun_105_wheeled | B12: vu_khi | C12: gun_105_wheeled | D12: 3 | E12: 120 | F12: 1 | G12: FALSE | H12: wheeled_gun | I12: Builds/effect_shots/gun_105_wheeled/ | J12: 8 | K12: 0 | L12: pending | M12: EffectShots.FxJobs (01_chien_dau/Vu_khi); Builds/effect_shots/gun_105_wheeled/
A13: gun_120_twin | B13: vu_khi | C13: gun_120_twin | D13: 3 | E13: 120 | F13: 1 | G13: FALSE | H13: twin_tank | I13: Builds/effect_shots/gun_120_twin/ | J13: 8 | K13: 0 | L13: pending | M13: EffectShots.FxJobs (01_chien_dau/Vu_khi); Builds/effect_shots/gun_120_twin/
... A59: thermobaric_rockets | B59: vu_khi | C59: thermobaric_rockets | D59: 4 | E59: 220 | F59: 1 | G59: FALSE | H59: thermobaric_launcher | I59: Builds/effect_shots/thermobaric_rockets/ | J59: 8 | K59: 0 | L59: pending | M59: EffectShots.FxJobs (01_chien_dau/Vu_khi); Builds/effect_shots/thermobaric_rockets/
A60: tier_T0 | B60: bac | D60: 0 | I60: Builds/effect_shots/tier_T0/ | J60: 8 | K60: 0 | L60: pending | M60: EffectShots.FxJobs (01_chien_dau/Vu_khi); Builds/effect_shots/tier_T0/
A61: tier_T1 | B61: bac | D61: 1 | I61: Builds/effect_shots/tier_T1/ | J61: 8 | K61: 0 | L61: pending | M61: EffectShots.FxJobs (01_chien_dau/Vu_khi); Builds/effect_shots/tier_T1/
A62: tier_T2 | B62: bac | D62: 2 | I62: Builds/effect_shots/tier_T2/ | J62: 8 | K62: 0 | L62: pending | M62: EffectShots.FxJobs (01_chien_dau/Vu_khi); Builds/effect_shots/tier_T2/
A63: tier_T3 | B63: bac | D63: 3 | I63: Builds/effect_shots/tier_T3/ | J63: 8 | K63: 0 | L63: pending | M63: EffectShots.FxJobs (01_chien_dau/Vu_khi); Builds/effect_shots/tier_T3/
A64: tier_T4 | B64: bac | D64: 4 | I64: Builds/effect_shots/tier_T4/ | J64: 8 | K64: 0 | L64: pending | M64: EffectShots.FxJobs (01_chien_dau/Vu_khi); Builds/effect_shots/tier_T4/
A65: tier_T5 | B65: bac | D65: 5 | I65: Builds/effect_shots/tier_T5/ | J65: 8 | K65: 0 | L65: pending | M65: EffectShots.FxJobs (01_chien_dau/Vu_khi); Builds/effect_shots/tier_T5/
A66: train_gun | B66: vu_khi | C66: train_gun | D66: 3 | E66: 152 | F66: 1 | G66: FALSE | H66: armored_train | I66: Builds/effect_shots/train_gun/ | J66: 8 | K66: 0 | L66: pending | M66: EffectShots.FxJobs (01_chien_dau/Vu_khi); Builds/effect_shots/train_gun/
A67: turret_gmlrs | B67: vu_khi | C67: turret_gmlrs | D67: 4 | E67: 227 | F67: 1 | G67: FALSE | H67: rocket_turret.guided | I67: Builds/effect_shots/turret_gmlrs/ | J67: 8 | K67: 0 | L67: pending | M67: EffectShots.FxJobs (01_chien_dau/Vu_khi); Builds/effect_shots/turret_gmlrs/
A68: turret_gun_120 | B68: vu_khi | C68: turret_gun_120 | D68: 3 | E68: 120 | F68: 1 | G68: FALSE | H68: gun_turret | I68: Builds/effect_shots/turret_gun_120/ | J68: 8 | K68: 0 | L68: pending | M68: EffectShots.FxJobs (01_chien_dau/Vu_khi); Builds/effect_shots/turret_gun_120/
A69: turret_gun_120_long | B69: vu_khi | C69: turret_gun_120_long | D69: 3 | E69: 120 | F69: 1 | G69: FALSE | H69: gun_turret.long;headquarters.fortress_ground | I69: Builds/effect_shots/turret_gun_120_long/ | J69: 8 | K69: 0 | L69: pending | M69: EffectShots.FxJobs (01_chien_dau/Vu_khi); Builds/effect_shots/turret_gun_120_long/
A70: turret_rockets | B70: vu_khi | C70: turret_rockets | D70: 3 | E70: 122 | F70: 1 | G70: FALSE | H70: rocket_turret | I70: Builds/effect_shots/turret_rockets/ | J70: 8 | K70: 0 | L70: pending | M70: EffectShots.FxJobs (01_chien_dau/Vu_khi); Builds/effect_shots/turret_rockets/
A71: turret_rockets_cluster | B71: vu_khi | C71: turret_rockets_cluster | D71: 3 | E71: 122 | F71: 1 | G71: FALSE | H71: rocket_turret.cluster | I71: Builds/effect_shots/turret_rockets_cluster/ | J71: 8 | K71: 0 | L71: pending | M71: EffectShots.FxJobs (01_chien_dau/Vu_khi); Builds/effect_shots/turret_rockets_cluster/

Sheet VFX_vu_khi_anh
A1: id | B1: vfx_vu_khi_id | C1: thu_tu | D1: khung | E1: thoi_diem_s | F1: duong_dan | G1: trang_thai | H1: nguon | I1: raw_json
A2: amos_120/fire_0.2s.png | B2: amos_120 | C2: 1 | D2: fire | E2: 0.2 | F2: Builds/effect_shots/amos_120/fire_0.2s.png | G2: pending | H2: Builds/effect_shots/amos_120/fire_0.2s.png
A3: amos_120/fire_0s.png | B3: amos_120 | C3: 0 | D3: fire | E3: 0 | F3: Builds/effect_shots/amos_120/fire_0s.png | G3: pending | H3: Builds/effect_shots/amos_120/fire_0s.png
A4: amos_120/fire_1s.png | B4: amos_120 | C4: 2 | D4: fire | E4: 1 | F4: Builds/effect_shots/amos_120/fire_1s.png | G4: pending | H4: Builds/effect_shots/amos_120/fire_1s.png
A5: amos_120/impact_0.5s.png | B5: amos_120 | C5: 4 | D5: impact | E5: 0.5 | F5: Builds/effect_shots/amos_120/impact_0.5s.png | G5: pending | H5: Builds/effect_shots/amos_120/impact_0.5s.png
A6: amos_120/impact_0s.png | B6: amos_120 | C6: 3 | D6: impact | E6: 0 | F6: Builds/effect_shots/amos_120/impact_0s.png | G6: pending | H6: Builds/effect_shots/amos_120/impact_0s.png
A7: amos_120/impact_2s.png | B7: amos_120 | C7: 5 | D7: impact | E7: 2 | F7: Builds/effect_shots/amos_120/impact_2s.png | G7: pending | H7: Builds/effect_shots/amos_120/impact_2s.png
A8: amos_120/impact_10s.png | B8: amos_120 | C8: 6 | D8: impact | E8: 10 | F8: Builds/effect_shots/amos_120/impact_10s.png | G8: pending | H8: Builds/effect_shots/amos_120/impact_10s.png
A9: amos_120/impact_30s.png | B9: amos_120 | C9: 7 | D9: impact | E9: 30 | F9: Builds/effect_shots/amos_120/impact_30s.png | G9: pending | H9: Builds/effect_shots/amos_120/impact_30s.png
A10: bastion_gun/fire_0.2s.png | B10: bastion_gun | C10: 1 | D10: fire | E10: 0.2 | F10: Builds/effect_shots/bastion_gun/fire_0.2s.png | G10: pending | H10: Builds/effect_shots/bastion_gun/fire_0.2s.png
A11: bastion_gun/fire_0s.png | B11: bastion_gun | C11: 0 | D11: fire | E11: 0 | F11: Builds/effect_shots/bastion_gun/fire_0s.png | G11: pending | H11: Builds/effect_shots/bastion_gun/fire_0s.png
A12: bastion_gun/fire_1s.png | B12: bastion_gun | C12: 2 | D12: fire | E12: 1 | F12: Builds/effect_shots/bastion_gun/fire_1s.png | G12: pending | H12: Builds/effect_shots/bastion_gun/fire_1s.png
A13: bastion_gun/impact_0.5s.png | B13: bastion_gun | C13: 4 | D13: impact | E13: 0.5 | F13: Builds/effect_shots/bastion_gun/impact_0.5s.png | G13: pending | H13: Builds/effect_shots/bastion_gun/impact_0.5s.png
... A17: bastion_gun/impact_30s.png | B17: bastion_gun | C17: 7 | D17: impact | E17: 30 | F17: Builds/effect_shots/bastion_gun/impact_30s.png | G17: pending | H17: Builds/effect_shots/bastion_gun/impact_30s.png
A18: bastion_gun/salvo.png | B18: bastion_gun | C18: 8 | D18: salvo | F18: Builds/effect_shots/bastion_gun/salvo.png | G18: pending | H18: Builds/effect_shots/bastion_gun/salvo.png
A19: bastion_gun/salvo_impact.png | B19: bastion_gun | C19: 9 | D19: salvo_impact | E19: 0.5 | F19: Builds/effect_shots/bastion_gun/salvo_impact.png | G19: pending | H19: Builds/effect_shots/bastion_gun/salvo_impact.png
A20: boss_howitzer/fire_0.2s.png | B20: boss_howitzer | C20: 1 | D20: fire | E20: 0.2 | F20: Builds/effect_shots/boss_howitzer/fire_0.2s.png | G20: pending | H20: Builds/effect_shots/boss_howitzer/fire_0.2s.png
A21: boss_howitzer/fire_0s.png | B21: boss_howitzer | C21: 0 | D21: fire | E21: 0 | F21: Builds/effect_shots/boss_howitzer/fire_0s.png | G21: pending | H21: Builds/effect_shots/boss_howitzer/fire_0s.png
A22: boss_howitzer/fire_1s.png | B22: boss_howitzer | C22: 2 | D22: fire | E22: 1 | F22: Builds/effect_shots/boss_howitzer/fire_1s.png | G22: pending | H22: Builds/effect_shots/boss_howitzer/fire_1s.png
A23: boss_howitzer/impact_0.5s.png | B23: boss_howitzer | C23: 4 | D23: impact | E23: 0.5 | F23: Builds/effect_shots/boss_howitzer/impact_0.5s.png | G23: pending | H23: Builds/effect_shots/boss_howitzer/impact_0.5s.png
A24: boss_howitzer/impact_0s.png | B24: boss_howitzer | C24: 3 | D24: impact | E24: 0 | F24: Builds/effect_shots/boss_howitzer/impact_0s.png | G24: pending | H24: Builds/effect_shots/boss_howitzer/impact_0s.png
A25: boss_howitzer/impact_2s.png | B25: boss_howitzer | C25: 5 | D25: impact | E25: 2 | F25: Builds/effect_shots/boss_howitzer/impact_2s.png | G25: pending | H25: Builds/effect_shots/boss_howitzer/impact_2s.png
A26: boss_howitzer/impact_10s.png | B26: boss_howitzer | C26: 6 | D26: impact | E26: 10 | F26: Builds/effect_shots/boss_howitzer/impact_10s.png | G26: pending | H26: Builds/effect_shots/boss_howitzer/impact_10s.png
A27: boss_howitzer/impact_30s.png | B27: boss_howitzer | C27: 7 | D27: impact | E27: 30 | F27: Builds/effect_shots/boss_howitzer/impact_30s.png | G27: pending | H27: Builds/effect_shots/boss_howitzer/impact_30s.png
A28: boss_rockets/fire_0.2s.png | B28: boss_rockets | C28: 1 | D28: fire | E28: 0.2 | F28: Builds/effect_shots/boss_rockets/fire_0.2s.png | G28: pending | H28: Builds/effect_shots/boss_rockets/fire_0.2s.png
A29: boss_rockets/fire_0s.png | B29: boss_rockets | C29: 0 | D29: fire | E29: 0 | F29: Builds/effect_shots/boss_rockets/fire_0s.png | G29: pending | H29: Builds/effect_shots/boss_rockets/fire_0s.png
A30: boss_rockets/fire_1s.png | B30: boss_rockets | C30: 2 | D30: fire | E30: 1 | F30: Builds/effect_shots/boss_rockets/fire_1s.png | G30: pending | H30: Builds/effect_shots/boss_rockets/fire_1s.png
... A59: cruiser_203/impact_30s.png | B59: cruiser_203 | C59: 7 | D59: impact | E59: 30 | F59: Builds/effect_shots/cruiser_203/impact_30s.png | G59: pending | H59: Builds/effect_shots/cruiser_203/impact_30s.png
A60: cruiser_203/salvo.png | B60: cruiser_203 | C60: 8 | D60: salvo | F60: Builds/effect_shots/cruiser_203/salvo.png | G60: pending | H60: Builds/effect_shots/cruiser_203/salvo.png
A61: cruiser_203/salvo_impact.png | B61: cruiser_203 | C61: 9 | D61: salvo_impact | E61: 0.5 | F61: Builds/effect_shots/cruiser_203/salvo_impact.png | G61: pending | H61: Builds/effect_shots/cruiser_203/salvo_impact.png
A62: grad_cluster/fire_0.2s.png | B62: grad_cluster | C62: 1 | D62: fire | E62: 0.2 | F62: Builds/effect_shots/grad_cluster/fire_0.2s.png | G62: pending | H62: Builds/effect_shots/grad_cluster/fire_0.2s.png
A63: grad_cluster/fire_0s.png | B63: grad_cluster | C63: 0 | D63: fire | E63: 0 | F63: Builds/effect_shots/grad_cluster/fire_0s.png | G63: pending | H63: Builds/effect_shots/grad_cluster/fire_0s.png
A64: grad_cluster/fire_1s.png | B64: grad_cluster | C64: 2 | D64: fire | E64: 1 | F64: Builds/effect_shots/grad_cluster/fire_1s.png | G64: pending | H64: Builds/effect_shots/grad_cluster/fire_1s.png
A65: grad_cluster/impact_0.5s.png | B65: grad_cluster | C65: 4 | D65: impact | E65: 0.5 | F65: Builds/effect_shots/grad_cluster/impact_0.5s.png | G65: pending | H65: Builds/effect_shots/grad_cluster/impact_0.5s.png
A66: grad_cluster/impact_0s.png | B66: grad_cluster | C66: 3 | D66: impact | E66: 0 | F66: Builds/effect_shots/grad_cluster/impact_0s.png | G66: pending | H66: Builds/effect_shots/grad_cluster/impact_0s.png
A67: grad_cluster/impact_2s.png | B67: grad_cluster | C67: 5 | D67: impact | E67: 2 | F67: Builds/effect_shots/grad_cluster/impact_2s.png | G67: pending | H67: Builds/effect_shots/grad_cluster/impact_2s.png
A68: grad_cluster/impact_10s.png | B68: grad_cluster | C68: 6 | D68: impact | E68: 10 | F68: Builds/effect_shots/grad_cluster/impact_10s.png | G68: pending | H68: Builds/effect_shots/grad_cluster/impact_10s.png
A69: grad_cluster/impact_30s.png | B69: grad_cluster | C69: 7 | D69: impact | E69: 30 | F69: Builds/effect_shots/grad_cluster/impact_30s.png | G69: pending | H69: Builds/effect_shots/grad_cluster/impact_30s.png
A70: gun_105_apfsds/fire_0.2s.png | B70: gun_105_apfsds | C70: 1 | D70: fire | E70: 0.2 | F70: Builds/effect_shots/gun_105_apfsds/fire_0.2s.png | G70: pending | H70: Builds/effect_shots/gun_105_apfsds/fire_0.2s.png
A71: gun_105_apfsds/fire_0s.png | B71: gun_105_apfsds | C71: 0 | D71: fire | E71: 0 | F71: Builds/effect_shots/gun_105_apfsds/fire_0s.png | G71: pending | H71: Builds/effect_shots/gun_105_apfsds/fire_0s.png
...

Sheet Am_thanh_so_do
A1: id | B1: do_dai_s | C1: lufs | D1: lufs_mmax | E1: dinh_db | F1: dinh_that_db | G1: duoi_150hz_pct | H1: duoi_s | I1: keng_noi_db | J1: keng_tat_s | K1: keng_rong_hz | L1: keng_tan_so_hz | M1: keng_bao_cao | N1: bao_cao_cu | O1: keng | P1: keng_ngoai_giap | Q1: nguon | R1: raw_json
A2: autocannon/autocannon_1 | B2: 0.695 | C2: -21.5 | D2: -18.6 | E2: -0.9 | F2: -0.8 | G2: 44.3 | H2: 0.56 | I2: 4.2 | J2: 0.116 | K2: 517 | L2: 3854 | M2: FALSE | N2: FALSE | O2: =AND($I$2>=12.0,$J$2>=0.12,$K$2<160.0) | P2: =AND($O$2,Am_thanh!$C$10<>"armour_metal") | Q2: Docs/audio/metrics.json: clips["autocannon/autocannon_1.ogg"]
A3: autocannon/autocannon_2 | B3: 0.695 | C3: -15.5 | D3: -14 | E3: -0.9 | F3: -0.9 | G3: 43.9 | H3: 0.46 | I3: 3.9 | J3: 0.035 | K3: 409 | L3: 4328 | M3: FALSE | N3: FALSE | O3: =AND($I$3>=12.0,$J$3>=0.12,$K$3<160.0) | P3: =AND($O$3,Am_thanh!$C$11<>"armour_metal") | Q3: Docs/audio/metrics.json: clips["autocannon/autocannon_2.ogg"]
A4: autocannon/autocannon_3 | B4: 0.682 | C4: -17.1 | D4: -15.4 | E4: -1 | F4: -1 | G4: 49.6 | H4: 0.34 | I4: 4.9 | J4: 0.035 | K4: 280 | L4: 3962 | M4: FALSE | N4: FALSE | O4: =AND($I$4>=12.0,$J$4>=0.12,$K$4<160.0) | P4: =AND($O$4,Am_thanh!$C$12<>"armour_metal") | Q4: Docs/audio/metrics.json: clips["autocannon/autocannon_3.ogg"]
A5: cannon/cannon_1 | B5: 1.5 | C5: -16.7 | D5: -14.5 | E5: -1.6 | F5: -1.6 | G5: 70.3 | H5: 0.82 | I5: 3.4 | J5: 0.081 | K5: 2304 | L5: 2196 | M5: FALSE | N5: FALSE | O5: =AND($I$5>=12.0,$J$5>=0.12,$K$5<160.0) | P5: =AND($O$5,Am_thanh!$C$13<>"armour_metal") | Q5: Docs/audio/metrics.json: clips["cannon/cannon_1.ogg"]
A6: cannon/cannon_2 | B6: 1.5 | C6: -20.6 | D6: -15.6 | E6: -1 | F6: -1 | G6: 53.9 | H6: 1.1 | I6: 2.3 | J6: 0.139 | K6: 2304 | L6: 2046 | M6: FALSE | N6: FALSE | O6: =AND($I$6>=12.0,$J$6>=0.12,$K$6<160.0) | P6: =AND($O$6,Am_thanh!$C$14<>"armour_metal") | Q6: Docs/audio/metrics.json: clips["cannon/cannon_2.ogg"]
A7: cannon/cannon_3 | B7: 1.384 | C7: -22.5 | D7: -16.5 | E7: -0.9 | F7: -0.9 | G7: 45.5 | H7: 1.11 | I7: 0 | J7: 0 | K7: 0 | L7: 0 | M7: FALSE | N7: FALSE | O7: =AND($I$7>=12.0,$J$7>=0.12,$K$7<160.0) | P7: =AND($O$7,Am_thanh!$C$15<>"armour_metal") | Q7: Docs/audio/metrics.json: clips["cannon/cannon_3.ogg"]
A8: click/click_1 | B8: 0.092 | C8: -21 | D8: -21 | E8: -1.7 | F8: -1.3 | G8: 32.5 | H8: 0.03 | I8: 8.1 | J8: 0.035 | K8: 194 | L8: 3187 | M8: FALSE | N8: FALSE | O8: =AND($I$8>=12.0,$J$8>=0.12,$K$8<160.0) | P8: =AND($O$8,Am_thanh!$C$16<>"armour_metal") | Q8: Docs/audio/metrics.json: clips["click/click_1.ogg"]
A9: click/click_2 | B9: 0.065 | C9: -23.8 | D9: -23.8 | E9: -1 | F9: -1 | G9: 1.3 | H9: 0.04 | I9: 0 | J9: 0 | K9: 0 | L9: 0 | M9: FALSE | N9: FALSE | O9: =AND($I$9>=12.0,$J$9>=0.12,$K$9<160.0) | P9: =AND($O$9,Am_thanh!$C$17<>"armour_metal") | Q9: Docs/audio/metrics.json: clips["click/click_2.ogg"]
A10: collapse/collapse_1 | B10: 3.697 | C10: -19.2 | D10: -15.1 | E10: -1 | F10: -0.3 | G10: 89.4 | H10: 1.61 | I10: 4.4 | J10: 0.023 | K10: 345 | L10: 2455 | M10: FALSE | N10: FALSE | O10: =AND($I$10>=12.0,$J$10>=0.12,$K$10<160.0) | P10: =AND($O$10,Am_thanh!$C$18<>"armour_metal") | Q10: Docs/audio/metrics.json: clips["collapse/collapse_1.ogg"]
A11: collapse/collapse_2 | B11: 3.853 | C11: -20.1 | D11: -15.5 | E11: -1 | F11: -1 | G11: 57.5 | H11: 2.57 | I11: 0.4 | J11: 0.116 | K11: 3295 | L11: 2024 | M11: FALSE | N11: FALSE | O11: =AND($I$11>=12.0,$J$11>=0.12,$K$11<160.0) | P11: =AND($O$11,Am_thanh!$C$19<>"armour_metal") | Q11: Docs/audio/metrics.json: clips["collapse/collapse_2.ogg"]
A12: debris/debris_1 | B12: 0.805 | C12: -20.3 | D12: -17.8 | E12: -0.9 | F12: -0.8 | G12: 4.4 | H12: 0.55 | I12: 5.1 | J12: 0.058 | K12: 301 | L12: 3230 | M12: FALSE | N12: FALSE | O12: =AND($I$12>=12.0,$J$12>=0.12,$K$12<160.0) | P12: =AND($O$12,Am_thanh!$C$20<>"armour_metal") | Q12: Docs/audio/metrics.json: clips["debris/debris_1.ogg"]
