Workbook

Sheet Chien_thuat
A1: id | B1: counters | C1: countered_by | D1: prefer | E1: commanders | F1: chapter | G1: check_with | H1: cp | I1: interlude | J1: modules | K1: modules_artillery_prep | L1: modules_attack_threshold | M1: modules_bounding | N1: modules_cohesion | O1: modules_counterattack | P1: modules_cp_saving | Q1: modules_drop_secondary | R1: modules_engage | S1: modules_fallback | T1: modules_flank | U1: modules_focus | V1: modules_heavy_lead | W1: modules_hold | X1: modules_hold_base | Y1: modules_hold_fire | Z1: modules_kite | AA1: modules_main_effort | AB1: modules_mass_support | AC1: modules_pace | AD1: modules_pincer | AE1: modules_sead_cards | AF1: modules_spread | AG1: modules_stance | AH1: modules_standoff_m | AI1: modules_targets | AJ1: modules_together | AK1: modules_tower_mode | AL1: modules_wait_air | AM1: name | AN1: nguon | AO1: raw_json
A2: air_superiority | B2: hit_and_run | C2: blitz | D2: fighter_jet;stealth_fighter;sam_launcher;long_sam;heavy_aa | E2: reyes | F2: 3 | G2: sead | H2: 0.15;0.12;0.08;0.08;0.2;0.1;0.22;0.05 | I2: 0 | AL2: 1 | AM2: Ưu thế trên không | AN2: Assets/MachineBrigade/Resources/Data/balance.json: aiBehaviour.tactics[10] | AO2: {"id":"air_superiority","name":"Ưu thế trên không","cp":[0.15,0.12,0.08,0.08,0.2,0.1,0.22,0.05],"prefer":["fighter_jet","stealth_fighter","sam_launcher","long_sam","heavy_aa"],"counters":["hit_and_run"],"counteredBy":["blitz"],"chapter":3,"interlude":0,"commanders":["reyes"],"checkWith":"sead","modules":{"waitAir":1}}
A3: all_out | B3: depth | C3: blitz | D3: main_battle_tank;heavy_tank;attack_jet;heavy_bomber | E3: okoye | F3: 10 | G3: breakthrough | H3: 0.3;0.2;0.1;0.1;0.1;0.08;0.07;0.05 | I3: 0 | P3: 1 | AB3: 1 | AJ3: 1 | AM3: Tổng tấn công | AN3: Assets/MachineBrigade/Resources/Data/balance.json: aiBehaviour.tactics[15] | AO3: {"id":"all_out","name":"Tổng tấn công","cp":[0.3,0.2,0.1,0.1,0.1,0.08,0.07,0.05],"prefer":["main_battle_tank","heavy_tank","attack_jet","heavy_bomber"],"counters":["depth"],"counteredBy":["blitz"],"chapter":10,"interlude":0,"commanders":["okoye"],"checkWith":"breakthrough","modules":{"cpSaving":1,"together":1,"massSupport":1}}
A4: ambush | B4: blitz | C4: bounding | D4: tank_destroyer;railgun_truck;fpv_carrier;scout_jeep;ew_jammer | E4: kerr | F4: 0 | H4: 0.15;0.15;0.3;0.1;0.12;0.08;0.02;0.08 | I4: 1 | Y4: 0.6 | AG4: HoldFire | AM4: Phục kích | AN4: Assets/MachineBrigade/Resources/Data/balance.json: aiBehaviour.tactics[6] | AO4: {"id":"ambush","name":"Phục kích","cp":[0.15,0.15,0.3,0.1,0.12,0.08,0.02,0.08],"prefer":["tank_destroyer","railgun_truck","fpv_carrier","scout_jeep","ew_jammer"],"counters":["blitz"],"counteredBy":["bounding"],"chapter":0,"interlude":1,"commanders":["kerr"],"checkWith":"","modules":{"holdFire":0.6,"stance":"HoldFire"}}
A5: attrition | B5: breakthrough | C5: blitz;encircle | D5: mlrs;shahed_truck;ballistic_launcher;recon_drone | E5: quist | F5: 8 | H5: 0.1;0.1;0.2;0.3;0.1;0.05;0.05;0.1 | I5: 0 | L5: 1.5 | R5: 0.9;1.0 | AH5: 1 | AM5: Tiêu hao | AN5: Assets/MachineBrigade/Resources/Data/balance.json: aiBehaviour.tactics[12] | AO5: {"id":"attrition","name":"Tiêu hao","cp":[0.1,0.1,0.2,0.3,0.1,0.05,0.05,0.1],"prefer":["mlrs","shahed_truck","ballistic_launcher","recon_drone"],"counters":["breakthrough"],"counteredBy":["blitz","encircle"],"chapter":8,"interlude":0,"commanders":["quist"],"checkWith":"","modules":{"attackThreshold":1.5,"engage":[0.9,1.0],"standoff":1}}
A6: balanced | E6: kade | F6: 0 | H6: 0.25;0.2;0.12;0.12;0.1;0.08;0.05;0.08 | I6: 0 | AM6: Cân bằng | AN6: Assets/MachineBrigade/Resources/Data/balance.json: aiBehaviour.tactics[0] | AO6: {"id":"balanced","name":"Cân bằng","cp":[0.25,0.2,0.12,0.12,0.1,0.08,0.05,0.08],"prefer":[],"counters":[],"counteredBy":[],"chapter":0,"interlude":0,"commanders":["kade"],"checkWith":"","modules":{}}
A7: base_defence | B7: blitz | C7: firepower;attrition | D7: tank_destroyer;aa_vehicle;mine_layer;engineer_vehicle | E7: brandt | F7: 1 | H7: 0.25;0.15;0.2;0.15;0.15;0.02;0.0;0.08 | I7: 0 | W7: 1 | X7: 1 | AK7: Lead | AM7: Bảo vệ căn cứ | AN7: Assets/MachineBrigade/Resources/Data/balance.json: aiBehaviour.tactics[14] | AO7: {"id":"base_defence","name":"Bảo vệ căn cứ","cp":[0.25,0.15,0.2,0.15,0.15,0.02,0.0,0.08],"prefer":["tank_destroyer","aa_vehicle","mine_layer","engineer_vehicle"],"counters":["blitz"],"counteredBy":["firepower","attrition"],"chapter":1,"interlude":0,"commanders":["brandt"],"checkWith":"","modules":{"hold":1,"holdBase":1,"towerMode":"Lead"}}
A8: blitz | B8: firepower | C8: depth;ambush | D8: armored_car;ifv;wheeled_gun;main_battle_tank;attack_helicopter | E8: mendez | F8: 2 | H8: 0.25;0.3;0.1;0.05;0.08;0.1;0.04;0.08 | I8: 0 | L8: 0.9 | N8: 0 | AM8: Tấn công chớp nhoáng | AN8: Assets/MachineBrigade/Resources/Data/balance.json: aiBehaviour.tactics[1] | AO8: {"id":"blitz","name":"Tấn công chớp nhoáng","cp":[0.25,0.3,0.1,0.05,0.08,0.1,0.04,0.08],"prefer":["armored_car","ifv","wheeled_gun","main_battle_tank","attack_helicopter"],"counters":["firepower"],"counteredBy":["depth","ambush"],"chapter":2,"interlude":0,"commanders":["mendez"],"checkWith":"","modules":{"attackThreshold":0.9,"cohesion":0}}
A9: bounding | B9: ambush | C9: blitz;firepower | D9: main_battle_tank;ifv | E9: kade | F9: 3 | H9: 0.3;0.25;0.12;0.1;0.1;0.05;0.0;0.08 | I9: 0 | M9: 1 | AC9: 0.7 | AM9: Yểm hộ luân phiên | AN9: Assets/MachineBrigade/Resources/Data/balance.json: aiBehaviour.tactics[5] | AO9: {"id":"bounding","name":"Yểm hộ luân phiên","cp":[0.3,0.25,0.12,0.1,0.1,0.05,0.0,0.08],"prefer":["main_battle_tank","ifv"],"counters":["ambush"],"counteredBy":["blitz","firepower"],"chapter":3,"interlude":0,"commanders":["kade"],"checkWith":"","modules":{"pace":0.7,"bounding":1}}
A10: breakthrough | B10: depth;encircle | C10: encircle;dispersal | D10: heavy_tank;titan_tank;twin_tank;armored_bulldozer;engineer_vehicle;thermobaric_launcher | E10: reyn | F10: 6 | G10: all_out | H10: 0.4;0.15;0.08;0.12;0.1;0.05;0.02;0.08 | I10: 0 | Q10: 1 | V10: 1 | AA10: 0.7 | AM10: Tập trung đột phá | AN10: Assets/MachineBrigade/Resources/Data/balance.json: aiBehaviour.tactics[8] | AO10: {"id":"breakthrough","name":"Tập trung đột phá","cp":[0.4,0.15,0.08,0.12,0.1,0.05,0.02,0.08],"prefer":["heavy_tank","titan_tank","twin_tank","armored_bulldozer","engineer_vehicle","thermobaric_launcher"],"counters":["depth","encircle"],"counteredBy":["encircle","dispersal"],"chapter":6,"interlude":0,"commanders":["reyn"],"checkWith":"all_out","modules":{"mainEffort":0.7,"heavyLead":1,"dropSecondary":1}}
A11: decapitation | B11: firepower | C11: depth | D11: armored_car;scout_heli;attack_helicopter;stealth_fighter | E11: kerr | F11: 9 | H11: 0.12;0.28;0.15;0.1;0.08;0.15;0.07;0.05 | I11: 0 | T11: 1.6 | AI11: Support;Artillery | AM11: Săn đầu | AN11: Assets/MachineBrigade/Resources/Data/balance.json: aiBehaviour.tactics[13] | AO11: {"id":"decapitation","name":"Săn đầu","cp":[0.12,0.28,0.15,0.1,0.08,0.15,0.07,0.05],"prefer":["armored_car","scout_heli","attack_helicopter","stealth_fighter"],"counters":["firepower"],"counteredBy":["depth"],"chapter":9,"interlude":0,"commanders":["kerr"],"checkWith":"","modules":{"flank":1.6,"targets":["Support","Artillery"]}}
A12: depth | B12: blitz;breakthrough | C12: firepower;encircle | D12: tank_destroyer;main_battle_tank;mine_layer;mortar_carrier;sam_launcher | E12: brandt | F12: 1 | H12: 0.25;0.15;0.18;0.15;0.12;0.05;0.02;0.08 | I12: 0 | O12: 1.3 | S12: 0.6 | W12: 1 | AM12: Phòng thủ chiều sâu | AN12: Assets/MachineBrigade/Resources/Data/balance.json: aiBehaviour.tactics[3] | AO12: {"id":"depth","name":"Phòng thủ chiều sâu","cp":[0.25,0.15,0.18,0.15,0.12,0.05,0.02,0.08],"prefer":["tank_destroyer","main_battle_tank","mine_layer","mortar_carrier","sam_launcher"],"counters":["blitz","breakthrough"],"counteredBy":["firepower","encircle"],"chapter":1,"interlude":0,"commanders":["brandt"],"checkWith":"","modules":{"fallback":0.6,"counterattack":1.3,"hold":1}}
A13: dispersal | B13: firepower;breakthrough | C13: blitz | D13: armored_car;light_tank;fpv_carrier;mortar_carrier | E13: venn | F13: 6 | G13: hit_and_run | H13: 0.15;0.25;0.15;0.15;0.1;0.1;0.03;0.07 | I13: 0 | U13: 0.5 | AF13: 2 | AM13: Phân tán | AN13: Assets/MachineBrigade/Resources/Data/balance.json: aiBehaviour.tactics[9] | AO13: {"id":"dispersal","name":"Phân tán","cp":[0.15,0.25,0.15,0.15,0.1,0.1,0.03,0.07],"prefer":["armored_car","light_tank","fpv_carrier","mortar_carrier"],"counters":["firepower","breakthrough"],"counteredBy":["blitz"],"chapter":6,"interlude":0,"commanders":["venn"],"checkWith":"hit_and_run","modules":{"focus":0.5,"spread":2.0}}
A14: encircle | B14: depth;base_defence | C14: breakthrough | D14: armored_car;ifv;wheeled_gun;light_tank;attack_helicopter | E14: adler | F14: 4 | H14: 0.22;0.28;0.15;0.08;0.1;0.1;0.02;0.05 | I14: 0 | T14: 1.6 | AD14: 1 | AM14: Bao vây | AN14: Assets/MachineBrigade/Resources/Data/balance.json: aiBehaviour.tactics[4] | AO14: {"id":"encircle","name":"Bao vây","cp":[0.22,0.28,0.15,0.08,0.1,0.1,0.02,0.05],"prefer":["armored_car","ifv","wheeled_gun","light_tank","attack_helicopter"],"counters":["depth","base_defence"],"counteredBy":["breakthrough"],"chapter":4,"interlude":0,"commanders":["adler"],"checkWith":"","modules":{"flank":1.6,"pincer":1}}
A15: firepower | B15: depth;base_defence | C15: blitz;hit_and_run;dispersal | D15: artillery;mlrs;heavy_rocket_artillery;mortar_carrier;ammo_carrier | E15: dahl | F15: 3 | H15: 0.2;0.12;0.08;0.3;0.12;0.05;0.05;0.08 | I15: 0 | K15: 1 | AM15: Hỏa lực áp đảo | AN15: Assets/MachineBrigade/Resources/Data/balance.json: aiBehaviour.tactics[2] | AO15: {"id":"firepower","name":"Hỏa lực áp đảo","cp":[0.2,0.12,0.08,0.3,0.12,0.05,0.05,0.08],"prefer":["artillery","mlrs","heavy_rocket_artillery","mortar_carrier","ammo_carrier"],"counters":["depth","base_defence"],"counteredBy":["blitz","hit_and_run","dispersal"],"chapter":3,"interlude":0,"commanders":["dahl"],"checkWith":"","modules":{"artilleryPrep":1.0}}
A16: hit_and_run | B16: firepower | C16: blitz;air_superiority | D16: wheeled_gun;armored_car;tank_destroyer;attack_helicopter;strike_drone | E16: mendez | F16: 5 | G16: dispersal | H16: 0.1;0.25;0.25;0.1;0.1;0.12;0.03;0.05 | I16: 0 | R16: 0.9;1.0 | Z16: 0.7 | AM16: Bắn và chạy | AN16: Assets/MachineBrigade/Resources/Data/balance.json: aiBehaviour.tactics[7] | AO16: {"id":"hit_and_run","name":"Bắn và chạy","cp":[0.1,0.25,0.25,0.1,0.1,0.12,0.03,0.05],"prefer":["wheeled_gun","armored_car","tank_destroyer","attack_helicopter","strike_drone"],"counters":["firepower"],"counteredBy":["blitz","air_superiority"],"chapter":5,"interlude":0,"commanders":["mendez"],"checkWith":"dispersal","modules":{"engage":[0.9,1.0],"kite":0.7}}
A17: sead | D17: attack_jet;stealth_fighter;ew_jammer;ballistic_launcher | E17: reyes | F17: 7 | G17: air_superiority | H17: 0.15;0.12;0.1;0.15;0.1;0.1;0.2;0.08 | I17: 0 | AE17: 1 | AI17: AntiAir | AM17: Chế áp phòng không trước | AN17: Assets/MachineBrigade/Resources/Data/balance.json: aiBehaviour.tactics[11] | AO17: {"id":"sead","name":"Chế áp phòng không trước","cp":[0.15,0.12,0.1,0.15,0.1,0.1,0.2,0.08],"prefer":["attack_jet","stealth_fighter","ew_jammer","ballistic_launcher"],"counters":[],"counteredBy":[],"chapter":7,"interlude":0,"commanders":["reyes"],"checkWith":"air_superiority","modules":{"targets":["AntiAir"],"seadCards":1}}

Sheet AI_ho_so_che_do
A1: id | B1: tactics | C1: advance | D1: auto_ai | E1: auto_ai_note | F1: controllers | G1: defender | H1: engagement | I1: escort_anchor | J1: escort_max_advance_distance | K1: escort_no_chase_outside_leash | L1: escort_rear_guard_weight | M1: escort_safe_zone_radius | N1: escort_threat_to_convoy_weight | O1: flags | P1: general_tactic | Q1: hq_skill_threat | R1: inherits | S1: leash_distance | T1: leash_region | U1: name | V1: no_chase | W1: objective_policy | X1: phased | Y1: spend | Z1: stall | AA1: support | AB1: target_mask | AC1: wall_route_breach | AD1: wall_route_route | AE1: wall_route_threat | AF1: nguon | AG1: raw_json
A2: assault | B2: depth;base_defence;attrition;ambush;balanced | C2: FALSE | E2: Khu kế tiếp, quỹ thời gian | F2: Commander;Static | G2: ai | H2: Normal | P2: FALSE | Q2: 10 | S2: 40 | T2: zone | U2: Công phá | W2: Mất khu thì lùi về khu sau (leashRegion theo khu) | Y2: TRUE | Z2: AttackerOnly | AA2: Normal | AB2: enemy | AC2: 0.9 | AD2: 1 | AE2: 1.2 | AF2: Assets/MachineBrigade/Resources/Data/balance.json: aiModeProfiles.profiles.assault | AG2: {"name":"Công phá","controllers":["Commander","Static"],"tactics":["depth","base_defence","attrition","ambush","balanced"],"generalTactic":false,"stall":"AttackerOnly","spend":true,"advance":false,"support":"Normal","engagement":"Normal","defender":"ai","hqSkillThreat":10,"wallRoute":{"route":1,"threat":1.2,"breach":0.9},"targetMask":["enemy"],"objectivePolicy":"Mất khu thì lùi về khu sau (leashRegion theo khu)","autoAiNote":"Khu kế tiếp, quỹ thời gian","leashRegion":"zone","leashDistance":40}
A3: bossrush | C3: FALSE | E3: 1) né cảnh báo chết người 2) bộ phận boss nguy hiểm 3) bộ phận lộ ra 4) thân | F3: Boss | G3: none | H3: Normal | O3: noGeneralTactic | P3: FALSE | U3: Săn trùm | Y3: FALSE | Z3: Off | AA3: Normal | AB3: enemy | AF3: Assets/MachineBrigade/Resources/Data/balance.json: aiModeProfiles.profiles.bossrush | AG3: {"name":"Săn trùm","controllers":["Boss"],"tactics":[],"generalTactic":false,"stall":"Off","spend":false,"advance":false,"support":"Normal","engagement":"Normal","defender":"none","targetMask":["enemy"],"objectivePolicy":"","autoAiNote":"1) né cảnh báo chết người 2) bộ phận boss nguy hiểm 3) bộ phận lộ ra 4) thân","flags":["noGeneralTactic"]}
A4: capture | B4: * | C4: TRUE | E4: Mục tiêu màn | F4: Commander | G4: none | H4: Normal | P4: TRUE | U4: Chiến dịch: chiếm | W4: Chiếm / tranh | Y4: TRUE | Z4: Both | AA4: Normal | AB4: enemy | AF4: Assets/MachineBrigade/Resources/Data/balance.json: aiModeProfiles.profiles.capture | AG4: {"name":"Chiến dịch: chiếm","controllers":["Commander"],"tactics":["*"],"generalTactic":true,"stall":"Both","spend":true,"advance":true,"support":"Normal","engagement":"Normal","defender":"none","targetMask":["enemy"],"objectivePolicy":"Chiếm / tranh","autoAiNote":"Mục tiêu màn"}
A5: conquest | B5: * | C5: TRUE | E5: Giữ cứ điểm đang mất nhanh nhất | F5: Commander | G5: none | H5: Normal | P5: FALSE | Q5: 8 | U5: Giữ cứ điểm | W5: Chặn mất điểm nhanh nhất; mục tiêu chế độ thắng sở thích chiến thuật | Y5: TRUE | Z5: Both | AA5: Normal | AB5: enemy | AC5: 1 | AD5: 1 | AE5: 1 | AF5: Assets/MachineBrigade/Resources/Data/balance.json: aiModeProfiles.profiles.conquest | AG5: {"name":"Giữ cứ điểm","controllers":["Commander"],"tactics":["*"],"generalTactic":false,"stall":"Both","spend":true,"advance":true,"support":"Normal","engagement":"Normal","defender":"none","hqSkillThreat":8,"wallRoute":{"route":1,"threat":1,"breach":1},"targetMask":["enemy"],"objectivePolicy":"Chặn mất điểm nhanh nhất; mục tiêu chế độ thắng sở thích chiến thuật","autoAiNote":"Giữ cứ điểm đang mất nhanh nhất"}
A6: deathmatch | B6: * | C6: TRUE | E6: Dồn hỏa lực, tránh biếu xe đắt | F6: Commander | G6: none | H6: Normal | O6: riskWeightByUnitValue | P6: FALSE | Q6: 8 | U6: Tử chiến | W6: riskWeightByUnitValue: tránh "biếu" xe đắt; dẫn điểm gần hết giờ thì giảm hung hăng (không rút hẳn) | Y6: TRUE | Z6: Both | AA6: Normal | AB6: enemy | AC6: 1 | AD6: 1 | AE6: 1 | AF6: Assets/MachineBrigade/Resources/Data/balance.json: aiModeProfiles.profiles.deathmatch | AG6: {"name":"Tử chiến","controllers":["Commander"],"tactics":["*"],"generalTactic":false,"stall":"Both","spend":true,"advance":true,"support":"Normal","engagement":"Normal","defender":"none","hqSkillThreat":8,"wallRoute":{"route":1,"threat":1,"breach":1},"targetMask":["enemy"],"objectivePolicy":"riskWeightByUnitValue: tránh \"biếu\" xe đắt; dẫn điểm gần hết giờ thì giảm hung hăng (không rút hẳn)","autoAiNote":"Dồn hỏa lực, tránh biếu xe đắt","flags":["riskWeightByUnitValue"]}
A7: defend | C7: FALSE | E7: Giữ tuyến, lùi tuyến có trật tự | F7: WaveDirector | G7: player | H7: Normal | P7: FALSE | U7: Phòng thủ / Vô tận | W7: Đội trong đợt vẫn dùng hành vi cấp đội (chọc thủng, che chắn, bảo vệ pháo, chọn mục tiêu) | Y7: FALSE | Z7: Off | AA7: Normal | AB7: enemy | AF7: Assets/MachineBrigade/Resources/Data/balance.json: aiModeProfiles.profiles.defend | AG7: {"name":"Phòng thủ / Vô tận","controllers":["WaveDirector"],"tactics":[],"generalTactic":false,"stall":"Off","spend":false,"advance":false,"support":"Normal","engagement":"Normal","defender":"player","targetMask":["enemy"],"objectivePolicy":"Đội trong đợt vẫn dùng hành vi cấp đội (chọc thủng, che chắn, bảo vệ pháo, chọn mục tiêu)","autoAiNote":"Giữ tuyến, lùi tuyến có trật tự"}
A8: escort | B8: * | C8: TRUE | D8: escort | E8: Ở quanh đoàn xe; mối đe dọa với đoàn trước; hỗ trợ không gọi đòn nổ lan chồng lên vùng an toàn của đoàn | F8: Commander | G8: none | H8: Normal | I8: convoyCentre | J8: 30 | K8: TRUE | L8: 0.3 | M8: 12 | N8: 2 | P8: TRUE | U8: Chiến dịch: hộ tống / di tản | W8: escortAnchor = tâm đoàn xe; maxAdvanceDistance; rearGuardWeight; threatToConvoyWeight; noChaseOutsideLeash | Y8: TRUE | Z8: Off | AA8: Normal | AB8: enemy | AF8: Assets/MachineBrigade/Resources/Data/balance.json: aiModeProfiles.profiles.escort | AG8: {"name":"Chiến dịch: hộ tống / di tản","controllers":["Commander"],"tactics":["*"],"generalTactic":true,"stall":"Off","spend":true,"advance":true,"support":"Normal","engagement":"Normal","defender":"none","targetMask":["enemy"],"objectivePolicy":"escortAnchor = tâm đoàn xe; maxAdvanceDistance; rearGuardWeight; threatToConvoyWeight; noChaseOutsideLeash","autoAiNote":"Ở quanh đoàn xe; mối đe dọa với đoàn trước; hỗ trợ không gọi đòn nổ lan chồng lên vùng an toàn của đoàn","escort":{"anchor":"convoyCentre","maxAdvanceDistance":30,"rearGuardWeight":0.3,"threatToConvoyWeight":2.0,"noChaseOutsideLeash":true,"safeZoneRadius":12},"autoAi":"escort"}
A9: fixed_deck | B9: * | C9: FALSE | E9: Theo special_rules; placed_allies theo lệnh Tấn công/Phòng thủ | G9: none | H9: Normal | P9: FALSE | R9: TRUE | U9: Màn bộ bài game | W9: Chỉ ghi đè bằng special_rules; ngừng bắn: targetFactionMask loại phe CEASEFIRE ở cấp sát thương (cả hỗ trợ, nổ lan), không chỉ ở AI | X9: TRUE | Y9: FALSE | Z9: Inherit | AA9: Normal | AB9: enemy | AF9: Assets/MachineBrigade/Resources/Data/balance.json: aiModeProfiles.profiles.fixed_deck | AG9: {"name":"Màn bộ bài game","controllers":[],"tactics":["*"],"generalTactic":false,"stall":"Inherit","spend":false,"advance":false,"support":"Normal","engagement":"Normal","defender":"none","targetMask":["enemy"],"objectivePolicy":"Chỉ ghi đè bằng special_rules; ngừng bắn: targetFactionMask loại phe CEASEFIRE ở cấp sát thương (cả hỗ trợ, nổ lan), không chỉ ở AI","autoAiNote":"Theo special_rules; placed_allies theo lệnh Tấn công/Phòng thủ","phased":true,"inherits":true}
A10: hill | B10: * | C10: TRUE | E10: Giữ đồi | F10: Commander | G10: none | H10: Normal | P10: FALSE | Q10: 8 | U10: Vua đồi | W10: Sàn cứng: không để đồi trống khi đủ quân tranh; 60 s cuối ưu tiên đồi cao hơn | Y10: TRUE | Z10: Both | AA10: Normal | AB10: enemy | AC10: 1 | AD10: 1 | AE10: 1 | AF10: Assets/MachineBrigade/Resources/Data/balance.json: aiModeProfiles.profiles.hill | AG10: {"name":"Vua đồi","controllers":["Commander"],"tactics":["*"],"generalTactic":false,"stall":"Both","spend":true,"advance":true,"support":"Normal","engagement":"Normal","defender":"none","hqSkillThreat":8,"wallRoute":{"route":1,"threat":1,"breach":1},"targetMask":["enemy"],"objectivePolicy":"Sàn cứng: không để đồi trống khi đủ quân tranh; 60 s cuối ưu tiên đồi cao hơn","autoAiNote":"Giữ đồi"}
A11: hold | B11: * | C11: TRUE | E11: Giữ mục tiêu | F11: Commander | G11: player | H11: Normal | P11: TRUE | U11: Chiến dịch: giữ / trụ | W11: Không ép người chơi rời mục tiêu | Y11: TRUE | Z11: AttackerOnly | AA11: Normal | AB11: enemy | AF11: Assets/MachineBrigade/Resources/Data/balance.json: aiModeProfiles.profiles.hold | AG11: {"name":"Chiến dịch: giữ / trụ","controllers":["Commander"],"tactics":["*"],"generalTactic":true,"stall":"AttackerOnly","spend":true,"advance":true,"support":"Normal","engagement":"Normal","defender":"player","targetMask":["enemy"],"objectivePolicy":"Không ép người chơi rời mục tiêu","autoAiNote":"Giữ mục tiêu"}
A12: hunt | B12: * | C12: TRUE | E12: Như cột trước | F12: Commander | G12: none | H12: Normal | P12: TRUE | U12: Chiến dịch: săn mục tiêu / chặn tàu | W12: Mục tiêu đánh dấu > hộ tống của nó > quân thường | Y12: TRUE | Z12: Both | AA12: Normal | AB12: enemy | AF12: Assets/MachineBrigade/Resources/Data/balance.json: aiModeProfiles.profiles.hunt | AG12: {"name":"Chiến dịch: săn mục tiêu / chặn tàu","controllers":["Commander"],"tactics":["*"],"generalTactic":true,"stall":"Both","spend":true,"advance":true,"support":"Normal","engagement":"Normal","defender":"none","targetMask":["enemy"],"objectivePolicy":"Mục tiêu đánh dấu > hộ tống của nó > quân thường","autoAiNote":"Như cột trước"}
A13: operation | B13: * | C13: TRUE | E13: Mục tiêu giai đoạn | F13: Commander;WaveDirector;Fortress;Boss;Static | G13: none | H13: Normal | P13: TRUE | U13: Chiến dịch lớn | W13: Mỗi giai đoạn có thể đổi controller, chiến thuật, áp lực, mục tiêu, supportPolicy; đồng minh (Thorne) dùng AI đồng minh | X13: TRUE | Y13: TRUE | Z13: Both | AA13: Normal | AB13: enemy | AF13: Assets/MachineBrigade/Resources/Data/balance.json: aiModeProfiles.profiles.operation | AG13: {"name":"Chiến dịch lớn","controllers":["Commander","WaveDirector","Fortress","Boss","Static"],"tactics":["*"],"generalTactic":true,"stall":"Both","spend":true,"advance":true,"support":"Normal","engagement":"Normal","defender":"none","targetMask":["enemy"],"objectivePolicy":"Mỗi giai đoạn có thể đổi controller, chiến thuật, áp lực, mục tiêu, supportPolicy; đồng minh (Thorne) dùng AI đồng minh","autoAiNote":"Mục tiêu giai đoạn","phased":true}
A14: outpost | B14: * | C14: TRUE | E14: Theo bước | F14: Commander | G14: none | H14: Normal | P14: TRUE | U14: Chiến dịch: lập tiền đồn | W14: Bước: dọn vùng → chiếm → dựng → giữ (phaseOverrides) | Y14: TRUE | Z14: ObjectiveStallOnly | AA14: Normal | AB14: enemy | AF14: Assets/MachineBrigade/Resources/Data/balance.json: aiModeProfiles.profiles.outpost | AG14: {"name":"Chiến dịch: lập tiền đồn","controllers":["Commander"],"tactics":["*"],"generalTactic":true,"stall":"ObjectiveStallOnly","spend":true,"advance":true,"support":"Normal","engagement":"Normal","defender":"none","targetMask":["enemy"],"objectivePolicy":"Bước: dọn vùng → chiếm → dựng → giữ (phaseOverrides)","autoAiNote":"Theo bước","phaseOverrides":[{"when":"step:clear","stall":"Both"},{"when":"step:capture","stall":"Both"},{"when":"step:build","stall":"ObjectiveStallOnly"},{"when":"step:hold","stall":"AttackerOnly"}]}
A15: protect | B15: * | C15: TRUE | D15: protectTarget | E15: Mối đe dọa trực tiếp lớn nhất với công trình được bảo vệ (không chỉ "công trình yếu nhất") | F15: Commander | G15: player | H15: Normal | P15: TRUE | U15: Chiến dịch: bảo vệ | Y15: TRUE | Z15: AttackerOnly | AA15: Normal | AB15: enemy | AF15: Assets/MachineBrigade/Resources/Data/balance.json: aiModeProfiles.profiles.protect | AG15: {"name":"Chiến dịch: bảo vệ","controllers":["Commander"],"tactics":["*"],"generalTactic":true,"stall":"AttackerOnly","spend":true,"advance":true,"support":"Normal","engagement":"Normal","defender":"player","targetMask":["enemy"],"objectivePolicy":"","autoAiNote":"Mối đe dọa trực tiếp lớn nhất với công trình được bảo vệ (không chỉ \"công trình yếu nhất\")","autoAi":"protectTarget"}
A16: recon | B16: ambush;base_defence | C16: FALSE | E16: engagementPolicy = AVOID_UNLESS_BLOCKING; không đuổi; ưu tiên đường tới điểm; Yểm trợ tự động không gọi pháo trước báo động | F16: Commander | G16: none | H16: AvoidUnlessBlocking | P16: FALSE | U16: Chiến dịch: trinh sát / thâm nhập | V16: TRUE | W16: supportPolicy = DISABLED_UNTIL_ALERT; sau báo động: phaseOverride sang hồ sơ chiến đấu | Y16: FALSE | Z16: Off | AA16: DisabledUntilAlert | AB16: enemy | AF16: Assets/MachineBrigade/Resources/Data/balance.json: aiModeProfiles.profiles.recon | AG16: {"name":"Chiến dịch: trinh sát / thâm nhập","controllers":["Commander"],"tactics":["ambush","base_defence"],"generalTactic":false,"stall":"Off","spend":false,"advance":false,"support":"DisabledUntilAlert","engagement":"AvoidUnlessBlocking","defender":"none","targetMask":["enemy"],"objectivePolicy":"supportPolicy = DISABLED_UNTIL_ALERT; sau báo động: phaseOverride sang hồ sơ chiến đấu","autoAiNote":"engagementPolicy = AVOID_UNLESS_BLOCKING; không đuổi; ưu tiên đường tới điểm; Yểm trợ tự động không gọi pháo trước báo động","noChase":true,"phaseOverrides":[{"when":"alert","profile":"capture"}]}
A17: relieve | B17: * | C17: TRUE | D17: breakSiege | E17: Phá vòng vây → bảo vệ quân được giải vây → rồi mới đuổi | F17: Commander | G17: none | H17: Normal | P17: TRUE | U17: Chiến dịch: giải vây | Y17: TRUE | Z17: Both | AA17: Normal | AB17: enemy | AF17: Assets/MachineBrigade/Resources/Data/balance.json: aiModeProfiles.profiles.relieve | AG17: {"name":"Chiến dịch: giải vây","controllers":["Commander"],"tactics":["*"],"generalTactic":true,"stall":"Both","spend":true,"advance":true,"support":"Normal","engagement":"Normal","defender":"none","targetMask":["enemy"],"objectivePolicy":"","autoAiNote":"Phá vòng vây → bảo vệ quân được giải vây → rồi mới đuổi","autoAi":"breakSiege"}
A18: shootdown | B18: * | C18: TRUE | E18: Giữ mạng phòng không và vùng phủ; không đuổi mục tiêu mặt đất vô ích | F18: Commander | G18: none | H18: Normal | P18: TRUE | U18: Chiến dịch: bắn hạ máy bay | Y18: TRUE | Z18: Both | AA18: Normal | AB18: enemy | AF18: Assets/MachineBrigade/Resources/Data/balance.json: aiModeProfiles.profiles.shootdown | AG18: {"name":"Chiến dịch: bắn hạ máy bay","controllers":["Commander"],"tactics":["*"],"generalTactic":true,"stall":"Both","spend":true,"advance":true,"support":"Normal","engagement":"Normal","defender":"none","targetMask":["enemy"],"objectivePolicy":"","autoAiNote":"Giữ mạng phòng không và vùng phủ; không đuổi mục tiêu mặt đất vô ích"}
A19: showdown | B19: * | C19: TRUE | E19: Thủ nhà, phá tuyến ngoài, đánh nhà chính | F19: Commander | G19: none | H19: Normal | P19: FALSE | Q19: 8 | U19: Đối công | W19: (1) thủ căn cứ khi có mối đe dọa đáng kể; (2) phá phòng tuyến ngoài (cổng hoặc phá tường theo routeCost + threatCost + breachTimeCost); (3) đánh nhà chính; (4) trung lập khi có lợi; dùng kỹ năng nhà chính | Y19: TRUE | Z19: Both | AA19: Normal | AB19: enemy | AC19: 0.9 | AD19: 1 | AE19: 1 | AF19: Assets/MachineBrigade/Resources/Data/balance.json: aiModeProfiles.profiles.showdown | AG19: {"name":"Đối công","controllers":["Commander"],"tactics":["*"],"generalTactic":false,"stall":"Both","spend":true,"advance":true,"support":"Normal","engagement":"Normal","defender":"none","hqSkillThreat":8,"wallRoute":{"route":1,"threat":1,"breach":0.9},"targetMask":["enemy"],"objectivePolicy":"(1) thủ căn cứ khi có mối đe dọa đáng kể; (2) phá phòng tuyến ngoài (cổng hoặc phá tường theo routeCost + threatCost + breachTimeCost); (3) đánh nhà chính; (4) trung lập khi có lợi; dùng kỹ năng nhà chính","autoAiNote":"Thủ nhà, phá tuyến ngoài, đánh nhà chính"}
A20: siege | B20: depth;base_defence;attrition;ambush;balanced | C20: FALSE | E20: Mục tiêu giai đoạn; né vùng siêu pháo | F20: WaveDirector;Fortress | G20: ai | H20: Normal | P20: FALSE | Q20: 12 | S20: 30 | T20: defenceLayer | U20: Công thành / Pháo đài tuần | W20: Đồn trú leash theo lớp phòng thủ; áp lực cho phe công là giờ, siêu pháo, mục tiêu | Y20: TRUE | Z20: Off | AA20: Normal | AB20: enemy | AC20: 0.8 | AD20: 1 | AE20: 1.2 | AF20: Assets/MachineBrigade/Resources/Data/balance.json: aiModeProfiles.profiles.siege | AG20: {"name":"Công thành / Pháo đài tuần","controllers":["WaveDirector","Fortress"],"tactics":["depth","base_defence","attrition","ambush","balanced"],"generalTactic":false,"stall":"Off","spend":true,"advance":false,"support":"Normal","engagement":"Normal","defender":"ai","hqSkillThreat":12,"wallRoute":{"route":1,"threat":1.2,"breach":0.8},"targetMask":["enemy"],"objectivePolicy":"Đồn trú leash theo lớp phòng thủ; áp lực cho phe công là giờ, siêu pháo, mục tiêu","autoAiNote":"Mục tiêu giai đoạn; né vùng siêu pháo","leashRegion":"defenceLayer","leashDistance":30}
A21: survival | C21: FALSE | E21: Giữ bãi thả; chặn mối đe dọa gần; không đuổi xa | F21: WaveDirector;Boss | G21: player | H21: Normal | P21: FALSE | U21: Sinh tồn | Y21: FALSE | Z21: Off | AA21: Normal | AB21: enemy | AF21: Assets/MachineBrigade/Resources/Data/balance.json: aiModeProfiles.profiles.survival | AG21: {"name":"Sinh tồn","controllers":["WaveDirector","Boss"],"tactics":[],"generalTactic":false,"stall":"Off","spend":false,"advance":false,"support":"Normal","engagement":"Normal","defender":"player","targetMask":["enemy"],"objectivePolicy":"","autoAiNote":"Giữ bãi thả; chặn mối đe dọa gần; không đuổi xa"}

Sheet AI_ho_so_pha
A1: id | B1: ai_ho_so_che_do_id | C1: thu_tu | D1: profile | E1: stall | F1: when | G1: nguon | H1: raw_json
A2: outpost/0 | B2: outpost | C2: 0 | E2: Both | F2: step:clear | G2: Assets/MachineBrigade/Resources/Data/balance.json: aiModeProfiles.profiles.outpost.phaseOverrides[0] | H2: {"when":"step:clear","stall":"Both"}
A3: outpost/1 | B3: outpost | C3: 1 | E3: Both | F3: step:capture | G3: Assets/MachineBrigade/Resources/Data/balance.json: aiModeProfiles.profiles.outpost.phaseOverrides[1] | H3: {"when":"step:capture","stall":"Both"}
A4: outpost/2 | B4: outpost | C4: 2 | E4: ObjectiveStallOnly | F4: step:build | G4: Assets/MachineBrigade/Resources/Data/balance.json: aiModeProfiles.profiles.outpost.phaseOverrides[2] | H4: {"when":"step:build","stall":"ObjectiveStallOnly"}
A5: outpost/3 | B5: outpost | C5: 3 | E5: AttackerOnly | F5: step:hold | G5: Assets/MachineBrigade/Resources/Data/balance.json: aiModeProfiles.profiles.outpost.phaseOverrides[3] | H5: {"when":"step:hold","stall":"AttackerOnly"}
A6: recon/0 | B6: recon | C6: 0 | D6: capture | F6: alert | G6: Assets/MachineBrigade/Resources/Data/balance.json: aiModeProfiles.profiles.recon.phaseOverrides[0] | H6: {"when":"alert","profile":"capture"}

Sheet AI_ho_so_anh_xa
A1: id | B1: loai | C1: khoa | D1: ho_so | E1: nguon | F1: raw_json
A2: goal.Boss | B2: goal | C2: Boss | D2: bossrush | E2: Assets/MachineBrigade/Resources/Data/balance.json: aiModeProfiles.goals.Boss | F2: "bossrush"
A3: goal.Capture | B3: goal | C3: Capture | D3: capture | E3: Assets/MachineBrigade/Resources/Data/balance.json: aiModeProfiles.goals.Capture | F3: "capture"
A4: goal.Destroy | B4: goal | C4: Destroy | D4: capture | E4: Assets/MachineBrigade/Resources/Data/balance.json: aiModeProfiles.goals.Destroy | F4: "capture"
A5: goal.Duel | B5: goal | C5: Duel | D5: capture | E5: Assets/MachineBrigade/Resources/Data/balance.json: aiModeProfiles.goals.Duel | F5: "capture"
A6: goal.Escort | B6: goal | C6: Escort | D6: escort | E6: Assets/MachineBrigade/Resources/Data/balance.json: aiModeProfiles.goals.Escort | F6: "escort"
A7: goal.Evacuate | B7: goal | C7: Evacuate | D7: escort | E7: Assets/MachineBrigade/Resources/Data/balance.json: aiModeProfiles.goals.Evacuate | F7: "escort"
A8: goal.Hold | B8: goal | C8: Hold | D8: hold | E8: Assets/MachineBrigade/Resources/Data/balance.json: aiModeProfiles.goals.Hold | F8: "hold"
A9: goal.Hunt | B9: goal | C9: Hunt | D9: hunt | E9: Assets/MachineBrigade/Resources/Data/balance.json: aiModeProfiles.goals.Hunt | F9: "hunt"
A10: goal.Intercept | B10: goal | C10: Intercept | D10: hunt | E10: Assets/MachineBrigade/Resources/Data/balance.json: aiModeProfiles.goals.Intercept | F10: "hunt"
A11: goal.Outpost | B11: goal | C11: Outpost | D11: outpost | E11: Assets/MachineBrigade/Resources/Data/balance.json: aiModeProfiles.goals.Outpost | F11: "outpost"
A12: goal.Protect | B12: goal | C12: Protect | D12: protect | E12: Assets/MachineBrigade/Resources/Data/balance.json: aiModeProfiles.goals.Protect | F12: "protect"
... A30: mode.Weekly | B30: mode | C30: Weekly | D30: siege | E30: Assets/MachineBrigade/Resources/Data/balance.json: aiModeProfiles.modes.Weekly | F30: "siege"

Sheet AI_tuong
A1: id | B1: chien_thuat_ua_thich | C1: chien_dich_deck | D1: chien_dich_supports | E1: noi_tai | F1: can_bang_deck | G1: can_bang_elites | H1: chien_dich_stance | I1: chien_dich_style | J1: nguon | K1: raw_json
A2: aurel | B2: all_out | C2: heavy_tank;ifv;railgun_truck;attack_helicopter;long_sam;heavy_rocket_artillery;titan_tank;fighter_jet | D2: cruise_missile;airstrike;napalm_strike | E2: gen.aurel | H2: Attack | I2: aurel | J2: Assets/MachineBrigade/Resources/Data/campaign.json: generals / Assets/MachineBrigade/Resources/Data/balance.json: generals, aiBehaviour.generals | K2: {"id":"aurel","deck":["heavy_tank","ifv","railgun_truck","attack_helicopter","long_sam","heavy_rocket_artillery","titan_tank","fighter_jet"],"supports":["cruise_missile","airstrike","napalm_strike"],"style":"aurel","stance":"Attack"}
A3: brandt | B3: depth | E3: gen.brandt | J3: Assets/MachineBrigade/Resources/Data/campaign.json: generals / Assets/MachineBrigade/Resources/Data/balance.json: generals, aiBehaviour.generals
A4: default | B4: balanced | E4: gen.default | J4: Assets/MachineBrigade/Resources/Data/campaign.json: generals / Assets/MachineBrigade/Resources/Data/balance.json: generals, aiBehaviour.generals
A5: hung | C5: main_battle_tank;heavy_tank;titan_tank;ifv;aa_vehicle;mlrs;tank_destroyer | D5: artillery_barrage;airstrike;cruise_missile | E5: gen.hung | H5: Attack | I5: aurel | J5: Assets/MachineBrigade/Resources/Data/campaign.json: generals / Assets/MachineBrigade/Resources/Data/balance.json: generals, aiBehaviour.generals | K5: {"id":"hung","deck":["main_battle_tank","heavy_tank","titan_tank","ifv","aa_vehicle","mlrs","tank_destroyer"],"supports":["artillery_barrage","airstrike","cruise_missile"],"style":"aurel","stance":"Attack"}
A6: kessler | B6: attrition | C6: wheeled_gun;ifv;main_battle_tank;heavy_tank;sam_launcher;fpv_carrier;mine_layer;mlrs | D6: remote_mines;artillery_barrage;repair_drop | E6: gen.kessler | H6: Defend | I6: kessler | J6: Assets/MachineBrigade/Resources/Data/campaign.json: generals / Assets/MachineBrigade/Resources/Data/balance.json: generals, aiBehaviour.generals | K6: {"id":"kessler","deck":["wheeled_gun","ifv","main_battle_tank","heavy_tank","sam_launcher","fpv_carrier","mine_layer","mlrs"],"supports":["remote_mines","artillery_barrage","repair_drop"],"style":"kessler","stance":"Defend"}
A7: orlov | B7: firepower | C7: mlrs;artillery;mortar_carrier;heavy_rocket_artillery;sam_launcher;main_battle_tank;aa_vehicle;command_vehicle | D7: artillery_barrage;cruise_missile;airstrike | E7: gen.orlov | G7: Artillery | H7: Defend | I7: orlov | J7: Assets/MachineBrigade/Resources/Data/campaign.json: generals / Assets/MachineBrigade/Resources/Data/balance.json: generals, aiBehaviour.generals | K7: {"id":"orlov","deck":["mlrs","artillery","mortar_carrier","heavy_rocket_artillery","sam_launcher","main_battle_tank","aa_vehicle","command_vehicle"],"supports":["artillery_barrage","cruise_missile","airstrike"],"style":"orlov","stance":"Defend"}
A8: quaden | C8: attack_helicopter;attack_jet;fighter_jet;strike_drone;aa_vehicle;main_battle_tank;sam_launcher | D8: airstrike;cruise_missile;napalm_strike | E8: gen.quaden | G8: Air | H8: Attack | I8: quaden | J8: Assets/MachineBrigade/Resources/Data/campaign.json: generals / Assets/MachineBrigade/Resources/Data/balance.json: generals, aiBehaviour.generals | K8: {"id":"quaden","deck":["attack_helicopter","attack_jet","fighter_jet","strike_drone","aa_vehicle","main_battle_tank","sam_launcher"],"supports":["airstrike","cruise_missile","napalm_strike"],"style":"quaden","stance":"Attack"}
A9: sen | C9: strike_drone;fpv_carrier;recon_drone;ew_jammer;ifv;main_battle_tank;aa_vehicle | D9: airstrike;cruise_missile;repair_drop | E9: gen.sen | G9: Drone | H9: Attack | I9: sen | J9: Assets/MachineBrigade/Resources/Data/campaign.json: generals / Assets/MachineBrigade/Resources/Data/balance.json: generals, aiBehaviour.generals | K9: {"id":"sen","deck":["strike_drone","fpv_carrier","recon_drone","ew_jammer","ifv","main_battle_tank","aa_vehicle"],"supports":["airstrike","cruise_missile","repair_drop"],"style":"sen","stance":"Attack"}
A10: thorne | B10: balanced | E10: gen.thorne | J10: Assets/MachineBrigade/Resources/Data/campaign.json: generals / Assets/MachineBrigade/Resources/Data/balance.json: generals, aiBehaviour.generals
A11: varga | B11: breakthrough | C11: light_tank;main_battle_tank;heavy_tank;tank_destroyer;ifv;flame_tank;twin_tank;fpv_carrier | D11: artillery_barrage;airstrike;repair_drop | E11: gen.varga | F11: armored_bulldozer | G11: Tank;Heavy | H11: Attack | I11: varga | J11: Assets/MachineBrigade/Resources/Data/campaign.json: generals / Assets/MachineBrigade/Resources/Data/balance.json: generals, aiBehaviour.generals | K11: {"id":"varga","deck":["light_tank","main_battle_tank","heavy_tank","tank_destroyer","ifv","flame_tank","twin_tank","fpv_carrier"],"supports":["artillery_barrage","airstrike","repair_drop"],"style":"varga","stance":"Attack"}
A12: venn | B12: dispersal | E12: gen.venn | J12: Assets/MachineBrigade/Resources/Data/campaign.json: generals / Assets/MachineBrigade/Resources/Data/balance.json: generals, aiBehaviour.generals
A13: wolff | B13: air_superiority | E13: gen.wolff | J13: Assets/MachineBrigade/Resources/Data/campaign.json: generals / Assets/MachineBrigade/Resources/Data/balance.json: generals, aiBehaviour.generals

Sheet AI_tham_so
A1: id | B1: khoi | C1: tham_so | D1: bac | E1: max | F1: metric | G1: min | H1: reason | I1: value | J1: nguon | K1: raw_json
A2: economy.airCap | B2: economy | C2: airCap | E2: 6 | F2: FPS ở trần quân | G2: 6 | I2: 6 | J2: Assets/MachineBrigade/Resources/Data/balance.json: ai.economy.airCap | K2: {"value":6.0,"min":6.0,"max":6.0,"metric":"FPS ở trần quân","reason":""}
A3: economy.attackThreshold | B3: economy | C3: attackThreshold | E3: 1.2 | F3: Tỷ lệ thời gian có giao tranh | G3: 1.2 | H3: Tỷ lệ sức mạnh ta / địch tối thiểu | I3: 1.2 | J3: Assets/MachineBrigade/Resources/Data/balance.json: ai.economy.attackThreshold | K3: {"value":1.2,"min":1.2,"max":1.2,"metric":"Tỷ lệ thời gian có giao tranh","reason":"Tỷ lệ sức mạnh ta / địch tối thiểu"}
A4: economy.baseIncome | B4: economy | C4: baseIncome | E4: 1 | F4: Số quân trung bình còn sống mỗi phe | G4: 1 | H4: Thu nhập khi chưa có cứ điểm | I4: 1 | J4: Assets/MachineBrigade/Resources/Data/balance.json: ai.economy.baseIncome | K4: {"value":1.0,"min":1.0,"max":1.0,"metric":"Số quân trung bình còn sống mỗi phe","reason":"Thu nhập khi chưa có cứ điểm"}
A5: economy.escalation/0 | B5: economy | C5: escalation | D5: 0 | E5: 30 | F5: Tỷ lệ thời gian có giao tranh | G5: 30 | H5: Các bậc sau: khoảng 50, 70, 90 s (bảng luật bên dưới) | I5: 30 | J5: Assets/MachineBrigade/Resources/Data/balance.json: ai.economy.escalation[0] | K5: {"value":30.0,"min":30.0,"max":30.0,"metric":"Tỷ lệ thời gian có giao tranh","reason":"Các bậc sau: khoảng 50, 70, 90 s (bảng luật bên dưới)"}
A6: economy.escalation/1 | B6: economy | C6: escalation | D6: 1 | E6: 50 | F6: Tỷ lệ thời gian có giao tranh | G6: 50 | H6: Các bậc sau: khoảng 50, 70, 90 s (bảng luật bên dưới) | I6: 50 | J6: Assets/MachineBrigade/Resources/Data/balance.json: ai.economy.escalation[1] | K6: {"value":50.0,"min":50.0,"max":50.0,"metric":"Tỷ lệ thời gian có giao tranh","reason":"Các bậc sau: khoảng 50, 70, 90 s (bảng luật bên dưới)"}
A7: economy.escalation/2 | B7: economy | C7: escalation | D7: 2 | E7: 70 | F7: Tỷ lệ thời gian có giao tranh | G7: 70 | H7: Các bậc sau: khoảng 50, 70, 90 s (bảng luật bên dưới) | I7: 70 | J7: Assets/MachineBrigade/Resources/Data/balance.json: ai.economy.escalation[2] | K7: {"value":70.0,"min":70.0,"max":70.0,"metric":"Tỷ lệ thời gian có giao tranh","reason":"Các bậc sau: khoảng 50, 70, 90 s (bảng luật bên dưới)"}
A8: economy.escalation/3 | B8: economy | C8: escalation | D8: 3 | E8: 90 | F8: Tỷ lệ thời gian có giao tranh | G8: 90 | H8: Các bậc sau: khoảng 50, 70, 90 s (bảng luật bên dưới) | I8: 90 | J8: Assets/MachineBrigade/Resources/Data/balance.json: ai.economy.escalation[3] | K8: {"value":90.0,"min":90.0,"max":90.0,"metric":"Tỷ lệ thời gian có giao tranh","reason":"Các bậc sau: khoảng 50, 70, 90 s (bảng luật bên dưới)"}
A9: economy.finalPhase | B9: economy | C9: finalPhase | E9: 120 | F9: Tỷ lệ thời gian có giao tranh | G9: 120 | H9: Chế độ giao tranh có pha cuối (ví dụ 2 phút cuối, điểm từ cứ điểm ×2) để trận luôn kết thúc. | I9: 120 | J9: Assets/MachineBrigade/Resources/Data/balance.json: ai.economy.finalPhase | K9: {"value":120,"min":120,"max":120,"metric":"Tỷ lệ thời gian có giao tranh","reason":"Chế độ giao tranh có pha cuối (ví dụ 2 phút cuối, điểm từ cứ điểm ×2) để trận luôn kết thúc."}
A10: economy.finalPhaseScale | B10: economy | C10: finalPhaseScale | E10: 2 | F10: Tỷ lệ thời gian có giao tranh | G10: 2 | H10: Chế độ giao tranh có pha cuối (ví dụ 2 phút cuối, điểm từ cứ điểm ×2) để trận luôn kết thúc. | I10: 2 | J10: Assets/MachineBrigade/Resources/Data/balance.json: ai.economy.finalPhaseScale | K10: {"value":2,"min":2,"max":2,"metric":"Tỷ lệ thời gian có giao tranh","reason":"Chế độ giao tranh có pha cuối (ví dụ 2 phút cuối, điểm từ cứ điểm ×2) để trận luôn kết thúc."}
A11: economy.groundCap | B11: economy | C11: groundCap | E11: 32 | F11: FPS ở trần quân | G11: 32 | H11: Không chiến thuật nào được nới | I11: 32 | J11: Assets/MachineBrigade/Resources/Data/balance.json: ai.economy.groundCap | K11: {"value":32.0,"min":32.0,"max":32.0,"metric":"FPS ở trần quân","reason":"Không chiến thuật nào được nới"}
A12: economy.perPoint | B12: economy | C12: perPoint | E12: 0.25 | F12: Số quân trung bình còn sống mỗi phe | G12: 0.25 | H12: Như hiện tại; chỉnh theo dữ liệu game | I12: 0.25 | J12: Assets/MachineBrigade/Resources/Data/balance.json: ai.economy.perPoint | K12: {"value":0.25,"min":0.25,"max":0.25,"metric":"Số quân trung bình còn sống mỗi phe","reason":"Như hiện tại; chỉnh theo dữ liệu game"}
A13: economy.stockCap | B13: economy | C13: stockCap | E13: 30 | F13: Số quân trung bình còn sống mỗi phe | G13: 30 | H13: Chỉ huy Vault: 45 | I13: 30 | J13: Assets/MachineBrigade/Resources/Data/balance.json: ai.economy.stockCap | K13: {"value":30.0,"min":30.0,"max":30.0,"metric":"Số quân trung bình còn sống mỗi phe","reason":"Chỉ huy Vault: 45"}
A14: economy.stockCapVault | B14: economy | C14: stockCapVault | E14: 45 | F14: Số quân trung bình còn sống mỗi phe | G14: 45 | H14: Chỉ huy Vault: 45 | I14: 45 | J14: Assets/MachineBrigade/Resources/Data/balance.json: ai.economy.stockCapVault | K14: {"value":45.0,"min":45.0,"max":45.0,"metric":"Số quân trung bình còn sống mỗi phe","reason":"Chỉ huy Vault: 45"}
A15: economy.useOrLoseRamp | B15: economy | C15: useOrLoseRamp | E15: 30 | F15: Số quân trung bình còn sống mỗi phe | G15: 30 | H15: Từ ngưỡng mặc định xuống ngưỡng thấp nhất | I15: 30 | J15: Assets/MachineBrigade/Resources/Data/balance.json: ai.economy.useOrLoseRamp | K15: {"value":30.0,"min":30.0,"max":30.0,"metric":"Số quân trung bình còn sống mỗi phe","reason":"Từ ngưỡng mặc định xuống ngưỡng thấp nhất"}
A16: economy.useOrLoseThreshold | B16: economy | C16: useOrLoseThreshold | E16: 0.9 | F16: Số quân trung bình còn sống mỗi phe | G16: 0.9 | H16: Khi đã chạm trần quân và CP đầy | I16: 0.9 | J16: Assets/MachineBrigade/Resources/Data/balance.json: ai.economy.useOrLoseThreshold | K16: {"value":0.9,"min":0.9,"max":0.9,"metric":"Số quân trung bình còn sống mỗi phe","reason":"Khi đã chạm trần quân và CP đầy"}
A17: params.airAaLimit | B17: params | C17: airAaLimit | E17: 1.5 | F17: Số máy bay bị hạ mỗi lượt | G17: 0.5 | I17: 1 | J17: Assets/MachineBrigade/Resources/Data/balance.json: ai.params.airAaLimit | K17: {"value":1.0,"min":0.5,"max":1.5,"metric":"Số máy bay bị hạ mỗi lượt","reason":""}
A18: params.artilleryPrep | B18: params | C18: artilleryPrep | E18: 2 | F18: Thời điểm đợt tấn công đầu tiên | G18: 0 | I18: 0 | J18: Assets/MachineBrigade/Resources/Data/balance.json: ai.params.artilleryPrep | K18: {"value":0.0,"min":0.0,"max":2.0,"metric":"Thời điểm đợt tấn công đầu tiên","reason":""}
A19: params.attackThreshold | B19: params | C19: attackThreshold | E19: 1.6 | F19: Tỷ lệ thời gian có giao tranh; số đợt tấn công thất bại | G19: 0.8 | H19: Thấp quá: lao vào chỗ chết; cao quá: trận đứng yên | I19: 1.2 | J19: Assets/MachineBrigade/Resources/Data/balance.json: ai.params.attackThreshold | K19: {"value":1.2,"min":0.8,"max":1.6,"metric":"Tỷ lệ thời gian có giao tranh; số đợt tấn công thất bại","reason":"Thấp quá: lao vào chỗ chết; cao quá: trận đứng yên"}
A20: params.cohesion | B20: params | C20: cohesion | E20: 1 | F20: Vi phạm đội hình mỗi phút | G20: 0 | I20: 1 | J20: Assets/MachineBrigade/Resources/Data/balance.json: ai.params.cohesion | K20: {"value":1.0,"min":0.0,"max":1.0,"metric":"Vi phạm đội hình mỗi phút","reason":""}
A21: params.confidenceDecay | B21: params | C21: confidenceDecay | E21: 0.12 | F21: Số lần AI đánh vào nơi địch đã đi; số lần bị bất ngờ | G21: 0.03 | H21: Theo độ khó: Cực khó giảm chậm hơn | I21: 0.06 | J21: Assets/MachineBrigade/Resources/Data/balance.json: ai.params.confidenceDecay | K21: {"value":0.06,"min":0.03,"max":0.12,"metric":"Số lần AI đánh vào nơi địch đã đi; số lần bị bất ngờ","reason":"Theo độ khó: Cực khó giảm chậm hơn"}
A22: params.cpSaving | B22: params | C22: cpSaving | E22: 1 | F22: CP trung bình tích trữ | G22: 0 | H22: Tổng tấn công | I22: 0 | J22: Assets/MachineBrigade/Resources/Data/balance.json: ai.params.cpSaving | K22: {"value":0.0,"min":0.0,"max":1.0,"metric":"CP trung bình tích trữ","reason":"Tổng tấn công"}
A23: params.emergencyCooldown | B23: params | C23: emergencyCooldown | E23: 40 | F23: Số lần dùng khẩn cấp mỗi phút; chỉ số đổi quyết định | G23: 15 | H23: Ngăn dùng khẩn cấp để lách luật cam kết | I23: 25 | J23: Assets/MachineBrigade/Resources/Data/balance.json: ai.params.emergencyCooldown | K23: {"value":25.0,"min":15.0,"max":40.0,"metric":"Số lần dùng khẩn cấp mỗi phút; chỉ số đổi quyết định","reason":"Ngăn dùng khẩn cấp để lách luật cam kết"}
A24: params.fallbackRatio | B24: params | C24: fallbackRatio | E24: 0.7 | F24: Số tuyến mất; thời lượng trận Phòng thủ | G24: 0.5 | H24: Không áp cho từng xe theo máu | I24: 0.6 | J24: Assets/MachineBrigade/Resources/Data/balance.json: ai.params.fallbackRatio | K24: {"value":0.6,"min":0.5,"max":0.7,"metric":"Số tuyến mất; thời lượng trận Phòng thủ","reason":"Không áp cho từng xe theo máu"}
A25: params.flankWeight | B25: params | C25: flankWeight | E25: 2 | F25: Tỷ lệ thời gian đánh sườn | G25: 0.5 | H25: Dấu vân hành vi | I25: 1 | J25: Assets/MachineBrigade/Resources/Data/balance.json: ai.params.flankWeight | K25: {"value":1.0,"min":0.5,"max":2.0,"metric":"Tỷ lệ thời gian đánh sườn","reason":"Dấu vân hành vi"}
A26: params.focusWeight | B26: params | C26: focusWeight | E26: 2 | F26: Số mục tiêu đổi mỗi phút; thời gian hạ mục tiêu | G26: 0.5 | I26: 1 | J26: Assets/MachineBrigade/Resources/Data/balance.json: ai.params.focusWeight | K26: {"value":1.0,"min":0.5,"max":2.0,"metric":"Số mục tiêu đổi mỗi phút; thời gian hạ mục tiêu","reason":""}
A27: params.holdFire | B27: params | C27: holdFire | E27: 0.6 | F27: Tỷ lệ thời gian giữ lửa; sát thương phát đầu | G27: 0 | H27: Phục kích | I27: 0 | J27: Assets/MachineBrigade/Resources/Data/balance.json: ai.params.holdFire | K27: {"value":0.0,"min":0.0,"max":0.6,"metric":"Tỷ lệ thời gian giữ lửa; sát thương phát đầu","reason":"Phục kích"}
A28: params.idleReassess | B28: params | C28: idleReassess | E28: 10 | F28: Tỷ lệ thời gian đứng yên không lý do | G28: 3 | I28: 5 | J28: Assets/MachineBrigade/Resources/Data/balance.json: ai.params.idleReassess | K28: {"value":5.0,"min":3.0,"max":10.0,"metric":"Tỷ lệ thời gian đứng yên không lý do","reason":""}
A29: params.mainEffort | B29: params | C29: mainEffort | E29: 0.8 | F29: Độ tập trung lực lượng | G29: 0.3 | I29: 0.5 | J29: Assets/MachineBrigade/Resources/Data/balance.json: ai.params.mainEffort | K29: {"value":0.5,"min":0.3,"max":0.8,"metric":"Độ tập trung lực lượng","reason":""}
A30: params.minCommit | B30: params | C30: minCommit | E30: 8 | F30: Số lần đổi trạng thái mỗi phút; tỷ lệ hành động bị bỏ dở | G30: 2 | H30: Như trên | I30: 4 | J30: Assets/MachineBrigade/Resources/Data/balance.json: ai.params.minCommit | K30: {"value":4.0,"min":2.0,"max":8.0,"metric":"Số lần đổi trạng thái mỗi phút; tỷ lệ hành động bị bỏ dở","reason":"Như trên"}
A31: params.overwhelmRatio | B31: params | C31: overwhelmRatio | E31: 3 | F31: Số xe bị hạ khi bị áp đảo; số lần gom | G31: 1.6 | I31: 2 | J31: Assets/MachineBrigade/Resources/Data/balance.json: ai.params.overwhelmRatio | K31: {"value":2.0,"min":1.6,"max":3.0,"metric":"Số xe bị hạ khi bị áp đảo; số lần gom","reason":""}
A32: params.reactionDelay | B32: params | C32: reactionDelay | E32: 1.5 | F32: Tỷ lệ né đòn có cảnh báo | G32: 0.3 | H32: Theo độ khó | I32: 0.8 | J32: Assets/MachineBrigade/Resources/Data/balance.json: ai.params.reactionDelay | K32: {"value":0.8,"min":0.3,"max":1.5,"metric":"Tỷ lệ né đòn có cảnh báo","reason":"Theo độ khó"}
A33: params.splashSpread | B33: params | C33: splashSpread | E33: 2 | F33: Số xe bị hạ bởi bắn lan mỗi phút; độ dàn trải đội | G33: 0.5 | I33: 1 | J33: Assets/MachineBrigade/Resources/Data/balance.json: ai.params.splashSpread | K33: {"value":1.0,"min":0.5,"max":2.0,"metric":"Số xe bị hạ bởi bắn lan mỗi phút; độ dàn trải đội","reason":""}
A34: params.stuckTime | B34: params | C34: stuckTime | E34: 5 | F34: Số lần kẹt mỗi phút, thời gian kẹt trung bình | G34: 2 | I34: 3 | J34: Assets/MachineBrigade/Resources/Data/balance.json: ai.params.stuckTime | K34: {"value":3.0,"min":2.0,"max":5.0,"metric":"Số lần kẹt mỗi phút, thời gian kẹt trung bình","reason":""}
A35: params.switchMargin | B35: params | C35: switchMargin | E35: 15 | F35: Số lần đổi hành động mỗi phút của đội | G35: 4 | H35: Thấp: đổi ý liên tục; cao: không phản ứng kịp | I35: 8 | J35: Assets/MachineBrigade/Resources/Data/balance.json: ai.params.switchMargin | K35: {"value":8.0,"min":4.0,"max":15.0,"metric":"Số lần đổi hành động mỗi phút của đội","reason":"Thấp: đổi ý liên tục; cao: không phản ứng kịp"}
A36: params.tacticCooldown | B36: params | C36: tacticCooldown | E36: 60 | F36: Số lần đổi mỗi trận; tỷ lệ thắng sau khi đổi | G36: 45 | I36: 50 | J36: Assets/MachineBrigade/Resources/Data/balance.json: ai.params.tacticCooldown | K36: {"value":50.0,"min":45.0,"max":60.0,"metric":"Số lần đổi mỗi trận; tỷ lệ thắng sau khi đổi","reason":""}
A37: params.tacticTransition | B37: params | C37: tacticTransition | E37: 8 | F37: Sát thương mất trong lúc chuyển | G37: 3 | H37: Cái giá của việc đổi | I37: 5 | J37: Assets/MachineBrigade/Resources/Data/balance.json: ai.params.tacticTransition | K37: {"value":5.0,"min":3.0,"max":8.0,"metric":"Sát thương mất trong lúc chuyển","reason":"Cái giá của việc đổi"}
A38: world.aaShare | B38: world | C38: aaShare | E38: 0.2 | F38: Số máy bay bị hạ mỗi lượt | G38: 0.05 | H38: MISMATCH: own anti-air share below this | I38: 0.1 | J38: Assets/MachineBrigade/Resources/Data/balance.json: ai.world.aaShare | K38: {"value":0.1,"min":0.05,"max":0.2,"metric":"Số máy bay bị hạ mỗi lượt","reason":"MISMATCH: own anti-air share below this"}
A39: world.airShare | B39: world | C39: airShare | E39: 0.4 | F39: Số máy bay bị hạ mỗi lượt | G39: 0.15 | H39: MISMATCH: enemy aircraft share of its strength | I39: 0.25 | J39: Assets/MachineBrigade/Resources/Data/balance.json: ai.world.airShare | K39: {"value":0.25,"min":0.15,"max":0.4,"metric":"Số máy bay bị hạ mỗi lượt","reason":"MISMATCH: enemy aircraft share of its strength"}
A40: world.armourShare | B40: world | C40: armourShare | E40: 0.6 | F40: Thời gian hạ mục tiêu | G40: 0.3 | H40: MISMATCH: enemy armour share of its strength | I40: 0.4 | J40: Assets/MachineBrigade/Resources/Data/balance.json: ai.world.armourShare | K40: {"value":0.4,"min":0.3,"max":0.6,"metric":"Thời gian hạ mục tiêu","reason":"MISMATCH: enemy armour share of its strength"}
...

Sheet AI_vai_tro
A1: id | B1: engage | C1: overwhelmed | D1: nguon | E1: raw_json
A2: Arty | C2: Scoot | D2: Assets/MachineBrigade/Resources/Data/balance.json: aiBehaviour.roles.Arty | E2: {"engage":[],"overwhelmed":"Scoot"}
A3: AttackHeli | B3: 0.85;1.0 | C3: Rearm | D3: Assets/MachineBrigade/Resources/Data/balance.json: aiBehaviour.roles.AttackHeli | E3: {"engage":[0.85,1.0],"overwhelmed":"Rearm"}
A4: Bomber | C4: Hold | D4: Assets/MachineBrigade/Resources/Data/balance.json: aiBehaviour.roles.Bomber | E4: {"engage":[],"overwhelmed":"Hold"}
A5: Bunker | C5: Hold | D5: Assets/MachineBrigade/Resources/Data/balance.json: aiBehaviour.roles.Bunker | E5: {"engage":[],"overwhelmed":"Hold"}
A6: CAS | B6: 0.6;1.0 | C6: Rearm | D6: Assets/MachineBrigade/Resources/Data/balance.json: aiBehaviour.roles.CAS | E6: {"engage":[0.6,1.0],"overwhelmed":"Rearm"}
A7: Drone | C7: Hold | D7: Assets/MachineBrigade/Resources/Data/balance.json: aiBehaviour.roles.Drone | E7: {"engage":[],"overwhelmed":"Hold"}
A8: Fighter | B8: 0.8;1.0 | C8: Rearm | D8: Assets/MachineBrigade/Resources/Data/balance.json: aiBehaviour.roles.Fighter | E8: {"engage":[0.8,1.0],"overwhelmed":"Rearm"}
A9: Flame | C9: Hold | D9: Assets/MachineBrigade/Resources/Data/balance.json: aiBehaviour.roles.Flame | E9: {"engage":[],"overwhelmed":"Hold"}
A10: Gunship | C10: Shift | D10: Assets/MachineBrigade/Resources/Data/balance.json: aiBehaviour.roles.Gunship | E10: {"engage":[],"overwhelmed":"Shift"}
A11: GunshipHeli | B11: 0.7;0.9 | C11: Rearm | D11: Assets/MachineBrigade/Resources/Data/balance.json: aiBehaviour.roles.GunshipHeli | E11: {"engage":[0.7,0.9],"overwhelmed":"Rearm"}
A12: Heavy | B12: 0.6;0.8 | C12: Hold | D12: Assets/MachineBrigade/Resources/Data/balance.json: aiBehaviour.roles.Heavy | E12: {"engage":[0.6,0.8],"overwhelmed":"Hold"}
A13: IFV | B13: 0.7;0.9 | C13: Shift | D13: Assets/MachineBrigade/Resources/Data/balance.json: aiBehaviour.roles.IFV | E13: {"engage":[0.7,0.9],"overwhelmed":"Shift"}
A14: Laser | C14: Shift | D14: Assets/MachineBrigade/Resources/Data/balance.json: aiBehaviour.roles.Laser | E14: {"engage":[],"overwhelmed":"Shift"}
A15: Light | B15: 0.85;1.0 | C15: Hold | D15: Assets/MachineBrigade/Resources/Data/balance.json: aiBehaviour.roles.Light | E15: {"engage":[0.85,1.0],"overwhelmed":"Hold"}
A16: MBT | B16: 0.75;0.9 | C16: Cover | D16: Assets/MachineBrigade/Resources/Data/balance.json: aiBehaviour.roles.MBT | E16: {"engage":[0.75,0.9],"overwhelmed":"Cover"}
A17: MLRS | C17: Scoot | D17: Assets/MachineBrigade/Resources/Data/balance.json: aiBehaviour.roles.MLRS | E17: {"engage":[],"overwhelmed":"Scoot"}
A18: Rail | B18: 0.9;1.0 | C18: Shift | D18: Assets/MachineBrigade/Resources/Data/balance.json: aiBehaviour.roles.Rail | E18: {"engage":[0.9,1.0],"overwhelmed":"Shift"}
A19: Recon | C19: Shift | D19: Assets/MachineBrigade/Resources/Data/balance.json: aiBehaviour.roles.Recon | E19: {"engage":[],"overwhelmed":"Shift"}
A20: SAM | B20: 0.8;1.0 | C20: Shift | D20: Assets/MachineBrigade/Resources/Data/balance.json: aiBehaviour.roles.SAM | E20: {"engage":[0.8,1.0],"overwhelmed":"Shift"}
A21: SPAAG | B21: 0.7;0.9 | C21: Hold | D21: Assets/MachineBrigade/Resources/Data/balance.json: aiBehaviour.roles.SPAAG | E21: {"engage":[0.7,0.9],"overwhelmed":"Hold"}
A22: ScoutHeli | B22: 0.9;1.0 | C22: Rearm | D22: Assets/MachineBrigade/Resources/Data/balance.json: aiBehaviour.roles.ScoutHeli | E22: {"engage":[0.9,1.0],"overwhelmed":"Rearm"}
A23: Siege | C23: Hold | D23: Assets/MachineBrigade/Resources/Data/balance.json: aiBehaviour.roles.Siege | E23: {"engage":[],"overwhelmed":"Hold"}
A24: Stealth | B24: 0.9;1.0 | C24: Shift | D24: Assets/MachineBrigade/Resources/Data/balance.json: aiBehaviour.roles.Stealth | E24: {"engage":[0.9,1.0],"overwhelmed":"Shift"}
A25: Strike | C25: Scoot | D25: Assets/MachineBrigade/Resources/Data/balance.json: aiBehaviour.roles.Strike | E25: {"engage":[],"overwhelmed":"Scoot"}
A26: Support | C26: Hold | D26: Assets/MachineBrigade/Resources/Data/balance.json: aiBehaviour.roles.Support | E26: {"engage":[],"overwhelmed":"Hold"}
A27: TD | B27: 0.9;1.0 | C27: Shift | D27: Assets/MachineBrigade/Resources/Data/balance.json: aiBehaviour.roles.TD | E27: {"engage":[0.9,1.0],"overwhelmed":"Shift"}
A28: UAV | B28: 0.9;1.0 | C28: Shift | D28: Assets/MachineBrigade/Resources/Data/balance.json: aiBehaviour.roles.UAV | E28: {"engage":[0.9,1.0],"overwhelmed":"Shift"}
A29: VBIED | C29: Hold | D29: Assets/MachineBrigade/Resources/Data/balance.json: aiBehaviour.roles.VBIED | E29: {"engage":[],"overwhelmed":"Hold"}

Sheet AI_don_vi
A1: id | B1: don_vi | C1: vai_tro | D1: nguon | E1: raw_json
A2: aa_corvette | B2: aa_corvette | C2: SAM | D2: Assets/MachineBrigade/Resources/Data/balance.json: aiBehaviour.units.aa_corvette | E2: "SAM"
A3: aa_destroyer | B3: aa_destroyer | C3: SAM | D3: Assets/MachineBrigade/Resources/Data/balance.json: aiBehaviour.units.aa_destroyer | E3: "SAM"
A4: aa_frigate | B4: aa_frigate | C4: SAM | D4: Assets/MachineBrigade/Resources/Data/balance.json: aiBehaviour.units.aa_frigate | E4: "SAM"
A5: aa_vehicle | B5: aa_vehicle | C5: SPAAG | D5: Assets/MachineBrigade/Resources/Data/balance.json: aiBehaviour.units.aa_vehicle | E5: "SPAAG"
A6: ammo_carrier | B6: ammo_carrier | C6: Support | D6: Assets/MachineBrigade/Resources/Data/balance.json: aiBehaviour.units.ammo_carrier | E6: "Support"
A7: armored_bulldozer | B7: armored_bulldozer | C7: Bunker | D7: Assets/MachineBrigade/Resources/Data/balance.json: aiBehaviour.units.armored_bulldozer | E7: "Bunker"
A8: armored_car | B8: armored_car | C8: Light | D8: Assets/MachineBrigade/Resources/Data/balance.json: aiBehaviour.units.armored_car | E8: "Light"
A9: artillery | B9: artillery | C9: Arty | D9: Assets/MachineBrigade/Resources/Data/balance.json: aiBehaviour.units.artillery | E9: "Arty"
A10: ashm_corvette | B10: ashm_corvette | C10: TD | D10: Assets/MachineBrigade/Resources/Data/balance.json: aiBehaviour.units.ashm_corvette | E10: "TD"
A11: attack_helicopter | B11: attack_helicopter | C11: AttackHeli | D11: Assets/MachineBrigade/Resources/Data/balance.json: aiBehaviour.units.attack_helicopter | E11: "AttackHeli"
A12: attack_jet | B12: attack_jet | C12: CAS | D12: Assets/MachineBrigade/Resources/Data/balance.json: aiBehaviour.units.attack_jet | E12: "CAS"
... A68: zu23_technical | B68: zu23_technical | C68: SPAAG | D68: Assets/MachineBrigade/Resources/Data/balance.json: aiBehaviour.units.zu23_technical | E68: "SPAAG"

Sheet AI_trang_thai
A1: id | B1: commit | C1: priority | D1: nguon | E1: raw_json
A2: APPROACH | B2: 3 | C2: 2 | D2: Assets/MachineBrigade/Resources/Data/balance.json: aiBehaviour.states.APPROACH | E2: {"priority":2,"commit":3.0}
A3: COMBAT | B3: 4 | C3: 3 | D3: Assets/MachineBrigade/Resources/Data/balance.json: aiBehaviour.states.COMBAT | E3: {"priority":3,"commit":4.0}
A4: FLANK | B4: 6 | C4: 2 | D4: Assets/MachineBrigade/Resources/Data/balance.json: aiBehaviour.states.FLANK | E4: {"priority":2,"commit":6.0}
A5: HOLD | B5: 5 | C5: 2 | D5: Assets/MachineBrigade/Resources/Data/balance.json: aiBehaviour.states.HOLD | E5: {"priority":2,"commit":5.0}
A6: OVERWATCH | B6: 4 | C6: 2 | D6: Assets/MachineBrigade/Resources/Data/balance.json: aiBehaviour.states.OVERWATCH | E6: {"priority":2,"commit":4.0}
A7: REGROUP | B7: 3 | C7: 3 | D7: Assets/MachineBrigade/Resources/Data/balance.json: aiBehaviour.states.REGROUP | E7: {"priority":3,"commit":3.0}
A8: TRAVEL | B8: 4 | C8: 1 | D8: Assets/MachineBrigade/Resources/Data/balance.json: aiBehaviour.states.TRAVEL | E8: {"priority":1,"commit":4.0}

Sheet AI_thap
A1: id | B1: thap | C1: mode | D1: modes | E1: nguon | F1: raw_json
A2: aa_gun_tower | B2: aa_gun_tower | C2: AirFirst | D2: Nearest | E2: Assets/MachineBrigade/Resources/Data/balance.json: aiBehaviour.towers.aa_gun_tower | F2: {"mode":"AirFirst","modes":["Nearest"]}
