Workbook

Sheet Mục lục
A1: Machine Brigade — Cân bằng đợt 2, bản v2 (2026-10-02)
A2: Bản này thay hoàn toàn Machine_Brigade_Can_bang_dot2.xlsx. Agent chỉ đọc sheet Manifest để sửa dữ liệu; mọi sheet khác là giải thích hoặc công thức. Đợt này thuần lý thuyết: không chạy mô phỏng, test trong game hay đo FPS.
A4: Sheet | B4: Nội dung
A5: Quy tắc | B5: Luật bắt buộc cho agent: trạng thái, kiểm tra trước khi áp, gói, làm tròn, baseCP, vũ khí dùng chung
A6: Quyết định | B6: D1–D9 đã chốt (thay cho danh sách DECIDE), lý do, gói bị ảnh hưởng
A7: Manifest | B7: NGUỒN DUY NHẤT để agent sửa dữ liệu. Chỉ dòng FIX/APPLY được áp
A8: Gói | B8: Danh sách gói, phụ thuộc, có cần viết code không
A9: Hệ số | B9: Tham số đầu vào (chữ xanh) của sheet Tính toán
A10: Tính toán | B10: Công thức sống: CP mới, máu, thưởng, hệ số sát thương, thả dù cho 100 xe. Manifest là bản đóng băng của sheet này
A11: Máy bay – số phát | B11: Số phát để hạ theo vũ khí phòng không tham chiếu và dải mục tiêu (thay sàn máu và cột Typhon/Icarus)
A12: Pháo sáng | B12: Chuyển đổi 23 máy bay/trực thăng từ hồi chiêu sang số lần
A13: APS | B13: SELF_APS và POINT_DEFENSE; khả năng gắn Trophy theo xe
A14: Vũ khí dùng chung | B14: Vì sao hệ số DPS phải đặt ở xe, không sửa vũ khí
A15: Gungnir | B15: Gói nâng Gungnir lên boss chủ lực
... A18: So với v1 | B18: Những gì đổi so với Machine_Brigade_Can_bang_dot2.xlsx
A20: Màu trạng thái
A21: FIX
A22: APPLY
A23: DECIDE
A24: HOLD
A25: CHECK
A26: REJECT

Sheet Quy tắc
A1: Mã | B1: Luật
A2: R1 Trạng thái | B2: FIX = phục hồi giá trị đã biết là đúng (known_good). APPLY = thay đổi đã duyệt. DECIDE = chờ chủ dự án. HOLD = chờ dữ liệu/đo. CHECK = đọc và báo cáo, không sửa. REJECT = bỏ. Agent CHỈ sửa dữ liệu theo FIX và APPLY. Ô trống hoặc mã lạ = bỏ qua (fail closed).
A3: R2 Kiểm tra trước khi áp | B3: Với mỗi dòng: hiện tại == new_value → ALREADY_APPLIED; hiện tại == expected_before (trong tolerance) → OK; khác → CONFLICT. Một dòng CONFLICT → bỏ cả gói và ghi log. Gói có cả OK và ALREADY_APPLIED vẫn áp nhưng ghi cảnh báo "gói từng bị áp dở".
A4: R3 Gói nguyên vẹn | B4: Mọi dòng cùng bundle_id áp cùng một commit hoặc không áp. Gói có depends_on chỉ áp khi các gói phụ thuộc đã áp xong (hoặc ALREADY_APPLIED). Không áp nửa gói của một xe.
A5: R4 Không đọc văn xuôi | B5: Agent không được đọc chuỗi kiểu "2352 → 6000" ở cột reason/derivation để sửa dữ liệu. Chỉ dùng entity_id, field_path, expected_before, new_value.
A6: R5 field_path là đường dẫn logic | B6: field_path (units.<id>.hp, units.<id>.cost…) là tên logic. Việc đầu tiên (CHECK C01) là lập bảng ánh xạ field_path → khóa thật trong balance.json/campaign.json. Trường nào không ánh xạ được thì gói đó CONFLICT, không đoán.
A7: R6 Làm tròn | B7: Một hàm chung ROUND_HALF_UP cho mọi CP suy ra (10 × 1,25 = 12,5 → 13). Máu làm tròn tới 10 bằng cùng kiểu. Không dùng round() của Python (làm tròn về số chẵn).
A8: R7 baseCP và chi phí gọi | B8: baseCP là giá gốc của thẻ sau định giá lại. runtimeCallCost là giá sau giảm giá hạng thẻ. Nhóm thưởng, thời gian thả dù, giá trị tiếp tế, phân loại cân bằng đều dùng baseCP. Không thẻ nào đổi nhóm vì giảm giá hạng thẻ.
A9: R8 Vũ khí dùng chung | B9: Cân bằng theo xe dùng units.<id>.outgoingDamageMult (nhân sát thương mọi vũ khí của xe đó). Không sửa vũ khí có scope=shared_weapon trừ khi manifest ghi rõ scope=shared_weapon. Test sau khi áp: mọi dòng scope=unit thì JSON vũ khí phải giữ nguyên byte-for-byte; nếu một vũ khí dùng chung đổi, liệt kê mọi xe mang nó.
A10: R9 Đơn vị | B10: So sánh sau khi chuẩn hóa đơn vị (cột unit). Tốc độ xoay: dữ liệu °/s, mã rad/s; test hồi quy bảo đảm tài liệu không in rad/s dưới nhãn °/s.
A11: R10 Số đo | B11: Bảng kết quả hiện tại chỉ dùng số đo có cùng hash balance.json, campaign.json, build, commit, phiên bản luật. Số đo lệch hash chuyển sang phụ lục "Lịch sử đo". Đợt này không chạy đo.
A12: R11 Nhổ lan | B12: Đơn vị nổ lan (cột AoE ở sheet Tính toán) nhận phần hệ số theo giá ngay, phần thưởng sức mạnh ở gói B5 (HOLD) cho tới khi có thước đo nổ lan.

Sheet Quyết định
A1: Mã | B1: Vấn đề | C1: Đã chốt | D1: Lý do | E1: Gói
A2: D1 | B2: Gungnir | C2: Nâng lên boss chủ lực: siêu vũ khí chu kỳ 45 s, targetingMode=GLOBAL, đòn pháo điện từ xuyên tuyến theo mô tả (xuyên tối đa 5 xe × 1.000, nổ cuối 2.000 lõi 12 m, rìa 20 m), máu theo công thức boss chủ lực chương 11. | D2: Là trận cuối của Orlov; giữ được cảm giác "khẩu pháo bắn khắp bản đồ"; luật "mini boss không có siêu vũ khí" được giữ nguyên. | E2: G1
A3: D2 | B3: Cách chỉnh DPS theo xe | C3: Thêm units.<id>.outgoingDamageMult. Bỏ luật "không đẩy sát thương mỗi phát ra ngoài thang cỡ nòng" của dot2 v1, chỉ cho hệ số này. | D3: Không tăng số đạn và hiệu ứng trên sân (hiệu năng điện thoại); không đụng 12 vũ khí dùng chung; giữ nhịp bắn, băng đạn, nạp đạn đặc trưng của từng vũ khí. | E3: S03, mọi B1, B5
A4: D3 | B4: Thưởng sức mạnh | C4: Đường C: thưởng = min(15%, max(0, 1,25% × (baseCP mới − 8))). 9 CP +1,25%, 12 CP +5%, 16 CP +10%, từ 20 CP +15%. | D4: Một dòng công thức, không có bậc 8 → 9 CP. | E4: B1, B5
A5: D4 | B5: Máu sau phục hồi | C5: Xe mặt đất theo công thức giá: Pháo phản lực nhiệt áp 1.980 × (11/9)^1,15 ≈ 2.490; Pháo cối công thành 3.300 × (15/12)^1,15 ≈ 4.270. Pháo hạm bay chốt 4.900 (12 phát Buk hiệu dụng, mép trên dải D8), không dùng 6.045. | D5: Một luật chung cho xe mặt đất; máy bay theo số phát vì cột Typhon 1.460 đã bị loại. | E5: B0, B1
A6: D5 | B6: Tốc độ 4 xe | C6: Về đúng giá trị đã biết: Tăng nhẹ lội nước 9, Xe bom bọc thép 13, Tăng phun lửa 6,5 (bằng Tăng chủ lực), Xe công binh 7. Chỉ FIX, không thêm giá trị mới. | D6: Không có dữ liệu chứng minh 8 / 11 / 5,5 / 5,5 tốt hơn giá trị cũ; đợt lý thuyết không tạo thay đổi mới khi không cần. | E6: B0
A7: D6 | B7: Pháo sáng | C7: Đổi từ hồi chiêu sang số lần dự trữ; tốc độ hồi giữ đúng hồi chiêu hiện tại (không làm yếu đi); 6 đơn vị thêm mới hồi 20 s; Oanh tạc cơ tàng hình bỏ pháo sáng theo luật "chỉ khi mẫu thật có"; Mồi bẫy nhiệt chỉ nâng cấp đơn vị đã có. | D7: Đổi hệ mà không đổi sức mạnh lâu dài; số lần dự trữ cho cảm giác đỡ đợt đầu. | E7: B2-FLR
A8: D7 | B8: APS | C8: SELF_APS của xe chỉ chặn tên lửa dẫn đường, drone, rốc-két bắn thẳng; hồi 10 s. Tăng thế hệ mới 2 lần (BUILT_IN), Siêu tăng 3 lần (BUILT_IN, mới). Tăng chủ lực RETROFIT_ELIGIBLE: Trophy cho 2 lần, hồi 20 s. BUILT_IN gắn Trophy: +1 lần, hồi nhanh hơn 25%. Tăng hạng nặng NONE. Phòng thủ điểm tách thành POINT_DEFENSE. | D8: Một xe diệt tăng không phá được T-14, hai xe thì phá được; xe diệt tăng dùng pháo không bị vô hiệu. | E8: B2-APS, S07
A9: D8 | B9: Số phát mục tiêu cho máy bay | C9: Thước đo chính: số phát Buk hiệu dụng (320 × hệ số với máy bay, giả định 1,3; CHECK C10). Dải: tiêm kích 3–5; máy bay ở lại lâu 8–12; cường kích/đi qua 4–8; drone và máy bay trinh sát 2–4. Bỏ sàn 85% đường cong máu. | D9: Đo sức sống bằng vũ khí phòng không thật thay vì vũ khí boss không truy được nguồn. | E9: B1 (máy bay)
A10: D9 | B10: Kho CP | C10: Phương án A: kho 30 → 45 (Công thành 40 → 55, Sinh tồn 30 → 40, Săn trùm 45 → 60, Vault 45 → 60). Ngưỡng tiếp tế giữ nguyên (HOLD) cho tới khi đọc code. | D10: Đơn vị 29 CP gọi được mà không chiếm cả kho; không thêm hệ điểm chỗ quân. | E10: E1

Sheet Manifest
A1: Nguồn duy nhất để agent sửa dữ liệu (R1–R5). Chỉ dòng FIX/APPLY được áp; HOLD/REJECT ở đây để giữ dấu vết. Giá trị đã đóng băng từ sheet Tính toán.
A3: bundle_id | B3: entity_id | C3: field_path | D3: unit | E3: value_type | F3: known_good | G3: expected_before | H3: new_value | I3: tolerance | J3: derivation | K3: status | L3: scope | M3: requires_code | N3: depends_on | O3: owner_decision_id | P3: validation | Q3: reason | R3: source
A4: S01 | B4: (hệ thống) | C4: — | D4: — | E4: code | J4: Manifest engine: đọc sheet Manifest, kiểm tra trước khi áp (R2), áp theo gói (R3), ghi log CONFLICT/ALREADY_APPLIED | K4: APPLY | L4: system | M4: =TRUE() -> TRUE | O4: — | P4: Test đi kèm phải pass | Q4: Manifest engine: đọc sheet Manifest, kiểm tra trước khi áp (R2), áp theo gói (R3), ghi log CONFLICT/ALREADY_APPLIED | R4: Review vòng 3–cuối
A5: S02 | B5: (hệ thống) | C5: — | D5: — | E5: code | J5: Hàm làm tròn chung ROUND_HALF_UP cho CP và máu (R6) | K5: APPLY | L5: system | M5: =TRUE() -> TRUE | N5: S01 | O5: — | P5: Test đi kèm phải pass | Q5: Hàm làm tròn chung ROUND_HALF_UP cho CP và máu (R6) | R5: Review vòng 3–cuối
A6: S03 | B6: (hệ thống) | C6: — | D6: — | E6: code | J6: Trường units.<id>.outgoingDamageMult (mặc định 1,0), nhân sát thương mọi vũ khí của xe; validator vũ khí dùng chung (R8) | K6: APPLY | L6: system | M6: =TRUE() -> TRUE | N6: S01 | O6: D2 | P6: Test đi kèm phải pass | Q6: Trường units.<id>.outgoingDamageMult (mặc định 1,0), nhân sát thương mọi vũ khí của xe; validator vũ khí dùng chung (R8) | R6: Review vòng 3–cuối
A7: S04 | B7: (hệ thống) | C7: — | D7: — | E7: code | J7: Tách baseCP và runtimeCallCost (R7); mọi phân nhóm dùng baseCP | K7: APPLY | L7: system | M7: =TRUE() -> TRUE | N7: S01 | O7: — | P7: Test đi kèm phải pass | Q7: Tách baseCP và runtimeCallCost (R7); mọi phân nhóm dùng baseCP | R7: Review vòng 3–cuối
A8: S05 | B8: (hệ thống) | C8: — | D8: — | E8: code | J8: Cờ năng lực đòn đánh: canHitGround, canHitAir, interceptable, flareEligible, apsEligible, ciwsEligible (dùng lại trường có sẵn nếu đã có; CHECK C13) | K8: APPLY | L8: system | M8: =TRUE() -> TRUE | N8: S01 | O8: D7 | P8: Test đi kèm phải pass | Q8: Cờ năng lực đòn đánh: canHitGround, canHitAir, interceptable, flareEligible, apsEligible, ciwsEligible (dùng lại trường có sẵn nếu đã có; CHECK C13) | R8: Review vòng 3–cuối
A9: S06 | B9: (hệ thống) | C9: — | D9: — | E9: code | J9: Pháo sáng theo số lần: maxCharges, rechargeSec, nạp đầy khi về sân bay; Mồi bẫy nhiệt chỉ nâng cấp đơn vị BUILT_IN | K9: APPLY | L9: system | M9: =TRUE() -> TRUE | N9: S01 | O9: D6 | P9: Test đi kèm phải pass | Q9: Pháo sáng theo số lần: maxCharges, rechargeSec, nạp đầy khi về sân bay; Mồi bẫy nhiệt chỉ nâng cấp đơn vị BUILT_IN | R9: Review vòng 3–cuối
A10: S07 | B10: (hệ thống) | C10: — | D10: — | E10: code | J10: interceptionSystem.mode = SELF_APS | POINT_DEFENSE; apsCapability = NONE | BUILT_IN | RETROFIT_ELIGIBLE; danh sách loại đạn chặn được tách: directMissile, drone, directRocket, artilleryRocket, mortarShell, artilleryShell, tankShell | K10: APPLY | L10: system | M10: =TRUE() -> TRUE | N10: S01 | O10: D7 | P10: Test đi kèm phải pass | Q10: interceptionSystem.mode = SELF_APS | POINT_DEFENSE; apsCapability = NONE | BUILT_IN | RETROFIT_ELIGIBLE; danh sách loại đạn chặn được tách: directMissile, drone, directRocket, artilleryRocket, mortarShell, artilleryShell, tankShell | R10: Review vòng 3–cuối
A11: S08 | B11: (hệ thống) | C11: — | D11: — | E11: code | J11: Lịch sử đo: gắn hash cho mọi số đo; số đo lệch hash chuyển sang phụ lục (R10) | K11: APPLY | L11: system | M11: =TRUE() -> TRUE | N11: S01 | O11: — | P11: Test đi kèm phải pass | Q11: Lịch sử đo: gắn hash cho mọi số đo; số đo lệch hash chuyển sang phụ lục (R10) | R11: Review vòng 3–cuối
A12: S09 | B12: (hệ thống) | C12: — | D12: — | E12: code | J12: Test hồi quy đơn vị tốc độ xoay (R9) | K12: APPLY | L12: system | M12: =TRUE() -> TRUE | N12: S01 | O12: — | P12: Test đi kèm phải pass | Q12: Test hồi quy đơn vị tốc độ xoay (R9) | R12: Review vòng 3–cuối
A13: E1 | B13: Chiếm cứ điểm / Tử chiến / Vua đồi | C13: modes.<mode>.cpStockCap | D13: CP | E13: int | G13: 30 | H13: 45 | I13: 0 | J13: Phương án A (sheet Kinh tế dot2 v1) | K13: APPLY | L13: system | M13: =FALSE() -> FALSE | N13: S01 | O13: D9 | P13: Kho mới ≥ giá đơn vị đắt nhất + 15 | Q13: Đơn vị 29 CP không chiếm cả kho | R13: dot2 v1 > Kinh tế
A14: E1 | B14: Công phá | C14: modes.<mode>.cpStockCap | D14: CP | E14: int | G14: 30 | H14: 45 | I14: 0 | J14: Phương án A (sheet Kinh tế dot2 v1) | K14: APPLY | L14: system | M14: =FALSE() -> FALSE | N14: S01 | O14: D9 | P14: Kho mới ≥ giá đơn vị đắt nhất + 15 | Q14: Đơn vị 29 CP không chiếm cả kho | R14: dot2 v1 > Kinh tế
A15: E1 | B15: Công thành | C15: modes.<mode>.cpStockCap | D15: CP | E15: int | G15: 40 | H15: 55 | I15: 0 | J15: Phương án A (sheet Kinh tế dot2 v1) | K15: APPLY | L15: system | M15: =FALSE() -> FALSE | N15: S01 | O15: D9 | P15: Kho mới ≥ giá đơn vị đắt nhất + 15 | Q15: Đơn vị 29 CP không chiếm cả kho | R15: dot2 v1 > Kinh tế
A16: E1 | B16: Phòng thủ / Vô tận | C16: modes.<mode>.cpStockCap | D16: CP | E16: int | G16: 30 | H16: 45 | I16: 0 | J16: Phương án A (sheet Kinh tế dot2 v1) | K16: APPLY | L16: system | M16: =FALSE() -> FALSE | N16: S01 | O16: D9 | P16: Kho mới ≥ giá đơn vị đắt nhất + 15 | Q16: Đơn vị 29 CP không chiếm cả kho | R16: dot2 v1 > Kinh tế
A17: E1 | B17: Sinh tồn | C17: modes.<mode>.cpStockCap | D17: CP | E17: int | G17: 30 | H17: 40 | I17: 0 | J17: Phương án A (sheet Kinh tế dot2 v1) | K17: APPLY | L17: system | M17: =FALSE() -> FALSE | N17: S01 | O17: D9 | P17: Kho mới ≥ giá đơn vị đắt nhất + 15 | Q17: Đơn vị 29 CP không chiếm cả kho | R17: dot2 v1 > Kinh tế
A18: E1 | B18: Săn trùm | C18: modes.<mode>.cpStockCap | D18: CP | E18: int | G18: 45 | H18: 60 | I18: 0 | J18: Phương án A (sheet Kinh tế dot2 v1) | K18: APPLY | L18: system | M18: =FALSE() -> FALSE | N18: S01 | O18: D9 | P18: Kho mới ≥ giá đơn vị đắt nhất + 15 | Q18: Đơn vị 29 CP không chiếm cả kho | R18: dot2 v1 > Kinh tế
A19: E1 | B19: Chỉ huy Vault | C19: modes.<mode>.cpStockCap | D19: CP | E19: int | G19: 45 | H19: 60 | I19: 0 | J19: Phương án A (sheet Kinh tế dot2 v1) | K19: APPLY | L19: system | M19: =FALSE() -> FALSE | N19: S01 | O19: D9 | P19: Kho mới ≥ giá đơn vị đắt nhất + 15 | Q19: Đơn vị 29 CP không chiếm cả kho | R19: dot2 v1 > Kinh tế
A20: E2 | B20: (tiếp tế) | C20: economy.supplyThreshold | D20: CP | E20: float | G20: 25.2 | J20: 24 × 1,05 hiện tại; 29,2 là đề xuất cũ | K20: HOLD | L20: system | M20: =FALSE() -> FALSE | N20: C02 | O20: — | P20: — | Q20: Chưa biết hình dạng đường phạt | R20: PDF tr. 266
A21: B0-sky_gunship | B21: sky_gunship | C21: units.sky_gunship.hp | D21: HP | E21: int | F21: 4400 | G21: 2352 | H21: 4400 | I21: 0 | J21: Phục hồi known_good ở giá hiện tại | K21: FIX | L21: unit | M21: =FALSE() -> FALSE | N21: S01 | O21: D4 | P21: hp == known_good | Q21: Dòng "Xem lại" đợt 1 bị áp nhầm | R21: dot2 v1 > Kiểm tra nhanh
A22: B0-thermobaric_launcher | B22: thermobaric_launcher | C22: units.thermobaric_launcher.hp | D22: HP | E22: int | F22: 1980 | G22: 990 | H22: 1980 | I22: 0 | J22: Phục hồi known_good ở giá hiện tại | K22: FIX | L22: unit | M22: =FALSE() -> FALSE | N22: S01 | O22: D4 | P22: hp == known_good | Q22: Dòng "Xem lại" đợt 1 bị áp nhầm | R22: dot2 v1 > Kiểm tra nhanh
A23: B0-siege_tank | B23: siege_tank | C23: units.siege_tank.hp | D23: HP | E23: int | F23: 3300 | G23: 1320 | H23: 3300 | I23: 0 | J23: Phục hồi known_good ở giá hiện tại | K23: FIX | L23: unit | M23: =FALSE() -> FALSE | N23: S01 | O23: D4 | P23: hp == known_good | Q23: Dòng "Xem lại" đợt 1 bị áp nhầm | R23: dot2 v1 > Kiểm tra nhanh
A24: B0-light_tank | B24: light_tank | C24: units.light_tank.speed | D24: m/s | E24: float | F24: 9 | G24: 4 | H24: 9 | I24: 0.001 | J24: Phục hồi known_good | K24: FIX | L24: unit | M24: =FALSE() -> FALSE | N24: S01 | O24: D5 | P24: speed == known_good | Q24: Dòng "Xem lại" đợt 1 bị áp nhầm | R24: dot2 v1 > Kiểm tra nhanh
A25: B0-vbied | B25: vbied | C25: units.vbied.speed | D25: m/s | E25: float | F25: 13 | G25: 6.7 | H25: 13 | I25: 0.001 | J25: Phục hồi known_good | K25: FIX | L25: unit | M25: =FALSE() -> FALSE | N25: S01 | O25: D5 | P25: speed == known_good | Q25: Dòng "Xem lại" đợt 1 bị áp nhầm | R25: dot2 v1 > Kiểm tra nhanh
A26: B0-flame_tank | B26: flame_tank | C26: units.flame_tank.speed | D26: m/s | E26: float | F26: 6.5 | G26: 4.6 | H26: 6.5 | I26: 0.001 | J26: Phục hồi known_good | K26: FIX | L26: unit | M26: =FALSE() -> FALSE | N26: S01 | O26: D5 | P26: speed == known_good | Q26: Dòng "Xem lại" đợt 1 bị áp nhầm | R26: dot2 v1 > Kiểm tra nhanh
A27: B0-engineer_vehicle | B27: engineer_vehicle | C27: units.engineer_vehicle.speed | D27: m/s | E27: float | F27: 7 | G27: 4.4 | H27: 7 | I27: 0.001 | J27: Phục hồi known_good | K27: FIX | L27: unit | M27: =FALSE() -> FALSE | N27: S01 | O27: D5 | P27: speed == known_good | Q27: Dòng "Xem lại" đợt 1 bị áp nhầm | R27: dot2 v1 > Kiểm tra nhanh
A28: B1-armored_car | B28: armored_car | C28: units.armored_car.dropDelaySec | D28: s | E28: float | G28: 3.5 | H28: 2.5 | I28: 0.001 | J28: baseCP mới ≤ 4: 2,5 s; ≥ 15: 5 s; còn lại 3,5 s | K28: APPLY | L28: unit | M28: =FALSE() -> FALSE | N28: S01, S02, S03, S04, E1 | O28: — | P28: Theo baseCP, không theo giá sau giảm | Q28: Xe rẻ phản ứng nhanh, xe đắt có khoảnh khắc ra quân | R28: Đã chốt
A29: B1-combat_wreck_car | B29: combat_wreck_car | C29: units.combat_wreck_car.dropDelaySec | D29: s | E29: float | G29: 3.5 | H29: 2.5 | I29: 0.001 | J29: baseCP mới ≤ 4: 2,5 s; ≥ 15: 5 s; còn lại 3,5 s | K29: APPLY | L29: unit | M29: =FALSE() -> FALSE | N29: S01, S02, S03, S04, E1 | O29: — | P29: Theo baseCP, không theo giá sau giảm | Q29: Xe rẻ phản ứng nhanh, xe đắt có khoảnh khắc ra quân | R29: Đã chốt
A30: B1-river_patrol_boat | B30: river_patrol_boat | C30: units.river_patrol_boat.cost | D30: CP | E30: int | G30: 5 | H30: 6 | I30: 0 | J30: ROUND_HALF_UP(5 × 1.15) | K30: APPLY | L30: unit | M30: =FALSE() -> FALSE | N30: S01, S02, S03, S04, E1 | O30: — | P30: baseCP dùng cho mọi phân nhóm | Q30: Định giá lại theo nhóm giá | R30: Đã chốt
A31: B1-river_patrol_boat | B31: river_patrol_boat | C31: units.river_patrol_boat.hp | D31: HP | E31: int | G31: 801 | H31: 990 | I31: 0 | J31: ROUND10(801 × (6/5)^1,15) | K31: APPLY | L31: unit | M31: =FALSE() -> FALSE | N31: S01, S02, S03, S04, E1 | O31: — | P31: hp == derivation | Q31: Máu tăng nhanh hơn giá | R31: Đã chốt; D4; D8
A32: B1-river_patrol_boat | B32: river_patrol_boat | C32: units.river_patrol_boat.outgoingDamageMult | D32: × | E32: float | G32: 1 | H32: 1.2 | I32: 0.0005 | J32: (6/5) × (1 + 0.0000) | K32: APPLY | L32: unit | M32: =FALSE() -> FALSE | N32: S01, S02, S03, S04, E1 | O32: D2, D3 | P32: Vũ khí dùng chung không đổi (R8) | Q32: Giữ giá trị mỗi CP sau tăng giá + thưởng | R32: Đã chốt; D3
A33: B1-airborne_vehicle | B33: airborne_vehicle | C33: units.airborne_vehicle.cost | D33: CP | E33: int | G33: 6 | H33: 7 | I33: 0 | J33: ROUND_HALF_UP(6 × 1.15) | K33: APPLY | L33: unit | M33: =FALSE() -> FALSE | N33: S01, S02, S03, S04, E1 | O33: — | P33: baseCP dùng cho mọi phân nhóm | Q33: Định giá lại theo nhóm giá | R33: Đã chốt
A34: B1-airborne_vehicle | B34: airborne_vehicle | C34: units.airborne_vehicle.hp | D34: HP | E34: int | G34: 1100 | H34: 1310 | I34: 0 | J34: ROUND10(1100 × (7/6)^1,15) | K34: APPLY | L34: unit | M34: =FALSE() -> FALSE | N34: S01, S02, S03, S04, E1 | O34: — | P34: hp == derivation | Q34: Máu tăng nhanh hơn giá | R34: Đã chốt; D4; D8
A35: B1-airborne_vehicle | B35: airborne_vehicle | C35: units.airborne_vehicle.outgoingDamageMult | D35: × | E35: float | G35: 1 | H35: 1.1667 | I35: 0.0005 | J35: (7/6) × (1 + 0.0000) | K35: APPLY | L35: unit | M35: =FALSE() -> FALSE | N35: S01, S02, S03, S04, E1 | O35: D2, D3 | P35: Vũ khí dùng chung không đổi (R8) | Q35: Giữ giá trị mỗi CP sau tăng giá + thưởng | R35: Đã chốt; D3
A36: B1-amphib_light_vehicle | B36: amphib_light_vehicle | C36: units.amphib_light_vehicle.cost | D36: CP | E36: int | G36: 6 | H36: 7 | I36: 0 | J36: ROUND_HALF_UP(6 × 1.15) | K36: APPLY | L36: unit | M36: =FALSE() -> FALSE | N36: S01, S02, S03, S04, E1 | O36: — | P36: baseCP dùng cho mọi phân nhóm | Q36: Định giá lại theo nhóm giá | R36: Đã chốt
A37: B1-amphib_light_vehicle | B37: amphib_light_vehicle | C37: units.amphib_light_vehicle.hp | D37: HP | E37: int | G37: 1199 | H37: 1430 | I37: 0 | J37: ROUND10(1199 × (7/6)^1,15) | K37: APPLY | L37: unit | M37: =FALSE() -> FALSE | N37: S01, S02, S03, S04, E1 | O37: — | P37: hp == derivation | Q37: Máu tăng nhanh hơn giá | R37: Đã chốt; D4; D8
A38: B1-amphib_light_vehicle | B38: amphib_light_vehicle | C38: units.amphib_light_vehicle.outgoingDamageMult | D38: × | E38: float | G38: 1 | H38: 1.1667 | I38: 0.0005 | J38: (7/6) × (1 + 0.0000) | K38: APPLY | L38: unit | M38: =FALSE() -> FALSE | N38: S01, S02, S03, S04, E1 | O38: D2, D3 | P38: Vũ khí dùng chung không đổi (R8) | Q38: Giữ giá trị mỗi CP sau tăng giá + thưởng | R38: Đã chốt; D3
A39: B1-ifv | B39: ifv | C39: units.ifv.cost | D39: CP | E39: int | G39: 6 | H39: 7 | I39: 0 | J39: ROUND_HALF_UP(6 × 1.15) | K39: APPLY | L39: unit | M39: =FALSE() -> FALSE | N39: S01, S02, S03, S04, E1 | O39: — | P39: baseCP dùng cho mọi phân nhóm | Q39: Định giá lại theo nhóm giá | R39: Đã chốt
... A169: B1-sky_gunship | B169: sky_gunship | C169: units.sky_gunship.cost | D169: CP | E169: int | G169: 22 | H169: 29 | I169: 0 | J169: ROUND_HALF_UP(22 × 1.3) | K169: APPLY | L169: unit | M169: =FALSE() -> FALSE | N169: S01, S02, S03, S04, E1, B0-sky_gunship, B2-FLR-sky_gunship, B3-AI | O169: — | P169: baseCP dùng cho mọi phân nhóm | Q169: Định giá lại theo nhóm giá | R169: Đã chốt
A170: B1-sky_gunship | B170: sky_gunship | C170: units.sky_gunship.hp | D170: HP | E170: int | F170: 4400 | G170: 4400 | H170: 4900 | I170: 0 | J170: D4/D8: 12 phát Buk hiệu dụng, mép trên dải 8–12 (máy bay ở lại lâu, không còn rút về sửa); thay cho 6.045 theo công thức giá | K170: APPLY | L170: unit | M170: =FALSE() -> FALSE | N170: S01, S02, S03, S04, E1, B0-sky_gunship, B2-FLR-sky_gunship, B3-AI | O170: D4/D8 | P170: Máy bay: số phát Buk hiệu dụng trong dải (sheet Máy bay – số phát) | Q170: Máu tăng nhanh hơn giá | R170: Đã chốt; D4; D8
...

Sheet Gói
A1: bundle_id | B1: Đối tượng | C1: Số dòng | D1: Trạng thái | E1: Cần viết code | F1: depends_on
A2: S01 | B2: (hệ thống) | C2: 1 | D2: APPLY | E2: Có
A3: S02 | B3: (hệ thống) | C3: 1 | D3: APPLY | E3: Có | F3: S01
A4: S03 | B4: (hệ thống) | C4: 1 | D4: APPLY | E4: Có | F4: S01
A5: S04 | B5: (hệ thống) | C5: 1 | D5: APPLY | E5: Có | F5: S01
A6: S05 | B6: (hệ thống) | C6: 1 | D6: APPLY | E6: Có | F6: S01
A7: S06 | B7: (hệ thống) | C7: 1 | D7: APPLY | E7: Có | F7: S01
A8: S07 | B8: (hệ thống) | C8: 1 | D8: APPLY | E8: Có | F8: S01
A9: S08 | B9: (hệ thống) | C9: 1 | D9: APPLY | E9: Có | F9: S01
A10: S09 | B10: (hệ thống) | C10: 1 | D10: APPLY | E10: Có | F10: S01
A11: E1 | B11: Chiếm cứ điểm / Tử chiến / Vua đồi | C11: 7 | D11: APPLY | E11: Không | F11: S01
A12: E2 | B12: (tiếp tế) | C12: 1 | D12: HOLD | E12: Không | F12: C02
A13: B0-sky_gunship | B13: sky_gunship | C13: 1 | D13: FIX | E13: Không | F13: S01
A14: B0-thermobaric_launcher | B14: thermobaric_launcher | C14: 1 | D14: FIX | E14: Không | F14: S01
... A151: G1 | B151: gungnir | C151: 5 | D151: APPLY | E151: Có | F151: C11, S01, S05
A152: R-supergun | B152: supergun_800 | C152: 1 | D152: REJECT | E152: Không
A153: R-radar | B153: radar_scout | C153: 1 | D153: REJECT | E153: Không
A154: R-floor | B154: (máy bay, xe nặng) | C154: 1 | D154: REJECT | E154: Không
A155: R-typhon | B155: (chỉ số) | C155: 1 | D155: REJECT | E155: Không
A156: R-icarus | B156: (chỉ số) | C156: 1 | D156: REJECT | E156: Không
A157: R-round-hover | B157: hover_gunboat | C157: 1 | D157: REJECT | E157: Không
A158: R-speed-new | B158: (4 xe) | C158: 1 | D158: REJECT | E158: Không

Sheet Hệ số
A1: Tham số (chữ xanh = đầu vào, sửa ở đây thì sheet Tính toán và Máy bay – số phát tính lại)
A3: Tham số | B3: Giá trị | C3: Nguồn
A4: Số mũ máu theo giá | B4: 1.15 | C4: Đã chốt
A5: Thưởng: hệ số mỗi CP | B5: 0.0125 | C5: D3
A6: Thưởng: trần | B6: 0.15 | C6: D3
A7: Thưởng: CP bắt đầu | B7: 8 | C7: D3
A8: Hệ số giá ≤ 4 CP | B8: 1 | C8: Đã chốt
A9: Hệ số giá 5–8 CP | B9: 1.15 | C9: Đã chốt
A10: Hệ số giá 9–13 CP | B10: 1.25 | C10: Đã chốt
A11: Hệ số giá ≥ 14 CP | B11: 1.3 | C11: Đã chốt
A12: Thả dù: CP ≤ (s = 2,5) | B12: 4 | C12: Đã chốt
A13: Thả dù: CP ≥ (s = 5) | B13: 15 | C13: Đã chốt
A14: Sát thương Buk | B14: 320 | C14: PDF bảng vũ khí: buk_launcher
A15: Hệ số Buk với máy bay | B15: 1.3 | C15: Giả định; CHECK C10
... A17: Sát thương tên lửa tiêm kích (air_to_air) | B17: 294 | C17: PDF bảng vũ khí

Sheet Tính toán
A1: id | B1: Tên | C1: Lớp | D1: AoE (1 = thưởng ở B5) | E1: CP hiện tại | F1: Hệ số giá | G1: CP mới | H1: Máu hiện tại | I1: Máu gốc (known_good) | J1: Máu theo công thức | K1: Máu chốt (ghi đè) | L1: Máu chốt | M1: Tỷ lệ giá | N1: Thưởng (D3) | O1: Hệ số sát thương áp ngay | P1: Hệ số sát thương đầy đủ | Q1: Thả dù (s)
A2: hover_gunboat | B2: Xuồng đệm khí hộ tống | C2: Xe nhẹ | D2: 0 | E2: 0 | F2: =IF(E2<=4,'Hệ số'!$B$8,IF(E2<=8,'Hệ số'!$B$9,IF(E2<=13,'Hệ số'!$B$10,'Hệ số'!$B$11))) -> 1 | G2: =ROUND(E2*F2,0) -> 0 | H2: 1144 | I2: 1144 | J2: =IF(OR(E2=0,G2=E2),I2,ROUND(I2*(G2/E2)^'Hệ số'!$B$4,-1)) -> 1144 | L2: =IF(K2="",J2,K2) -> 1144 | M2: =IF(E2=0,1,G2/E2) -> 1 | N2: =IF(E2=0,0,MIN('Hệ số'!$B$6,MAX(0,'Hệ số'!$B$5*(G2-'Hệ số'!$B$7)))) -> 0 | O2: =ROUND(IF(D2=1,M2,M2*(1+N2)),4) -> 1 | P2: =ROUND(M2*(1+N2),4) -> 1 | Q2: =IF(E2=0,"",IF(G2<='Hệ số'!$B$12,2.5,IF(G2>='Hệ số'!$B$13,5,3.5)))
A3: armored_car | B3: Xe bọc thép bánh lốp | C3: Xe nhẹ | D3: 0 | E3: 3 | F3: =IF(E3<=4,'Hệ số'!$B$8,IF(E3<=8,'Hệ số'!$B$9,IF(E3<=13,'Hệ số'!$B$10,'Hệ số'!$B$11))) -> 1 | G3: =ROUND(E3*F3,0) -> 3 | H3: 660 | I3: 660 | J3: =IF(OR(E3=0,G3=E3),I3,ROUND(I3*(G3/E3)^'Hệ số'!$B$4,-1)) -> 660 | L3: =IF(K3="",J3,K3) -> 660 | M3: =IF(E3=0,1,G3/E3) -> 1 | N3: =IF(E3=0,0,MIN('Hệ số'!$B$6,MAX(0,'Hệ số'!$B$5*(G3-'Hệ số'!$B$7)))) -> 0 | O3: =ROUND(IF(D3=1,M3,M3*(1+N3)),4) -> 1 | P3: =ROUND(M3*(1+N3),4) -> 1 | Q3: =IF(E3=0,"",IF(G3<='Hệ số'!$B$12,2.5,IF(G3>='Hệ số'!$B$13,5,3.5))) -> 2.5
A4: combat_wreck_car | B4: Xe khi hỏng thành công sự | C4: Xe nhẹ | D4: 0 | E4: 4 | F4: =IF(E4<=4,'Hệ số'!$B$8,IF(E4<=8,'Hệ số'!$B$9,IF(E4<=13,'Hệ số'!$B$10,'Hệ số'!$B$11))) -> 1 | G4: =ROUND(E4*F4,0) -> 4 | H4: 900 | I4: 900 | J4: =IF(OR(E4=0,G4=E4),I4,ROUND(I4*(G4/E4)^'Hệ số'!$B$4,-1)) -> 900 | L4: =IF(K4="",J4,K4) -> 900 | M4: =IF(E4=0,1,G4/E4) -> 1 | N4: =IF(E4=0,0,MIN('Hệ số'!$B$6,MAX(0,'Hệ số'!$B$5*(G4-'Hệ số'!$B$7)))) -> 0 | O4: =ROUND(IF(D4=1,M4,M4*(1+N4)),4) -> 1 | P4: =ROUND(M4*(1+N4),4) -> 1 | Q4: =IF(E4=0,"",IF(G4<='Hệ số'!$B$12,2.5,IF(G4>='Hệ số'!$B$13,5,3.5))) -> 2.5
A5: river_patrol_boat | B5: Tàu tuần tra sông | C5: Xe nhẹ | D5: 0 | E5: 5 | F5: =IF(E5<=4,'Hệ số'!$B$8,IF(E5<=8,'Hệ số'!$B$9,IF(E5<=13,'Hệ số'!$B$10,'Hệ số'!$B$11))) -> 1.15 | G5: =ROUND(E5*F5,0) -> 6 | H5: 801 | I5: 801 | J5: =IF(OR(E5=0,G5=E5),I5,ROUND(I5*(G5/E5)^'Hệ số'!$B$4,-1)) -> 990 | L5: =IF(K5="",J5,K5) -> 990 | M5: =IF(E5=0,1,G5/E5) -> 1.2 | N5: =IF(E5=0,0,MIN('Hệ số'!$B$6,MAX(0,'Hệ số'!$B$5*(G5-'Hệ số'!$B$7)))) -> 0 | O5: =ROUND(IF(D5=1,M5,M5*(1+N5)),4) -> 1.2 | P5: =ROUND(M5*(1+N5),4) -> 1.2 | Q5: =IF(E5=0,"",IF(G5<='Hệ số'!$B$12,2.5,IF(G5>='Hệ số'!$B$13,5,3.5))) -> 3.5
A6: airborne_vehicle | B6: Xe đổ bộ đường không | C6: Xe nhẹ | D6: 0 | E6: 6 | F6: =IF(E6<=4,'Hệ số'!$B$8,IF(E6<=8,'Hệ số'!$B$9,IF(E6<=13,'Hệ số'!$B$10,'Hệ số'!$B$11))) -> 1.15 | G6: =ROUND(E6*F6,0) -> 7 | H6: 1100 | I6: 1100 | J6: =IF(OR(E6=0,G6=E6),I6,ROUND(I6*(G6/E6)^'Hệ số'!$B$4,-1)) -> 1310 | L6: =IF(K6="",J6,K6) -> 1310 | M6: =IF(E6=0,1,G6/E6) -> 1.1666667 | N6: =IF(E6=0,0,MIN('Hệ số'!$B$6,MAX(0,'Hệ số'!$B$5*(G6-'Hệ số'!$B$7)))) -> 0 | O6: =ROUND(IF(D6=1,M6,M6*(1+N6)),4) -> 1.1667 | P6: =ROUND(M6*(1+N6),4) -> 1.1667 | Q6: =IF(E6=0,"",IF(G6<='Hệ số'!$B$12,2.5,IF(G6>='Hệ số'!$B$13,5,3.5))) -> 3.5
A7: amphib_light_vehicle | B7: Xe lội nước tốc độ cao | C7: Xe nhẹ | D7: 0 | E7: 6 | F7: =IF(E7<=4,'Hệ số'!$B$8,IF(E7<=8,'Hệ số'!$B$9,IF(E7<=13,'Hệ số'!$B$10,'Hệ số'!$B$11))) -> 1.15 | G7: =ROUND(E7*F7,0) -> 7 | H7: 1199 | I7: 1199 | J7: =IF(OR(E7=0,G7=E7),I7,ROUND(I7*(G7/E7)^'Hệ số'!$B$4,-1)) -> 1430 | L7: =IF(K7="",J7,K7) -> 1430 | M7: =IF(E7=0,1,G7/E7) -> 1.1666667 | N7: =IF(E7=0,0,MIN('Hệ số'!$B$6,MAX(0,'Hệ số'!$B$5*(G7-'Hệ số'!$B$7)))) -> 0 | O7: =ROUND(IF(D7=1,M7,M7*(1+N7)),4) -> 1.1667 | P7: =ROUND(M7*(1+N7),4) -> 1.1667 | Q7: =IF(E7=0,"",IF(G7<='Hệ số'!$B$12,2.5,IF(G7>='Hệ số'!$B$13,5,3.5))) -> 3.5
A8: ifv | B8: Xe chiến đấu bộ binh | C8: Xe nhẹ | D8: 0 | E8: 6 | F8: =IF(E8<=4,'Hệ số'!$B$8,IF(E8<=8,'Hệ số'!$B$9,IF(E8<=13,'Hệ số'!$B$10,'Hệ số'!$B$11))) -> 1.15 | G8: =ROUND(E8*F8,0) -> 7 | H8: 1144 | I8: 1144 | J8: =IF(OR(E8=0,G8=E8),I8,ROUND(I8*(G8/E8)^'Hệ số'!$B$4,-1)) -> 1370 | L8: =IF(K8="",J8,K8) -> 1370 | M8: =IF(E8=0,1,G8/E8) -> 1.1666667 | N8: =IF(E8=0,0,MIN('Hệ số'!$B$6,MAX(0,'Hệ số'!$B$5*(G8-'Hệ số'!$B$7)))) -> 0 | O8: =ROUND(IF(D8=1,M8,M8*(1+N8)),4) -> 1.1667 | P8: =ROUND(M8*(1+N8),4) -> 1.1667 | Q8: =IF(E8=0,"",IF(G8<='Hệ số'!$B$12,2.5,IF(G8>='Hệ số'!$B$13,5,3.5))) -> 3.5
A9: auto_loader_howitzer | B9: Lựu pháo nạp tự động | C9: Xe nhẹ | D9: 1 | E9: 8 | F9: =IF(E9<=4,'Hệ số'!$B$8,IF(E9<=8,'Hệ số'!$B$9,IF(E9<=13,'Hệ số'!$B$10,'Hệ số'!$B$11))) -> 1.15 | G9: =ROUND(E9*F9,0) -> 9 | H9: 1599 | I9: 1599 | J9: =IF(OR(E9=0,G9=E9),I9,ROUND(I9*(G9/E9)^'Hệ số'!$B$4,-1)) -> 1830 | L9: =IF(K9="",J9,K9) -> 1830 | M9: =IF(E9=0,1,G9/E9) -> 1.125 | N9: =IF(E9=0,0,MIN('Hệ số'!$B$6,MAX(0,'Hệ số'!$B$5*(G9-'Hệ số'!$B$7)))) -> 0.0125 | O9: =ROUND(IF(D9=1,M9,M9*(1+N9)),4) -> 1.125 | P9: =ROUND(M9*(1+N9),4) -> 1.1391 | Q9: =IF(E9=0,"",IF(G9<='Hệ số'!$B$12,2.5,IF(G9>='Hệ số'!$B$13,5,3.5))) -> 3.5
A10: river_gunboat | B10: Pháo hạm sông | C10: Xe nhẹ | D10: 0 | E10: 9 | F10: =IF(E10<=4,'Hệ số'!$B$8,IF(E10<=8,'Hệ số'!$B$9,IF(E10<=13,'Hệ số'!$B$10,'Hệ số'!$B$11))) -> 1.25 | G10: =ROUND(E10*F10,0) -> 11 | H10: 2499 | I10: 2499 | J10: =IF(OR(E10=0,G10=E10),I10,ROUND(I10*(G10/E10)^'Hệ số'!$B$4,-1)) -> 3150 | L10: =IF(K10="",J10,K10) -> 3150 | M10: =IF(E10=0,1,G10/E10) -> 1.2222222 | N10: =IF(E10=0,0,MIN('Hệ số'!$B$6,MAX(0,'Hệ số'!$B$5*(G10-'Hệ số'!$B$7)))) -> 0.0375 | O10: =ROUND(IF(D10=1,M10,M10*(1+N10)),4) -> 1.2681 | P10: =ROUND(M10*(1+N10),4) -> 1.2681 | Q10: =IF(E10=0,"",IF(G10<='Hệ số'!$B$12,2.5,IF(G10>='Hệ số'!$B$13,5,3.5))) -> 3.5
A11: coastal_ashm_vehicle | B11: Xe tên lửa chống hạm bờ biển | C11: Xe nhẹ | D11: 1 | E11: 10 | F11: =IF(E11<=4,'Hệ số'!$B$8,IF(E11<=8,'Hệ số'!$B$9,IF(E11<=13,'Hệ số'!$B$10,'Hệ số'!$B$11))) -> 1.25 | G11: =ROUND(E11*F11,0) -> 13 | H11: 900 | I11: 900 | J11: =IF(OR(E11=0,G11=E11),I11,ROUND(I11*(G11/E11)^'Hệ số'!$B$4,-1)) -> 1220 | L11: =IF(K11="",J11,K11) -> 1220 | M11: =IF(E11=0,1,G11/E11) -> 1.3 | N11: =IF(E11=0,0,MIN('Hệ số'!$B$6,MAX(0,'Hệ số'!$B$5*(G11-'Hệ số'!$B$7)))) -> 0.0625 | O11: =ROUND(IF(D11=1,M11,M11*(1+N11)),4) -> 1.3 | P11: =ROUND(M11*(1+N11),4) -> 1.3813 | Q11: =IF(E11=0,"",IF(G11<='Hệ số'!$B$12,2.5,IF(G11>='Hệ số'!$B$13,5,3.5))) -> 3.5
A12: ground_cruise_missile_vehicle | B12: Xe phóng tên lửa hành trình | C12: Xe nhẹ | D12: 1 | E12: 12 | F12: =IF(E12<=4,'Hệ số'!$B$8,IF(E12<=8,'Hệ số'!$B$9,IF(E12<=13,'Hệ số'!$B$10,'Hệ số'!$B$11))) -> 1.25 | G12: =ROUND(E12*F12,0) -> 15 | H12: 1001 | I12: 1001 | J12: =IF(OR(E12=0,G12=E12),I12,ROUND(I12*(G12/E12)^'Hệ số'!$B$4,-1)) -> 1290 | L12: =IF(K12="",J12,K12) -> 1290 | M12: =IF(E12=0,1,G12/E12) -> 1.25 | N12: =IF(E12=0,0,MIN('Hệ số'!$B$6,MAX(0,'Hệ số'!$B$5*(G12-'Hệ số'!$B$7)))) -> 0.0875 | O12: =ROUND(IF(D12=1,M12,M12*(1+N12)),4) -> 1.25 | P12: =ROUND(M12*(1+N12),4) -> 1.3594 | Q12: =IF(E12=0,"",IF(G12<='Hệ số'!$B$12,2.5,IF(G12>='Hệ số'!$B$13,5,3.5))) -> 5
A13: supply_truck | B13: Xe tải tiếp tế | C13: Hỗ trợ | D13: 0 | E13: 0 | F13: =IF(E13<=4,'Hệ số'!$B$8,IF(E13<=8,'Hệ số'!$B$9,IF(E13<=13,'Hệ số'!$B$10,'Hệ số'!$B$11))) -> 1 | G13: =ROUND(E13*F13,0) -> 0 | H13: 1540 | I13: 1540 | J13: =IF(OR(E13=0,G13=E13),I13,ROUND(I13*(G13/E13)^'Hệ số'!$B$4,-1)) -> 1540 | L13: =IF(K13="",J13,K13) -> 1540 | M13: =IF(E13=0,1,G13/E13) -> 1 | N13: =IF(E13=0,0,MIN('Hệ số'!$B$6,MAX(0,'Hệ số'!$B$5*(G13-'Hệ số'!$B$7)))) -> 0 | O13: =ROUND(IF(D13=1,M13,M13*(1+N13)),4) -> 1 | P13: =ROUND(M13*(1+N13),4) -> 1 | Q13: =IF(E13=0,"",IF(G13<='Hệ số'!$B$12,2.5,IF(G13>='Hệ số'!$B$13,5,3.5)))
... A42: stealth_fighter | B42: Tiêm kích tàng hình | C42: Máy bay | D42: 0 | E42: 13 | F42: =IF(E42<=4,'Hệ số'!$B$8,IF(E42<=8,'Hệ số'!$B$9,IF(E42<=13,'Hệ số'!$B$10,'Hệ số'!$B$11))) -> 1.25 | G42: =ROUND(E42*F42,0) -> 16 | H42: 1056 | I42: 1056 | J42: =IF(OR(E42=0,G42=E42),I42,ROUND(I42*(G42/E42)^'Hệ số'!$B$4,-1)) -> 1340 | L42: =IF(K42="",J42,K42) -> 1340 | M42: =IF(E42=0,1,G42/E42) -> 1.2307692 | N42: =IF(E42=0,0,MIN('Hệ số'!$B$6,MAX(0,'Hệ số'!$B$5*(G42-'Hệ số'!$B$7)))) -> 0.1 | O42: =ROUND(IF(D42=1,M42,M42*(1+N42)),4) -> 1.3538 | P42: =ROUND(M42*(1+N42),4) -> 1.3538 | Q42: =IF(E42=0,"",IF(G42<='Hệ số'!$B$12,2.5,IF(G42>='Hệ số'!$B$13,5,3.5))) -> 5
A43: swarm_carrier | B43: Máy bay mẹ thả drone | C43: Máy bay | D43: 1 | E43: 13 | F43: =IF(E43<=4,'Hệ số'!$B$8,IF(E43<=8,'Hệ số'!$B$9,IF(E43<=13,'Hệ số'!$B$10,'Hệ số'!$B$11))) -> 1.25 | G43: =ROUND(E43*F43,0) -> 16 | H43: 1390 | I43: 1390 | J43: =IF(OR(E43=0,G43=E43),I43,ROUND(I43*(G43/E43)^'Hệ số'!$B$4,-1)) -> 1760 | K43: 2400 | L43: =IF(K43="",J43,K43) -> 2400 | M43: =IF(E43=0,1,G43/E43) -> 1.2307692 | N43: =IF(E43=0,0,MIN('Hệ số'!$B$6,MAX(0,'Hệ số'!$B$5*(G43-'Hệ số'!$B$7)))) -> 0.1 | O43: =ROUND(IF(D43=1,M43,M43*(1+N43)),4) -> 1.2308 | P43: =ROUND(M43*(1+N43),4) -> 1.3538 | Q43: =IF(E43=0,"",IF(G43<='Hệ số'!$B$12,2.5,IF(G43>='Hệ số'!$B$13,5,3.5))) -> 5
A44: twin_rotor_gunship | B44: Pháo hạm trực thăng hai rô-to | C44: Trực thăng | D44: 0 | E44: 14 | F44: =IF(E44<=4,'Hệ số'!$B$8,IF(E44<=8,'Hệ số'!$B$9,IF(E44<=13,'Hệ số'!$B$10,'Hệ số'!$B$11))) -> 1.3 | G44: =ROUND(E44*F44,0) -> 18 | H44: 3500 | I44: 3500 | J44: =IF(OR(E44=0,G44=E44),I44,ROUND(I44*(G44/E44)^'Hệ số'!$B$4,-1)) -> 4670 | L44: =IF(K44="",J44,K44) -> 4670 | M44: =IF(E44=0,1,G44/E44) -> 1.2857143 | N44: =IF(E44=0,0,MIN('Hệ số'!$B$6,MAX(0,'Hệ số'!$B$5*(G44-'Hệ số'!$B$7)))) -> 0.125 | O44: =ROUND(IF(D44=1,M44,M44*(1+N44)),4) -> 1.4464 | P44: =ROUND(M44*(1+N44),4) -> 1.4464 | Q44: =IF(E44=0,"",IF(G44<='Hệ số'!$B$12,2.5,IF(G44>='Hệ số'!$B$13,5,3.5))) -> 5
A45: gunship_heli | B45: Trực thăng vũ trang bọc giáp | C45: Trực thăng | D45: 0 | E45: 15 | F45: =IF(E45<=4,'Hệ số'!$B$8,IF(E45<=8,'Hệ số'!$B$9,IF(E45<=13,'Hệ số'!$B$10,'Hệ số'!$B$11))) -> 1.3 | G45: =ROUND(E45*F45,0) -> 20 | H45: 2600 | I45: 2600 | J45: =IF(OR(E45=0,G45=E45),I45,ROUND(I45*(G45/E45)^'Hệ số'!$B$4,-1)) -> 3620 | L45: =IF(K45="",J45,K45) -> 3620 | M45: =IF(E45=0,1,G45/E45) -> 1.3333333 | N45: =IF(E45=0,0,MIN('Hệ số'!$B$6,MAX(0,'Hệ số'!$B$5*(G45-'Hệ số'!$B$7)))) -> 0.15 | O45: =ROUND(IF(D45=1,M45,M45*(1+N45)),4) -> 1.5333 | P45: =ROUND(M45*(1+N45),4) -> 1.5333 | Q45: =IF(E45=0,"",IF(G45<='Hệ số'!$B$12,2.5,IF(G45>='Hệ số'!$B$13,5,3.5))) -> 5
A46: glide_bomber | B46: Máy bay ném bom lượn tầm xa | C46: Máy bay | D46: 1 | E46: 16 | F46: =IF(E46<=4,'Hệ số'!$B$8,IF(E46<=8,'Hệ số'!$B$9,IF(E46<=13,'Hệ số'!$B$10,'Hệ số'!$B$11))) -> 1.3 | G46: =ROUND(E46*F46,0) -> 21 | H46: 2200 | I46: 2200 | J46: =IF(OR(E46=0,G46=E46),I46,ROUND(I46*(G46/E46)^'Hệ số'!$B$4,-1)) -> 3010 | L46: =IF(K46="",J46,K46) -> 3010 | M46: =IF(E46=0,1,G46/E46) -> 1.3125 | N46: =IF(E46=0,0,MIN('Hệ số'!$B$6,MAX(0,'Hệ số'!$B$5*(G46-'Hệ số'!$B$7)))) -> 0.15 | O46: =ROUND(IF(D46=1,M46,M46*(1+N46)),4) -> 1.3125 | P46: =ROUND(M46*(1+N46),4) -> 1.5094 | Q46: =IF(E46=0,"",IF(G46<='Hệ số'!$B$12,2.5,IF(G46>='Hệ số'!$B$13,5,3.5))) -> 5
A47: stealth_naval_strike | B47: Cường kích tàng hình trên hạm | C47: Máy bay | D47: 0 | E47: 17 | F47: =IF(E47<=4,'Hệ số'!$B$8,IF(E47<=8,'Hệ số'!$B$9,IF(E47<=13,'Hệ số'!$B$10,'Hệ số'!$B$11))) -> 1.3 | G47: =ROUND(E47*F47,0) -> 22 | H47: 1500 | I47: 1500 | J47: =IF(OR(E47=0,G47=E47),I47,ROUND(I47*(G47/E47)^'Hệ số'!$B$4,-1)) -> 2020 | L47: =IF(K47="",J47,K47) -> 2020 | M47: =IF(E47=0,1,G47/E47) -> 1.2941176 | N47: =IF(E47=0,0,MIN('Hệ số'!$B$6,MAX(0,'Hệ số'!$B$5*(G47-'Hệ số'!$B$7)))) -> 0.15 | O47: =ROUND(IF(D47=1,M47,M47*(1+N47)),4) -> 1.4882 | P47: =ROUND(M47*(1+N47),4) -> 1.4882 | Q47: =IF(E47=0,"",IF(G47<='Hệ số'!$B$12,2.5,IF(G47>='Hệ số'!$B$13,5,3.5))) -> 5
A48: attack_jet | B48: Máy bay cường kích | C48: Máy bay | D48: 0 | E48: 18 | F48: =IF(E48<=4,'Hệ số'!$B$8,IF(E48<=8,'Hệ số'!$B$9,IF(E48<=13,'Hệ số'!$B$10,'Hệ số'!$B$11))) -> 1.3 | G48: =ROUND(E48*F48,0) -> 23 | H48: 1870 | I48: 1870 | J48: =IF(OR(E48=0,G48=E48),I48,ROUND(I48*(G48/E48)^'Hệ số'!$B$4,-1)) -> 2480 | L48: =IF(K48="",J48,K48) -> 2480 | M48: =IF(E48=0,1,G48/E48) -> 1.2777778 | N48: =IF(E48=0,0,MIN('Hệ số'!$B$6,MAX(0,'Hệ số'!$B$5*(G48-'Hệ số'!$B$7)))) -> 0.15 | O48: =ROUND(IF(D48=1,M48,M48*(1+N48)),4) -> 1.4694 | P48: =ROUND(M48*(1+N48),4) -> 1.4694 | Q48: =IF(E48=0,"",IF(G48<='Hệ số'!$B$12,2.5,IF(G48>='Hệ số'!$B$13,5,3.5))) -> 5
A49: stealth_bomber | B49: Oanh tạc cơ tàng hình | C49: Máy bay | D49: 1 | E49: 21 | F49: =IF(E49<=4,'Hệ số'!$B$8,IF(E49<=8,'Hệ số'!$B$9,IF(E49<=13,'Hệ số'!$B$10,'Hệ số'!$B$11))) -> 1.3 | G49: =ROUND(E49*F49,0) -> 27 | H49: 1980 | I49: 1980 | J49: =IF(OR(E49=0,G49=E49),I49,ROUND(I49*(G49/E49)^'Hệ số'!$B$4,-1)) -> 2640 | L49: =IF(K49="",J49,K49) -> 2640 | M49: =IF(E49=0,1,G49/E49) -> 1.2857143 | N49: =IF(E49=0,0,MIN('Hệ số'!$B$6,MAX(0,'Hệ số'!$B$5*(G49-'Hệ số'!$B$7)))) -> 0.15 | O49: =ROUND(IF(D49=1,M49,M49*(1+N49)),4) -> 1.2857 | P49: =ROUND(M49*(1+N49),4) -> 1.4786 | Q49: =IF(E49=0,"",IF(G49<='Hệ số'!$B$12,2.5,IF(G49>='Hệ số'!$B$13,5,3.5))) -> 5
A50: heavy_bomber | B50: Oanh tạc cơ chiến lược | C50: Máy bay | D50: 1 | E50: 22 | F50: =IF(E50<=4,'Hệ số'!$B$8,IF(E50<=8,'Hệ số'!$B$9,IF(E50<=13,'Hệ số'!$B$10,'Hệ số'!$B$11))) -> 1.3 | G50: =ROUND(E50*F50,0) -> 29 | H50: 3300 | I50: 3300 | J50: =IF(OR(E50=0,G50=E50),I50,ROUND(I50*(G50/E50)^'Hệ số'!$B$4,-1)) -> 4530 | L50: =IF(K50="",J50,K50) -> 4530 | M50: =IF(E50=0,1,G50/E50) -> 1.3181818 | N50: =IF(E50=0,0,MIN('Hệ số'!$B$6,MAX(0,'Hệ số'!$B$5*(G50-'Hệ số'!$B$7)))) -> 0.15 | O50: =ROUND(IF(D50=1,M50,M50*(1+N50)),4) -> 1.3182 | P50: =ROUND(M50*(1+N50),4) -> 1.5159 | Q50: =IF(E50=0,"",IF(G50<='Hệ số'!$B$12,2.5,IF(G50>='Hệ số'!$B$13,5,3.5))) -> 5
A51: sky_gunship | B51: Pháo hạm bay | C51: Máy bay | D51: 0 | E51: 22 | F51: =IF(E51<=4,'Hệ số'!$B$8,IF(E51<=8,'Hệ số'!$B$9,IF(E51<=13,'Hệ số'!$B$10,'Hệ số'!$B$11))) -> 1.3 | G51: =ROUND(E51*F51,0) -> 29 | H51: 2352 | I51: 4400 | J51: =IF(OR(E51=0,G51=E51),I51,ROUND(I51*(G51/E51)^'Hệ số'!$B$4,-1)) -> 6050 | K51: 4900 | L51: =IF(K51="",J51,K51) -> 4900 | M51: =IF(E51=0,1,G51/E51) -> 1.3181818 | N51: =IF(E51=0,0,MIN('Hệ số'!$B$6,MAX(0,'Hệ số'!$B$5*(G51-'Hệ số'!$B$7)))) -> 0.15 | O51: =ROUND(IF(D51=1,M51,M51*(1+N51)),4) -> 1.5159 | P51: =ROUND(M51*(1+N51),4) -> 1.5159 | Q51: =IF(E51=0,"",IF(G51<='Hệ số'!$B$12,2.5,IF(G51>='Hệ số'!$B$13,5,3.5))) -> 5
A52: scout_jeep | B52: Xe trinh sát hạng nhẹ | C52: Trinh sát | D52: 0 | E52: 2 | F52: =IF(E52<=4,'Hệ số'!$B$8,IF(E52<=8,'Hệ số'!$B$9,IF(E52<=13,'Hệ số'!$B$10,'Hệ số'!$B$11))) -> 1 | G52: =ROUND(E52*F52,0) -> 2 | H52: 264 | I52: 264 | J52: =IF(OR(E52=0,G52=E52),I52,ROUND(I52*(G52/E52)^'Hệ số'!$B$4,-1)) -> 264 | L52: =IF(K52="",J52,K52) -> 264 | M52: =IF(E52=0,1,G52/E52) -> 1 | N52: =IF(E52=0,0,MIN('Hệ số'!$B$6,MAX(0,'Hệ số'!$B$5*(G52-'Hệ số'!$B$7)))) -> 0 | O52: =ROUND(IF(D52=1,M52,M52*(1+N52)),4) -> 1 | P52: =ROUND(M52*(1+N52),4) -> 1 | Q52: =IF(E52=0,"",IF(G52<='Hệ số'!$B$12,2.5,IF(G52>='Hệ số'!$B$13,5,3.5))) -> 2.5
A53: vbied | B53: Xe bom bọc thép | C53: Trinh sát | D53: 0 | E53: 3 | F53: =IF(E53<=4,'Hệ số'!$B$8,IF(E53<=8,'Hệ số'!$B$9,IF(E53<=13,'Hệ số'!$B$10,'Hệ số'!$B$11))) -> 1 | G53: =ROUND(E53*F53,0) -> 3 | H53: 801 | I53: 801 | J53: =IF(OR(E53=0,G53=E53),I53,ROUND(I53*(G53/E53)^'Hệ số'!$B$4,-1)) -> 801 | L53: =IF(K53="",J53,K53) -> 801 | M53: =IF(E53=0,1,G53/E53) -> 1 | N53: =IF(E53=0,0,MIN('Hệ số'!$B$6,MAX(0,'Hệ số'!$B$5*(G53-'Hệ số'!$B$7)))) -> 0 | O53: =ROUND(IF(D53=1,M53,M53*(1+N53)),4) -> 1 | P53: =ROUND(M53*(1+N53),4) -> 1 | Q53: =IF(E53=0,"",IF(G53<='Hệ số'!$B$12,2.5,IF(G53>='Hệ số'!$B$13,5,3.5))) -> 2.5
A54: radar_scout | B54: Xe trinh sát bọc thép radar mặt đất | C54: Trinh sát | D54: 0 | E54: 4 | F54: =IF(E54<=4,'Hệ số'!$B$8,IF(E54<=8,'Hệ số'!$B$9,IF(E54<=13,'Hệ số'!$B$10,'Hệ số'!$B$11))) -> 1 | G54: =ROUND(E54*F54,0) -> 4 | H54: 700 | I54: 700 | J54: =IF(OR(E54=0,G54=E54),I54,ROUND(I54*(G54/E54)^'Hệ số'!$B$4,-1)) -> 700 | L54: =IF(K54="",J54,K54) -> 700 | M54: =IF(E54=0,1,G54/E54) -> 1 | N54: =IF(E54=0,0,MIN('Hệ số'!$B$6,MAX(0,'Hệ số'!$B$5*(G54-'Hệ số'!$B$7)))) -> 0 | O54: =ROUND(IF(D54=1,M54,M54*(1+N54)),4) -> 1 | P54: =ROUND(M54*(1+N54),4) -> 1 | Q54: =IF(E54=0,"",IF(G54<='Hệ số'!$B$12,2.5,IF(G54>='Hệ số'!$B$13,5,3.5))) -> 2.5
A55: radar_support_vehicle | B55: Xe radar phòng không di động | C55: Trinh sát | D55: 0 | E55: 5 | F55: =IF(E55<=4,'Hệ số'!$B$8,IF(E55<=8,'Hệ số'!$B$9,IF(E55<=13,'Hệ số'!$B$10,'Hệ số'!$B$11))) -> 1.15 | G55: =ROUND(E55*F55,0) -> 6 | H55: 900 | I55: 900 | J55: =IF(OR(E55=0,G55=E55),I55,ROUND(I55*(G55/E55)^'Hệ số'!$B$4,-1)) -> 1110 | L55: =IF(K55="",J55,K55) -> 1110 | M55: =IF(E55=0,1,G55/E55) -> 1.2 | N55: =IF(E55=0,0,MIN('Hệ số'!$B$6,MAX(0,'Hệ số'!$B$5*(G55-'Hệ số'!$B$7)))) -> 0 | O55: =ROUND(IF(D55=1,M55,M55*(1+N55)),4) -> 1.2 | P55: =ROUND(M55*(1+N55),4) -> 1.2 | Q55: =IF(E55=0,"",IF(G55<='Hệ số'!$B$12,2.5,IF(G55>='Hệ số'!$B$13,5,3.5))) -> 3.5
A56: light_tank | B56: Tăng nhẹ lội nước | C56: Xe tăng | D56: 0 | E56: 3 | F56: =IF(E56<=4,'Hệ số'!$B$8,IF(E56<=8,'Hệ số'!$B$9,IF(E56<=13,'Hệ số'!$B$10,'Hệ số'!$B$11))) -> 1 | G56: =ROUND(E56*F56,0) -> 3 | H56: 1012 | I56: 1012 | J56: =IF(OR(E56=0,G56=E56),I56,ROUND(I56*(G56/E56)^'Hệ số'!$B$4,-1)) -> 1012 | L56: =IF(K56="",J56,K56) -> 1012 | M56: =IF(E56=0,1,G56/E56) -> 1 | N56: =IF(E56=0,0,MIN('Hệ số'!$B$6,MAX(0,'Hệ số'!$B$5*(G56-'Hệ số'!$B$7)))) -> 0 | O56: =ROUND(IF(D56=1,M56,M56*(1+N56)),4) -> 1 | P56: =ROUND(M56*(1+N56),4) -> 1 | Q56: =IF(E56=0,"",IF(G56<='Hệ số'!$B$12,2.5,IF(G56>='Hệ số'!$B$13,5,3.5))) -> 2.5
A57: airborne_light_tank | B57: Tăng nhẹ thả dù | C57: Xe tăng | D57: 0 | E57: 5 | F57: =IF(E57<=4,'Hệ số'!$B$8,IF(E57<=8,'Hệ số'!$B$9,IF(E57<=13,'Hệ số'!$B$10,'Hệ số'!$B$11))) -> 1.15 | G57: =ROUND(E57*F57,0) -> 6 | H57: 1300 | I57: 1300 | J57: =IF(OR(E57=0,G57=E57),I57,ROUND(I57*(G57/E57)^'Hệ số'!$B$4,-1)) -> 1600 | L57: =IF(K57="",J57,K57) -> 1600 | M57: =IF(E57=0,1,G57/E57) -> 1.2 | N57: =IF(E57=0,0,MIN('Hệ số'!$B$6,MAX(0,'Hệ số'!$B$5*(G57-'Hệ số'!$B$7)))) -> 0 | O57: =ROUND(IF(D57=1,M57,M57*(1+N57)),4) -> 1.2 | P57: =ROUND(M57*(1+N57),4) -> 1.2 | Q57: =IF(E57=0,"",IF(G57<='Hệ số'!$B$12,2.5,IF(G57>='Hệ số'!$B$13,5,3.5))) -> 3.5
A58: flame_tank | B58: Tăng phun lửa | C58: Xe tăng | D58: 0 | E58: 5 | F58: =IF(E58<=4,'Hệ số'!$B$8,IF(E58<=8,'Hệ số'!$B$9,IF(E58<=13,'Hệ số'!$B$10,'Hệ số'!$B$11))) -> 1.15 | G58: =ROUND(E58*F58,0) -> 6 | H58: 1320 | I58: 1320 | J58: =IF(OR(E58=0,G58=E58),I58,ROUND(I58*(G58/E58)^'Hệ số'!$B$4,-1)) -> 1630 | L58: =IF(K58="",J58,K58) -> 1630 | M58: =IF(E58=0,1,G58/E58) -> 1.2 | N58: =IF(E58=0,0,MIN('Hệ số'!$B$6,MAX(0,'Hệ số'!$B$5*(G58-'Hệ số'!$B$7)))) -> 0 | O58: =ROUND(IF(D58=1,M58,M58*(1+N58)),4) -> 1.2 | P58: =ROUND(M58*(1+N58),4) -> 1.2 | Q58: =IF(E58=0,"",IF(G58<='Hệ số'!$B$12,2.5,IF(G58>='Hệ số'!$B$13,5,3.5))) -> 3.5
A59: turtle_tank | B59: Tăng mái che | C59: Xe tăng | D59: 0 | E59: 7 | F59: =IF(E59<=4,'Hệ số'!$B$8,IF(E59<=8,'Hệ số'!$B$9,IF(E59<=13,'Hệ số'!$B$10,'Hệ số'!$B$11))) -> 1.15 | G59: =ROUND(E59*F59,0) -> 8 | H59: 2860 | I59: 2860 | J59: =IF(OR(E59=0,G59=E59),I59,ROUND(I59*(G59/E59)^'Hệ số'!$B$4,-1)) -> 3330 | L59: =IF(K59="",J59,K59) -> 3330 | M59: =IF(E59=0,1,G59/E59) -> 1.1428571 | N59: =IF(E59=0,0,MIN('Hệ số'!$B$6,MAX(0,'Hệ số'!$B$5*(G59-'Hệ số'!$B$7)))) -> 0 | O59: =ROUND(IF(D59=1,M59,M59*(1+N59)),4) -> 1.1429 | P59: =ROUND(M59*(1+N59),4) -> 1.1429 | Q59: =IF(E59=0,"",IF(G59<='Hệ số'!$B$12,2.5,IF(G59>='Hệ số'!$B$13,5,3.5))) -> 3.5
A60: bmpt | B60: Xe hỗ trợ tăng | C60: Xe tăng | D60: 0 | E60: 9 | F60: =IF(E60<=4,'Hệ số'!$B$8,IF(E60<=8,'Hệ số'!$B$9,IF(E60<=13,'Hệ số'!$B$10,'Hệ số'!$B$11))) -> 1.25 | G60: =ROUND(E60*F60,0) -> 11 | H60: 2530 | I60: 2530 | J60: =IF(OR(E60=0,G60=E60),I60,ROUND(I60*(G60/E60)^'Hệ số'!$B$4,-1)) -> 3190 | L60: =IF(K60="",J60,K60) -> 3190 | M60: =IF(E60=0,1,G60/E60) -> 1.2222222 | N60: =IF(E60=0,0,MIN('Hệ số'!$B$6,MAX(0,'Hệ số'!$B$5*(G60-'Hệ số'!$B$7)))) -> 0.0375 | O60: =ROUND(IF(D60=1,M60,M60*(1+N60)),4) -> 1.2681 | P60: =ROUND(M60*(1+N60),4) -> 1.2681 | Q60: =IF(E60=0,"",IF(G60<='Hệ số'!$B$12,2.5,IF(G60>='Hệ số'!$B$13,5,3.5))) -> 3.5
A61: recoilless_jeep | B61: Xe jeep súng không giật | C61: Diệt tăng | D61: 0 | E61: 3 | F61: =IF(E61<=4,'Hệ số'!$B$8,IF(E61<=8,'Hệ số'!$B$9,IF(E61<=13,'Hệ số'!$B$10,'Hệ số'!$B$11))) -> 1 | G61: =ROUND(E61*F61,0) -> 3 | H61: 350 | I61: 350 | J61: =IF(OR(E61=0,G61=E61),I61,ROUND(I61*(G61/E61)^'Hệ số'!$B$4,-1)) -> 350 | L61: =IF(K61="",J61,K61) -> 350 | M61: =IF(E61=0,1,G61/E61) -> 1 | N61: =IF(E61=0,0,MIN('Hệ số'!$B$6,MAX(0,'Hệ số'!$B$5*(G61-'Hệ số'!$B$7)))) -> 0 | O61: =ROUND(IF(D61=1,M61,M61*(1+N61)),4) -> 1 | P61: =ROUND(M61*(1+N61),4) -> 1 | Q61: =IF(E61=0,"",IF(G61<='Hệ số'!$B$12,2.5,IF(G61>='Hệ số'!$B$13,5,3.5))) -> 2.5
A62: towed_at_gun | B62: Pháo chống tăng kéo cỡ lớn | C62: Diệt tăng | D62: 0 | E62: 4 | F62: =IF(E62<=4,'Hệ số'!$B$8,IF(E62<=8,'Hệ số'!$B$9,IF(E62<=13,'Hệ số'!$B$10,'Hệ số'!$B$11))) -> 1 | G62: =ROUND(E62*F62,0) -> 4 | H62: 801 | I62: 801 | J62: =IF(OR(E62=0,G62=E62),I62,ROUND(I62*(G62/E62)^'Hệ số'!$B$4,-1)) -> 801 | L62: =IF(K62="",J62,K62) -> 801 | M62: =IF(E62=0,1,G62/E62) -> 1 | N62: =IF(E62=0,0,MIN('Hệ số'!$B$6,MAX(0,'Hệ số'!$B$5*(G62-'Hệ số'!$B$7)))) -> 0 | O62: =ROUND(IF(D62=1,M62,M62*(1+N62)),4) -> 1 | P62: =ROUND(M62*(1+N62),4) -> 1 | Q62: =IF(E62=0,"",IF(G62<='Hệ số'!$B$12,2.5,IF(G62>='Hệ số'!$B$13,5,3.5))) -> 2.5
A63: fpv_carrier | B63: Xe phóng drone FPV | C63: Diệt tăng | D63: 0 | E63: 6 | F63: =IF(E63<=4,'Hệ số'!$B$8,IF(E63<=8,'Hệ số'!$B$9,IF(E63<=13,'Hệ số'!$B$10,'Hệ số'!$B$11))) -> 1.15 | G63: =ROUND(E63*F63,0) -> 7 | H63: 924 | I63: 924 | J63: =IF(OR(E63=0,G63=E63),I63,ROUND(I63*(G63/E63)^'Hệ số'!$B$4,-1)) -> 1100 | L63: =IF(K63="",J63,K63) -> 1100 | M63: =IF(E63=0,1,G63/E63) -> 1.1666667 | N63: =IF(E63=0,0,MIN('Hệ số'!$B$6,MAX(0,'Hệ số'!$B$5*(G63-'Hệ số'!$B$7)))) -> 0 | O63: =ROUND(IF(D63=1,M63,M63*(1+N63)),4) -> 1.1667 | P63: =ROUND(M63*(1+N63),4) -> 1.1667 | Q63: =IF(E63=0,"",IF(G63<='Hệ số'!$B$12,2.5,IF(G63>='Hệ số'!$B$13,5,3.5))) -> 3.5
... A101: titan_tank | B101: Siêu tăng | C101: Hạng nặng | D101: 0 | E101: 18 | F101: =IF(E101<=4,'Hệ số'!$B$8,IF(E101<=8,'Hệ số'!$B$9,IF(E101<=13,'Hệ số'!$B$10,'Hệ số'!$B$11))) -> 1.3 | G101: =ROUND(E101*F101,0) -> 23 | H101: 5720 | I101: 5720 | J101: =IF(OR(E101=0,G101=E101),I101,ROUND(I101*(G101/E101)^'Hệ số'!$B$4,-1)) -> 7580 | L101: =IF(K101="",J101,K101) -> 7580 | M101: =IF(E101=0,1,G101/E101) -> 1.2777778 | N101: =IF(E101=0,0,MIN('Hệ số'!$B$6,MAX(0,'Hệ số'!$B$5*(G101-'Hệ số'!$B$7)))) -> 0.15 | O101: =ROUND(IF(D101=1,M101,M101*(1+N101)),4) -> 1.4694 | P101: =ROUND(M101*(1+N101),4) -> 1.4694 | Q101: =IF(E101=0,"",IF(G101<='Hệ số'!$B$12,2.5,IF(G101>='Hệ số'!$B$13,5,3.5))) -> 5

Sheet Máy bay – số phát
A1: Số phát để hạ (làm tròn lên) với máu chốt ở sheet Tính toán. Thước đo chính: Buk hiệu dụng = sát thương × hệ số với máy bay (Hệ số). PK nhẹ và tên lửa tiêm kích chưa tính hệ số loại sát thương, chỉ để tham khảo. Đây là số "đòn sạch": chưa tính pháo sáng.
A3: id | B3: Tên | C3: Nhóm (D8) | D3: CP mới | E3: Máu chốt | F3: Buk hiệu dụng (phát) | G3: PK nhẹ (phát, thô) | H3: Tên lửa tiêm kích (phát, thô) | I3: Dải thấp | J3: Dải cao | K3: Trong dải?
A4: fighter_jet | B4: Tiêm kích | C4: Tiêm kích | D4: ='Tính toán'!G40 -> 15 | E4: ='Tính toán'!L40 -> 1480 | F4: =ROUNDUP(E4/('Hệ số'!$B$14*'Hệ số'!$B$15),0) -> 4 | G4: =ROUNDUP(E4/'Hệ số'!$B$16,0) -> 9 | H4: =ROUNDUP(E4/'Hệ số'!$B$17,0) -> 6 | I4: 3 | J4: 5 | K4: =IF(AND(F4>=I4,F4<=J4),"Có",IF(D4<=8,"Ngoài dải (thẻ rẻ, chấp nhận)","Ngoài dải — báo cáo")) -> Có
A5: interceptor_jet | B5: Tiêm kích đánh chặn | C5: Tiêm kích | D5: ='Tính toán'!G41 -> 16 | E5: ='Tính toán'!L41 -> 1650 | F5: =ROUNDUP(E5/('Hệ số'!$B$14*'Hệ số'!$B$15),0) -> 4 | G5: =ROUNDUP(E5/'Hệ số'!$B$16,0) -> 10 | H5: =ROUNDUP(E5/'Hệ số'!$B$17,0) -> 6 | I5: 3 | J5: 5 | K5: =IF(AND(F5>=I5,F5<=J5),"Có",IF(D5<=8,"Ngoài dải (thẻ rẻ, chấp nhận)","Ngoài dải — báo cáo")) -> Có
A6: stealth_fighter | B6: Tiêm kích tàng hình | C6: Tiêm kích | D6: ='Tính toán'!G42 -> 16 | E6: ='Tính toán'!L42 -> 1340 | F6: =ROUNDUP(E6/('Hệ số'!$B$14*'Hệ số'!$B$15),0) -> 4 | G6: =ROUNDUP(E6/'Hệ số'!$B$16,0) -> 8 | H6: =ROUNDUP(E6/'Hệ số'!$B$17,0) -> 5 | I6: 3 | J6: 5 | K6: =IF(AND(F6>=I6,F6<=J6),"Có",IF(D6<=8,"Ngoài dải (thẻ rẻ, chấp nhận)","Ngoài dải — báo cáo")) -> Có
A7: heavy_lift_helicopter | B7: Trực thăng cẩu tháp | C7: Ở lại lâu | D7: ='Tính toán'!G33 -> 8 | E7: ='Tính toán'!L33 -> 2100 | F7: =ROUNDUP(E7/('Hệ số'!$B$14*'Hệ số'!$B$15),0) -> 6 | G7: =ROUNDUP(E7/'Hệ số'!$B$16,0) -> 12 | H7: =ROUNDUP(E7/'Hệ số'!$B$17,0) -> 8 | I7: 8 | J7: 12 | K7: =IF(AND(F7>=I7,F7<=J7),"Có",IF(D7<=8,"Ngoài dải (thẻ rẻ, chấp nhận)","Ngoài dải — báo cáo")) -> Ngoài dải (thẻ rẻ, chấp nhận)
A8: aerial_tanker | B8: Máy bay tiếp dầu | C8: Ở lại lâu | D8: ='Tính toán'!G36 -> 9 | E8: ='Tính toán'!L36 -> 2860 | F8: =ROUNDUP(E8/('Hệ số'!$B$14*'Hệ số'!$B$15),0) -> 7 | G8: =ROUNDUP(E8/'Hệ số'!$B$16,0) -> 17 | H8: =ROUNDUP(E8/'Hệ số'!$B$17,0) -> 10 | I8: 8 | J8: 12 | K8: =IF(AND(F8>=I8,F8<=J8),"Có",IF(D8<=8,"Ngoài dải (thẻ rẻ, chấp nhận)","Ngoài dải — báo cáo")) -> Ngoài dải — báo cáo
A9: twin_rotor_gunship | B9: Pháo hạm trực thăng hai rô-to | C9: Ở lại lâu | D9: ='Tính toán'!G44 -> 18 | E9: ='Tính toán'!L44 -> 4670 | F9: =ROUNDUP(E9/('Hệ số'!$B$14*'Hệ số'!$B$15),0) -> 12 | G9: =ROUNDUP(E9/'Hệ số'!$B$16,0) -> 27 | H9: =ROUNDUP(E9/'Hệ số'!$B$17,0) -> 16 | I9: 8 | J9: 12 | K9: =IF(AND(F9>=I9,F9<=J9),"Có",IF(D9<=8,"Ngoài dải (thẻ rẻ, chấp nhận)","Ngoài dải — báo cáo")) -> Có
A10: gunship_heli | B10: Trực thăng vũ trang bọc giáp | C10: Ở lại lâu | D10: ='Tính toán'!G45 -> 20 | E10: ='Tính toán'!L45 -> 3620 | F10: =ROUNDUP(E10/('Hệ số'!$B$14*'Hệ số'!$B$15),0) -> 9 | G10: =ROUNDUP(E10/'Hệ số'!$B$16,0) -> 21 | H10: =ROUNDUP(E10/'Hệ số'!$B$17,0) -> 13 | I10: 8 | J10: 12 | K10: =IF(AND(F10>=I10,F10<=J10),"Có",IF(D10<=8,"Ngoài dải (thẻ rẻ, chấp nhận)","Ngoài dải — báo cáo")) -> Có
A11: sky_gunship | B11: Pháo hạm bay | C11: Ở lại lâu | D11: ='Tính toán'!G51 -> 29 | E11: ='Tính toán'!L51 -> 4900 | F11: =ROUNDUP(E11/('Hệ số'!$B$14*'Hệ số'!$B$15),0) -> 12 | G11: =ROUNDUP(E11/'Hệ số'!$B$16,0) -> 28 | H11: =ROUNDUP(E11/'Hệ số'!$B$17,0) -> 17 | I11: 8 | J11: 12 | K11: =IF(AND(F11>=I11,F11<=J11),"Có",IF(D11<=8,"Ngoài dải (thẻ rẻ, chấp nhận)","Ngoài dải — báo cáo")) -> Có
A12: heavy_bomber | B12: Oanh tạc cơ chiến lược | C12: Ở lại lâu | D12: ='Tính toán'!G50 -> 29 | E12: ='Tính toán'!L50 -> 4530 | F12: =ROUNDUP(E12/('Hệ số'!$B$14*'Hệ số'!$B$15),0) -> 11 | G12: =ROUNDUP(E12/'Hệ số'!$B$16,0) -> 26 | H12: =ROUNDUP(E12/'Hệ số'!$B$17,0) -> 16 | I12: 8 | J12: 12 | K12: =IF(AND(F12>=I12,F12<=J12),"Có",IF(D12<=8,"Ngoài dải (thẻ rẻ, chấp nhận)","Ngoài dải — báo cáo")) -> Có
A13: scout_heli | B13: Trực thăng trinh sát vũ trang | C13: Cường kích / đi qua | D13: ='Tính toán'!G30 -> 6 | E13: ='Tính toán'!L30 -> 1140 | F13: =ROUNDUP(E13/('Hệ số'!$B$14*'Hệ số'!$B$15),0) -> 3 | G13: =ROUNDUP(E13/'Hệ số'!$B$16,0) -> 7 | H13: =ROUNDUP(E13/'Hệ số'!$B$17,0) -> 4 | I13: 4 | J13: 8 | K13: =IF(AND(F13>=I13,F13<=J13),"Có",IF(D13<=8,"Ngoài dải (thẻ rẻ, chấp nhận)","Ngoài dải — báo cáo")) -> Ngoài dải (thẻ rẻ, chấp nhận)
A14: prop_attack_plane | B14: Máy bay cường kích cánh quạt | C14: Cường kích / đi qua | D14: ='Tính toán'!G35 -> 8 | E14: ='Tính toán'!L35 -> 1050 | F14: =ROUNDUP(E14/('Hệ số'!$B$14*'Hệ số'!$B$15),0) -> 3 | G14: =ROUNDUP(E14/'Hệ số'!$B$16,0) -> 6 | H14: =ROUNDUP(E14/'Hệ số'!$B$17,0) -> 4 | I14: 4 | J14: 8 | K14: =IF(AND(F14>=I14,F14<=J14),"Có",IF(D14<=8,"Ngoài dải (thẻ rẻ, chấp nhận)","Ngoài dải — báo cáo")) -> Ngoài dải (thẻ rẻ, chấp nhận)
A15: light_attack_heli | B15: Trực thăng tấn công hạng nhẹ | C15: Cường kích / đi qua | D15: ='Tính toán'!G34 -> 8 | E15: ='Tính toán'!L34 -> 1280 | F15: =ROUNDUP(E15/('Hệ số'!$B$14*'Hệ số'!$B$15),0) -> 4 | G15: =ROUNDUP(E15/'Hệ số'!$B$16,0) -> 8 | H15: =ROUNDUP(E15/'Hệ số'!$B$17,0) -> 5 | I15: 4 | J15: 8 | K15: =IF(AND(F15>=I15,F15<=J15),"Có",IF(D15<=8,"Ngoài dải (thẻ rẻ, chấp nhận)","Ngoài dải — báo cáo")) -> Có
A16: attack_helicopter | B16: Trực thăng tấn công | C16: Cường kích / đi qua | D16: ='Tính toán'!G38 -> 11 | E16: ='Tính toán'!L38 -> 2220 | F16: =ROUNDUP(E16/('Hệ số'!$B$14*'Hệ số'!$B$15),0) -> 6 | G16: =ROUNDUP(E16/'Hệ số'!$B$16,0) -> 13 | H16: =ROUNDUP(E16/'Hệ số'!$B$17,0) -> 8 | I16: 4 | J16: 8 | K16: =IF(AND(F16>=I16,F16<=J16),"Có",IF(D16<=8,"Ngoài dải (thẻ rẻ, chấp nhận)","Ngoài dải — báo cáo")) -> Có
A17: swarm_carrier | B17: Máy bay mẹ thả drone | C17: Cường kích / đi qua | D17: ='Tính toán'!G43 -> 16 | E17: ='Tính toán'!L43 -> 2400 | F17: =ROUNDUP(E17/('Hệ số'!$B$14*'Hệ số'!$B$15),0) -> 6 | G17: =ROUNDUP(E17/'Hệ số'!$B$16,0) -> 14 | H17: =ROUNDUP(E17/'Hệ số'!$B$17,0) -> 9 | I17: 4 | J17: 8 | K17: =IF(AND(F17>=I17,F17<=J17),"Có",IF(D17<=8,"Ngoài dải (thẻ rẻ, chấp nhận)","Ngoài dải — báo cáo")) -> Có
A18: glide_bomber | B18: Máy bay ném bom lượn tầm xa | C18: Cường kích / đi qua | D18: ='Tính toán'!G46 -> 21 | E18: ='Tính toán'!L46 -> 3010 | F18: =ROUNDUP(E18/('Hệ số'!$B$14*'Hệ số'!$B$15),0) -> 8 | G18: =ROUNDUP(E18/'Hệ số'!$B$16,0) -> 18 | H18: =ROUNDUP(E18/'Hệ số'!$B$17,0) -> 11 | I18: 4 | J18: 8 | K18: =IF(AND(F18>=I18,F18<=J18),"Có",IF(D18<=8,"Ngoài dải (thẻ rẻ, chấp nhận)","Ngoài dải — báo cáo")) -> Có
A19: stealth_naval_strike | B19: Cường kích tàng hình trên hạm | C19: Cường kích / đi qua | D19: ='Tính toán'!G47 -> 22 | E19: ='Tính toán'!L47 -> 2020 | F19: =ROUNDUP(E19/('Hệ số'!$B$14*'Hệ số'!$B$15),0) -> 5 | G19: =ROUNDUP(E19/'Hệ số'!$B$16,0) -> 12 | H19: =ROUNDUP(E19/'Hệ số'!$B$17,0) -> 7 | I19: 4 | J19: 8 | K19: =IF(AND(F19>=I19,F19<=J19),"Có",IF(D19<=8,"Ngoài dải (thẻ rẻ, chấp nhận)","Ngoài dải — báo cáo")) -> Có
A20: attack_jet | B20: Máy bay cường kích | C20: Cường kích / đi qua | D20: ='Tính toán'!G48 -> 23 | E20: ='Tính toán'!L48 -> 2480 | F20: =ROUNDUP(E20/('Hệ số'!$B$14*'Hệ số'!$B$15),0) -> 6 | G20: =ROUNDUP(E20/'Hệ số'!$B$16,0) -> 15 | H20: =ROUNDUP(E20/'Hệ số'!$B$17,0) -> 9 | I20: 4 | J20: 8 | K20: =IF(AND(F20>=I20,F20<=J20),"Có",IF(D20<=8,"Ngoài dải (thẻ rẻ, chấp nhận)","Ngoài dải — báo cáo")) -> Có
A21: stealth_bomber | B21: Oanh tạc cơ tàng hình | C21: Cường kích / đi qua | D21: ='Tính toán'!G49 -> 27 | E21: ='Tính toán'!L49 -> 2640 | F21: =ROUNDUP(E21/('Hệ số'!$B$14*'Hệ số'!$B$15),0) -> 7 | G21: =ROUNDUP(E21/'Hệ số'!$B$16,0) -> 16 | H21: =ROUNDUP(E21/'Hệ số'!$B$17,0) -> 9 | I21: 4 | J21: 8 | K21: =IF(AND(F21>=I21,F21<=J21),"Có",IF(D21<=8,"Ngoài dải (thẻ rẻ, chấp nhận)","Ngoài dải — báo cáo")) -> Có
A22: uav_loiter_strike | B22: UAV lượn tấn công | C22: Drone / trinh sát | D22: ='Tính toán'!G29 -> 0 | E22: ='Tính toán'!L29 -> 550 | F22: =ROUNDUP(E22/('Hệ số'!$B$14*'Hệ số'!$B$15),0) -> 2 | G22: =ROUNDUP(E22/'Hệ số'!$B$16,0) -> 4 | H22: =ROUNDUP(E22/'Hệ số'!$B$17,0) -> 2 | I22: 2 | J22: 4 | K22: =IF(AND(F22>=I22,F22<=J22),"Có",IF(D22<=8,"Ngoài dải (thẻ rẻ, chấp nhận)","Ngoài dải — báo cáo")) -> Có
A23: recon_drone | B23: UAV trinh sát | C23: Drone / trinh sát | D23: ='Tính toán'!G31 -> 7 | E23: ='Tính toán'!L31 -> 840 | F23: =ROUNDUP(E23/('Hệ số'!$B$14*'Hệ số'!$B$15),0) -> 3 | G23: =ROUNDUP(E23/'Hệ số'!$B$16,0) -> 5 | H23: =ROUNDUP(E23/'Hệ số'!$B$17,0) -> 3 | I23: 2 | J23: 4 | K23: =IF(AND(F23>=I23,F23<=J23),"Có",IF(D23<=8,"Ngoài dải (thẻ rẻ, chấp nhận)","Ngoài dải — báo cáo")) -> Có
A24: wingman_drone | B24: Drone hộ vệ | C24: Drone / trinh sát | D24: ='Tính toán'!G32 -> 7 | E24: ='Tính toán'!L32 -> 790 | F24: =ROUNDUP(E24/('Hệ số'!$B$14*'Hệ số'!$B$15),0) -> 2 | G24: =ROUNDUP(E24/'Hệ số'!$B$16,0) -> 5 | H24: =ROUNDUP(E24/'Hệ số'!$B$17,0) -> 3 | I24: 2 | J24: 4 | K24: =IF(AND(F24>=I24,F24<=J24),"Có",IF(D24<=8,"Ngoài dải (thẻ rẻ, chấp nhận)","Ngoài dải — báo cáo")) -> Có
A25: recon_jet | B25: Máy bay trinh sát tốc độ cao | C25: Drone / trinh sát | D25: ='Tính toán'!G37 -> 9 | E25: ='Tính toán'!L37 -> 920 | F25: =ROUNDUP(E25/('Hệ số'!$B$14*'Hệ số'!$B$15),0) -> 3 | G25: =ROUNDUP(E25/'Hệ số'!$B$16,0) -> 6 | H25: =ROUNDUP(E25/'Hệ số'!$B$17,0) -> 4 | I25: 2 | J25: 4 | K25: =IF(AND(F25>=I25,F25<=J25),"Có",IF(D25<=8,"Ngoài dải (thẻ rẻ, chấp nhận)","Ngoài dải — báo cáo")) -> Có
A26: strike_drone | B26: UAV tấn công | C26: Drone / trinh sát | D26: ='Tính toán'!G39 -> 11 | E26: ='Tính toán'!L39 -> 1330 | F26: =ROUNDUP(E26/('Hệ số'!$B$14*'Hệ số'!$B$15),0) -> 4 | G26: =ROUNDUP(E26/'Hệ số'!$B$16,0) -> 8 | H26: =ROUNDUP(E26/'Hệ số'!$B$17,0) -> 5 | I26: 2 | J26: 4 | K26: =IF(AND(F26>=I26,F26<=J26),"Có",IF(D26<=8,"Ngoài dải (thẻ rẻ, chấp nhận)","Ngoài dải — báo cáo")) -> Có

Sheet Pháo sáng
A1: Hồi chiêu hiện tại đọc từ thẻ xe trong PDF (tr. 45–61), agent xác nhận lại trong balance.json (CHECK C05). Đổi hệ giữ nguyên nhịp hồi để không làm yếu đi; số lần dự trữ là phần thêm. Nạp đầy khi về Bãi đáp hoặc sở chỉ huy.
A3: id | B3: Đơn vị | C3: Có pháo sáng (hiện tại) | D3: Hồi chiêu hiện tại (s) | E3: Có pháo sáng (mới) | F3: Số lần dự trữ | G3: Hồi 1 lần (s) | H3: Loại thay đổi | I3: Trạng thái | J3: Đồ trang bị
A4: uav_loiter_strike | B4: UAV lượn tấn công | C4: Không | D4: — | E4: Không | F4: 0 | G4: — | H4: Không đổi | I4: — | J4: Không gắn được Mồi bẫy nhiệt
A5: scout_heli | B5: Trực thăng trinh sát vũ trang | C5: Không | D5: — | E5: Có | F5: 2 | G5: 20 | H5: Thêm mới | I5: APPLY | J5: Đơn vị BUILT_IN gắn Mồi bẫy nhiệt: +1 lần, hồi nhanh hơn 25%
A6: recon_drone | B6: UAV trinh sát | C6: Không | D6: — | E6: Không | F6: 0 | G6: — | H6: Không đổi | I6: — | J6: Không gắn được Mồi bẫy nhiệt
A7: wingman_drone | B7: Drone hộ vệ | C7: Không | D7: — | E7: Không | F7: 0 | G7: — | H7: Không đổi | I7: — | J7: Không gắn được Mồi bẫy nhiệt
A8: heavy_lift_helicopter | B8: Trực thăng cẩu tháp | C8: Không | D8: — | E8: Có | F8: 3 | G8: 20 | H8: Thêm mới | I8: APPLY | J8: Đơn vị BUILT_IN gắn Mồi bẫy nhiệt: +1 lần, hồi nhanh hơn 25%
A9: light_attack_heli | B9: Trực thăng tấn công hạng nhẹ | C9: Không | D9: — | E9: Có | F9: 2 | G9: 20 | H9: Thêm mới | I9: APPLY | J9: Đơn vị BUILT_IN gắn Mồi bẫy nhiệt: +1 lần, hồi nhanh hơn 25%
A10: prop_attack_plane | B10: Máy bay cường kích cánh quạt | C10: Không | D10: — | E10: Có | F10: 2 | G10: 20 | H10: Thêm mới | I10: APPLY | J10: Đơn vị BUILT_IN gắn Mồi bẫy nhiệt: +1 lần, hồi nhanh hơn 25%
A11: aerial_tanker | B11: Máy bay tiếp dầu | C11: Không | D11: — | E11: Có | F11: 3 | G11: 20 | H11: Thêm mới | I11: APPLY | J11: Đơn vị BUILT_IN gắn Mồi bẫy nhiệt: +1 lần, hồi nhanh hơn 25%
A12: recon_jet | B12: Máy bay trinh sát tốc độ cao | C12: Không | D12: — | E12: Không | F12: 0 | G12: — | H12: Không đổi | I12: — | J12: Không gắn được Mồi bẫy nhiệt
A13: attack_helicopter | B13: Trực thăng tấn công | C13: Có | D13: 20 | E13: Có | F13: 2 | G13: 20 | H13: Đổi hệ | I13: APPLY | J13: Đơn vị BUILT_IN gắn Mồi bẫy nhiệt: +1 lần, hồi nhanh hơn 25%
A14: strike_drone | B14: UAV tấn công | C14: Không | D14: — | E14: Không | F14: 0 | G14: — | H14: Không đổi | I14: — | J14: Không gắn được Mồi bẫy nhiệt
A15: fighter_jet | B15: Tiêm kích | C15: Có | D15: 16 | E15: Có | F15: 2 | G15: 16 | H15: Đổi hệ | I15: APPLY | J15: Đơn vị BUILT_IN gắn Mồi bẫy nhiệt: +1 lần, hồi nhanh hơn 25%
A16: interceptor_jet | B16: Tiêm kích đánh chặn | C16: Có | D16: 16 | E16: Có | F16: 2 | G16: 16 | H16: Đổi hệ | I16: APPLY | J16: Đơn vị BUILT_IN gắn Mồi bẫy nhiệt: +1 lần, hồi nhanh hơn 25%
A17: stealth_fighter | B17: Tiêm kích tàng hình | C17: Có | D17: 16 | E17: Có | F17: 2 | G17: 16 | H17: Đổi hệ | I17: APPLY | J17: Đơn vị BUILT_IN gắn Mồi bẫy nhiệt: +1 lần, hồi nhanh hơn 25%
A18: swarm_carrier | B18: Máy bay mẹ thả drone | C18: Có | D18: 11 | E18: Có | F18: 3 | G18: 11 | H18: Đổi hệ | I18: APPLY | J18: Đơn vị BUILT_IN gắn Mồi bẫy nhiệt: +1 lần, hồi nhanh hơn 25%
A19: twin_rotor_gunship | B19: Pháo hạm trực thăng hai rô-to | C19: Không | D19: — | E19: Có | F19: 3 | G19: 20 | H19: Thêm mới | I19: APPLY | J19: Đơn vị BUILT_IN gắn Mồi bẫy nhiệt: +1 lần, hồi nhanh hơn 25%
A20: gunship_heli | B20: Trực thăng vũ trang bọc giáp | C20: Có | D20: 20 | E20: Có | F20: 2 | G20: 20 | H20: Đổi hệ | I20: APPLY | J20: Đơn vị BUILT_IN gắn Mồi bẫy nhiệt: +1 lần, hồi nhanh hơn 25%
