Workbook

Sheet Mục lục
A1: Nhóm | B1: Sheet | C1: Nội dung
A2: Bắt đầu | B2: Tổng quan | C2: Nguồn, nguyên tắc quyết định, vấn đề chung, thang máu boss
A3: Bắt đầu | B3: Cốt truyện | C3: Cốt truyện đầy đủ: bối cảnh, nhân vật, 12 chương, 3 chương xen kẽ, phần kết, móc nối
A4: Quyết định | B4: Thay đổi chi tiết | C4: Danh sách hành động: mọi thay đổi cụ thể, xếp theo ưu tiên
A5: Quyết định | B5: Kiểm tra từng mục | C5: Giữ / Đổi / Xem lại cho từng mục của mọi xe, tháp, boss
A6: Quyết định | B6: Cân bằng lần 2 | C6: Đánh giá lại sau khi áp đợt 1: còn mạnh, còn yếu, cần theo dõi
A7: Quyết định | B7: Việc cho agent | C7: Danh sách việc cho agent code, sheet nguồn và tiêu chí đạt
A8: Đơn vị | B8: Phương tiện | C8: Chỉ số, miêu tả, hình dạng cho AI vẽ, đề xuất và lý do
A9: Đơn vị | B9: Công trình | C9: Như trên, cho tháp, công trình, nhánh
A10: Đơn vị | B10: Boss | C10: Như trên, cho boss và mini boss
A11: Đơn vị | B11: Boss đề xuất | C11: Máu, DPS mục tiêu, vũ khí thêm, siêu vũ khí (chỉ boss chủ lực)
A12: Đơn vị | B12: Tên đề xuất | C12: Tên đầy đủ, tên ngắn, tên tiếng Anh
... A28: Tham chiếu | B28: Hướng dẫn vẽ | C28: Quy trình và mẫu prompt để dựng model chất lượng cao

Sheet Tổng quan
A1: Rà soát cân bằng Machine Brigade (bản 2)
A2: Nguồn | B2: Machine_Brigade_Design_Review_1.pdf (264 trang): thẻ phần 8 và 11; bảng 9, 9b (giá trị thực chiến), 10b (nhịp bắn, đường đạn, di chuyển), 10c (tầm nổ), 12 (thẻ hỗ trợ). Giá và thông số ngoài đời là ước lượng từ thông tin công khai, chỉ dùng để so thứ tự tương đối.
A3: Cách đọc | B3: Sheet "Vũ khí đề xuất" có mọi vũ khí (154) với số hiện tại và đề xuất cho sát thương, chế độ bắn, viên/s, số viên mỗi băng hoặc loạt, thời gian nạp, tầm, tốc độ bay, nổ lan, và DPS đề xuất theo từng cấp giáp 0–5, trên không, công trình (công thức). Sheet "Đơn vị – vũ khí" và "Tổng DPS đơn vị" cộng DPS theo từng xe, tháp, boss. Sheet "Boss đề xuất": máu, DPS mục tiêu, vũ khí thêm, siêu vũ khí (chỉ boss chủ lực; mini boss bỏ đòn lớn). Sheet "Công trình mới" và "Tên lửa & bom mới" có đủ chỉ số. Sheet "Kiểm tra từng mục" đi qua mọi mục của mọi xe, tháp, boss (tên, máu, giáp từng mặt, tốc độ, tốc độ xoay, kích thước, tầm nhìn, tầm bắn, giá, vũ khí, hành vi, nổ khi bị phá, tham khảo) và ghi Giữ / Đổi / Xem lại kèm lý do. Sheet "Thay đổi chi tiết" là danh sách hành động: mỗi dòng một thay đổi cụ thể (vũ khí thêm/bỏ/đổi, cỡ nòng, sát thương, nhịp, tầm, giáp, máu, tốc độ, giá, hành vi) kèm lý do. Các sheet Phương tiện, Công trình, Boss, Vũ khí tổng hợp lại theo từng đơn vị. Các cột có công thức tự tính lại khi sửa số.
A5: NGUYÊN TẮC DÙNG ĐỂ QUYẾT
A6: Tốc độ tên lửa | B6: Tính từ lúc phóng tới lúc trúng trong tầm của game (đã nén rất nhiều so với ngoài đời), không dùng Mach thật. Hai điều kiện: (1) tên lửa phòng không và không đối không phải nhanh hơn mục tiêu nhanh nhất nó cần bắt khoảng 1,2–1,5 lần (tiêm kích bay 40 m/s, drone hộ vệ 46 m/s, trong khi tên lửa hiện chỉ 24 m/s); (2) thời gian bay tới tầm tối đa khoảng 0,6–2 giây, để vẫn nhìn thấy, vẫn bị pháo sáng và APS đánh chặn. Tên lửa chống tăng lái bằng dây cố ý chậm (khoảng 2 s) để khói, APS và né có tác dụng; tên lửa hành trình và Shahed cố ý chậm để phòng không có cơ hội. Chi tiết ở sheet "Tốc độ tên lửa".
A7: Giá (CP) | B7: Quyết theo hai yếu tố: (1) tác động lên trận đấu, đo bằng giá trị thực chiến trên mỗi CP so với trung vị của cùng vai trò (sheet "Giá CP"); (2) chi phí sản xuất ngoài đời, chỉ để giữ thứ tự hợp lý trong cùng vai trò (đồ rẻ ngoài đời không nên đắt trong game và ngược lại), không quy đổi thẳng vì chênh lệch ngoài đời quá lớn (B-2 đắt gấp hàng trăm lần một chiếc tăng).
A8: Bán kính nổ | B8: Bán kính ≈ 10 m × (khối lượng/500 kg)^(1/3), lấy FAB-500 = 10 m làm mốc; cùng một loại đạn phải cùng bán kính ở mọi đơn vị.
A9: Nhịp bắn | B9: Giữ DPS duy trì như hiện tại, nhưng đổi nhịp bắn (viên/s, loạt, nghỉ) cho giống vũ khí thật, để mỗi vũ khí có cảm giác riêng (luồng đạn CIWS, loạt pháo tự động, phát đơn pháo tăng).
A10: Sát thương mỗi phát | B10: Theo thang cỡ nòng và đầu nổ của prompt 13 (không đổi trong bản này, trừ chỗ ghi rõ).
A11: Kích thước | B11: Xe mặt đất 0,8 × kích thước thật; máy bay và trực thăng 0,4 × thật (sải cánh / rô-to); đạn phóng từ mặt đất 0,8 ×, từ máy bay 0,5 ×, tối thiểu 0,8 m; boss theo thiết kế (×1,3–1,5 so với mẫu), trùm cuối là vật thể lớn nhất. Nổ khi bị phá ≈ 3 m + 0,45 × chiều dài xe (+3 m nếu chở nhiều đạn). Hiệu ứng nổ trên màn hình phải bằng bán kính gây sát thương. Xem sheet Tỷ lệ map.
A12: Tên | B12: Tên thẻ mô tả vai trò bằng tiếng Việt, không chứa tên mẫu thật (tên mẫu thật để ở dòng phụ theo ngụy trang); có tên ngắn cho HUD và tên tiếng Anh; một đơn vị chỉ một tên ở mọi bảng. Xem sheet Tên đề xuất.
A14: VẤN ĐỀ CHUNG
A15: 1. Tên lửa chậm hơn mục tiêu | B15: Mọi tên lửa phòng không và không đối không bay 24 m/s, chậm hơn tiêm kích (40) và drone hộ vệ (46). Kh-29L và R-60 chỉ 10 m/s.
A16: 2. Cùng vũ khí, khác tốc độ | B16: S-8 (20/27/48), Hydra (48/38), Grad (24/52/55), GMLRS (24/52), TOS (24/45), Hellfire (12/21/24), Lancet (28/16), FPV (26/18).
A17: 3. Bán kính nổ ngược khối lượng | B17: Kh-101 400 kg (6 m) và JASSM 450 kg (5 m) nổ nhỏ hơn FAB-250 (8 m); pháo 460 mm (7 m) nhỏ hơn cối 240 mm (9 m); 155 mm có 4 giá trị khác nhau.
A18: 4. Phòng không tháp ngược cỡ ô | B18: Tháp ô nhỏ 300, Patriot ô lớn 188.
A19: 5. Máu boss ngược thứ bậc | B19: Trùm cuối ít máu hơn boss chương 5; boss chủ lực chương 11 ít máu hơn nhiều mini boss; boss chương 1 gần bằng boss cuối game.
A20: 6. Mâu thuẫn với danh sách giữ lại | B20: Pháo tự hành dùng model CAESAR; Tăng hạng nặng tham khảo T-14.
A21: 7. Tham khảo lệch vũ khí | B21: Tháp phòng không (GDF 35 mm / 2A38 30 mm), nhánh tên lửa ô nhỏ (Buk), Scylla (pháo 460 mm), Icarus (pháo xe tăng), Mi-24 (Hellfire của Mỹ).
A22: 8. Ô nhỏ thiếu chống tăng | B22: Ô nhỏ có chống xe nhẹ, phòng không, EW, chướng ngại, kinh tế, nhưng không có tháp chống tăng (trừ bãi mìn). Xem "Ụ pháo chống tăng" ở sheet Đề xuất thêm.
A23: 9. Bảng 9b thiếu xe hỗ trợ | B23: Xe hỗ trợ có giá trị 0. Cần chỉ số "giá trị hỗ trợ" (máu sửa, đạn nạp, tên lửa hút, sát thương khiên chặn).
A25: THANG MÁU BOSS CHỦ LỰC (gốc, trước scale) | B25: Mini boss khoảng 45–60% boss chủ lực cùng chương.
A26: Chương 1 | B26: 12000
A27: Chương 2 | B27: 13000
A28: Chương 3 | B28: 15000
A29: Chương 4 | B29: 17000
A30: Chương 5 | B30: 18000
A31: Chương 6 | B31: 19000
A32: Chương 7 | B32: 20000
A33: Chương 8 | B33: 21000
A34: Chương 9 | B34: 22000
A35: Chương 10 | B35: 23000
A36: Chương 11 | B36: 24000
A37: Chương 12 | B37: 26000

Sheet Cốt truyện
A1: Phần | B1: Mục | C1: Nội dung
A2: Bối cảnh | B2: Thế giới | C2: Tương lai gần. Meridian Coast là vùng ven biển giàu dầu mỏ và khoáng sản. Sau khi chính quyền trong vùng sụp đổ, một tập đoàn khai khoáng thuê Hegemon, tập đoàn quân sự tư nhân lớn nhất thế giới, để "giữ ổn định". Trong hai năm, Hegemon trở thành thế lực chiếm đóng và biến cả vùng thành nơi thử nghiệm vũ khí.
A3: Bối cảnh | B3: Phe ta | C3: Các tỉnh còn lại lập ra Meridian Accord. Lực lượng mạnh nhất là 7th Mechanized Brigade ("Machine Brigade"), chỉ gồm phương tiện, đánh bằng thả dù và tốc độ. Người chơi là chỉ huy chiến trường của lữ đoàn.
A4: Bối cảnh | B4: Mối đe dọa | C4: Dự án Icarus của Director Lucien Aurel: vũ khí quỹ đạo có thể tấn công bất kỳ điểm nào trên mặt đất mà không ai chạm tới được.
A5: Mở đầu | B5: Cảnh nhảy tới tương lai | C5: Vài giây của cảnh cuối: bầu trời Helion, thanh tungsten rơi xuống, giọng Aurel: "Họ vẫn chưa hiểu." Cắt về Stormbeach, ba năm trước.
A6: Nhân vật | B6: Colonel Marcus Kade "Iron" | C6: Chỉ huy trực tiếp, giọng chính trên thoại. Bình tĩnh, thực dụng, tin vào lữ đoàn hơn các chính trị gia. Đền đáp ở phần kết: từ chối ghế chính phủ, ở lại với lữ đoàn.
A7: Nhân vật | B7: Engineer Mara Lind | C7: Phụ trách căn cứ. Từng thiết kế Behemoth cho Hegemon, bỏ đi vì mặc cảm. Đối mặt Behemoth Mk.0 do chính mình thiết kế (Xen kẽ I). Đền đáp: Behemoth bà sửa lại chiến đấu cùng lữ đoàn ở Helion.
A8: Nhân vật | B8: Lieutenant Jonah Reyes "Hawk" | C8: Chỉ huy không quân. Có món nợ với Raven, người bắn hạ đồng đội cũ của anh. Bị bắn rơi sau chiến tuyến (Xen kẽ III); đấu tay đôi với Raven và bắn phát cuối hạ Roc (chương 10).
A9: Nhân vật | B9: Captain Nadia Kerr | C9: Sĩ quan tình báo, giao nhiệm vụ phụ, giải mã dự án địch. Cài manh mối về Thorne từ chương 4; phát hiện cú phản bội đầu tiên ở chương 7.
A10: Nhân vật | B10: Major Brandt | C10: Chỉ huy đồn trú bờ biển phía tây, tin tuyệt đối vào pháo đài. Đầu hàng ở chương 1, quay lại giúp phe ta phòng thủ ở chương 6 (mở chỉ huy "Bulwark").
A11: Nhân vật | B11: General Viktor Varga "Anvil" | C11: Tướng thiết giáp, cha đẻ Behemoth; già, trọng danh dự, tôn trọng người chơi. Ngừng bắn với Kade để sơ tán Hollow Dam (chương 6). Ngã xuống ở Helion.
A12: Nhân vật | B12: Colonel Ilya Orlov "Winter" | C12: Tướng pháo binh, lạnh lùng, thích thắng từ xa. Rút lui ở chương 3 ("Mùa đông luôn quay lại"), trận cuối với Gungnir ở chương 11.
... A35: Cơ chế kể chuyện | B35: Tóm tắt | C35: Bản đồ mặt trận đổi màu theo tiến độ; manh mối về Thorne ở chương 4–6; lựa chọn có hệ quả ở chương 4, 8, 11; chiến lợi phẩm gắn truyện; hồ sơ tình báo; tranh truyện cuối chương; thoại dạng chữ; khoảnh khắc cốt truyện làm chậm thời gian (5–6 lần cả chiến dịch).

Sheet Thay đổi chi tiết
A1: id | B1: Đơn vị | C1: Hạng mục | D1: Hiện tại | E1: Đề xuất (cụ thể) | F1: Lý do thay đổi | G1: Tham khảo (ngoài đời / game) | H1: Ưu tiên
A2: aa_turret | B2: Tháp phòng không | C2: Vũ khí và tham khảo | D2: tham khảo Oerlikon GDF 35 mm nhưng vũ khí 2A38 30 mm · chống máy bay 300 | E2: chọn một: đổi vũ khí thành Oerlikon 35 mm hoặc đổi tham khảo sang 2A38; chống máy bay 300→240 | F2: Tham khảo lệch vũ khí; tháp ô nhỏ đang mạnh hơn Patriot ô lớn. | G2: Skyguard/GDF (35 mm) hoặc Tunguska (2A38) | H2: Cao
A3: artillery | B3: Pháo tự hành | C3: Vũ khí: lựu pháo 155 mm | D3: 0,10 phát/s · DPS duy trì 27 · giá trị thấp hơn Pháo phản lực cùng giá | E3: 0,14 phát/s · bắn 3 loạt rồi dời vị trí (giữ) | F3: Pháo tự hành đang kém hẳn pháo phản lực 6 CP (331 so với 510 theo vai trò). | G3: M109A7: 4 phát/phút tối đa | H3: Cao
A4: artillery | B4: Pháo tự hành | C4: Model và tham khảo | D4: CAESAR bánh lốp (nằm trong danh sách giữ lại) | E4: Đổi model sang M109A7 xích; giáp trước 1→2; tốc độ 7→6 | F4: Để CAESAR cho thẻ "Pháo bánh lốp bắn rồi chạy" sau này, không vướng danh sách giữ lại. | G4: M109A7 Paladin | H4: Cao
A5: attack_helicopter | B5: Trực thăng tấn công | C5: Giá | D5: 11 CP (hiệu quả 0,66 × trung vị trực thăng) | E5: 9 CP | F5: Yếu hơn các trực thăng khác tính theo CP. | G5: AH-64D | H5: Cao
A6: attack_jet | B6: Máy bay cường kích | C6: Vũ khí: FAB-250 | D6: 2 quả mỗi lần đầy đạn | E6: 1 quả | F6: Giá trị lên công sự 1.156 cao nhất nhóm cùng giá. | G6: Su-25: tải trọng hỗn hợp | H6: Cao
A7: attack_jet | B7: Máy bay cường kích | C7: Vũ khí: Kh-29L, R-60 | D7: tốc độ 10 (bay 4 s và 2,8 s, chậm như drone) | E7: Kh-29L: 32 (bay 1,25 s) · R-60: 42 | F7: Tên lửa không đối đất nặng và tên lửa không đối không đang chậm nhất game. | G7: Kh-29L: Mach 2,5; R-60: Mach 2,7 | H7: Cao
A8: attack_jet | B8: Máy bay cường kích | C8: Giá | D8: 16 CP (hiệu quả 1,27) | E8: 18 CP | F8: Mạnh nhất nhóm máy bay tính theo CP. | G8: Su-25 ~11 triệu USD, A-10 ~19 triệu USD | H8: Cao
A9: caspian | B9: Caspian · Tàu bay sát mặt nước | C9: Vũ khí | D9: chỉ AK-630 · DPS 22/11/7 | E9: thêm 2 tháp 23 mm đôi và 1 tên lửa chống hạm bắn thường mỗi lượt lướt | F9: Mini boss gần như không có vũ khí ngoài đòn lớn. | G9: Lun: 6 Moskit, 4 tháp 23 mm | H9: Cao
A10: daedalus | B10: Daedalus · Tàu đổ bộ quỹ đạo | C10: Máu, vũ khí | D10: 9.435 · 2 pháo 30 mm | E10: ~24.000 · thêm 2 tháp laser phòng thủ điểm và 2 pháo 57 mm dưới bụng | F10: Boss chủ lực chương 11 yếu hơn nhiều mini boss. | G10: Acclamator (Star Wars) | H10: Cao
A11: fighter_jet | B11: Tiêm kích | C11: Vũ khí: AIM-120, AIM-9X | D11: tốc độ 24 (chậm hơn tiêm kích 40 m/s) | E11: AIM-120: 60 (bay 1 s) · AIM-9X: 55 | F11: Tên lửa phải bắt kịp mục tiêu nhanh nhất. | G11: AIM-120: Mach 4; AIM-9X: Mach 2,5+ | H11: Cao
A12: heavy_tank | B12: Tăng hạng nặng | C12: Giá (CP) | D12: 12 | E12: 13 CP | F12: Xem sheet Giá CP. | H12: Cao
A13: iron_beam | B13: La-de phòng không | C13: Giá | D13: 7 CP · giá trị 87 (0,33 × trung vị) · bắn 8% thời gian | E13: 6 CP | F13: Gần như vô dụng hiện tại. | G13: Iron Beam: chi phí mỗi phát rất thấp | H13: Cao
A14: iron_beam | B14: La-de phòng không | C14: Vũ khí: laser 100 kW | D14: 7,5/tick · DPS 143 lý thuyết | E14: 10/tick · DPS ~190; mở rộng APS: đánh chặn cả đạn cối và rốc-két pháo binh trong 30 m; ưu tiên drone | F14: Vai trò thật của Iron Beam là chặn drone, rốc-két, cối. | G14: Rafael Iron Beam | H14: Cao
A15: long_sam | B15: Tên lửa phòng không tầm xa | C15: Giá | D15: 11 CP (hiệu quả 2,29 × trung vị) | E15: 14 CP | F15: Hiệu quả gấp đôi các xe phòng không khác; S-400 ngoài đời cực đắt. | G15: S-400: ~500 triệu USD một tiểu đoàn | H15: Cao
A16: missile_battery | B16: Tên lửa Patriot tầm xa | C16: Vũ khí: Patriot PAC-2 | D16: chống máy bay 188 · tốc độ 24 (bay 3,75 s) | E16: chống máy bay 300 · tốc độ 60 (bay 1,5 s) | F16: Tháp ô lớn phải mạnh hơn tháp ô nhỏ; tên lửa phải bắt kịp máy bay. | G16: PAC-2: Mach 4 | H16: Cao
A17: rocket_turret.guided | B17: Dàn rốc-két · nhánh Rốc-két dẫn đường | C17: Vũ khí: GMLRS dẫn đường | D17: 100/phát · nổ lan 3 m · tốc độ 24 · DPS 27/27 | E17: 160/phát · nổ lan 4,5 m · tốc độ 50 · mục tiêu ~60/60 | F17: Nhánh gần như vô dụng; GMLRS thật chính xác và mạnh với công trình. | G17: GMLRS: đầu nổ 90 kg | H17: Cao
A18: sam_launcher | B18: Tên lửa phòng không | C18: Giá | D18: 5 CP (hiệu quả 1,61 × trung vị) | E18: 7 CP | F18: Hiệu quả cao nhất nhóm phòng không di động; Buk ngoài đời đắt hơn Gepard nhiều. | G18: Buk TELAR ~10–15 triệu USD | H18: Cao
A19: sam_launcher | B19: Tên lửa phòng không | C19: Vũ khí: 9M317 Buk | D19: tốc độ 24 (bay 2,3 s, chậm hơn tiêm kích 40 m/s) | E19: tốc độ 50 (bay 1,1 s) | F19: Tên lửa không đuổi kịp máy bay nhanh. | G19: 9M317: Mach 4 | H19: Cao
A20: scout_heli | B20: Trực thăng trinh sát | C20: Giá | D20: 4 CP · giá trị vs xe nhẹ 956 (cao nhất game theo CP) | E20: 5 CP | F20: Trực thăng trinh sát đang là thẻ diệt xe nhẹ mạnh nhất. | G20: MH-6 Little Bird ~5 triệu USD | H20: Cao
A21: scout_heli | B21: Trực thăng trinh sát | C21: Vũ khí: Hydra 70 | D21: 12 quả mỗi lần đầy đạn | E21: 6 quả | F21: Giảm sức phá xe nhẹ, giữ minigun để vẫn đúng vai trò trinh sát vũ trang. | G21: AH-6: 2 ống 7 quả Hydra | H21: Cao
A22: scout_jeep | B22: Xe trinh sát | C22: Tầm nhìn | D22: 35 m | E22: 55 m | F22: Trinh sát đang nhìn kém xe bọc thép; không làm được việc trinh sát. | G22: Fennek / LRV có cột quan sát và kính nhiệt | H22: Cao
A23: scout_jeep | B23: Xe trinh sát | C23: Hành vi | D23: Không có ẩn | E23: Ẩn khi đứng yên (chỉ lộ ở 60% tầm nhìn địch), lộ khi bắn | F23: Trinh sát thật dựa vào ngụy trang và đứng quan sát. | G23: Fennek; Wargame (đơn vị trinh sát ẩn khi đứng yên) | H23: Cao
A24: scylla | B24: Scylla · Tàu khu trục | C24: Vũ khí, máu | D24: pháo 460 mm (của Yamato) · 13.370 máu | E24: pháo 130 mm AK-130 đôi + bệ tên lửa chống hạm + CIWS · ~9.000 máu | F24: Tàu khu trục mini boss mang pháo thiết giáp hạm, máu cao hơn boss chủ lực. | G24: Sovremenny (AK-130, P-270 Moskit) | H24: Cao
... A26: silver_bug | B26: Icarus · Phi thuyền quỹ đạo | C26: Vũ khí | D26: 2 pháo Rh-120 xe tăng, 2 Oerlikon 35, 2 Bofors 40 | E26: thay bằng 2 coilgun và 2 tháp laser phòng thủ điểm; pháo thông thường chỉ ở tháp phụ pha 3 (xác rơi) | F26: Phi thuyền quỹ đạo mang pháo xe tăng là vô lý. | G26: Polyus/Skif-DM; SOLG (Ace Combat 5) | H26: Cao
A27: stealth_fighter | B27: Tiêm kích tàng hình | C27: Giá (CP) | D27: 14 | E27: 13 CP | F27: Xem sheet Giá CP. | H27: Cao
A28: strike_drone | B28: UAV tấn công | C28: Giá | D28: 8 CP · 469/670/734 | E28: 9 CP (giữ 4 Hellfire) | F28: Vẫn mạnh gấp rưỡi xe diệt tăng cùng giá khi không có phòng không. | G28: MQ-9 Reaper ~30 triệu USD, mang 4 Hellfire | H28: Cao
A29: swarm_carrier | B29: Máy bay mẹ thả drone | C29: Vũ khí: thêm Rapid Dragon | D29: 8 drone FPV + bom SDB; khung C-130 to bằng Pháo hạm bay (22 CP) nhưng chỉ 8 CP | E29: Bỏ SDB; thêm 2 tên lửa hành trình thả từ khoang (410/quả, Nổ mạnh xuyên 3, nổ lan 9 m, tầm 90, tốc độ 20) mỗi lượt, giữ 8 drone | F29: Máy bay to như vậy mà rẻ là không hợp lý; thêm vũ khí để xứng giá mới. Rapid Dragon là hệ thống thật cho máy bay vận tải thả tên lửa hành trình theo pallet. | G29: Rapid Dragon (C-130/C-17 thả JASSM-ER) | H29: Cao
A30: swarm_carrier | B30: Máy bay mẹ thả drone | C30: Giá | D30: 8 CP | E30: 13 CP | F30: Ngang tầm máy bay lớn khác sau khi có thêm tên lửa hành trình; C-130 ngoài đời ~70 triệu USD, đắt hơn Apache. | G30: C-130 | H30: Cao
A31: titan_tank | B31: Siêu tăng Titan | C31: Giá (CP) | D31: 16 | E31: 18 CP | F31: Xem sheet Giá CP. | H31: Cao
A32: wheeled_gun | B32: Pháo bánh lốp diệt tăng | C32: Máu | D32: 1.914 (gần bằng tăng chủ lực 1.980) | E32: 1.500 | F32: Xe bánh lốp giáp nhẹ không thể trâu như tăng. | G32: Centauro II: giáp chống 14,5–30 mm | H32: Cao
A33: wheeled_gun | B33: Pháo bánh lốp diệt tăng | C33: Vũ khí: 120 mm | D33: 0,36 phát/s (nạp 2,8 s, nhanh hơn MBT) | E33: 0,27 phát/s (DPS duy trì 94→~70) | F33: Nạp tay không thể nhanh hơn tăng chủ lực; đang lấn át Pháo chống tăng. | G33: Centauro II nạp tay | H33: Cao
A34: zu23_technical | B34: Bán tải ZU-23 | C34: Vũ khí: ZU-23-2 | D34: 15/phát · 11 viên/s · tầm 32 m · giá trị vs máy bay 62 | E34: 7/phát · 25 viên/s · tầm 38 m (giữ DPS) | F34: Hiệu quả chỉ 0,24 lần trung vị phòng không; tầm quá ngắn nên máy bay bắn trước. | G34: ZU-23-2: 2.000 phát/phút, tầm 2,5 km | H34: Cao
A35: aa_turret.sam | B35: Tháp phòng không · nhánh Trạm tên lửa | C35: Tham khảo | D35: 9K37 Buk (hệ thống lớn) | E35: Mistral / RBS-70 / Starstreak LML (bệ nhỏ) | F35: Buk là hệ thống cỡ tiểu đoàn, không hợp tháp ô nhỏ. | G35: Mistral ATLAS, RBS-70 | H35: Trung
A36: aa_vehicle | B36: Xe phòng không | C36: Vũ khí: Stinger | D36: tốc độ 24 (bay 1,8 s) | E36: tốc độ 42 (bay 1,05 s) | F36: Tên lửa phải nhanh hơn mục tiêu (cường kích bay 32 m/s); hiện chậm hơn. | G36: Stinger: Mach 2,2 | H36: Trung
A37: aa_vehicle | B37: Xe phòng không | C37: Giáp (T/H/S/N) | D37: 1/0/0/0 | E37: 2/1/1/0 | F37: Gepard dùng khung Leopard 1. | H37: Trung
A38: argus | B38: Argus · Khí cầu trinh sát | C38: Máu | D38: 7410 | E38: 10350–13800 | F38: Theo thang máu boss mới (Tổng quan): mini boss bằng 45–60% boss chủ lực chương 10. Máu gốc trước scale chiến dịch. | H38: Trung
A39: armored_bulldozer | B39: Xe ủi bọc thép | C39: Tốc độ | D39: 5 | E39: 4 m/s | F39: D9R thật chỉ ~15 km/h; giữ nhanh hơn thực tế một chút để không kẹt nhịp. | H39: Trung
A40: armored_train | B40: Juggernaut · Đoàn tàu bọc thép | C40: Máu | D40: 5820 | E40: 7650–10200 | F40: Theo thang máu boss mới (Tổng quan): mini boss bằng 45–60% boss chủ lực chương 4. Máu gốc trước scale chiến dịch. | H40: Trung
A41: artillery | B41: Pháo tự hành | C41: Giáp (T/H/S/N) | D41: 1/0/0/0 | E41: 2/1/1/0 | F41: M109 có giáp nhẹ chống mảnh (nếu đổi model sang M109). | H41: Trung
...

Sheet Kiểm tra từng mục
A1: id | B1: Đơn vị | C1: Mục | D1: Hiện tại | E1: Kết quả | F1: Đề xuất | G1: Lý do | H1: Ưu tiên
A2: hover_gunboat | B2: Xuồng cao tốc đệm khí | C2: Tên | D2: Xuồng cao tốc đệm khí | E2: Đổi | F2: Xuồng đệm khí hộ tống · ngắn: Xuồng hộ tống · EN: Escort Hovercraft | G2: Nói rõ vai trò hộ tống boss. | H2: Thấp
A3: hover_gunboat | B3: Xuồng cao tốc đệm khí | C3: Giáp (T/H/S/N) | D3: 1/0/0/0 | E3: Giữ | G3: Giả tưởng / máy bay; khớp vai trò.
A4: hover_gunboat | B4: Xuồng cao tốc đệm khí | C4: Tốc độ | D4: 8.5 | E4: Giữ | G4: Giả tưởng; so với xe cùng lớp.
A5: hover_gunboat | B5: Xuồng cao tốc đệm khí | C5: Tốc độ xoay thân / tháp | D5: 1 / 3 | E5: Giữ | G5: Hợp lý so với loại xe.
A6: hover_gunboat | B6: Xuồng cao tốc đệm khí | C6: Kích thước model (dài × rộng × cao) | D6: 14.0 × 3.9 × 4.4 | E6: Giữ | G6: Giả tưởng; so với xe cùng lớp.
A7: hover_gunboat | B7: Xuồng cao tốc đệm khí | C7: Tầm nhìn | D7: 46 | E7: Giữ | G7: Khớp vai trò.
A8: hover_gunboat | B8: Xuồng cao tốc đệm khí | C8: Tầm bắn | D8: 34 | E8: Giữ | G8: Thứ tự tầm hợp lý trong nhóm.
A9: hover_gunboat | B9: Xuồng cao tốc đệm khí | C9: Giá (CP) | D9: 0 | E9: Giữ | G9: Hiệu quả trong khoảng ±25% trung vị, thứ tự giá hợp ngoài đời (sheet Giá CP).
A10: hover_gunboat | B10: Xuồng cao tốc đệm khí | C10: Vũ khí: AK-630 30 mm | D10: 22/phát · 60 viên/s · băng 15 · nạp 14,7 s · DPS duy trì 22 | E10: Đổi | F10: 12/phát · 60 viên/s · băng 60 · nạp 5 s · DPS duy trì ~85 | G10: Bắn 0,25 s rồi im 14,7 s: không giống CIWS, và hộ tống boss gần như vô hại. | H10: Thấp
A11: hover_gunboat | B11: Xuồng cao tốc đệm khí | C11: Hành vi | D11: Vừa chạy vừa bắn; Bắn hết 15 viên thì thay băng; Xe bọc thép | E11: Giữ | G11: Hợp vai trò.
A12: hover_gunboat | B12: Xuồng cao tốc đệm khí | C12: Nổ khi bị phá (bán kính) | D12: 6 m · 140 sát thương | E12: Đổi | F12: ~9 m | G12: Bán kính nổ khi bị phá nên theo cỡ xe, cộng thêm nếu xe chở nhiều đạn/nhiên liệu. | H12: Thấp
A13: hover_gunboat | B13: Xuồng cao tốc đệm khí | C13: Tham khảo / model | D13: tàu tấn công nhanh vỏ lướt, AK-630 30 mm — Xuồng pháo hộ tống tàu đệm khí | E13: Giữ | G13: Khớp vũ khí và vai trò.
A14: armored_car | B14: Xe bọc thép | C14: Tên | D14: Xe bọc thép | E14: Đổi | F14: Xe bọc thép bánh lốp · ngắn: Bánh lốp · EN: Armored Car | G14: "Xe bọc thép" quá chung, trùng với nhiều xe khác cũng bọc thép. | H14: Thấp
A15: armored_car | B15: Xe bọc thép | C15: Máu | D15: 660 | E15: Giữ | G15: Máu/CP 1.07 × trung vị lớp Xe nhẹ.
A16: armored_car | B16: Xe bọc thép | C16: Giáp (T/H/S/N) | D16: 1/0/0/0 | E16: Giữ | G16: Khớp mẫu thật theo thang 0–4.
A17: armored_car | B17: Xe bọc thép | C17: Tốc độ | D17: 11.5 | E17: Giữ | G17: Gần tốc độ thật × hệ số nén (11.1).
A18: armored_car | B18: Xe bọc thép | C18: Tốc độ xoay thân / tháp | D18: 3 / 4 | E18: Giữ | G18: Hợp lý so với loại xe.
A19: armored_car | B19: Xe bọc thép | C19: Kích thước model (dài × rộng × cao) | D19: 5.9 × 2.3 × 2.7 | E19: Đổi | F19: 4.6 × 2.0 × 1.4 | G19: Mẫu thật Pandur I 6x6: 5.7 × 2.5 m; theo tỷ lệ chung (mặt đất 0,8) nên là 4.6 × 2.0 m. Đổi kích thước thì chỉnh vùng va chạm và chạy lại test xe kẹt. | H19: Thấp
A20: armored_car | B20: Xe bọc thép | C20: Tầm nhìn | D20: 36 | E20: Đổi | F20: 42 m | G20: Xe bánh lốp trinh sát đi trước tuyến; hiện nhìn kém cả xuồng (46). | H20: Thấp
A21: armored_car | B21: Xe bọc thép | C21: Tầm bắn | D21: 30 | E21: Đổi | F21: 42 m | G21: Xe bánh lốp trinh sát đi trước tuyến; hiện nhìn kém cả xuồng (46). | H21: Thấp
A22: armored_car | B22: Xe bọc thép | C22: Giá (CP) | D22: 3 | E22: Giữ | G22: Hiệu quả trong khoảng ±25% trung vị, thứ tự giá hợp ngoài đời (sheet Giá CP).
A23: armored_car | B23: Xe bọc thép | C23: Vũ khí | D23: 2 | E23: Giữ | G23: Bộ vũ khí khớp mẫu thật và vai trò.
A24: armored_car | B24: Xe bọc thép | C24: Hành vi | D24: Vừa chạy vừa bắn; Bắn hết 19 viên thì thay băng; Xe chiến đấu bộ binh | E24: Giữ | G24: Hợp vai trò.
A25: armored_car | B25: Xe bọc thép | C25: Nổ khi bị phá (bán kính) | D25: 5 m · 100 sát thương | E25: Giữ | G25: Hợp với cỡ xe.
A26: armored_car | B26: Xe bọc thép | C26: Tham khảo / model | D26: Pandur I 6x6, M242 Bushmaster 25 mm — ước đoán: xe bọc thép 6x6 bánh lộ ngoài, tháp pháo t | E26: Giữ | G26: Khớp vũ khí và vai trò.
A27: ifv | B27: Xe chiến đấu bộ binh | C27: Tên | D27: Xe chiến đấu bộ binh | E27: Giữ | F27: Xe chiến đấu bộ binh · ngắn: Xe bộ binh · EN: Infantry Fighting Vehicle | G27: Giữ.
A28: ifv | B28: Xe chiến đấu bộ binh | C28: Máu | D28: 1144 | E28: Giữ | G28: Máu/CP 0.93 × trung vị lớp Xe nhẹ.
A29: ifv | B29: Xe chiến đấu bộ binh | C29: Giáp (T/H/S/N) | D29: 2/1/0/0 | E29: Giữ | G29: Khớp mẫu thật theo thang 0–4.
A30: ifv | B30: Xe chiến đấu bộ binh | C30: Tốc độ | D30: 9 | E30: Đổi | F30: 8 m/s | G30: Bradley và tăng chủ lực chạy gần như ngang nhau ngoài đời; hiện IFV nhanh gấp rưỡi tăng. | H30: Trung
A31: ifv | B31: Xe chiến đấu bộ binh | C31: Tốc độ xoay thân / tháp | D31: 2 / 3 | E31: Giữ | G31: Hợp lý so với loại xe.
A32: ifv | B32: Xe chiến đấu bộ binh | C32: Kích thước model (dài × rộng × cao) | D32: 6.2 × 2.7 × 3.1 | E32: Giữ | G32: Khớp tỷ lệ chung (mẫu thật 6.55 m).
A33: ifv | B33: Xe chiến đấu bộ binh | C33: Tầm nhìn | D33: 34 | E33: Giữ | G33: Khớp vai trò.
A34: ifv | B34: Xe chiến đấu bộ binh | C34: Tầm bắn | D34: 34 | E34: Đổi | F34: tầm 40 m · tốc độ 20 (bay 2,0 s tới tầm tối đa) | G34: Tên lửa chống tăng phải bắn xa hơn pháo xe tăng (34 m), nếu không thì không có lý do mang. | H34: Trung
A35: ifv | B35: Xe chiến đấu bộ binh | C35: Giá (CP) | D35: 6 | E35: Giữ | G35: Hiệu quả trong khoảng ±25% trung vị, thứ tự giá hợp ngoài đời (sheet Giá CP).
A36: ifv | B36: Xe chiến đấu bộ binh | C36: Vũ khí: 2A42 30 mm | D36: 22/phát · 4,9 viên/s liên tục · băng 26 | E36: Đổi | F36: 22/phát · loạt 10 viên ở 9 viên/s · nghỉ 1,5 s · DPS duy trì giữ ~94 | G36: Ngoài đời 2A42 bắn loạt nhanh; cảm giác "xả loạt" khác súng máy. | H36: Trung
A37: ifv | B37: Xe chiến đấu bộ binh | C37: Vũ khí: TOW-2 | D37: tầm 34 m · tốc độ 19 | E37: Đổi | F37: tầm 40 m · tốc độ 20 (bay 2,0 s tới tầm tối đa) | G37: Tên lửa chống tăng phải bắn xa hơn pháo xe tăng (34 m), nếu không thì không có lý do mang. | H37: Trung
A38: ifv | B38: Xe chiến đấu bộ binh | C38: Hành vi | D38: Vừa chạy vừa bắn; Bắn hết 26 viên thì thay băng; Khói: khi bị bắn (mỗi 30 giây); | E38: Giữ | G38: Hợp vai trò.
A39: ifv | B39: Xe chiến đấu bộ binh | C39: Nổ khi bị phá (bán kính) | D39: 6 m · 160 sát thương | E39: Giữ | G39: Hợp với cỡ xe.
A40: ifv | B40: Xe chiến đấu bộ binh | C40: Tham khảo / model | D40: M2 Bradley, BMP-3, 2A42 30 mm, BGM-71 TOW-2 — Xe chiến đấu bộ binh bánh xích, pháo 30 mm v | E40: Giữ | G40: Khớp vũ khí và vai trò.
...

Sheet Cân bằng lần 2
A1: id | B1: Đơn vị | C1: Nhóm (9b) | D1: CP hiện | E1: CP sau đợt 1 | F1: DPS lý thuyết đề xuất / CP | G1: Hệ số so trung vị nhóm (DPS) | H1: Giá trị thực chiến / CP (sau đổi giá) | I1: Hệ số so trung vị nhóm (thực chiến) | J1: Kết luận | K1: Đề xuất đợt 2
A2: armored_car | B2: Xe bọc thép | C2: Light | D2: 3 | E2: 3 | F2: 17.4 | G2: 1.05 | H2: 138 | I2: 0.88 | J2: Ổn | K2: Trong khoảng mục tiêu.
A3: ifv | B3: Xe chiến đấu bộ binh | C3: Light | D3: 6 | E3: 6 | F3: 15.6 | G3: 0.95 | H3: 174 | I3: 1.12 | J3: Ổn | K3: Trong khoảng mục tiêu.
A4: engineer_vehicle | B4: Xe công binh | C4: Support | D4: 3 | E4: 3 | F4: 16.7 | G4: 1.67 | H4: 0 | I4: 0 | J4: Ổn | K4: Xe hỗ trợ: giá trị chiến đấu thấp là đúng.
A6: ammo_carrier | B6: Xe tiếp đạn | C6: Support | D6: 4 | E6: 4 | F6: 12.5 | G6: 1.25 | H6: 0 | I6: 0 | J6: Ổn | K6: Xe hỗ trợ: giá trị chiến đấu thấp là đúng.
A8: ew_jammer | B8: Xe tác chiến điện tử | C8: Support | D8: 5 | E8: 5 | F8: 10 | G8: 1 | H8: 0 | I8: 0 | J8: Ổn | K8: Xe hỗ trợ: giá trị chiến đấu thấp là đúng.
A9: mine_layer | B9: Xe rải mìn | C9: Support | D9: 5 | E9: 5 | F9: 10 | G9: 1 | H9: 102 | I9: 0.62 | J9: Ổn | K9: Xe hỗ trợ: giá trị chiến đấu thấp là đúng.
A10: command_vehicle | B10: Xe chỉ huy | C10: Support | D10: 6 | E10: 6 | F10: 8.4 | G10: 0.83 | H10: 0 | I10: 0 | J10: Ổn | K10: Xe hỗ trợ: giá trị chiến đấu thấp là đúng.
A11: shield_carrier | B11: Xe phát khiên | C11: Support | D11: 7 | E11: 7 | F11: 7.2 | G11: 0.71 | H11: 0 | I11: 0 | J11: Ổn | K11: Xe hỗ trợ: giá trị chiến đấu thấp là đúng.
A12: scout_jeep | B12: Xe trinh sát | C12: Scout | D12: 2 | E12: 2 | F12: 25.1 | G12: 0.15 | H12: 84 | I12: 1.04 | J12: Ổn | K12: Trinh sát: đo bằng tầm nhìn và thời gian sống, không phải DPS.
A13: vbied | B13: Xe bom tự sát bọc thép | C13: Scout | D13: 3 | E13: 3 | F13: 308 | G13: 1.85 | H13: 78 | I13: 0.96 | J13: Ổn | K13: Trinh sát: đo bằng tầm nhìn và thời gian sống, không phải DPS.
A14: light_tank | B14: Tăng hạng nhẹ | C14: Tank | D14: 3 | E14: 3 | F14: 13 | G14: 1 | H14: 222 | I14: 0.48 | J14: Ổn | K14: Trong khoảng mục tiêu.
A15: flame_tank | B15: Tăng phun lửa | C15: Heavy | D15: 5 | E15: 5 | F15: 14.3 | G15: 1.18 | H15: 258 | I15: 0.66 | J15: Ổn | K15: Trong khoảng mục tiêu.
... A56: laser_tank | B56: Xe la-de tập trung | C56: TankHunter | D56: 10 | E56: 9 | F56: 11.7 | G56: 1.1 | H56: 372 | I56: 0.8 | J56: Ổn | K56: Trong khoảng mục tiêu.
A57: Ngoài đời · kiểm tra lại | B57: — | C57: — | J57: Còn lại | K57: Sau khi áp đợt 1: (1) tên lửa phòng không nhanh hơn mọi máy bay; (2) mọi đạn cùng loại cùng tốc độ và bán kính; (3) nhịp bắn các pháo CIWS và cao xạ đã thành luồng; (4) các xe bỏ súng máy không có thật (Buk, Iskander, Smerch, HIMARS) cần hộ tống — theo dõi tỷ lệ bị xe nhẹ áp sát diệt; (5) kích thước đổi theo tỷ lệ 0,8/0,4 phải chạy lại test xe kẹt và vùng va chạm; (6) máu boss mới là máu gốc trước scale chiến dịch.

Sheet Việc cho agent
A1: Mã | B1: Nhóm | C1: Việc | D1: Sheet nguồn | E1: Tiêu chí đạt | F1: Ưu tiên
A2: A1 | B2: Dữ liệu | C2: Áp mọi dòng của sheet Thay đổi chi tiết vào balance.json theo thứ tự ưu tiên Cao → Trung → Thấp; mỗi nhóm một commit. | D2: Thay đổi chi tiết | E2: Test cũ pass; bảng 9 và 9b tạo lại từ dữ liệu mới | F2: Cao
A3: A2 | B3: Dữ liệu | C3: Áp các cột "đề xuất" của sheet Vũ khí đề xuất (sát thương, chế độ, viên/s, băng/loạt, nạp, tầm, tốc độ, nổ lan, xuyên). | D3: Vũ khí đề xuất | E3: DPS duy trì trong game khớp cột DPS đề xuất ±5% | F3: Cao
A4: A3 | B4: Dữ liệu | C4: Thống nhất mọi vũ khí cùng loại (cùng tên thật) về cùng tốc độ bay, bán kính nổ, model đạn; gom thành "họ vũ khí" trong dữ liệu để sửa một chỗ. | D4: Tốc độ tên lửa, Vũ khí đề xuất | E4: Test quét: không có hai vũ khí cùng tên thật khác tốc độ hoặc bán kính | F4: Cao
A5: A4 | B5: Hệ thống | C5: Luật tên lửa phòng không: tốc độ ≥ 1,3 × mục tiêu nhanh nhất; test tự động bắn tiêm kích và drone hộ vệ ở tầm tối đa. | D5: Tốc độ tên lửa | E5: Tỷ lệ trúng khi không có pháo sáng ≥ 90% | F5: Cao
A6: A5 | B6: Hệ thống | C6: Bán kính nổ tính từ khối lượng thuốc nổ (luật ở Tổng quan) và hiệu ứng nổ trên màn hình bằng đúng bán kính gây sát thương. | D6: Tổng quan, Vũ khí đề xuất | E6: Test so hiệu ứng với bán kính | F6: Trung
A7: B1 | B7: Model | C7: Đổi kích thước theo tỷ lệ chung (mặt đất 0,8, trên không 0,4) cho các dòng "Kích thước" cần đổi; cập nhật vùng va chạm; chạy lại test xe kẹt trên mọi map. | D7: Kiểm tra từng mục | E7: Không xe kẹt; thứ tự to nhỏ đúng trong cùng lớp | F7: Cao
A8: B2 | B8: Model | C8: Dựng lại model theo cột Hình dạng và sheet Hướng dẫn vẽ; ưu tiên: Tăng chủ lực, Su-27, máy bay mẹ (cùng khung với pháo hạm), Apache, Icarus, Daedalus. | D8: Phương tiện, Boss, Hướng dẫn vẽ | E8: Ảnh bóng từ trên xuống nhận ra được; lưu ảnh trước/sau | F8: Trung
A9: B3 | B9: Model | C9: Model đạn riêng cho Kh-29L và GBU-39 SDB; đạn 203 mm dùng tỷ lệ 1,3; kích thước đạn theo sheet Kích thước đạn. | D9: Kích thước đạn | E9: Không vũ khí nào dùng nhầm model | F9: Thấp
A10: C1 | B10: Boss | C10: Áp máu và DPS theo sheet Boss đề xuất; chỉ boss chủ lực có siêu vũ khí; bỏ đòn lớn của mini boss. | D10: Boss đề xuất | E10: Test: mini boss không có siêu vũ khí; chu kỳ siêu vũ khí đúng; thời lượng trận trong mục tiêu | F10: Cao
A11: C2 | B11: Boss | C11: Hiển thị vũ khí chính còn thiếu (pháo 80 cm của Gungnir, bánh gầu của Kronos) trong dữ liệu và tài liệu. | D11: Boss | E11: Có trong bảng vũ khí | F11: Thấp
A12: D1 | B12: Tên | C12: Áp sheet Tên đề xuất vào localization (tên đầy đủ, tên ngắn, tiếng Anh); một đơn vị một tên ở mọi bảng. | D12: Tên đề xuất | E12: Test quét: không còn tên cũ, không có hai tên cho một id | F12: Trung
... A18: F2 | B18: Nội dung mới | C18: Làm theo thứ tự ưu tiên: công trình Cao (Tường chắn đạn, Mồi nhử, Trung tâm điều khiển hỏa lực, Ụ pháo chống tăng, Flak 88) rồi thẻ hỗ trợ mới rồi xe mới. | D18: Công trình mới, Thẻ hỗ trợ mới, Đề xuất thêm | E18: Mỗi thứ mới có test hành vi, thẻ Hướng dẫn, model | F18: Thấp

Sheet Phương tiện
A1: id | B1: Tên | C1: Lớp | D1: Miêu tả | E1: Hình dạng (cho AI vẽ) | F1: Mở khóa hiện tại | G1: Mở khóa đề xuất | H1: Mua sớm | I1: CP | J1: Máu | K1: Giáp T/H/S/N | L1: Tốc độ (m/s) | M1: Tầm nhìn (m) | N1: DPS nhẹ | O1: DPS nặng | P1: DPS bay | Q1: DPS công trình | R1: DPS nặng / CP | S1: Máu / CP | T1: Giá trị vs xe nhẹ | U1: vs xe tăng | V1: vs công sự | W1: vs máy bay | X1: vs tăng + PK | Y1: Thời gian bắn | Z1: Sống (s) | AA1: Hiệu quả so với trung vị vai trò | AB1: Tham khảo (ngoài đời / game) | AC1: Mạnh với | AD1: Yếu trước | AE1: Cách đánh | AF1: Hành vi | AG1: Vũ khí | AH1: Đề xuất | AI1: Lý do thay đổi | AJ1: Ưu tiên
A2: hover_gunboat | B2: Xuồng cao tốc đệm khí | C2: Xe nhẹ | D2: pháo 30 mm sáu nòng trên thân đệm khí nhỏ; nó chạy cạnh tàu đệm khí đổ bộ trên cả đất liền lẫn mặt nước. nhanh, khó bắt, nhưng giáp mỏng: xe tăng hay pháo tự động nào cũng hạ được. | E2: Thân xuồng đệm khí thấp, váy cao su đen quanh đáy, 2 quạt đẩy lớn phía sau trong vòng bảo vệ, tháp pháo 6 nòng nhỏ phía trước. Từ trên xuống: hình giọt nước, hai vòng quạt tròn ở đuôi. Kích thước hiện 14.0 × 3.9 × 4.4 m. Vũ khí nhìn thấy: AK-630 30 mm. Vạch màu phe trên nóc và hai hông; không dùng phù hiệu, cờ hay logo quốc gia thật. | F2: thắng màn mở khóa trong chiến dịch, hoặc mua sớm 300 xu | G2: Không mở (hộ tống boss) | H2: — | I2: 0 | J2: 1144 | K2: 1/0/0/0 | L2: 8.5 | M2: 46 | N2: 22 | O2: 11 | P2: 7 | Q2: 11 | R2: =IFERROR(O2/I2,"") | S2: =IFERROR(J2/I2,"") | AB2: tàu tấn công nhanh vỏ lướt, AK-630 30 mm — Xuồng pháo hộ tống tàu đệm khí | AC2: giáp 0, giáp 1, giáp 2 | AD2: súng máy hạng nặng, lửa, pháo tự động, nổ mạnh, năng lượng, đánh nóc, nổ lõm, pháo xe tăng | AE2: pháo 30 mm sáu nòng trên thân đệm khí nhỏ; nó chạy cạnh tàu đệm khí đổ bộ trên cả đất liền lẫn mặt nước. | AF2: Vừa chạy vừa bắn; Bắn hết 15 viên thì thay băng; Xe bọc thép | AG2: AK-630 30 mm [Động năng, xuyên 2, đạn pháo động năng (pháo tự động)] 22/phát · băng 15 viên, 60 viên/s, thay 14.71 s · tầm 34 m · Tất cả | AH2: • Vũ khí: AK-630 30 mm: 12/phát · 60 viên/s · băng 60 · nạp 5 s · DPS duy trì ~85 | AI2: • Vũ khí: AK-630 30 mm: Bắn 0,25 s rồi im 14,7 s: không giống CIWS, và hộ tống boss gần như vô hại. | AJ2: Thấp
A3: armored_car | B3: Xe bọc thép | C3: Xe nhẹ | D3: pháo 25 mm vừa chạy vừa bắn cả đất lẫn trời, mạnh nhất với xe nhẹ và trực thăng; chiếm cứ điểm nhanh gấp đôi. thắng trinh sát, pháo binh, xe phòng không và xe hỗ trợ; đạn nảy khỏi xe tăng và tháp canh nên thua chúng. | E3: Xe 6 bánh lộ ngoài, thân hình hộp vát nghiêng phía trước, tháp pháo nhỏ ở giữa với nòng 25 mm dài. Từ trên xuống: chữ nhật hẹp, 3 cặp bánh nhô ra hai bên, tháp tròn giữa thân. Kích thước đề xuất khoảng 4.6 × 2.0 × 1.4 m (dài × rộng × cao; 0,8 × mẫu thật Pandur I 6x6). Vũ khí nhìn thấy: M242 Bushmaster 25 mm, PKT / M240 7.62 mm. Vạch màu phe trên nóc và hai hông; không dùng phù hiệu, cờ hay logo quốc gia thật. | F3: có sẵn từ đầu | G3: Có sẵn | H3: — | I3: 3 | J3: 660 | K3: 1/0/0/0 | L3: 11.5 | M3: 36 | N3: 78 | O3: 32 | P3: 12 | Q3: 35 | R3: =IFERROR(O3/I3,"") | S3: =IFERROR(J3/I3,"") | T3: 207 | U3: 69 | V3: 43 | W3: 2 | X3: 84 | Y3: 59% | Z3: 22 | AA3: 0.88 | AB3: Pandur I 6x6, M242 Bushmaster 25 mm — ước đoán: xe bọc thép 6x6 bánh lộ ngoài, tháp pháo tự động nhỏ | AC3: giáp 0, giáp 1, giáp 2 | AD3: súng máy hạng nặng, lửa, pháo tự động, nổ mạnh, năng lượng, đánh nóc, nổ lõm, pháo xe tăng | AE3: pháo 25 mm vừa chạy vừa bắn cả đất lẫn trời, mạnh nhất với xe nhẹ và trực thăng; chiếm cứ điểm nhanh gấp đôi. | AF3: Vừa chạy vừa bắn; Bắn hết 19 viên thì thay băng; Xe chiến đấu bộ binh | AG3: M242 Bushmaster 25 mm [Động năng, xuyên 2, đạn pháo động năng (pháo tự động)] 17/phát · băng 19 viên, 4 viên/s, thay 1 s · tầm 30 m · Mặt đất PKT / M240 7.62 mm [Động năng, xuyên 0, đạn súng] 6/phát · băng 41 viên, 12 viên/s, thay 1.59 s · tầm 20 m · Tất cả | AH3: • Tầm nhìn: 42 m | AI3: • Tầm nhìn: Xe bánh lốp trinh sát đi trước tuyến; hiện nhìn kém cả xuồng (46). | AJ3: Thấp
A4: ifv | B4: Xe chiến đấu bộ binh | C4: Xe nhẹ | D4: pháo tự động vừa chạy vừa bắn xe nhẹ và máy bay, kèm tên lửa chống tăng TOW (34 m) cho xe tăng; chiếm cứ điểm nhanh gấp 3, thắng trinh sát, xe nhẹ, pháo binh và phòng không, gây sát thương cả xe tăng; đấu tay đôi với tăng vẫn thua. | E4: Xe xích 6 bánh chịu lực, thân cao hơn tăng, tháp lệch trái có nòng 30 mm ngắn và hộp phóng TOW gắn bên hông tháp, cửa đuôi lớn. Từ trên xuống: thân chữ nhật, hộp tên lửa vuông bên hông tháp. Kích thước đề xuất khoảng 5.2 × 2.9 × 2.4 m (dài × rộng × cao; 0,8 × mẫu thật M2 Bradley). Vũ khí nhìn thấy: 2A42 30 mm, PKT / M240 7.62 mm, BGM-71 TOW-2. Vạch màu phe trên nóc và hai hông; không dùng phù hiệu, cờ hay logo quốc gia thật. | F4: có sẵn từ đầu | G4: Có sẵn | H4: — | I4: 6 | J4: 1144 | K4: 2/1/0/0 | L4: 9 | M4: 34 | N4: 136 | O4: 67 | P4: 12 | Q4: 66 | R4: =IFERROR(O4/I4,"") | S4: =IFERROR(J4/I4,"") | T4: 238 | U4: 110 | V4: 53 | W4: 1 | X4: 129 | Y4: 51% | Z4: 32 | AA4: 1.12 | AB4: M2 Bradley, BMP-3, 2A42 30 mm, BGM-71 TOW-2 — Xe chiến đấu bộ binh bánh xích, pháo 30 mm và bệ TOW | AC4: giáp 0, giáp 1, giáp 2, giáp 3, giáp 4, công trình | AD4: lửa, pháo tự động, nổ mạnh, năng lượng, đánh nóc, nổ lõm, pháo xe tăng | AE4: pháo tự động vừa chạy vừa bắn xe nhẹ và máy bay, kèm tên lửa chống tăng TOW (34 m) cho xe tăng; chiếm cứ điểm nhanh gấp 3, | AF4: Vừa chạy vừa bắn; Bắn hết 26 viên thì thay băng; Khói: khi bị bắn (mỗi 30 giây); Hỗ trợ (9); Xe tiếp tế | AG4: 2A42 30 mm [Động năng, xuyên 2, đạn pháo động năng (pháo tự động)] 22/phát · băng 26 viên, 5 viên/s, thay 1 s · tầm 30 m · Mặt đất PKT / M240 7.62 mm [Động năng, xuyên 0, đạn súng] 6/phát · băng 41 viên, 12 viên/s, thay 1.59 s · tầm 20 m · Tất cả BGM-71 TOW-2 [Nổ lõm, xuyên 4, tên lửa chống tăng dẫn đường] 190/phát · hồi 12.33 s · tầm 34 m · Mặt đất | AH4: • Vũ khí: 2A42 30 mm: 22/phát · loạt 10 viên ở 9 viên/s · nghỉ 1,5 s · DPS duy trì giữ ~94 • Vũ khí: TOW-2: tầm 40 m · tốc độ 20 (bay 2,0 s tới tầm tối đa) | AI4: • Vũ khí: 2A42 30 mm: Ngoài đời 2A42 bắn loạt nhanh; cảm giác "xả loạt" khác súng máy. • Vũ khí: TOW-2: Tên lửa chống tăng phải bắn xa hơn pháo xe tăng (34 m), nếu không thì không có lý do mang. | AJ4: Trung
A5: supply_truck | B5: Xe tiếp tế | C5: Hỗ trợ | D5: chỉ có súng máy nhẹ; nó chạy theo lộ trình tới kho và không chiếm được cứ điểm. đủ giáp để chịu vài phát, nhưng không đánh lại được thứ gì đáng kể. | E5: Xe tải 8 bánh, ca-bin phía trước, thùng hàng phủ bạt với thùng gỗ và thùng đạn nhìn thấy, súng máy trên vòng nóc ca-bin. Từ trên xuống: dài, ca-bin nhỏ, thùng hàng chiếm 2/3. Kích thước đề xuất khoảng 8.2 × 2.0 × 2.1 m (dài × rộng × cao; 0,8 × mẫu thật M977 HEMTT). Vũ khí nhìn thấy: M2 Browning 12.7 mm. Vạch màu phe trên nóc và hai hông; không dùng phù hiệu, cờ hay logo quốc gia thật. | F5: thắng màn mở khóa trong chiến dịch, hoặc mua sớm 300 xu | G5: Nhiệm vụ (không vào bộ bài) | H5: — | I5: 0 | J5: 1540 | K5: cấp 0 (Không giáp) | L5: 3.6 | M5: 26 | N5: 46 | O5: 14 | P5: 16 | Q5: 16 | R5: =IFERROR(O5/I5,"") | S5: =IFERROR(J5/I5,"") | AB5: M977 HEMTT, KamAZ-5350, M2 Browning 12,7 mm — ước đoán: xe tải tiếp tế, súng máy trên vòng nóc | AC5: giáp 0, giáp 1 | AD5: súng bộ binh, súng máy hạng nặng, lửa, mảnh, pháo tự động, nổ mạnh, năng lượng, nổ lõm, pháo xe tăng | AE5: chỉ có súng máy nhẹ; nó chạy theo lộ trình tới kho và không chiếm được cứ điểm. | AF5: Đi sau tuyến đầu, cạnh các xe nó phục vụ; Bắn hết 28 viên thì thay băng; Xe công binh | AG5: M2 Browning 12.7 mm [Động năng, xuyên 1, đạn súng (cỡ lớn)] 10/phát · băng 28 viên, 9 viên/s, thay 1.94 s · tầm 22 m · Tất cả | AH5: Giữ. | AI5: Xe hỗ trợ, chưa có chỉ số đo; giữ. | AJ5: Thấp
A6: engineer_vehicle | B6: Xe công binh | C6: Hỗ trợ | D6: chỉ có súng máy nóc; sửa chữa xe ta trong vòng 14 m (2,5% máu mỗi giây) và tháp ta chậm bằng nửa, gỡ mìn nó thấy, phá vật cản giúp tuyến xe tăng và căn cứ đang giữ trụ lâu hơn hẳn; tự đánh thì yếu, trinh sát và xe bọc thép dễ bắt nạt nó. | E6: Khung xe tăng không tháp, cần cẩu gập trên nóc, lưỡi ủi phía trước. Từ trên xuống: cần cẩu chéo dọc thân, lưỡi ủi rộng hơn thân. Kích thước đề xuất khoảng 6.9 × 3.0 × 2.6 m (dài × rộng × cao; 0,8 × mẫu thật M88A2 / BREM-1). Vũ khí nhìn thấy: M2 Browning 12.7 mm. Vạch màu phe trên nóc và hai hông; không dùng phù hiệu, cờ hay logo quốc gia thật. | F6: thắng màn mở khóa trong chiến dịch, hoặc mua sớm 750 xu | G6: Chương 1 | H6: 300 xu | I6: 3 | J6: 1760 | K6: 2/1/0/0 | L6: 7 | M6: 30 | N6: 46 | O6: 13 | P6: 16 | Q6: 16 | R6: =IFERROR(O6/I6,"") | S6: =IFERROR(J6/I6,"") | T6: 0 | U6: 0 | V6: 0 | W6: 0 | X6: 0 | Y6: 0% | Z6: 90 | AB6: BREM-1, M88 Hercules — Xe cứu kéo công binh có lưỡi ủi và cần cẩu | AC6: giáp 0, giáp 1 | AD6: lửa, pháo tự động, nổ mạnh, năng lượng, đánh nóc, nổ lõm, pháo xe tăng | AE6: chỉ có súng máy nóc; sửa chữa xe ta trong vòng 14 m (2,5% máu mỗi giây) và tháp ta chậm bằng nửa, gỡ mìn nó thấy, phá vật cản | AF6: Đi sau tuyến đầu, cạnh các xe nó phục vụ; Bắn hết 28 viên thì thay băng; Sửa xe ta trong 14 m (2,5% máu mỗi giây; tháp một nửa); Xe tạo khói | AG6: M2 Browning 12.7 mm [Động năng, xuyên 1, đạn súng (cỡ lớn)] 10/phát · băng 28 viên, 9 viên/s, thay 2.02 s · tầm 15 m · Tất cả | AH6: Giữ. | AI6: Xe hỗ trợ, chưa có chỉ số đo; giữ. | AJ6: Thấp
A8: ammo_carrier | B8: Xe tiếp đạn | C8: Hỗ trợ | D8: chỉ có súng máy nóc; bệ phóng và xe tên lửa hết đạn trong vòng 14 m nạp nhanh gấp ba, trực thăng trong vòng 12 m hồi tên lửa và giữ pháo phản lực và trực thăng bắn liên tục; giáp mỏng và nổ rất mạnh, nên giữ xa chỗ giao tranh. | E8: Xe tải 8 bánh chở giá đạn kim loại mở, thùng đạn xếp tầng màu ô-liu, cần cẩu nhỏ phía sau. Từ trên xuống: các thùng đạn xếp lưới. Kích thước đề xuất khoảng 8.2 × 2.0 × 2.1 m (dài × rộng × cao; 0,8 × mẫu thật M977 HEMTT). Vũ khí nhìn thấy: M2 Browning 12.7 mm. Vạch màu phe trên nóc và hai hông; không dùng phù hiệu, cờ hay logo quốc gia thật. | F8: thắng màn mở khóa trong chiến dịch, hoặc mua sớm 900 xu | G8: Chương 2 | H8: 300 xu | I8: 4 | J8: 1144 | K8: cấp 0 (Không giáp) | L8: 8.5 | M8: 30 | N8: 46 | O8: 13 | P8: 16 | Q8: 16 | R8: =IFERROR(O8/I8,"") | S8: =IFERROR(J8/I8,"") | T8: 0 | U8: 0 | V8: 0 | W8: 0 | X8: 0 | Y8: 0% | Z8: 90 | AB8: M977 HEMTT, KamAZ-5350, M2 Browning 12,7 mm — ước đoán: xe tải hậu cần chở đạn, súng máy trên vòng nóc | AC8: giáp 0, giáp 1 | AD8: súng bộ binh, súng máy hạng nặng, lửa, mảnh, pháo tự động, nổ mạnh, năng lượng, nổ lõm, pháo xe tăng | AE8: chỉ có súng máy nóc; bệ phóng và xe tên lửa hết đạn trong vòng 14 m nạp nhanh gấp ba, trực thăng trong vòng 12 m hồi tên lửa và | AF8: Đi sau tuyến đầu, cạnh các xe nó phục vụ M2; Bắn hết 28 viên thì thay băng Sá; Xe phóng trong 14 m được thêm một phát mỗi 4 giây ngoài tốc độ nạp của nó Bă; Trực thăng trong 12 m hồi đạn nhanh gấp 2 lần Tầ; M2; Radar phản pháo | AG8: M2 Browning 12.7 mm [Động năng, xuyên 1, đạn súng (cỡ lớn)] 10/phát · băng 28 viên, 9 viên/s, thay 2.02 s · tầm 15 m · Tất cả | AH8: Giữ. | AI8: Xe hỗ trợ, chưa có chỉ số đo; giữ. | AJ8: Thấp
A10: ew_jammer | B10: Xe tác chiến điện tử | C10: Hỗ trợ | D10: chỉ có súng máy nóc; tên lửa, drone và hỏa lực yểm trợ của địch nhắm vào vùng gây nhiễu 32 m đều bị lệch. khắc chế xe tên lửa chống tăng, xe drone, trực thăng và đòn yểm trợ địch; vô dụng trước súng và đạn pháo thường. | E10: Xe tải 8 bánh mang đĩa ăng-ten lớn hình chảo hoặc cột ăng-ten lưới cao, thân phẳng. Từ trên xuống: chảo tròn lớn. Kích thước đề xuất khoảng 8.8 × 2.4 × 3.2 m (dài × rộng × cao; 0,8 × mẫu thật Krasukha-4 (BAZ-6910)). Vũ khí nhìn thấy: M2 Browning 12.7 mm. Vạch màu phe trên nóc và hai hông; không dùng phù hiệu, cờ hay logo quốc gia thật. | F10: thắng màn mở khóa trong chiến dịch, hoặc mua sớm 1.050 xu | G10: Chương 5 | H10: 800 xu | I10: 5 | J10: 836 | K10: 1/0/0/0 | L10: 8 | M10: 40 | N10: 46 | O10: 13 | P10: 16 | Q10: 16 | R10: =IFERROR(O10/I10,"") | S10: =IFERROR(J10/I10,"") | T10: 0 | U10: 0 | V10: 0 | W10: 0 | X10: 0 | Y10: 0% | Z10: 90 | AB10: Krasukha-4, Leer-3 — Xe tác chiến điện tử 6x6, cột ăng-ten gây nhiễu | AC10: giáp 0, giáp 1 | AD10: súng máy hạng nặng, lửa, pháo tự động, nổ mạnh, năng lượng, đánh nóc, nổ lõm, pháo xe tăng | AE10: chỉ có súng máy nóc; tên lửa, drone và hỏa lực yểm trợ của địch nhắm vào vùng gây nhiễu 32 m đều bị lệch. | AF10: Đi sau tuyến đầu, cạnh các xe nó phục vụ M; Bắn hết 28 viên thì thay băng S; Gây nhiễu vũ khí dẫn đường và hỏa lực yểm trợ địch trong 32 m B; T; M; Xe rải mìn | AG10: M2 Browning 12.7 mm [Động năng, xuyên 1, đạn súng (cỡ lớn)] 10/phát · băng 28 viên, 9 viên/s, thay 2.02 s · tầm 15 m · Tất cả | AH10: Giữ. | AI10: Xe hỗ trợ, chưa có chỉ số đo; giữ. | AJ10: Thấp
A11: mine_layer | B11: Xe rải mìn | C11: Hỗ trợ | D11: có súng máy nóc; khi chạy, cứ 6 giây thả một quả mìn chống tăng (tối đa 8), xe địch cán phải là nổ tung. trừng phạt xe tăng và đoàn xe đi theo một lối; xe tăng rùa có trục lăn phá mìn, máy bay thì không sợ. | E11: Khung xích thấp, máng thả mìn nghiêng ở đuôi, thùng mìn xếp trên nóc. Từ trên xuống: máng dài ở sau. Kích thước đề xuất khoảng 7.4 × 2.6 × 2.0 m (dài × rộng × cao; 0,8 × mẫu thật GMZ-3). Vũ khí nhìn thấy: M2 Browning 12.7 mm. Vạch màu phe trên nóc và hai hông; không dùng phù hiệu, cờ hay logo quốc gia thật. | F11: thắng màn mở khóa trong chiến dịch, hoặc mua sớm 1.050 xu | G11: Chương 3 | H11: 300 xu | I11: 5 | J11: 924 | K11: 1/0/0/0 | L11: 8 | M11: 30 | N11: 46 | O11: 13 | P11: 16 | Q11: 16 | R11: =IFERROR(O11/I11,"") | S11: =IFERROR(J11/I11,"") | T11: 102 | U11: 77 | V11: 9 | W11: 7 | X11: 102 | Y11: 51% | Z11: 28 | AA11: 0.62 | AB11: GMZ-3, MT-LB — Xe rải mìn bánh xích, máng thả mìn phía sau | AC11: giáp 0, giáp 1 | AD11: súng máy hạng nặng, lửa, pháo tự động, nổ mạnh, năng lượng, đánh nóc, nổ lõm, pháo xe tăng | AE11: có súng máy nóc; khi chạy, cứ 6 giây thả một quả mìn chống tăng (tối đa 8), xe địch cán phải là nổ tung. | AF11: Đi sau tuyến đầu, cạnh các xe nó phục vụ M; Bắn hết 28 viên thì thay băng S; Rải một quả mìn mỗi 6 giây (tối đa 8) B; T; M; Xe chỉ huy | AG11: M2 Browning 12.7 mm [Động năng, xuyên 1, đạn súng (cỡ lớn)] 10/phát · băng 28 viên, 9 viên/s, thay 2.02 s · tầm 15 m · Tất cả | AH11: Giữ. | AI11: Giá trị thực chiến nằm trong khoảng mục tiêu (hiệu quả 0.62 × trung vị vai trò). | AJ11: Thấp
A12: command_vehicle | B12: Xe chỉ huy | C12: Hỗ trợ | D12: chỉ có súng máy trên nóc; quân ta trong 25 m bắn nhanh hơn 10%; đứng yên 5 giây là thành bãi thả dù tiền tuyến, quân mới đáp làm mọi cụm quân quanh nó mạnh hơn và đưa quân tiếp viện ra tận tiền tuyến; thứ gì với tới cũng hạ nó nhanh. | E12: Xe 8 bánh, thân cao, nhiều cột ăng-ten roi và một cột kính viễn vọng gập, lều chỉ huy gắn sau. Từ trên xuống: nhiều chấm ăng-ten, cột dài nằm dọc. Kích thước đề xuất khoảng 5.6 × 2.2 × 2.1 m (dài × rộng × cao; 0,8 × mẫu thật Stryker CV). Vũ khí nhìn thấy: M2 Browning 12.7 mm. Vạch màu phe trên nóc và hai hông; không dùng phù hiệu, cờ hay logo quốc gia thật. | F12: thắng màn mở khóa trong chiến dịch, hoặc mua sớm 1.200 xu | G12: Chương 4 | H12: 800 xu | I12: 6 | J12: 1232 | K12: 2/1/0/0 | L12: 8 | M12: 44 | N12: 46 | O12: 13 | P12: 16 | Q12: 16 | R12: =IFERROR(O12/I12,"") | S12: =IFERROR(J12/I12,"") | T12: 0 | U12: 0 | V12: 0 | W12: 0 | X12: 0 | Y12: 0% | Z12: 90 | AB12: M1130 Stryker CV, BTR-80 KShM, LAV-C2 — Xe chỉ huy 8x8, cột ăng-ten kính viễn vọng gập | AC12: giáp 0, giáp 1 | AD12: lửa, pháo tự động, nổ mạnh, năng lượng, đánh nóc, nổ lõm, pháo xe tăng | AE12: chỉ có súng máy trên nóc; quân ta trong 25 m bắn nhanh hơn 10%; đứng yên 5 giây là thành bãi thả dù tiền tuyến, quân mới đáp | AF12: Đi sau tuyến đầu, cạnh các xe nó phục vụ; Bắn hết 28 viên thì thay băng; Xe phát khiên | AG12: M2 Browning 12.7 mm [Động năng, xuyên 1, đạn súng (cỡ lớn)] 10/phát · băng 28 viên, 9 viên/s, thay 2.02 s · tầm 15 m · Tất cả | AH12: Giữ. | AI12: Xe hỗ trợ, chưa có chỉ số đo; giữ. | AJ12: Thấp
A13: shield_carrier | B13: Xe phát khiên | C13: Hỗ trợ | D13: vòm khiên 12 m quanh xe hấp thụ 1.000 sát thương từ đạn pháo, đạn súng, bom và tên lửa cho mọi đơn vị phe ta bên trong, rồi vỡ; giúp tuyến xe tăng áp sát dưới làn đạn; vũ khí năng lượng xuyên thẳng qua, nhiều vòm không cộng dồn, và bản thân xe giáp mỏng. | E13: Xe 8 bánh mang bệ phát khiên hình vòm/kim loại có vòng phát sáng màu phe; khi hoạt động có vòm bán trong suốt 12 m. Từ trên xuống: đĩa tròn phát sáng giữa thân. Kích thước đề xuất khoảng 6.3 × 2.4 × 1.9 m (dài × rộng × cao; 0,8 × mẫu thật Boxer 8x8 (khung)). Vũ khí nhìn thấy: M2 Browning 12.7 mm. Vạch màu phe trên nóc và hai hông; không dùng phù hiệu, cờ hay logo quốc gia thật. | F13: thắng màn mở khóa trong chiến dịch, hoặc mua sớm 1.350 xu | G13: Xen kẽ II | H13: 1.500 xu | I13: 7 | J13: 1056 | K13: 1/0/0/0 | L13: 8.5 | M13: 36 | N13: 46 | O13: 13 | P13: 16 | Q13: 16 | R13: =IFERROR(O13/I13,"") | S13: =IFERROR(J13/I13,"") | T13: 0 | U13: 0 | V13: 0 | W13: 0 | X13: 0 | Y13: 0% | Z13: 90 | AB13: xe 8x8 kiểu Boxer / Stryker · Shield Battery (StarCraft II), Bubble Shield (Halo 3) — ước đoán: xe 8x8 mang máy phát khiên năng lượng | AC13: giáp 0, giáp 1 | AD13: súng máy hạng nặng, lửa, pháo tự động, nổ mạnh, năng lượng, đánh nóc, nổ lõm, pháo xe tăng | AE13: vòm khiên 12 m quanh xe hấp thụ 1.000 sát thương từ đạn pháo, đạn súng, bom và tên lửa cho mọi đơn vị phe ta bên trong, rồi vỡ; | AF13: Đi sau tuyến đầu, cạnh các xe nó phục vụ; Bắn hết 28 viên thì thay băng; Vòm khiên 12 m: hấp thụ 1000 sát thương cho phe ta bên trong (trừ năng lượng), hồi lại 20; giây sau đòn cuối; các vòm không cộng dồn; Trinh sát (2); Xe trinh sát | AG13: M2 Browning 12.7 mm [Động năng, xuyên 1, đạn súng (cỡ lớn)] 10/phát · băng 28 viên, 9 viên/s, thay 2.02 s · tầm 15 m · Tất cả | AH13: Giữ. | AI13: Xe hỗ trợ, chưa có chỉ số đo; giữ. | AJ13: Thấp
A14: scout_jeep | B14: Xe trinh sát | C14: Trinh sát | D14: súng máy tầm gần, vừa chạy vừa bắn. Nhìn xa để phát hiện địch cho cả quân, chiếm cứ điểm nhanh gấp đôi. diệt được pháo binh và xe hỗ trợ đi lẻ; thua mọi xe bọc thép, xe tăng và tháp canh. | E14: Xe 4x4 mui trần nhỏ, khung chống lật, súng máy trên chốt giữa, can nhiên liệu sau. Từ trên xuống: nhỏ nhất game, thấy rõ người lái và súng. Kích thước đề xuất khoảng 2.7 × 1.3 × 1.4 m (dài × rộng × cao; 0,8 × mẫu thật M151 / LRV). Vũ khí nhìn thấy: M2 Browning 12.7 mm. Vạch màu phe trên nóc và hai hông; không dùng phù hiệu, cờ hay logo quốc gia thật. | F14: có sẵn từ đầu | G14: Có sẵn | H14: — | I14: 2 | J14: 264 | K14: cấp 0 (Không giáp) | L14: 12 | M14: 35 | N14: 46 | O14: 14 | P14: 16 | Q14: 16 | R14: =IFERROR(O14/I14,"") | S14: =IFERROR(J14/I14,"") | T14: 84 | U14: 9 | V14: 7 | W14: 3 | X14: 19 | Y14: 34% | Z14: 12 | AA14: 1.04 | AB14: M151 MUTT, Land Rover WMIK, M2 Browning 12,7 mm — ước đoán: xe trinh sát 4x4 mui trần gắn súng máy trên chốt | AC14: giáp 0, giáp 1 | AD14: súng bộ binh, súng máy hạng nặng, lửa, mảnh, pháo tự động, nổ mạnh, năng lượng, nổ lõm, pháo xe tăng | AE14: súng máy tầm gần, vừa chạy vừa bắn. Nhìn xa để phát hiện địch cho cả quân, chiếm cứ điểm nhanh gấp đôi. | AF14: Vừa chạy vừa bắn; Bắn hết 28 viên thì thay băng; Xe bom tự sát bọc thép | AG14: M2 Browning 12.7 mm [Động năng, xuyên 1, đạn súng (cỡ lớn)] 10/phát · băng 28 viên, 9 viên/s, thay 1.94 s · tầm 22 m · Tất cả | AH14: • Tầm nhìn: 55 m • Hành vi: Ẩn khi đứng yên (chỉ lộ ở 60% tầm nhìn địch), lộ khi bắn | AI14: • Tầm nhìn: Trinh sát đang nhìn kém xe bọc thép; không làm được việc trinh sát. • Hành vi: Trinh sát thật dựa vào ngụy trang và đứng quan sát. | AJ14: Cao
A15: vbied | B15: Xe bom tự sát bọc thép | C15: Trinh sát | D15: lao thẳng vào địch rồi tự nổ: 700 sát thương trong bán kính 7,5 m, một nửa lên tháp và công trình. Bị bắn hạ giữa đường thì nổ phá nát pháo binh, xe hỗ trợ và cụm xe nhẹ; súng bắn nhanh và xe bọc thép chặn được nó, và căn cứ chịu được cả dòng xe bom. | E15: Bán tải dân sự hàn tấm thép chắp vá phủ gần kín, khe nhìn nhỏ, tấm thép mặt trước dày hơn, không vũ khí nhìn thấy. Từ trên xuống: hộp thép thô, mép tấm không đều. Kích thước đề xuất khoảng 4.2 × 1.5 × 1.8 m (dài × rộng × cao; 0,8 × mẫu thật bán tải bọc thép chắp vá). Vũ khí nhìn thấy: car bomb (900 kg) 900 mm. Vạch màu phe trên nóc và hai hông; không dùng phù hiệu, cờ hay logo quốc gia thật. | F15: thắng màn mở khóa trong chiến dịch, hoặc mua sớm 750 xu | G15: Chương 2 | H15: 300 xu | I15: 3 | J15: 572 | K15: cấp 0 (Không giáp) | L15: 13 | M15: 30 | N15: 924 | O15: 770 | P15: 0 | Q15: 693 | R15: =IFERROR(O15/I15,"") | S15: =IFERROR(J15/I15,"") | T15: 78 | U15: 29 | V15: 128 | W15: 0 | X15: 25 | Y15: 4% | Z15: 10 | AA15: 0.96 | AB15: xe bom tự sát bọc thép ở Mosul 2016-17 ('Iron Coffin') — Xe bán tải bom tự sát bọc thép hàn chắp vá | AC15: giáp 0, giáp 1, giáp 2, giáp 3, giáp 4, công trình | AD15: súng bộ binh, súng máy hạng nặng, lửa, mảnh, pháo tự động, nổ mạnh, năng lượng, nổ lõm, pháo xe tăng | AE15: lao thẳng vào địch rồi tự nổ: 700 sát thương trong bán kính 7,5 m, một nửa lên tháp và công trình. Bị bắn hạ giữa đường thì nổ | AF15: Lao thẳng vào mục tiêu và tự nổ; Xe tăng (4); Tăng hạng nhẹ | AG15: car bomb (900 kg) 900 mm [Nổ mạnh, xuyên 4, bom hạng nặng (xe bom) nổ lan] 770/phát · hồi 1 s · tầm 3m · Mặt đất | AH15: • Giáp: trước 2 / hông 1 / sau 0 / nóc 0 • Máu, nổ lan: 800 máu · nổ lan 10 m | AI15: • Giáp: Tên "bọc thép" nhưng giáp 0; chỉ gây sát thương 4% thời gian vì chết trước khi tới. • Máu, nổ lan: Cần sống đủ tới mục tiêu; 900 kg thuốc nổ theo thang bom phải nổ rộng hơn bom 250 kg (8 m). | AJ15: Trung
A16: light_tank | B16: Tăng hạng nhẹ | C16: Xe tăng | D16: pháo 57 mm xuyên giáp vừa chạy vừa bắn, tầm ngắn nhất trong các xe tăng; súng đồng trục bắn máy bay khi mặt đất đã sạch. thắng xe nhẹ, trinh sát và xe phòng không; thua tăng nặng hơn, xe diệt tăng và trực thăng tấn công. | E16: Tăng nhẹ thân thấp dạng thuyền (lội nước), tháp nhỏ đặt lệch trước, nòng 57 mm dài và mảnh. Từ trên xuống: mũi vát như thuyền. Kích thước đề xuất khoảng 6.1 × 2.6 × 1.8 m (dài × rộng × cao; 0,8 × mẫu thật PT-76 / ZBD-05). Vũ khí nhìn thấy: S-60 57 mm (2A91), PKT / M240 7.62 mm. Vạch màu phe trên nóc và hai hông; không dùng phù hiệu, cờ hay logo quốc gia thật. | F16: có sẵn từ đầu | G16: Chương 1 | H16: 300 xu | I16: 3 | J16: 1012 | K16: 2/1/0/0 | L16: 9 | M16: 30 | N16: 54 | O16: 20 | P16: 12 | Q16: 23 | R16: =IFERROR(O16/I16,"") | S16: =IFERROR(J16/I16,"") | T16: 354 | U16: 90 | V16: 47 | W16: 2 | X16: 114 | Y16: 57% | Z16: 45 | AA16: 0.48 | AB16: PT-76, ZBD-05, AU-220M 57 mm (mô-đun không người lái) — Xe tăng nhẹ lội nước, mô-đun 57 mm đặt lệch về trước | AC16: giáp 0, giáp 1, giáp 2 | AD16: lửa, pháo tự động, nổ mạnh, năng lượng, đánh nóc, nổ lõm, pháo xe tăng | AE16: pháo 57 mm xuyên giáp vừa chạy vừa bắn, tầm ngắn nhất trong các xe tăng; súng đồng trục bắn máy bay khi mặt đất đã sạch. | AF16: Vừa chạy vừa bắn; Tăng phun lửa | AG16: S-60 57 mm (2A91) [Động năng, xuyên 2, đạn pháo động năng] 77/phát · hồi 2.53 s · tầm 28 m · Mặt đất PKT / M240 7.62 mm [Động năng, xuyên 0, đạn súng] 6/phát · băng 41 viên, 12 viên/s, thay 1.59 s · tầm 20 m · Tất cả | AH16: • Vũ khí: 57 mm: 77/phát · loạt 2 phát ở 2 phát/s · nghỉ 3,5 s · DPS duy trì ~35 • Tầm nhìn: 36 m | AI16: • Vũ khí: 57 mm: Pháo 57 mm tự động nhưng đang bắn như pháo nạp tay. • Tầm nhìn: Tăng nhẹ lội nước thường làm trinh sát cho tuyến. | AJ16: Thấp
A17: flame_tank | B17: Tăng phun lửa | C17: Xe tăng | D17: súng phun lửa phải áp sát mới bắn; luồng lửa lan ra cả nhóm, cực mạnh với xe nhẹ và lô cốt. thiêu rụi xe nhẹ, trinh sát và tháp canh khi áp sát; xe tăng và mọi thứ bắn xa hơn hạ nó trước khi tới nơi. | E17: Tăng thân T-55, tháp tròn, vòi phun ngắn to thay nòng pháo, 2 bình nhiên liệu bọc giáp trên sàn sau. Từ trên xuống: vòi ngắn, hai bình tròn đỏ sẫm ở đuôi. Kích thước đề xuất khoảng 7.2 × 2.6 × 1.9 m (dài × rộng × cao; 0,8 × mẫu thật TO-55 (khung T-55)). Vũ khí nhìn thấy: flamethrower, PKT / M240 7.62 mm. Vạch màu phe trên nóc và hai hông; không dùng phù hiệu, cờ hay logo quốc gia thật. | F17: thắng màn mở khóa trong chiến dịch, hoặc mua sớm 1.050 xu | G17: Chương 2 | H17: 300 xu | I17: 5 | J17: 1320 | K17: 3/2/1/1 | L17: 6.5 | M17: 26 | N17: 143 | O17: 40 | P17: 12 | Q17: 54 | R17: =IFERROR(O17/I17,"") | S17: =IFERROR(J17/I17,"") | T17: 587 | U17: 133 | V17: 53 | W17: 2 | X17: 105 | Y17: 48% | Z17: 50 | AA17: 0.66 | AB17: M67 Zippo, TO-55 · Flame Tank (Command & Conquer) — ước đoán: xe tăng phun lửa, thùng nhiên liệu bọc giáp sau tháp | AC17: giáp 0, giáp 1, giáp 2 | AD17: nổ mạnh, đánh nóc, nổ lõm, pháo xe tăng | AE17: súng phun lửa phải áp sát mới bắn; luồng lửa lan ra cả nhóm, cực mạnh với xe nhẹ và lô cốt. | AF17: Vừa chạy vừa bắn; Xe tăng rùa | AG17: flamethrower [Lửa, xuyên 1, lửa nổ lan] 24/phát · hồi 0.25 s · tầm 13 m · Mặt đất PKT / M240 7.62 mm [Động năng, xuyên 0, đạn súng] 6/phát · băng 41 viên, 12 viên/s, thay 1.59 s · tầm 20 m · Tất cả | AH17: • Vũ khí: súng phun lửa: sát thương −10% lên xe nhẹ; giữ giá 5 CP | AI17: • Vũ khí: súng phun lửa: Mạnh nhất theo CP khi đánh gần xe nhẹ; nhưng yếu với tăng và công sự nên giữ giá. | AJ17: Thấp
A20: rocket_technical | B20: Bán tải rốc-két | C20: Pháo binh | D20: dừng lại rồi phóng một loạt tám rốc-két khá tản mát tới 48 m; hết sáu loạt phải đứng yên nạp lại. Có thêm súng máy. phá tháp canh và cụm địch với giá rẻ; chết trước gần như mọi khẩu súng với tới nó. | E20: Bán tải dân sự, giàn rốc-két 12 ống nhỏ trên thùng sau. Từ trên xuống: lưới ống tròn nhỏ ở thùng sau. Kích thước đề xuất khoảng 4.2 × 1.4 × 1.6 m (dài × rộng × cao; 0,8 × mẫu thật Toyota Hilux + Type 63). Vũ khí nhìn thấy: Type 63 107 mm, M2 Browning 12.7 mm. Vạch màu phe trên nóc và hai hông; không dùng phù hiệu, cờ hay logo quốc gia thật. | F20: thắng màn mở khóa trong chiến dịch, hoặc mua sớm 750 xu | G20: Chương 1 | H20: 300 xu | I20: 3 | J20: 506 | K20: cấp 0 (Không giáp) | L20: 13 | M20: 30 | N20: 71 | O20: 38 | P20: 16 | Q20: 35 | R20: =IFERROR(O20/I20,"") | S20: =IFERROR(J20/I20,"") | T20: 204 | U20: 184 | V20: 322 | W20: 2 | X20: 38 | Y20: 48% | Z20: 51 | AA20: 0.56 | AB20: Toyota Hilux 'technical', Type 63 107 mm — Xe bán tải dân sự gắn giàn rốc-két 12 ống | AC20: giáp 0, giáp 1, giáp 2, công trình | AD20: súng bộ binh, súng máy hạng nặng, lửa, mảnh, pháo tự động, nổ mạnh, năng lượng, nổ lõm, pháo xe tăng | AE20: dừng lại rồi phóng một loạt tám rốc-két khá tản mát tới 48 m; hết sáu loạt phải đứng yên nạp lại. Có thêm súng máy. | AF20: Dừng lại mới bắn, từ 12-48 m; cần ta nhìn thấy mục tiêu (tự nó hoặc quân bạn); Hết đạn thì nạp lại tại chỗ, hoặc tới Xe tiếp đạn hay về nhà khi nhanh hơn; Xe súng cối | AG20: Type 63 107 mm [Nổ mạnh, xuyên 2, rốc-két đánh nóc] nổ lan/phát · 50 · tầm loạt 5, hồi 5.1 s · 48 m (tối thiểu 12) M2 Browning 12.7 mm [Động năng, xuyên 1, đạn súng (cỡ lớn)] 10/phát · băng 28 viên, 9 viên/s, thay 1.94 s · tầm 13 m · Tất cả | AH20: Giữ. | AI20: Giá trị thực chiến nằm trong khoảng mục tiêu (hiệu quả 0.56 × trung vị vai trò). | AJ20: Thấp
